Workbook

Sheet Performances by Week
E1: Status: | F1: Updated 9/29 | H1: Denotes Piazza | I1: Update all fields in Blue each week | J1: We expect 50% of Single Sales 1 Week Prior | K1: 85%+ occupancy | V1: 100%+ of Target
K2: 70-85% occupancy | V2: 90-99% of Target
G3: Week # | K3: <70% occupancy | V3: <90% of Target
D4: TICKET SALES REPORT as of 9/29/2025 | G4: 5 | I4: TOTAL SALES (Singles + Subs) | S4: Single Tickets | AB4: Subscription Tickets | AF4: Hall Data | AI4: Audience Data | AL4: Revenue last week | AM4: Increase over week
A5: Wk # | B5: # Weeks Until Perf | C5: Perf. Week (Mon) | D5: Performance | G5: Performance Date(s) | H5: Performance Type | I5: % OCC Target | J5: Actual OCC SOLD | K5: Actual Total Tickets Sold | L5: Total Actual Revenue | M5: TOTAL BUDGET | N5: Actual - Budget | O5: Projected Total OCC at Performance | P5: Projected Total Tickets Sold | Q5: Projected Total Revenue | R5: Projected- Budget | S5: Actual Single Tickets Sold | T5: Maximum Single Ticket Capacity | U5: Target Single Tickets for % OCC Target | V5: Projected Single Tickets | W5: Projected Single Tickets vs % OCC Target | X5: Actual Revenue | Y5: BUDGET | Z5: Actual/ Budget % | AA5: Projected/ Budget % | AB5: Actual Sub Tickets Sold | AC5: Actual Revenue | AD5: BUDGET | AE5: Actual vs Budget % | AF5: Max CAP | AG5: Single Ticket ATP | AH5: # New HH | AI5: # Ret HH | AJ5: # Total HH
A6: 1 | B6: =A6-$G$4 -> -4 | C6: 45901 | D6: 26 Morgan Freeman's Symphonic Blues | G6: 45902.833 | H6: Specials | I6: 0.85 | J6: =K6/AF6 -> 0.89093702 | K6: =S6+AB6 -> 1160 | L6: =X6+AC6 -> 137698 | M6: =Y6+AD6 -> 153473 | N6: =L6-M6 -> -15775 | O6: =IF(P6="Too early",P6,P6/AF6) -> #N/A | P6: =IF(V6="Too early",V6,V6+AB6) -> #N/A | Q6: =AC6+V6*AG6 -> #N/A | R6: =IF(V6="Too early",V6,Q6-M6) -> #N/A | S6: 1160 | T6: =AF6-AB6 -> 1302 | U6: =(AF6-AB6)*I6 -> 1106.7 | V6: =IF(B6<11,MIN((S6/VLOOKUP(B6,'Sales Pacing'!$A$23:$E$36,2)),T6),"Too early") -> #N/A | W6: =IF(V6="Too early","Too early",V6/U6) -> #N/A | X6: 137698 | Y6: 153473 | Z6: =IF(X6>0,X6/Y6,"") -> 0.89721319 | AA6: =IF($V6="Too early",V6,V6*AG6/Y6) -> #N/A | AD6: 0 | AE6: =IF(AC6>0,AC6/AD6,"") | AF6: 1302 | AG6: =X6/S6 -> 118.70517 | AH6: 228 | AI6: 295 | AJ6: 523 | AK6: 137698 | AL6: =L6-AK6 -> 0
A7: 1 | B7: =A7-$G$4 -> -4 | C7: 45901 | D7: 26 Morgan Freeman's Symphonic Blues | G7: 45903.833 | H7: Specials | I7: 0.85 | J7: =K7/AF7 -> 0.87480799 | K7: =S7+AB7 -> 1139 | L7: =X7+AC7 -> 134386 | M7: =Y7+AD7 -> 153473 | N7: =L7-M7 -> -19087 | O7: =IF(P7="Too early",P7,P7/AF7) -> #N/A | P7: =IF(V7="Too early",V7,V7+AB7) -> #N/A | Q7: =AC7+V7*AG7 -> #N/A | R7: =IF(V7="Too early",V7,Q7-M7) -> #N/A | S7: 1139 | T7: =AF7-AB7 -> 1302 | U7: =(AF7-AB7)*I7 -> 1106.7 | V7: =IF(B7<11,MIN((S7/VLOOKUP(B7,'Sales Pacing'!$A$23:$E$36,2)),T7),"Too early") -> #N/A | W7: =IF(V7="Too early","Too early",V7/U7) -> #N/A | X7: 134386 | Y7: 153473 | Z7: =IF(X7>0,X7/Y7,"") -> 0.87563285 | AA7: =IF($V7="Too early",V7,V7*AG7/Y7) -> #N/A | AD7: 0 | AE7: =IF(AC7>0,AC7/AD7,"") | AF7: 1302 | AG7: =X7/S7 -> 117.98595 | AH7: 227 | AI7: 289 | AJ7: 516 | AK7: 134386 | AL7: =L7-AK7 -> 0
A8: 1 | B8: =A8-$G$4 -> -4 | C8: 45901 | D8: 26 La nuit sombre | G8: 45905.833 | H8: Specials | I8: 0.85 | J8: =K8/AF8 -> 1.165 | K8: =S8+AB8 -> 699 | L8: =X8+AC8 -> 20005 | M8: =Y8+AD8 -> 15000 | N8: =L8-M8 -> 5005 | O8: =IF(P8="Too early",P8,P8/AF8) -> #N/A | P8: =IF(V8="Too early",V8,V8+AB8) -> #N/A | Q8: =AC8+V8*AG8 -> #N/A | R8: =IF(V8="Too early",V8,Q8-M8) -> #N/A | S8: 699 | T8: =AF8-AB8 -> 600 | U8: =(AF8-AB8)*I8 -> 510 | V8: =IF(B8<11,MIN((S8/VLOOKUP(B8,'Sales Pacing'!$A$23:$E$36,2)),T8),"Too early") -> #N/A | W8: =IF(V8="Too early","Too early",V8/U8) -> #N/A | X8: 20005 | Y8: 15000 | Z8: =IF(X8>0,X8/Y8,"") -> 1.3336667 | AA8: =IF($V8="Too early",V8,V8*AG8/Y8) -> #N/A | AD8: 0 | AE8: =IF(AC8>0,AC8/AD8,"") | AF8: 600 | AG8: =X8/S8 -> 28.619456 | AH8: 86 | AI8: 209 | AJ8: 295 | AK8: 20005 | AL8: =L8-AK8 -> 0
A9: 2 | B9: =A9-$G$4 -> -3 | C9: 45908 | D9: OPEN - Recording Week | J9: =K9/AF9 -> #DIV/0! | K9: =S9+AB9 -> 0 | P9: =IF(V9="Too early",V9,V9+AB9) -> #N/A | Q9: =AC9+V9*AG9 -> #N/A | R9: =IF(V9="Too early",V9,Q9-M9) -> #N/A | T9: =AF9-AB9 -> 0 | U9: =(AF9-AB9)*I9 -> 0 | V9: =IF(B9<11,MIN((S9/VLOOKUP(B9,'Sales Pacing'!$A$23:$E$36,2)),T9),"Too early") -> #N/A | Z9: =IF(X9>0,X9/Y9,"") | AE9: N/A
A10: 3 | B10: =A10-$G$4 -> -2 | C10: 45915 | D10: 26 PS1 Music of Journey | G10: 45919.833 | H10: Pops | I10: 0.85 | J10: =K10/AF10 -> 0.71069182 | K10: =S10+AB10 -> 1130 | L10: =X10+AC10 -> 75221.6 | M10: =Y10+AD10 -> 100666 | N10: =L10-M10 -> -25444.4 | O10: =IF(P10="Too early",P10,P10/AF10) -> #N/A | P10: =IF(V10="Too early",V10,V10+AB10) -> #N/A | Q10: =AC10+V10*AG10 -> #N/A | R10: =IF(V10="Too early",V10,Q10-M10) -> #N/A | S10: 515 | T10: =AF10-AB10 -> 975 | U10: =(AF10-AB10)*I10 -> 828.75 | V10: =IF(B10<11,MIN((S10/VLOOKUP(B10,'Sales Pacing'!$A$23:$E$36,2)),T10),"Too early") -> #N/A | W10: =IF(V10="Too early","Too early",V10/U10) -> #N/A | X10: 29853 | Y10: 59333 | Z10: =IF(X10>0,X10/Y10,"") -> 0.50314328 | AA10: =IF($V10="Too early",V10,V10*AG10/Y10) -> #N/A | AB10: 615 | AC10: 45368.6 | AD10: 41333 | AE10: =IF(AC10>0,AC10/AD10,"") -> 1.0976363 | AF10: 1590 | AG10: =X10/S10 -> 57.96699 | AH10: 67 | AI10: 416 | AJ10: 483 | AK10: 71854.6 | AL10: =L10-AK10 -> 3367
A11: 3 | B11: =A11-$G$4 -> -2 | C11: 45915 | D11: 26 PS1 Music of Journey | G11: 45920.833 | H11: Pops | I11: 0.85 | J11: =K11/AF11 -> 0.66918239 | K11: =S11+AB11 -> 1064 | L11: =X11+AC11 -> 73932.3 | M11: =Y11+AD11 -> 100667 | N11: =L11-M11 -> -26734.7 | O11: =IF(P11="Too early",P11,P11/AF11) -> #N/A | P11: =IF(V11="Too early",V11,V11+AB11) -> #N/A | Q11: =AC11+V11*AG11 -> #N/A | R11: =IF(V11="Too early",V11,Q11-M11) -> #N/A | S11: 550 | T11: =AF11-AB11 -> 1076 | U11: =(AF11-AB11)*I11 -> 914.6 | V11: =IF(B11<11,MIN((S11/VLOOKUP(B11,'Sales Pacing'!$A$23:$E$36,2)),T11),"Too early") -> #N/A | W11: =IF(V11="Too early","Too early",V11/U11) -> #N/A | X11: 35384 | Y11: 59333 | Z11: =IF(X11>0,X11/Y11,"") -> 0.5963629 | AA11: =IF($V11="Too early",V11,V11*AG11/Y11) -> #N/A | AB11: 514 | AC11: 38548.3 | AD11: 41334 | AE11: =IF(AC11>0,AC11/AD11,"") -> 0.93260512 | AF11: 1590 | AG11: =X11/S11 -> 64.334545 | AH11: 78 | AI11: 376 | AJ11: 454 | AK11: 70013.3 | AL11: =L11-AK11 -> 3919
A12: 3 | B12: =A12-$G$4 -> -2 | C12: 45915 | D12: 26 PS1 Music of Journey | G12: 45921.583 | H12: Pops | I12: 0.85 | J12: =K12/AF12 -> 0.6327044 | K12: =S12+AB12 -> 1006 | L12: =X12+AC12 -> 64333.8 | M12: =Y12+AD12 -> 100666 | N12: =L12-M12 -> -36332.2 | O12: =IF(P12="Too early",P12,P12/AF12) -> #N/A | P12: =IF(V12="Too early",V12,V12+AB12) -> #N/A | Q12: =AC12+V12*AG12 -> #N/A | R12: =IF(V12="Too early",V12,Q12-M12) -> #N/A | S12: 662 | T12: =AF12-AB12 -> 1246 | U12: =(AF12-AB12)*I12 -> 1059.1 | V12: =IF(B12<11,MIN((S12/VLOOKUP(B12,'Sales Pacing'!$A$23:$E$36,2)),T12),"Too early") -> #N/A | W12: =IF(V12="Too early","Too early",V12/U12) -> #N/A | X12: 40186 | Y12: 59333 | Z12: =IF(X12>0,X12/Y12,"") -> 0.67729594 | AA12: =IF($V12="Too early",V12,V12*AG12/Y12) -> #N/A | AB12: 344 | AC12: 24147.8 | AD12: 41333 | AE12: =IF(AC12>0,AC12/AD12,"") -> 0.58422568 | AF12: 1590 | AG12: =X12/S12 -> 60.703927 | AH12: 74 | AI12: 286 | AJ12: 360 | AK12: 56072.3 | AL12: =L12-AK12 -> 8261.5
A13: 4 | B13: =A13-$G$4 -> -1 | C13: 45922 | D13: 26 FS1 The Orchestra Games | G13: 45928.583 | H13: Family | I13: 0.5 | J13: =K13/AF13 -> 0.53993856 | K13: =S13+AB13 -> 703 | L13: =X13+AC13 -> 22183 | M13: =Y13+AD13 -> 19500 | N13: =L13-M13 -> 2683 | O13: =IF(P13="Too early",P13,P13/AF13) -> #N/A | P13: =IF(V13="Too early",V13,V13+AB13) -> #N/A | Q13: =IF(V13="Too early",V13,AC13+V13*AG13) -> #N/A | R13: =IF(V13="Too early",V13,Q13-M13) -> #N/A | S13: 507 | T13: =AF13-AB13 -> 1106 | U13: =(AF13-AB13)*I13 -> 553 | V13: =IF(B13<11,MIN((S13/VLOOKUP(B13,'Sales Pacing'!$A$23:$E$36,2)),T13),"Too early") -> #N/A | W13: =IF(V13="Too early","Too early",V13/U13) -> #N/A | X13: 16966 | Y13: 10000 | Z13: =IF(X13>0,X13/Y13,"") -> 1.6966 | AA13: =IF($V13="Too early",V13,V13*AG13/Y13) -> #N/A | AB13: 196 | AC13: 5217 | AD13: 9500 | AE13: =IF(AC13>0,AC13/AD13,"") -> 0.54915789 | AF13: 1302 | AG13: =X13/S13 -> 33.463511 | AH13: 21 | AI13: 104 | AJ13: 125 | AK13: 12684 | AL13: =L13-AK13 -> 9499
A14: 5 | B14: =A14-$G$4 -> 0 | C14: 45929 | D14: OPEN - was Chicken Fried | J14: =K14/AF14 -> #DIV/0! | Q14: =IF(V14="Too early",V14,AC14+V14*AG14) -> 0 | R14: =IF(V14="Too early",V14,Q14-M14) -> 0 | T14: =AF14-AB14 -> 0 | U14: =(AF14-AB14)*I14 -> 0 | V14: =IF(B14<11,MIN((S14/VLOOKUP(B14,'Sales Pacing'!$A$23:$E$36,2)),T14),"Too early") -> 0
A15: 6 | B15: =A15-$G$4 -> 1 | C15: 45936 | D15: 26 CS01 Appalachian Spring | G15: 45940.833 | H15: Classical | I15: 0.85 | J15: =K15/AF15 -> 0.58269365 | K15: =S15+AB15 -> 835 | L15: =X15+AC15 -> 50877 | M15: =Y15+AD15 -> 49999 | N15: =L15-M15 -> 878 | O15: =IF(P15="Too early",P15,P15/AF15) -> 0.74078323 | P15: =IF(V15="Too early",V15,V15+AB15) -> 1061.5424 | Q15: =IF(V15="Too early",V15,AC15+V15*AG15) -> 62630.797 | R15: =IF(V15="Too early",V15,Q15-M15) -> 12631.797 | S15: 326 | T15: =AF15-AB15 -> 924 | U15: =(AF15-AB15)*I15 -> 785.4 | V15: =IF(B15<11,MIN((S15/VLOOKUP(B15,'Sales Pacing'!$A$23:$E$36,2)),T15),"Too early") -> 552.54237 | W15: =IF(V15="Too early","Too early",V15/U15) -> 0.70351715 | X15: 16914 | Y15: 16666 | Z15: =IF(X15>0,X15/Y15,"") -> 1.0148806 | AA15: =IF($V15="Too early",V15,V15*AG15/Y15) -> 1.7201366 | AB15: 509 | AC15: 33963 | AD15: 33333 | AE15: =IF(AC15>0,AC15/AD15,"") -> 1.0189002 | AF15: 1433 | AG15: =X15/S15 -> 51.883436 | AH15: 13 | AI15: 370 | AJ15: 383 | AK15: 47640 | AL15: =L15-AK15 -> 3237
A16: 6 | B16: =A16-$G$4 -> 1 | C16: 45936 | D16: 26 CS01 Appalachian Spring | G16: 45941.833 | H16: Classical | I16: 0.85 | J16: =K16/AF16 -> 0.64549895 | K16: =S16+AB16 -> 925 | L16: =X16+AC16 -> 58900.1 | M16: =Y16+AD16 -> 49999 | N16: =L16-M16 -> 8901.1 | O16: =IF(P16="Too early",P16,P16/AF16) -> 0.81765172 | P16: =IF(V16="Too early",V16,V16+AB16) -> 1171.6949 | Q16: =IF(V16="Too early",V16,AC16+V16*AG16) -> 73004.1 | R16: =IF(V16="Too early",V16,Q16-M16) -> 23005.1 | S16: 355 | T16: =AF16-AB16 -> 863 | U16: =(AF16-AB16)*I16 -> 733.55 | V16: =IF(B16<11,MIN((S16/VLOOKUP(B16,'Sales Pacing'!$A$23:$E$36,2)),T16),"Too early") -> 601.69492 | W16: =IF(V16="Too early","Too early",V16/U16) -> 0.82025072 | X16: 20296 | Y16: 16666 | Z16: =IF(X16>0,X16/Y16,"") -> 1.2178087 | AA16: =IF($V16="Too early",V16,V16*AG16/Y16) -> 2.0640826 | AB16: 570 | AC16: 38604.1 | AD16: 33333 | AE16: =IF(AC16>0,AC16/AD16,"") -> 1.1581346 | AF16: 1433 | AG16: =X16/S16 -> 57.171831 | AH16: 21 | AI16: 386 | AJ16: 407 | AK16: 55614.1 | AL16: =L16-AK16 -> 3286
A17: 6 | B17: =A17-$G$4 -> 1 | C17: 45936 | D17: 26 CS01 Appalachian Spring | G17: 45942.583 | H17: Classical | I17: 0.85 | J17: =K17/AF17 -> 0.71807397 | K17: =S17+AB17 -> 1029 | L17: =X17+AC17 -> 63564.6 | M17: =Y17+AD17 -> 50000 | N17: =L17-M17 -> 13564.6 | O17: =IF(P17="Too early",P17,P17/AF17) -> 0.92659704 | P17: =IF(V17="Too early",V17,V17+AB17) -> 1327.8136 | Q17: =IF(V17="Too early",V17,AC17+V17*AG17) -> 80868.685 | R17: =IF(V17="Too early",V17,Q17-M17) -> 30868.685 | S17: 430 | T17: =AF17-AB17 -> 834 | U17: =(AF17-AB17)*I17 -> 708.9 | V17: =IF(B17<11,MIN((S17/VLOOKUP(B17,'Sales Pacing'!$A$23:$E$36,2)),T17),"Too early") -> 728.81356 | W17: =IF(V17="Too early","Too early",V17/U17) -> 1.0280908 | X17: 24901 | Y17: 16666 | Z17: =IF(X17>0,X17/Y17,"") -> 1.4941198 | AA17: =IF($V17="Too early",V17,V17*AG17/Y17) -> 2.5324064 | AB17: 599 | AC17: 38663.6 | AD17: 33334 | AE17: =IF(AC17>0,AC17/AD17,"") -> 1.1598848 | AF17: 1433 | AG17: =X17/S17 -> 57.909302 | AH17: 17 | AI17: 455 | AJ17: 472 | AK17: 57932.6 | AL17: =L17-AK17 -> 5632
A18: 7 | B18: =A18-$G$4 -> 2 | C18: 45943 | D18: 26 Top Gun: Maverick in Concert | G18: 45947.792 | H18: Specials/Film | I18: 0.85 | J18: =K18/AF18 -> 0.65284178 | K18: =S18+AB18 -> 850 | L18: =X18+AC18 -> 63699 | M18: =Y18+AD18 -> 103497 | N18: =L18-M18 -> -39798 | O18: =IF(P18="Too early",P18,P18/AF18) -> 1 | P18: =IF(V18="Too early",V18,V18+AB18) -> 1302 | Q18: =IF(V18="Too early",V18,AC18+V18*AG18) -> 97571.88 | R18: =IF(V18="Too early",V18,Q18-M18) -> -5925.12 | S18: 850 | T18: =AF18-AB18 -> 1302 | U18: =(AF18-AB18)*I18 -> 1106.7 | V18: =IF(B18<11,MIN((S18/VLOOKUP(B18,'Sales Pacing'!$A$23:$E$36,2)),T18),"Too early") -> 1302 | W18: =IF(V18="Too early","Too early",V18/U18) -> 1.1764706 | X18: 63699 | Y18: 103497 | Z18: =IF(X18>0,X18/Y18,"") -> 0.61546711 | AA18: =IF($V18="Too early",V18,V18*AG18/Y18) -> 0.9427508 | AE18: =IF(AC18>0,AC18/AD18,"") | AF18: 1302 | AG18: =X18/S18 -> 74.94 | AH18: 51 | AI18: 179 | AJ18: 230 | AK18: 48750 | AL18: =L18-AK18 -> 14949
A19: 7 | B19: =A19-$G$4 -> 2 | C19: 45943 | D19: 26 Top Gun: Maverick in Concert | G19: 45948.792 | H19: Specials/Film | I19: 0.85 | J19: =K19/AF19 -> 0.75729647 | K19: =S19+AB19 -> 986 | L19: =X19+AC19 -> 73005 | M19: =Y19+AD19 -> 103497 | N19: =L19-M19 -> -30492 | O19: =IF(P19="Too early",P19,P19/AF19) -> 1 | P19: =IF(V19="Too early",V19,V19+AB19) -> 1302 | Q19: =IF(V19="Too early",V19,AC19+V19*AG19) -> 96402.14 | R19: =IF(V19="Too early",V19,Q19-M19) -> -7094.86 | S19: 986 | T19: =AF19-AB19 -> 1302 | U19: =(AF19-AB19)*I19 -> 1106.7 | V19: =IF(B19<11,MIN((S19/VLOOKUP(B19,'Sales Pacing'!$A$23:$E$36,2)),T19),"Too early") -> 1302 | W19: =IF(V19="Too early","Too early",V19/U19) -> 1.1764706 | X19: 73005 | Y19: 103497 | Z19: =IF(X19>0,X19/Y19,"") -> 0.70538276 | AA19: =IF($V19="Too early",V19,V19*AG19/Y19) -> 0.93144864 | AE19: =IF(AC19>0,AC19/AD19,"") | AF19: 1302 | AG19: =X19/S19 -> 74.041582 | AH19: 74 | AI19: 184 | AJ19: 258 | AK19: 60628 | AL19: =L19-AK19 -> 12377
A20: 7 | B20: =A20-$G$4 -> 2 | C20: 45943 | D20: 26 Top Gun: Maverick in Concert | G20: 45949.583 | H20: Specials/Film | I20: 0.85 | J20: =K20/AF20 -> 0.55913978 | K20: =S20+AB20 -> 728 | L20: =X20+AC20 -> 55135 | M20: =Y20+AD20 -> 103496 | N20: =L20-M20 -> -48361 | O20: =IF(P20="Too early",P20,P20/AF20) -> 1 | P20: =IF(V20="Too early",V20,V20+AB20) -> 1302 | Q20: =IF(V20="Too early",V20,AC20+V20*AG20) -> 98606.827 | R20: =IF(V20="Too early",V20,Q20-M20) -> -4889.1731 | S20: 728 | T20: =AF20-AB20 -> 1302 | U20: =(AF20-AB20)*I20 -> 1106.7 | V20: =IF(B20<11,MIN((S20/VLOOKUP(B20,'Sales Pacing'!$A$23:$E$36,2)),T20),"Too early") -> 1302 | W20: =IF(V20="Too early","Too early",V20/U20) -> 1.1764706 | X20: 55135 | Y20: 103496 | Z20: =IF(X20>0,X20/Y20,"") -> 0.5327259 | AA20: =IF($V20="Too early",V20,V20*AG20/Y20) -> 0.95275979 | AE20: =IF(AC20>0,AC20/AD20,"") | AF20: 1302 | AG20: =X20/S20 -> 75.73489 | AH20: 38 | AI20: 149 | AJ20: 187 | AK20: 44494 | AL20: =L20-AK20 -> 10641
A21: 8 | B21: =A21-$G$4 -> 3 | C21: 45950 | D21: 26 The Lodger | G21: 45952.792 | H21: Specials/Film | I21: 0.5 | J21: =K21/AF21 -> 0.19662058 | K21: =S21+AB21 -> 256 | L21: =X21+AC21 -> 13747 | M21: =Y21+AD21 -> 50000 | N21: =L21-M21 -> -36253 | O21: =IF(P21="Too early",P21,P21/AF21) -> 0.50415534 | P21: =IF(V21="Too early",V21,V21+AB21) -> 656.41026 | Q21: =IF(V21="Too early",V21,AC21+V21*AG21) -> 35248.718 | R21: =IF(V21="Too early",V21,Q21-M21) -> -14751.282 | S21: 256 | T21: =AF21-AB21 -> 1302 | U21: =(AF21-AB21)*I21 -> 651 | V21: =IF(B21<11,MIN((S21/VLOOKUP(B21,'Sales Pacing'!$A$23:$E$36,2)),T21),"Too early") -> 656.41026 | W21: =IF(V21="Too early","Too early",V21/U21) -> 1.0083107 | X21: 13747 | Y21: 50000 | Z21: =IF(X21>0,X21/Y21,"") -> 0.27494 | AA21: =IF($V21="Too early",V21,V21*AG21/Y21) -> 0.70497436 | AE21: =IF(AC21>0,AC21/AD21,"") | AF21: 1302 | AG21: =X21/S21 -> 53.699219 | AH21: 5 | AI21: 78 | AJ21: 83 | AK21: 10588 | AL21: =L21-AK21 -> 3159
A22: 8 | B22: =A22-$G$4 -> 3 | C22: 45950 | D22: 26 PS2 90s Mixtape | G22: 45954.833 | H22: Pops | I22: 0.85 | J22: =K22/AF22 -> 0.53647799 | K22: =S22+AB22 -> 853 | L22: =X22+AC22 -> 60234.9 | M22: =Y22+AD22 -> 92333 | N22: =L22-M22 -> -32098.1 | O22: =IF(P22="Too early",P22,P22/AF22) -> 0.67911627 | P22: =IF(V22="Too early",V22,V22+AB22) -> 1079.7949 | Q22: =IF(V22="Too early",V22,AC22+V22*AG22) -> 74241.438 | R22: =IF(V22="Too early",V22,Q22-M22) -> -18091.562 | S22: 145 | T22: =AF22-AB22 -> 882 | U22: =(AF22-AB22)*I22 -> 749.7 | V22: =IF(B22<11,MIN((S22/VLOOKUP(B22,'Sales Pacing'!$A$23:$E$36,2)),T22),"Too early") -> 371.79487 | W22: =IF(V22="Too early","Too early",V22/U22) -> 0.49592487 | X22: 8955 | Y22: 53333 | Z22: =IF(X22>0,X22/Y22,"") -> 0.1679073 | AA22: =IF($V22="Too early",V22,V22*AG22/Y22) -> 0.43053154 | AB22: 708 | AC22: 51279.9 | AD22: 39000 | AE22: =IF(AC22>0,AC22/AD22,"") -> 1.3148692 | AF22: 1590 | AG22: =X22/S22 -> 61.758621 | AH22: 7 | AI22: 350 | AJ22: 357 | AK22: 57609.1 | AL22: =L22-AK22 -> 2625.8
A23: 8 | B23: =A23-$G$4 -> 3 | C23: 45950 | D23: 26 PS2 90s Mixtape | G23: 45955.833 | H23: Pops | I23: 0.85 | J23: =K23/AF23 -> 0.51509434 | K23: =S23+AB23 -> 819 | L23: =X23+AC23 -> 56647.8 | M23: =Y23+AD23 -> 92333 | N23: =L23-M23 -> -35685.2 | O23: =IF(P23="Too early",P23,P23/AF23) -> 0.70199968 | P23: =IF(V23="Too early",V23,V23+AB23) -> 1116.1795 | Q23: =IF(V23="Too early",V23,AC23+V23*AG23) -> 74614.646 | R23: =IF(V23="Too early",V23,Q23-M23) -> -17718.354 | S23: 190 | T23: =AF23-AB23 -> 961 | U23: =(AF23-AB23)*I23 -> 816.85 | V23: =IF(B23<11,MIN((S23/VLOOKUP(B23,'Sales Pacing'!$A$23:$E$36,2)),T23),"Too early") -> 487.17949 | W23: =IF(V23="Too early","Too early",V23/U23) -> 0.59641242 | X23: 11487 | Y23: 53333 | Z23: =IF(X23>0,X23/Y23,"") -> 0.2153826 | AA23: =IF($V23="Too early",V23,V23*AG23/Y23) -> 0.55226307 | AB23: 629 | AC23: 45160.8 | AD23: 39000 | AE23: =IF(AC23>0,AC23/AD23,"") -> 1.1579692 | AF23: 1590 | AG23: =X23/S23 -> 60.457895 | AH23: 11 | AI23: 320 | AJ23: 311 | AK23: 52382.8 | AL23: =L23-AK23 -> 4265
A24: 8 | B24: =A24-$G$4 -> 3 | C24: 45950 | D24: 26 PS2 90s Mixtape | G24: 45956.583 | H24: Pops | I24: 0.85 | J24: =K24/AF24 -> 0.3427673 | K24: =S24+AB24 -> 545 | L24: =X24+AC24 -> 36579.5 | M24: =Y24+AD24 -> 92333 | N24: =L24-M24 -> -55753.5 | O24: =IF(P24="Too early",P24,P24/AF24) -> 0.5031124 | P24: =IF(V24="Too early",V24,V24+AB24) -> 799.94872 | Q24: =IF(V24="Too early",V24,AC24+V24*AG24) -> 53285.679 | R24: =IF(V24="Too early",V24,Q24-M24) -> -39047.321 | S24: 163 | T24: =AF24-AB24 -> 1208 | U24: =(AF24-AB24)*I24 -> 1026.8 | V24: =IF(B24<11,MIN((S24/VLOOKUP(B24,'Sales Pacing'!$A$23:$E$36,2)),T24),"Too early") -> 417.94872 | W24: =IF(V24="Too early","Too early",V24/U24) -> 0.40704004 | X24: 10681 | Y24: 53333 | Z24: =IF(X24>0,X24/Y24,"") -> 0.20027 | AA24: =IF($V24="Too early",V24,V24*AG24/Y24) -> 0.51351282 | AB24: 382 | AC24: 25898.5 | AD24: 39000 | AE24: =IF(AC24>0,AC24/AD24,"") -> 0.6640641 | AF24: 1590 | AG24: =X24/S24 -> 65.527607 | AH24: 6 | AI24: 209 | AJ24: 203 | AK24: 31818.5 | AL24: =L24-AK24 -> 4761
A25: 9 | B25: =A25-$G$4 -> 4 | C25: 45957 | D25: 26 On-Stage 1 George Li | G25: 45959.833 | H25: On Stage | I25: 0.85 | J25: =K25/AF25 -> 0.29 | K25: =S25+AB25 -> 29 | L25: =X25+AC25 -> 3360 | M25: 11200 | N25: =L25-M25 -> -7840 | O25: =IF(P25="Too early",P25,P25/AF25) -> 0.87878788 | P25: =IF(V25="Too early",V25,V25+AB25) -> 87.878788 | Q25: =IF(V25="Too early",V25,AC25+V25*AG25) -> 10181.818 | R25: =IF(V25="Too early",V25,Q25-M25) -> -1018.1818 | S25: 29 | T25: =AF25-AB25 -> 100 | U25: =(AF25-AB25)*I25 -> 85 | V25: =IF(B25<11,MIN((S25/VLOOKUP(B25,'Sales Pacing'!$A$23:$E$36,2)),T25),"Too early") -> 87.878788 | W25: =IF(V25="Too early","Too early",V25/U25) -> 1.0338681 | X25: 3360 | Y25: 11200 | Z25: =IF(X25>0,X25/Y25,"") -> 0.3 | AA25: =IF($V25="Too early",V25,V25*AG25/Y25) -> 0.90909091 | AE25: =IF(AC25>0,AC25/AD25,"") | AF25: 100 | AG25: =X25/S25 -> 115.86207 | AH25: 0 | AI25: 11 | AJ25: 11 | AK25: 2800 | AL25: =L25-AK25 -> 560
A26: 9 | B26: =A26-$G$4 -> 4 | C26: 45957 | D26: 26 CS02 Rachmaninoff Cele Pt 1 | G26: 45961.833 | H26: Classical | I26: 0.5 | J26: =K26/AF26 -> 0.33914864 | K26: =S26+AB26 -> 486 | L26: =X26+AC26 -> 31409 | M26: =Y26+AD26 -> 52000 | N26: =L26-M26 -> -20591 | O26: =IF(P26="Too early",P26,P26/AF26) -> 0.54317072 | P26: =IF(V26="Too early",V26,V26+AB26) -> 778.36364 | Q26: =IF(V26="Too early",V26,AC26+V26*AG26) -> 46855.545 | R26: =IF(V26="Too early",V26,Q26-M26) -> -5144.4545 | S26: 144 | T26: =AF26-AB26 -> 1091 | U26: =(AF26-AB26)*I26 -> 545.5 | V26: =IF(B26<11,MIN((S26/VLOOKUP(B26,'Sales Pacing'!$A$23:$E$36,2)),T26),"Too early") -> 436.36364 | W26: =IF(V26="Too early","Too early",V26/U26) -> 0.79993334 | X26: 7608 | Y26: 22000 | Z26: =IF(X26>0,X26/Y26,"") -> 0.34581818 | AA26: =IF($V26="Too early",V26,V26*AG26/Y26) -> 1.0479339 | AB26: 342 | AC26: 23801 | AD26: 30000 | AE26: =IF(AC26>0,AC26/AD26,"") -> 0.79336667 | AF26: 1433 | AG26: =X26/S26 -> 52.833333 | AH26: 10 | AI26: 222 | AJ26: 232 | AK26: 30757 | AL26: =L26-AK26 -> 652
A27: 9 | B27: =A27-$G$4 -> 4 | C27: 45957 | D27: 26 CS02 Rachmaninoff Cele Pt 1 | G27: 45962.833 | H27: Classical | I27: 0.85 | J27: =K27/AF27 -> 0.70062805 | K27: =S27+AB27 -> 1004 | L27: =X27+AC27 -> 61737 | M27: =Y27+AD27 -> 86500 | N27: =L27-M27 -> -24763 | O27: =IF(P27="Too early",P27,P27/AF27) -> 1 | P27: =IF(V27="Too early",V27,V27+AB27) -> 1433 | Q27: =IF(V27="Too early",V27,AC27+V27*AG27) -> 86030.327 | R27: =IF(V27="Too early",V27,Q27-M27) -> -469.67265 | S27: 446 | T27: =AF27-AB27 -> 875 | U27: =(AF27-AB27)*I27 -> 743.75 | V27: =IF(B27<11,MIN((S27/VLOOKUP(B27,'Sales Pacing'!$A$23:$E$36,2)),T27),"Too early") -> 875 | W27: =IF(V27="Too early","Too early",V27/U27) -> 1.1764706 | X27: 25256 | Y27: 31500 | Z27: =IF(X27>0,X27/Y27,"") -> 0.80177778 | AA27: =IF($V27="Too early",V27,V27*AG27/Y27) -> 1.5729945 | AB27: 558 | AC27: 36481 | AD27: 55000 | AE27: =IF(AC27>0,AC27/AD27,"") -> 0.66329091 | AF27: 1433 | AG27: =X27/S27 -> 56.627803 | AH27: 26 | AI27: 397 | AJ27: 423 | AK27: 57693 | AL27: =L27-AK27 -> 4044
A28: 9 | B28: =A28-$G$4 -> 4 | C28: 45957 | D28: 26 CS02 Rachmaninoff Cele Pt 1 | G28: 45963.583 | H28: Classical | I28: 0.85 | J28: =K28/AF28 -> 0.60711793 | K28: =S28+AB28 -> 870 | L28: =X28+AC28 -> 54318.1 | M28: =Y28+AD28 -> 86500 | N28: =L28-M28 -> -32181.9 | O28: =IF(P28="Too early",P28,P28/AF28) -> 1 | P28: =IF(V28="Too early",V28,V28+AB28) -> 1433 | Q28: =IF(V28="Too early",V28,AC28+V28*AG28) -> 87343.789 | R28: =IF(V28="Too early",V28,Q28-M28) -> 843.78932 | S28: 309 | T28: =AF28-AB28 -> 872 | U28: =(AF28-AB28)*I28 -> 741.2 | V28: =IF(B28<11,MIN((S28/VLOOKUP(B28,'Sales Pacing'!$A$23:$E$36,2)),T28),"Too early") -> 872 | W28: =IF(V28="Too early","Too early",V28/U28) -> 1.1764706 | X28: 18126 | Y28: 31500 | Z28: =IF(X28>0,X28/Y28,"") -> 0.57542857 | AA28: =IF($V28="Too early",V28,V28*AG28/Y28) -> 1.6238632 | AB28: 561 | AC28: 36192.1 | AD28: 55000 | AE28: =IF(AC28>0,AC28/AD28,"") -> 0.65803818 | AF28: 1433 | AG28: =X28/S28 -> 58.660194 | AH28: 17 | AI28: 407 | AJ28: 424 | AK28: 51432.1 | AL28: =L28-AK28 -> 2886
A29: 10 | B29: =A29-$G$4 -> 5 | C29: 45964 | D29: 26 FS2 Carnival of the Animals | G29: 45970.583 | H29: Family | I29: 0.5 | J29: =K29/AF29 -> 0.36615385 | K29: =S29+AB29 -> 476 | L29: =X29+AC29 -> 11664 | M29: =Y29+AD29 -> 19500 | N29: =L29-M29 -> -7836 | O29: =IF(P29="Too early",P29,P29/AF29) -> 0.66948718 | P29: =IF(V29="Too early",V29,V29+AB29) -> 870.33333 | Q29: =IF(V29="Too early",V29,AC29+V29*AG29) -> 22929.333 | R29: =IF(V29="Too early",V29,Q29-M29) -> 3429.3333 | S29: 169 | T29: =AF29-AB29 -> 993 | U29: =(AF29-AB29)*I29 -> 496.5 | V29: =IF(B29<11,MIN((S29/VLOOKUP(B29,'Sales Pacing'!$A$23:$E$36,2)),T29),"Too early") -> 563.33333 | W29: =IF(V29="Too early","Too early",V29/U29) -> 1.1346089 | X29: 4828 | Y29: 10000 | Z29: =IF(X29>0,X29/Y29,"") -> 0.4828 | AA29: =IF($V29="Too early",V29,V29*AG29/Y29) -> 1.6093333 | AB29: 307 | AC29: 6836 | AD29: 9500 | AE29: =IF(AC29>0,AC29/AD29,"") -> 0.71957895 | AF29: 1300 | AG29: =X29/S29 -> 28.568047 | AH29: 9 | AI29: 103 | AJ29: 112 | AK29: 10703 | AL29: =L29-AK29 -> 961
A30: 11 | B30: =A30-$G$4 -> 6 | C30: 45971 | D30: OPEN | J30: =K30/AF30 -> #DIV/0! | K30: =S30+AB30 -> 0 | L30: =X30+AC30 -> 0 | M30: =Y30+AD30 -> 0 | P30: =IF(V30="Too early",V30,V30+AB30) -> 0 | Q30: =IF(V30="Too early",V30,AC30+V30*AG30) -> #DIV/0! | R30: =IF(V30="Too early",V30,Q30-M30) -> #DIV/0! | T30: =AF30-AB30 -> 0 | U30: =(AF30-AB30)*I30 -> 0 | V30: =IF(B30<7,(S30/VLOOKUP(B30,'Sales Pacing'!$A$23:$E$36,2)),"Too early") -> 0 | Z30: =IF(X30>0,X30/Y30,"") | AE30: N/A | AG30: =X30/S30 -> #DIV/0! | AK30: 0
A31: 12 | B31: =A31-$G$4 -> 7 | C31: 45978 | D31: 26 CS03 Matthias and Mahler 7 | G31: 45982.833 | H31: Classical | I31: 0.5 | J31: =K31/AF31 -> 0.27798742 | K31: =S31+AB31 -> 442 | L31: =X31+AC31 -> 29152 | M31: =Y31+AD31 -> 40000 | N31: =L31-M31 -> -10848 | O31: =IF(P31="Too early",P31,P31/AF31) -> 0.42735849 | P31: =IF(V31="Too early",V31,V31+AB31) -> 679.5 | Q31: =IF(V31="Too early",V31,AC31+V31*AG31) -> 41198 | R31: =IF(V31="Too early",V31,Q31-M31) -> 1198 | S31: 75 | T31: =AF31-AB31 -> 1223 | U31: =(AF31-AB31)*I31 -> 611.5 | V31: =IF(B31<11,MIN((S31/VLOOKUP(B31,'Sales Pacing'!$A$23:$E$36,2)),T31),"Too early") -> 312.5 | W31: =IF(V31="Too early","Too early",V31/U31) -> 0.51103843 | X31: 3804 | Y31: 15000 | Z31: =IF(X31>0,X31/Y31,"") -> 0.2536 | AA31: =IF($V31="Too early",V31,V31*AG31/Y31) -> 1.0566667 | AB31: 367 | AC31: 25348 | AD31: 25000 | AE31: =IF(AC31>0,AC31/AD31,"") -> 1.01392 | AF31: 1590 | AG31: =X31/S31 -> 50.72 | AH31: 1 | AI31: 221 | AJ31: 222 | AK31: 29114 | AL31: =L31-AK31 -> 38
A32: 12 | B32: =A32-$G$4 -> 7 | C32: 45978 | D32: 26 CS03 Matthias and Mahler 7 | G32: 45983.833 | H32: Classical | I32: 0.85 | J32: =K32/AF32 -> 0.45660377 | K32: =S32+AB32 -> 726 | L32: =X32+AC32 -> 48098.9 | M32: =Y32+AD32 -> 66500 | N32: =L32-M32 -> -18401.1 | O32: =IF(P32="Too early",P32,P32/AF32) -> 0.74140461 | P32: =IF(V32="Too early",V32,V32+AB32) -> 1178.8333 | Q32: =IF(V32="Too early",V32,AC32+V32*AG32) -> 74673.567 | R32: =IF(V32="Too early",V32,Q32-M32) -> 8173.5667 | S32: 143 | T32: =AF32-AB32 -> 1007 | U32: =(AF32-AB32)*I32 -> 855.95 | V32: =IF(B32<11,MIN((S32/VLOOKUP(B32,'Sales Pacing'!$A$23:$E$36,2)),T32),"Too early") -> 595.83333 | W32: =IF(V32="Too early","Too early",V32/U32) -> 0.69610764 | X32: 8392 | Y32: 11500 | Z32: =IF(X32>0,X32/Y32,"") -> 0.72973913 | AA32: =IF($V32="Too early",V32,V32*AG32/Y32) -> 3.0405797 | AB32: 583 | AC32: 39706.9 | AD32: 55000 | AE32: =IF(AC32>0,AC32/AD32,"") -> 0.72194364 | AF32: 1590 | AG32: =X32/S32 -> 58.685315 | AH32: 4 | AI32: 347 | AJ32: 351 | AK32: 47477.9 | AL32: =L32-AK32 -> 621
A33: 12 | B33: =A33-$G$4 -> 7 | C33: 45978 | D33: 26 CS03 Matthias and Mahler 7 | G33: 45984.583 | H33: Classical | I33: 0.85 | J33: =K33/AF33 -> 0.44968553 | K33: =S33+AB33 -> 715 | L33: =X33+AC33 -> 46572.2 | M33: =Y33+AD33 -> 66500 | N33: =L33-M33 -> -19927.8 | O33: =IF(P33="Too early",P33,P33/AF33) -> 0.63490566 | P33: =IF(V33="Too early",V33,V33+AB33) -> 1009.5 | Q33: =IF(V33="Too early",V33,AC33+V33*AG33) -> 66892.7 | R33: =IF(V33="Too early",V33,Q33-M33) -> 392.7 | S33: 93 | T33: =AF33-AB33 -> 968 | U33: =(AF33-AB33)*I33 -> 822.8 | V33: =IF(B33<11,MIN((S33/VLOOKUP(B33,'Sales Pacing'!$A$23:$E$36,2)),T33),"Too early") -> 387.5 | W33: =IF(V33="Too early","Too early",V33/U33) -> 0.47095284 | X33: 6417 | Y33: 11500 | Z33: =IF(X33>0,X33/Y33,"") -> 0.558 | AA33: =IF($V33="Too early",V33,V33*AG33/Y33) -> 2.325 | AB33: 622 | AC33: 40155.2 | AD33: 55000 | AE33: =IF(AC33>0,AC33/AD33,"") -> 0.73009455 | AF33: 1590 | AG33: =X33/S33 -> 69 | AH33: 3 | AI33: 391 | AJ33: 394 | AK33: 46613.2 | AL33: =L33-AK33 -> -41
A34: 13 | B34: =A34-$G$4 -> 8 | C34: 45985 | D34: 26 Elf™ in Concert | G34: 45989.792 | H34: Specials/Film | I34: 0.85 | J34: =K34/AF34 -> 0.26036866 | K34: =S34+AB34 -> 339 | L34: =X34+AC34 -> 23191 | M34: =Y34+AD34 -> 107500 | N34: =L34-M34 -> -84309 | O34: =IF(P34="Too early",P34,P34/AF34) -> 1 | P34: =IF(V34="Too early",V34,V34+AB34) -> 1302 | Q34: =IF(V34="Too early",V34,AC34+V34*AG34) -> 89069.858 | R34: =IF(V34="Too early",V34,Q34-M34) -> -18430.142 | S34: 339 | T34: =AF34-AB34 -> 1302 | U34: =(AF34-AB34)*I34 -> 1106.7 | V34: =IF(B34<11,MIN((S34/VLOOKUP(B34,'Sales Pacing'!$A$23:$E$36,2)),T34),"Too early") -> 1302 | W34: =IF(V34="Too early","Too early",V34/U34) -> 1.1764706 | X34: 23191 | Y34: 107500 | Z34: =IF(X34>0,X34/Y34,"") -> 0.21573023 | AA34: =IF($V34="Too early",V34,V34*AG34/Y34) -> 0.82855682 | AE34: =IF(AC34>0,AC34/AD34,"") | AF34: 1302 | AG34: =X34/S34 -> 68.410029 | AH34: 17 | AI34: 45 | AJ34: 62 | AK34: 20977.6 | AL34: =L34-AK34 -> 2213.4
A35: 13 | B35: =A35-$G$4 -> 8 | C35: 45985 | D35: 26 Elf™ in Concert | G35: 45990.542 | H35: Specials/Film | I35: 0.85 | J35: =K35/AF35 -> 0.31797235 | K35: =S35+AB35 -> 414 | L35: =X35+AC35 -> 27757 | M35: =Y35+AD35 -> 107500 | N35: =L35-M35 -> -79743 | O35: =IF(P35="Too early",P35,P35/AF35) -> 1 | P35: =IF(V35="Too early",V35,V35+AB35) -> 1302 | Q35: =IF(V35="Too early",V35,AC35+V35*AG35) -> 87293.754 | R35: =IF(V35="Too early",V35,Q35-M35) -> -20206.246 | S35: 414 | T35: =AF35-AB35 -> 1302 | U35: =(AF35-AB35)*I35 -> 1106.7 | V35: =IF(B35<11,MIN((S35/VLOOKUP(B35,'Sales Pacing'!$A$23:$E$36,2)),T35),"Too early") -> 1302 | W35: =IF(V35="Too early","Too early",V35/U35) -> 1.1764706 | X35: 27757 | Y35: 107500 | Z35: =IF(X35>0,X35/Y35,"") -> 0.25820465 | AA35: =IF($V35="Too early",V35,V35*AG35/Y35) -> 0.81203492 | AE35: =IF(AC35>0,AC35/AD35,"") | AF35: 1302 | AG35: =X35/S35 -> 67.045894 | AH35: 22 | AI35: 53 | AJ35: 75 | AK35: 24414.6 | AL35: =L35-AK35 -> 3342.4
A36: 13 | B36: =A36-$G$4 -> 8 | C36: 45985 | D36: 26 Elf™ in Concert | G36: 45990.792 | H36: Specials/Film | I36: 0.85 | J36: =K36/AF36 -> 0.25268817 | K36: =S36+AB36 -> 329 | L36: =X36+AC36 -> 22388 | M36: =Y36+AD36 -> 107500 | N36: =L36-M36 -> -85112 | O36: =IF(P36="Too early",P36,P36/AF36) -> 1 | P36: =IF(V36="Too early",V36,V36+AB36) -> 1302 | Q36: =IF(V36="Too early",V36,AC36+V36*AG36) -> 88599.319 | R36: =IF(V36="Too early",V36,Q36-M36) -> -18900.681 | S36: 329 | T36: =AF36-AB36 -> 1302 | U36: =(AF36-AB36)*I36 -> 1106.7 | V36: =IF(B36<11,MIN((S36/VLOOKUP(B36,'Sales Pacing'!$A$23:$E$36,2)),T36),"Too early") -> 1302 | W36: =IF(V36="Too early","Too early",V36/U36) -> 1.1764706 | X36: 22388 | Y36: 107500 | Z36: =IF(X36>0,X36/Y36,"") -> 0.20826047 | AA36: =IF($V36="Too early",V36,V36*AG36/Y36) -> 0.82417971 | AE36: =IF(AC36>0,AC36/AD36,"") | AF36: 1302 | AG36: =X36/S36 -> 68.048632 | AH36: 12 | AI36: 56 | AJ36: 68 | AK36: 19000 | AL36: =L36-AK36 -> 3388
A37: 13 | B37: =A37-$G$4 -> 8 | C37: 45985 | D37: 26 Elf™ in Concert | G37: 45991.583 | H37: Specials/Film | I37: 0.85 | J37: =K37/AF37 -> 0.41628264 | K37: =S37+AB37 -> 542 | L37: =X37+AC37 -> 37521 | M37: =Y37+AD37 -> 107500 | N37: =L37-M37 -> -69979 | O37: =IF(P37="Too early",P37,P37/AF37) -> 1 | P37: =IF(V37="Too early",V37,V37+AB37) -> 1302 | Q37: =IF(V37="Too early",V37,AC37+V37*AG37) -> 90133.472 | R37: =IF(V37="Too early",V37,Q37-M37) -> -17366.528 | S37: 542 | T37: =AF37-AB37 -> 1302 | U37: =(AF37-AB37)*I37 -> 1106.7 | V37: =IF(B37<11,MIN((S37/VLOOKUP(B37,'Sales Pacing'!$A$23:$E$36,2)),T37),"Too early") -> 1302 | W37: =IF(V37="Too early","Too early",V37/U37) -> 1.1764706 | X37: 37521 | Y37: 107500 | Z37: =IF(X37>0,X37/Y37,"") -> 0.34903256 | AA37: =IF($V37="Too early",V37,V37*AG37/Y37) -> 0.83845091 | AE37: =IF(AC37>0,AC37/AD37,"") | AF37: 1302 | AG37: =X37/S37 -> 69.226937 | AH37: 21 | AI37: 88 | AJ37: 109 | AK37: 34569.6 | AL37: =L37-AK37 -> 2951.4
A38: 14 | B38: =A38-$G$4 -> 9 | C38: 45992 | D38: 26 Handel's Messiah | G38: 45996.792 | H38: Holiday | I38: 0.85 | J38: =K38/AF38 -> 0.26029309 | K38: =S38+AB38 -> 373 | L38: =X38+AC38 -> 19843.5 | M38: =Y38+AD38 -> 78333 | N38: =L38-M38 -> -58489.5 | O38: =IF(P38="Too early",P38,P38/AF38) -> 1 | P38: =IF(V38="Too early",V38,V38+AB38) -> 1433 | Q38: =IF(V38="Too early",V38,AC38+V38*AG38) -> 76235.216 | R38: =IF(V38="Too early",V38,Q38-M38) -> -2097.7842 | S38: 373 | T38: =AF38-AB38 -> 1433 | U38: =(AF38-AB38)*I38 -> 1218.05 | V38: =IF(B38<11,MIN((S38/VLOOKUP(B38,'Sales Pacing'!$A$23:$E$36,2)),T38),"Too early") -> 1433 | W38: =IF(V38="Too early","Too early",V38/U38) -> 1.1764706 | X38: 19843.5 | Y38: 78333 | Z38: =IF(X38>0,X38/Y38,"") -> 0.25332235 | AA38: =IF($V38="Too early",V38,V38*AG38/Y38) -> 0.97321966 | AE38: =IF(AC38>0,AC38/AD38,"") | AF38: 1433 | AG38: =X38/S38 -> 53.199732 | AH38: 19 | AI38: 86 | AJ38: 105 | AK38: 18853.5 | AL38: =L38-AK38 -> 990
A39: 14 | B39: =A39-$G$4 -> 9 | C39: 45992 | D39: 26 Handel's Messiah | G39: 45997.792 | H39: Holiday | I39: 0.85 | J39: =K39/AF39 -> 0.26378227 | K39: =S39+AB39 -> 378 | L39: =X39+AC39 -> 22606.5 | M39: =Y39+AD39 -> 78334 | N39: =L39-M39 -> -55727.5 | O39: =IF(P39="Too early",P39,P39/AF39) -> 1 | P39: =IF(V39="Too early",V39,V39+AB39) -> 1433 | Q39: =IF(V39="Too early",V39,AC39+V39*AG39) -> 85701.361 | R39: =IF(V39="Too early",V39,Q39-M39) -> 7367.3611 | S39: 378 | T39: =AF39-AB39 -> 1433 | U39: =(AF39-AB39)*I39 -> 1218.05 | V39: =IF(B39<11,MIN((S39/VLOOKUP(B39,'Sales Pacing'!$A$23:$E$36,2)),T39),"Too early") -> 1433 | W39: =IF(V39="Too early","Too early",V39/U39) -> 1.1764706 | X39: 22606.5 | Y39: 78334 | Z39: =IF(X39>0,X39/Y39,"") -> 0.28859116 | AA39: =IF($V39="Too early",V39,V39*AG39/Y39) -> 1.0940506 | AE39: =IF(AC39>0,AC39/AD39,"") | AF39: 1433 | AG39: =X39/S39 -> 59.805556 | AH39: 20 | AI39: 95 | AJ39: 115 | AK39: 22001.5 | AL39: =L39-AK39 -> 605
A40: 14 | B40: =A40-$G$4 -> 9 | C40: 45992 | D40: 26 Handel's Messiah | G40: 45998.583 | H40: Holiday | I40: 0.85 | J40: =K40/AF40 -> 0.2965806 | K40: =S40+AB40 -> 425 | L40: =X40+AC40 -> 22602.5 | M40: =Y40+AD40 -> 78333 | N40: =L40-M40 -> -55730.5 | O40: =IF(P40="Too early",P40,P40/AF40) -> 1 | P40: =IF(V40="Too early",V40,V40+AB40) -> 1433 | Q40: =IF(V40="Too early",V40,AC40+V40*AG40) -> 76210.312 | R40: =IF(V40="Too early",V40,Q40-M40) -> -2122.6882 | S40: 425 | T40: =AF40-AB40 -> 1433 | U40: =(AF40-AB40)*I40 -> 1218.05 | V40: =IF(B40<11,MIN((S40/VLOOKUP(B40,'Sales Pacing'!$A$23:$E$36,2)),T40),"Too early") -> 1433 | W40: =IF(V40="Too early","Too early",V40/U40) -> 1.1764706 | X40: 22602.5 | Y40: 78333 | Z40: =IF(X40>0,X40/Y40,"") -> 0.28854378 | AA40: =IF($V40="Too early",V40,V40*AG40/Y40) -> 0.97290174 | AE40: =IF(AC40>0,AC40/AD40,"") | AF40: 1433 | AG40: =X40/S40 -> 53.182353 | AH40: 26 | AI40: 105 | AJ40: 131 | AK40: 21652.5 | AL40: =L40-AK40 -> 950
...

Sheet PS1 Journey
B1: # weeks out
A2: Single Tickets | B2: 5 | C2: 4 | D2: 3 | E2: 2 | F2: 1 | G2: 0 | L2: Estimates Only | P2: Historical Data
A3: PS1 Journey | B3: 45880 | C3: 45887 | D3: 45894 | E3: 45901 | F3: 45908 | G3: 45915 | H3: # Single Tickets to sell out 100% | I3: Projected OCC% | K3: # Weeks Until Performance | L3: 10 | M3: 9 | N3: 8 | O3: 7 | P3: 6 | Q3: 5 | R3: 4 | S3: 3 | T3: 2 | U3: 1 | V3: 0
A4: 9/19/2025 Sales (Fri) | B4: 60 | C4: 160 | D4: 205 | E4: 262 | F4: 311 | G4: 390 | H4: ='Performances by Week'!AF10-'Performances by Week'!AB10 -> 975 | I4: ='Performances by Week'!O10 -> #N/A | K4: Classical | L4: 0.15 | M4: 0.18 | N4: 0.21 | O4: 0.24 | P4: 0.27 | Q4: 0.3 | R4: 0.33 | S4: 0.39 | T4: 0.46 | U4: 0.59 | V4: 1
A5: 9/20/2025 Sales (Sat) | B5: 63 | C5: 206 | D5: 250 | E5: 294 | F5: 360 | G5: 422 | H5: ='Performances by Week'!AF11-'Performances by Week'!AB11 -> 1076 | I5: ='Performances by Week'!O11 -> #N/A | K5: Pops | L5: 0.15 | M5: 0.18 | N5: 0.21 | O5: 0.24 | P5: 0.27 | Q5: 0.3 | R5: 0.33 | S5: 0.39 | T5: 0.46 | U5: 0.59 | V5: 1
A6: 9/21/2025 Sales (Sun) | B6: 57 | C6: 219 | D6: 296 | E6: 322 | F6: 444 | G6: 516 | H6: ='Performances by Week'!AF12-'Performances by Week'!AB12 -> 1246 | I6: ='Performances by Week'!O12 -> #N/A | K6: Specials | L6: 0.15 | M6: 0.18 | N6: 0.21 | O6: 0.24 | P6: 0.27 | Q6: 0.3 | R6: 0.33 | S6: 0.39 | T6: 0.46 | U6: 0.59 | V6: 1
A7: Pace for 85% OCC | B7: =$H$7*$H$10*Q5 -> 280.245 | C7: =$H$7*$H$10*R5 -> 308.2695 | D7: =$H$7*$H$10*S5 -> 364.3185 | E7: =$H$7*$H$10*T5 -> 429.709 | F7: =$H$7*$H$10*U5 -> 551.1485 | G7: =$H$7*$H$10*V5 -> 934.15 | H7: =AVERAGE(H4:H6) -> 1099 | K7: Other | L7: 0.15 | M7: 0.18 | N7: 0.21 | O7: 0.24 | P7: 0.27 | Q7: 0.3 | R7: 0.33 | S7: 0.39 | T7: 0.46 | U7: 0.59 | V7: 1
A8: Avg/Show vs Target Pace: | B8: =IF(B4>0,AVERAGE(B4:B6)-B7,"TBD") -> -220.245 | C8: =IF(C4>0,AVERAGE(C4:C6)-C7,"TBD") -> -113.2695 | D8: =IF(D4>0,AVERAGE(D4:D6)-D7,"TBD") -> -113.98517 | E8: =IF(E4>0,AVERAGE(E4:E6)-E7,"TBD") -> -137.04233 | F8: =IF(F4>0,AVERAGE(F4:F6)-F7,"TBD") -> -179.48183 | G8: =IF(G4>0,AVERAGE(G4:G6)-G7,"TBD") -> -491.48333
H9: OCC Target
H10: 0.85
I12: Final Sales: | J12: Sep 15-21 Sales | K12: % of Total
I13: 511 | J13: =I13-G4 -> 121 | K13: =J13/I13 -> 0.23679061
I14: 550 | J14: =I14-G5 -> 128 | K14: =J14/I14 -> 0.23272727
I15: 662 | J15: =I15-G6 -> 146 | K15: =J15/I15 -> 0.22054381

Sheet CS1 Appalachian
B1: # weeks out
A2: Single Tickets | B2: 8 | C2: 7 | D2: 6 | E2: 5 | F2: 4 | G2: 3 | H2: 2 | I2: 1 | J2: 0 | O2: Estimates Only | S2: Historical Data
A3: CS1 Appalachian | B3: 45880 | C3: 45887 | D3: 45894 | E3: 45901 | F3: 45908 | G3: 45915 | H3: 45922 | I3: 45929 | J3: 45936 | K3: # Single Tickets to sell out 100% | L3: Projected OCC% | N3: # Weeks Until Performance | O3: 10 | P3: 9 | Q3: 8 | R3: 7 | S3: 6 | T3: 5 | U3: 4 | V3: 3 | W3: 2 | X3: 1 | Y3: 0
A4: 10/10/2025 Sales (Fri) | B4: 60 | C4: 100 | D4: 106 | E4: 135 | F4: 193 | G4: 212 | H4: 238 | I4: 326 | K4: =1433-543 -> 890 | L4: ='Performances by Week'!O15 -> 0.74078323 | N4: Classical | O4: 0.15 | P4: 0.18 | Q4: 0.21 | R4: 0.24 | S4: 0.27 | T4: 0.3 | U4: 0.33 | V4: 0.39 | W4: 0.46 | X4: 0.59 | Y4: 1
A5: 10/11/2025 Sales (Sat) | B5: 63 | C5: 98 | D5: 115 | E5: 130 | F5: 179 | G5: 225 | H5: 258 | I5: 355 | K5: =1433-581 -> 852 | L5: ='Performances by Week'!O16 -> 0.81765172 | N5: Pops | O5: 0.15 | P5: 0.18 | Q5: 0.21 | R5: 0.24 | S5: 0.27 | T5: 0.3 | U5: 0.33 | V5: 0.39 | W5: 0.46 | X5: 0.59 | Y5: 1
A6: 10/12/2025 Sales (Sun) | B6: 57 | C6: 137 | D6: 154 | E6: 174 | F6: 239 | G6: 295 | H6: 328 | I6: 430 | K6: =1433-613 -> 820 | L6: ='Performances by Week'!O17 -> 0.92659704 | N6: Specials | O6: 0.15 | P6: 0.18 | Q6: 0.21 | R6: 0.24 | S6: 0.27 | T6: 0.3 | U6: 0.33 | V6: 0.39 | W6: 0.46 | X6: 0.59 | Y6: 1
A7: Pace for 85% OCC | B7: =$K$7*$K$10*Q4 -> 151.725 | C7: =$K$7*$K$10*R4 -> 173.4 | D7: =$K$7*$K$10*S4 -> 195.075 | E7: =$K$7*$K$10*T4 -> 216.75 | F7: =$K$7*$K$10*U4 -> 238.425 | G7: =$K$7*$K$10*V4 -> 281.775 | H7: =$K$7*$K$10*W4 -> 332.35 | I7: =$K$7*$K$10*X4 -> 426.275 | J7: =$K$7*$K$10*Y4 -> 722.5 | K7: 850 | N7: Other | O7: 0.15 | P7: 0.18 | Q7: 0.21 | R7: 0.24 | S7: 0.27 | T7: 0.3 | U7: 0.33 | V7: 0.39 | W7: 0.46 | X7: 0.59 | Y7: 1
A8: Avg/Show vs Target Pace: | B8: =IF(B4>0,AVERAGE(B4:B6)-B7,"TBD") -> -91.725 | C8: =IF(C4>0,AVERAGE(C4:C6)-C7,"TBD") -> -61.733333 | D8: =IF(D4>0,AVERAGE(D4:D6)-D7,"TBD") -> -70.075 | E8: =IF(E4>0,AVERAGE(E4:E6)-E7,"TBD") -> -70.416667 | F8: =IF(F4>0,AVERAGE(F4:F6)-F7,"TBD") -> -34.758333 | G8: =IF(G4>0,AVERAGE(G4:G6)-G7,"TBD") -> -37.775 | H8: =IF(H4>0,AVERAGE(H4:H6)-H7,"TBD") -> -57.683333 | I8: =IF(I4>0,AVERAGE(I4:I6)-I7,"TBD") -> -55.941667 | J8: =IF(J4>0,AVERAGE(J4:J6)-J7,"TBD") -> TBD
E9: =E7-D7 -> 21.675 | F9: =F7-E7 -> 21.675 | G9: =G7-F7 -> 43.35 | H9: =H7-G7 -> 50.575 | K9: OCC Target
K10: 0.85

Sheet PS2 90s Mixtape
B1: # Weeks Out | Q1: Estimates Only | U1: Historical Data
A2: Single Tickets | B2: 10 | C2: 9 | D2: 8 | E2: 7 | F2: 6 | G2: 5 | H2: 4 | I2: 3 | J2: 2 | K2: 1 | L2: 0 | P2: # Weeks Until Performance | Q2: 10 | R2: 9 | S2: 8 | T2: 7 | U2: 6 | V2: 5 | W2: 4 | X2: 3 | Y2: 2 | Z2: 1 | AA2: 0
A3: PS2 90s Mixtape (Name?) | B3: 45880 | C3: 45887 | D3: 45894 | E3: 45901 | F3: 45908 | G3: 45915 | H3: 45922 | I3: 45929 | J3: 45936 | K3: 45943 | L3: 45950 | M3: # Single Tickets to sell out 100% | N3: Projected OCC% | P3: Classical | Q3: 0.15 | R3: 0.18 | S3: 0.21 | T3: 0.24 | U3: 0.27 | V3: 0.3 | W3: 0.33 | X3: 0.39 | Y3: 0.46 | Z3: 0.59 | AA3: 1
A4: 10/24/2025 Sales (Fri) | B4: 60 | C4: 64 | D4: 68 | E4: 74 | F4: 80 | G4: 92 | H4: 145 | M4: ='Performances by Week'!AF22-'Performances by Week'!AB22 -> 882 | N4: ='Performances by Week'!O22 -> 0.67911627 | P4: Pops | Q4: 0.15 | R4: 0.18 | S4: 0.21 | T4: 0.24 | U4: 0.27 | V4: 0.3 | W4: 0.33 | X4: 0.39 | Y4: 0.46 | Z4: 0.59 | AA4: 1
A5: 10/25/2025 Sales (Sat) | B5: 63 | C5: 63 | D5: 73 | E5: 93 | F5: 106 | G5: 114 | H5: 190 | M5: ='Performances by Week'!AF23-'Performances by Week'!AB23 -> 961 | N5: ='Performances by Week'!O23 -> 0.70199968 | P5: Specials | Q5: 0.15 | R5: 0.18 | S5: 0.21 | T5: 0.24 | U5: 0.27 | V5: 0.3 | W5: 0.33 | X5: 0.39 | Y5: 0.46 | Z5: 0.59 | AA5: 1
A6: 10/26/2025 Sales (Sun) | B6: 57 | C6: 59 | D6: 66 | E6: 74 | F6: 76 | G6: 87 | H6: 163 | M6: ='Performances by Week'!AF24-'Performances by Week'!AB24 -> 1208 | N6: ='Performances by Week'!O24 -> 0.5031124 | P6: Other | Q6: 0.15 | R6: 0.18 | S6: 0.21 | T6: 0.24 | U6: 0.27 | V6: 0.3 | W6: 0.33 | X6: 0.39 | Y6: 0.46 | Z6: 0.59 | AA6: 1
A7: Pace for 85% OCC | B7: =$M$7*$M$10*Q4 -> 129.6675 | C7: =$M$7*$M$10*R4 -> 155.601 | D7: =$M$7*$M$10*S4 -> 181.5345 | E7: =$M$7*$M$10*T4 -> 207.468 | F7: =$M$7*$M$10*U4 -> 233.4015 | G7: =$M$7*$M$10*V4 -> 259.335 | H7: =$M$7*$M$10*W4 -> 285.2685 | I7: =$M$7*$M$10*X4 -> 337.1355 | ... L7: =$M$7*$M$10*AA4 -> 864.45 | M7: =AVERAGE(M4:M6) -> 1017
A8: Avg/Show vs Target Pace: | B8: =IF(B4>0,AVERAGE(B4:B6)-B7,"TBD") -> -69.6675 | C8: =IF(C4>0,AVERAGE(C4:C6)-C7,"TBD") -> -93.601 | D8: =IF(D4>0,AVERAGE(D4:D6)-D7,"TBD") -> -112.5345 | E8: =IF(E4>0,AVERAGE(E4:E6)-E7,"TBD") -> -127.13467 | F8: =IF(F4>0,AVERAGE(F4:F6)-F7,"TBD") -> -146.06817 | G8: =IF(G4>0,AVERAGE(G4:G6)-G7,"TBD") -> -161.66833 | H8: =IF(H4>0,AVERAGE(H4:H6)-H7,"TBD") -> -119.2685 | I8: =IF(I4>0,AVERAGE(I4:I6)-I7,"TBD") -> TBD | ... L8: =IF(L4>0,AVERAGE(L4:L6)-L7,"TBD") -> TBD
M9: OCC Target
M10: 0.85

Sheet MFSB
A1: Single Tickets | B1: 3 | C1: 2 | D1: 1 | E1: 0 | L1: Single Tickets
A2: MFSB | B2: 45880 | C2: 45887 | D2: 45894 | E2: 45901 | F2: # Single Tickets to sell out 100% | K2: # Weeks Until Performance | L2: Classical | M2: Pops | N2: Specials | O2: Other
A3: 9/2/2025 Sales (Tue) | B3: 754 | C3: 915 | D3: 1013 | E3: 1096 | G3: =E3/F5 -> 0.84178187
A4: 9/3/2025 Sales (Wed) | B4: 651 | C4: 826 | D4: 926 | E4: 1027 | G4: =E4/F5 -> 0.78878648 | K4: 0 | L4: 1 | M4: 1 | N4: 1 | O4: 1
A5: Pace for 85% OCC | B5: =$F$5*$G$5*N7 -> 431.613 | C5: =$F$5*$G$5*N6 -> 509.082 | D5: =$F$5*$G$5*N5 -> 652.953 | E5: =$F$5*$G$5*N4 -> 1106.7 | F5: 1302 | G5: 0.85 | K5: 1 | L5: 0.59 | M5: 0.59 | N5: 0.59 | O5: 0.59
K6: 2 | L6: 0.46 | M6: 0.46 | N6: 0.46 | O6: 0.46
K7: 3 | L7: 0.39 | M7: 0.39 | N7: 0.39 | O7: 0.39
K8: 4 | L8: 0.33 | M8: 0.33 | N8: 0.33 | O8: 0.33
K9: 5 | L9: 0.3 | M9: 0.3 | N9: 0.3 | O9: 0.3
K10: 6 | L10: 0.27 | M10: 0.27 | N10: 0.27 | O10: 0.27

Sheet CS2 Rachmaninoff
D1: # weeks out
A2: Single Tickets | B2: 10 | C2: 9 | D2: 8 | E2: 7 | F2: 6 | G2: 5 | H2: 4 | I2: 3 | J2: 2 | K2: 1 | L2: 0 | Q2: Estimates Only | U2: Historical Data
A3: CS2 Rachmaninoff | B3: 45887 | C3: 45894 | D3: 45901 | E3: 45908 | F3: 45915 | G3: 45922 | H3: 45929 | I3: 45936 | J3: 45943 | K3: 45950 | L3: 45957 | M3: # Single Tickets to sell out 100% | N3: Projected OCC% | P3: # Weeks Until Performance | Q3: 10 | R3: 9 | S3: 8 | T3: 7 | U3: 6 | V3: 5 | W3: 4 | X3: 3 | Y3: 2 | Z3: 1 | AA3: 0
A4: 10/31/2025 Sales (Fri, Piazza) | B4: 87 | C4: 93 | D4: 102 | E4: 106 | F4: 111 | G4: 124 | H4: 144 | M4: ='Performances by Week'!AF26-'Performances by Week'!AB26 -> 1091 | N4: ='Performances by Week'!O26 -> 0.54317072 | P4: Classical | Q4: 0.15 | R4: 0.18 | S4: 0.21 | T4: 0.24 | U4: 0.27 | V4: 0.3 | W4: 0.33 | X4: 0.39 | Y4: 0.46 | Z4: 0.59 | AA4: 1
A5: 11/01/2025 Sales (Sat) | B5: 192 | C5: 209 | D5: 256 | E5: 310 | F5: 340 | G5: 382 | H5: 446 | M5: ='Performances by Week'!AF27-'Performances by Week'!AB27 -> 875 | N5: ='Performances by Week'!O27 -> 1 | P5: Pops | Q5: 0.15 | R5: 0.18 | S5: 0.21 | T5: 0.24 | U5: 0.27 | V5: 0.3 | W5: 0.33 | X5: 0.39 | Y5: 0.46 | Z5: 0.59 | AA5: 1
A6: 11/02/2025 Sales (Sun) | B6: 138 | C6: 165 | D6: 187 | E6: 219 | F6: 232 | G6: 267 | H6: 309 | M6: ='Performances by Week'!AF28-'Performances by Week'!AB28 -> 872 | N6: ='Performances by Week'!O28 -> 1 | P6: Specials | Q6: 0.15 | R6: 0.18 | S6: 0.21 | T6: 0.24 | U6: 0.27 | V6: 0.3 | W6: 0.33 | X6: 0.39 | Y6: 0.46 | Z6: 0.59 | AA6: 1
A7: Pace for 85% OCC | B7: =$M$7*$M$10*Q4 -> 120.615 | C7: =$M$7*$M$10*R4 -> 144.738 | D7: =$M$7*$M$10*S4 -> 168.861 | E7: =$M$7*$M$10*T4 -> 192.984 | F7: =$M$7*$M$10*U4 -> 217.107 | G7: =$M$7*$M$10*V4 -> 241.23 | H7: =$M$7*$M$10*W4 -> 265.353 | I7: =$M$7*$M$10*X4 -> 313.599 | ... L7: =$M$7*$M$10*AA4 -> 804.1 | M7: =AVERAGE(M4:M6) -> 946 | P7: Other | Q7: 0.15 | R7: 0.18 | S7: 0.21 | T7: 0.24 | U7: 0.27 | V7: 0.3 | W7: 0.33 | X7: 0.39 | Y7: 0.46 | Z7: 0.59 | AA7: 1
A8: Avg/Show vs Target Pace: | B8: =IF(B4>0,AVERAGE(B4:B6)-B7,"TBD") -> 18.385 | C8: =IF(C4>0,AVERAGE(C4:C6)-C7,"TBD") -> 10.928667 | D8: =IF(D4>0,AVERAGE(D4:D6)-D7,"TBD") -> 12.805667 | E8: =IF(E4>0,AVERAGE(E4:E6)-E7,"TBD") -> 18.682667 | F8: =IF(F4>0,AVERAGE(F4:F6)-F7,"TBD") -> 10.559667 | G8: =IF(G4>0,AVERAGE(G4:G6)-G7,"TBD") -> 16.436667 | H8: =IF(H4>0,AVERAGE(H4:H6)-H7,"TBD") -> 34.313667 | I8: =IF(I4>0,AVERAGE(I4:I6)-I7,"TBD") -> TBD | ... L8: =IF(L4>0,AVERAGE(L4:L6)-L7,"TBD") -> TBD
M9: OCC Target
M10: 0.85

Sheet CS3 Mahler
D1: # weeks out
A2: Single Tickets | B2: 10 | C2: 9 | D2: 8 | E2: 7 | F2: 6 | G2: 5 | H2: 4 | I2: 3 | J2: 2 | K2: 1 | L2: 0 | Q2: Estimates Only | U2: Historical Data
A3: CS3 Mahler | B3: 45908 | C3: 45915 | D3: 45922 | E3: 45929 | F3: 45936 | G3: 45943 | H3: 45950 | I3: 45957 | J3: 45964 | K3: 45971 | L3: 45978 | M3: # Single Tickets to sell out 100% | N3: Projected OCC% | P3: # Weeks Until Performance | Q3: 10 | R3: 9 | S3: 8 | T3: 7 | U3: 6 | V3: 5 | W3: 4 | X3: 3 | Y3: 2 | Z3: 1 | AA3: 0
A4: 11/21/2025 Sales (Fri, Piazza) | B4: 55 | C4: 60 | D4: 66 | E4: 75 | M4: ='Performances by Week'!AF31-'Performances by Week'!AB31 -> 1223 | N4: ='Performances by Week'!O31 -> 0.42735849 | P4: Classical | Q4: 0.15 | R4: 0.18 | S4: 0.21 | T4: 0.24 | U4: 0.27 | V4: 0.3 | W4: 0.33 | X4: 0.39 | Y4: 0.46 | Z4: 0.59 | AA4: 1
A5: 11/22/2025 Sales (Sat) | B5: 95 | C5: 110 | D5: 114 | E5: 143 | M5: ='Performances by Week'!AF32-'Performances by Week'!AB32 -> 1007 | N5: ='Performances by Week'!O32 -> 0.74140461 | P5: Pops | Q5: 0.15 | R5: 0.18 | S5: 0.21 | T5: 0.24 | U5: 0.27 | V5: 0.3 | W5: 0.33 | X5: 0.39 | Y5: 0.46 | Z5: 0.59 | AA5: 1
A6: 11/23/2025 Sales (Sun) | B6: 75 | C6: 81 | D6: 83 | E6: 93 | M6: ='Performances by Week'!AF33-'Performances by Week'!AB33 -> 968 | N6: ='Performances by Week'!O33 -> 0.63490566 | P6: Specials | Q6: 0.15 | R6: 0.18 | S6: 0.21 | T6: 0.24 | U6: 0.27 | V6: 0.3 | W6: 0.33 | X6: 0.39 | Y6: 0.46 | Z6: 0.59 | AA6: 1
A7: Pace for 85% OCC | B7: =$M$7*$M$10*Q4 -> 135.915 | C7: =$M$7*$M$10*R4 -> 163.098 | D7: =$M$7*$M$10*S4 -> 190.281 | E7: =$M$7*$M$10*T4 -> 217.464 | F7: =$M$7*$M$10*U4 -> 244.647 | G7: =$M$7*$M$10*V4 -> 271.83 | H7: =$M$7*$M$10*W4 -> 299.013 | I7: =$M$7*$M$10*X4 -> 353.379 | ... L7: =$M$7*$M$10*AA4 -> 906.1 | M7: =AVERAGE(M4:M6) -> 1066 | P7: Other | Q7: 0.15 | R7: 0.18 | S7: 0.21 | T7: 0.24 | U7: 0.27 | V7: 0.3 | W7: 0.33 | X7: 0.39 | Y7: 0.46 | Z7: 0.59 | AA7: 1
A8: Avg/Show vs Target Pace: | B8: =IF(B4>0,AVERAGE(B4:B6)-B7,"TBD") -> -60.915 | C8: =IF(C4>0,AVERAGE(C4:C6)-C7,"TBD") -> -79.431333 | D8: =IF(D4>0,AVERAGE(D4:D6)-D7,"TBD") -> -102.61433 | E8: =IF(E4>0,AVERAGE(E4:E6)-E7,"TBD") -> -113.79733 | F8: =IF(F4>0,AVERAGE(F4:F6)-F7,"TBD") -> TBD | G8: =IF(G4>0,AVERAGE(G4:G6)-G7,"TBD") -> TBD | H8: =IF(H4>0,AVERAGE(H4:H6)-H7,"TBD") -> TBD | I8: =IF(I4>0,AVERAGE(I4:I6)-I7,"TBD") -> TBD | ... L8: =IF(L4>0,AVERAGE(L4:L6)-L7,"TBD") -> TBD
M9: OCC Target
M10: 0.85

Sheet Elf
D1: # weeks out
A2: Single Tickets | B2: 10 | C2: 9 | D2: 8 | E2: 7 | F2: 6 | G2: 5 | H2: 4 | I2: 3 | J2: 2 | K2: 1 | L2: 0 | Q2: Estimates Only | U2: Historical Data
A3: Elf in Concert | B3: 45915 | C3: 45922 | D3: 45929 | E3: 45936 | F3: 45943 | G3: 45950 | H3: 45957 | I3: 45964 | J3: 45971 | K3: 45978 | L3: 45985 | M3: # Single Tickets to sell out 100% | N3: Projected OCC% | P3: # Weeks Until Performance | Q3: 10 | R3: 9 | S3: 8 | T3: 7 | U3: 6 | V3: 5 | W3: 4 | X3: 3 | Y3: 2 | Z3: 1 | AA3: 0
A4: 11/28/2025 (Fri) | B4: 306 | C4: 323 | D4: 339 | M4: ='Performances by Week'!AF34-'Performances by Week'!AB34 -> 1302 | N4: ='Performances by Week'!O34 -> 1 | P4: Classical | Q4: 0.15 | R4: 0.18 | S4: 0.21 | T4: 0.24 | U4: 0.27 | V4: 0.3 | W4: 0.33 | X4: 0.39 | Y4: 0.46 | Z4: 0.59 | AA4: 1
A5: 11/29/2025 (Sat 1) | B5: 370 | C5: 374 | D5: 414 | M5: ='Performances by Week'!AF35-'Performances by Week'!AB35 -> 1302 | N5: ='Performances by Week'!O35 -> 1 | P5: Pops | Q5: 0.15 | R5: 0.18 | S5: 0.21 | T5: 0.24 | U5: 0.27 | V5: 0.3 | W5: 0.33 | X5: 0.39 | Y5: 0.46 | Z5: 0.59 | AA5: 1
A6: 11/29/2025 (Sat 2) | B6: 283 | C6: 303 | D6: 329 | M6: ='Performances by Week'!AF36-'Performances by Week'!AB36 -> 1302 | N6: ='Performances by Week'!O36 -> 1 | P6: Specials | Q6: 0.15 | R6: 0.18 | S6: 0.21 | T6: 0.24 | U6: 0.27 | V6: 0.3 | W6: 0.33 | X6: 0.39 | Y6: 0.46 | Z6: 0.59 | AA6: 1
A7: 11/30/2025 (Sun) | B7: 483 | C7: 514 | D7: 542 | M7: ='Performances by Week'!AF37-'Performances by Week'!AB37 -> 1302 | N7: ='Performances by Week'!O37 -> 1 | P7: Other | Q7: 0.15 | R7: 0.18 | S7: 0.21 | T7: 0.24 | U7: 0.27 | V7: 0.3 | W7: 0.33 | X7: 0.39 | Y7: 0.46 | Z7: 0.59 | AA7: 1
A8: Pace for 85% OCC | B8: =$M$8*$M$13*Q6 -> 166.005 | C8: =$M$8*$M$13*R6 -> 199.206 | D8: =$M$8*$M$13*S6 -> 232.407 | E8: =$M$8*$M$13*T6 -> 265.608 | F8: =$M$8*$M$13*U6 -> 298.809 | G8: =$M$8*$M$13*V6 -> 332.01 | H8: =$M$8*$M$13*W6 -> 365.211 | I8: =$M$8*$M$13*X6 -> 431.613 | ... L8: =$M$8*$M$13*AA6 -> 1106.7 | M8: =AVERAGE(M4:M7) -> 1302
A9: Home Alone 2024 | B9: =AVERAGE(B32:B35) -> 480.5 | C9: =AVERAGE(C32:C35) -> 532.5 | D9: =AVERAGE(D32:D35) -> 570.5 | E9: =AVERAGE(E32:E35) -> 607.5 | F9: =AVERAGE(F32:F35) -> 645.75 | G9: =AVERAGE(G32:G35) -> 720 | H9: =AVERAGE(H32:H35) -> 836.5 | I9: =AVERAGE(I32:I35) -> 956.75 | ... L9: =AVERAGE(L32:L35) -> 1293.25
A10: Muppet XMas 2023 | B10: =AVERAGE(B43:B44) -> 943.5 | C10: =AVERAGE(C43:C44) -> 992.5 | D10: =AVERAGE(D43:D44) -> 1056 | E10: =AVERAGE(E43:E44) -> 1088 | F10: =AVERAGE(F43:F44) -> 1158 | G10: =AVERAGE(G43:G44) -> 1220 | H10: =AVERAGE(H43:H44) -> 1242.5 | I10: =AVERAGE(I43:I44) -> 1259.5 | ... L10: =AVERAGE(L43:L44) -> 1288.5
A11: Avg/Show vs 2024 Pace: | B11: =IF(B4>0,AVERAGE(B4:B7)-B9,"TBD") -> -120 | C11: =IF(C4>0,AVERAGE(C4:C7)-C9,"TBD") -> -154 | D11: =IF(D4>0,AVERAGE(D4:D7)-D9,"TBD") -> -164.5 | E11: =IF(E4>0,AVERAGE(E4:E7)-E9,"TBD") -> TBD | F11: =IF(F4>0,AVERAGE(F4:F7)-F9,"TBD") -> TBD | G11: =IF(G4>0,AVERAGE(G4:G7)-G9,"TBD") -> TBD | H11: =IF(H4>0,AVERAGE(H4:H7)-H9,"TBD") -> TBD | I11: =IF(I4>0,AVERAGE(I4:I7)-I9,"TBD") -> TBD | ... L11: =IF(L4>0,AVERAGE(L4:L7)-L9,"TBD") -> TBD
M12: OCC Target
M13: 0.85
A30: Single Tickets | B30: 10 | C30: 9 | D30: 8 | E30: 7 | F30: 6 | G30: 5 | H30: 4 | I30: 3 | J30: 2 | K30: 1 | L30: 0
A31: Home Alone | B31: 45551 | C31: 45558 | D31: 45565 | E31: 45572 | F31: 45579 | G31: 45586 | H31: 45593 | I31: 45600 | J31: 45607 | K31: 45614 | L31: 45621 | M31: # Single Tickets to sell out 100% | N31: Final Occupancy Sold %
A32: 11/29/2024 Sales (Friday) | B32: 395 | C32: 422 | D32: 451 | E32: 488 | F32: 518 | G32: 591 | H32: 667 | I32: 754 | J32: 913 | K32: 1165 | L32: 1276 | M32: 1342 | N32: 0.9664
A33: 11/30/2024, 2pm (Saturday) | B33: 604 | C33: 669 | D33: 701 | E33: 735 | F33: 763 | G33: 832 | H33: 955 | I33: 1040 | J33: 1229 | K33: 1269 | L33: 1301 | M33: 1342 | N33: 0.9873
A34: 11/30/2024, 8pm (Saturday) | B34: 302 | C34: 353 | D34: 391 | E34: 422 | F34: 454 | G34: 500 | H34: 657 | I34: 813 | J34: 988 | K34: 1200 | L34: 1301 | M34: 1342 | N34: 0.9836
A35: 12/01/2024 Sales (Sunday) | B35: 621 | C35: 686 | D35: 739 | E35: 785 | F35: 848 | G35: 957 | H35: 1067 | I35: 1220 | J35: 1269 | K35: 1275 | L35: 1295 | M35: 1342 | N35: 0.9813
A36: Pace for 85% OCC
A37: Avg/Show vs Target Pace:
M38: OCC Target
M39: 0.85
A41: Single Tickets | B41: 10 | C41: 9 | D41: 8 | E41: 7 | F41: 6 | G41: 5 | H41: 4 | I41: 3 | J41: 2 | K41: 1 | L41: 0
A42: A Muppet Christmas Carol | B42: 45194 | C42: 45201 | D42: 45208 | E42: 45215 | F42: 45222 | G42: 45229 | H42: 45236 | I42: 45243 | J42: 45250 | K42: 45988 | L42: 45995 | M42: # Single Tickets to sell out 100% | N42: Final Occupancy Sold %
A43: 12/08/2023 Sales (Friday) | B43: 844 | C43: 894 | D43: 980 | E43: 1010 | F43: 1104 | G43: 1218 | H43: 1244 | I43: 1264 | J43: 1268 | K43: 1279 | L43: 1289 | M43: 1334 | N43: 0.9962
A44: 12/09/2023, 1pm Sales (Saturday) | B44: 1043 | C44: 1091 | D44: 1132 | E44: 1166 | F44: 1212 | G44: 1222 | H44: 1241 | I44: 1255 | J44: 1265 | K44: 1270 | L44: 1288 | M44: 1334 | N44: 0.979
A45: Pace for 85% OCC
A46: Avg/Show vs Target Pace:
M47: OCC Target
M48: 0.85

Sheet Messiah
D1: # weeks out
A2: Single Tickets | B2: 10 | C2: 9 | D2: 8 | E2: 7 | F2: 6 | G2: 5 | H2: 4 | I2: 3 | J2: 2 | K2: 1 | L2: 0 | Q2: Estimates Only | U2: Historical Data
A3: Handel's Messiah | B3: 45922 | C3: 45929 | D3: 45936 | E3: 45943 | F3: 45950 | G3: 45957 | H3: 45964 | I3: 45971 | J3: 45978 | K3: 45985 | L3: 45992 | M3: # Single Tickets to sell out 100% | N3: Projected OCC% | P3: # Weeks Until Performance | Q3: 10 | R3: 9 | S3: 8 | T3: 7 | U3: 6 | V3: 5 | W3: 4 | X3: 3 | Y3: 2 | Z3: 1 | AA3: 0
A4: 12/5/2025 (Fri) | B4: 369 | C4: 395 | M4: ='Performances by Week'!AF38-'Performances by Week'!AB38 -> 1433 | N4: ='Performances by Week'!O38 -> 1 | P4: Classical | Q4: 0.15 | R4: 0.18 | S4: 0.21 | T4: 0.24 | U4: 0.27 | V4: 0.3 | W4: 0.33 | X4: 0.39 | Y4: 0.46 | Z4: 0.59 | AA4: 1
A5: 12/6/2025 (Sat) | B5: 369 | C5: 386 | M5: ='Performances by Week'!AF39-'Performances by Week'!AB39 -> 1433 | N5: ='Performances by Week'!O39 -> 1 | P5: Pops | Q5: 0.15 | R5: 0.18 | S5: 0.21 | T5: 0.24 | U5: 0.27 | V5: 0.3 | W5: 0.33 | X5: 0.39 | Y5: 0.46 | Z5: 0.59 | AA5: 1
A6: 12/7/2025 (Sun) | B6: 410 | C6: 443 | M6: ='Performances by Week'!AF40-'Performances by Week'!AB40 -> 1433 | N6: ='Performances by Week'!O40 -> 1 | P6: Specials | Q6: 0.15 | R6: 0.18 | S6: 0.21 | T6: 0.24 | U6: 0.27 | V6: 0.3 | W6: 0.33 | X6: 0.39 | Y6: 0.46 | Z6: 0.59 | AA6: 1
A7: Pace for 85% OCC | B7: =$M$7*$M$14*Q6 -> 182.7075 | C7: =$M$7*$M$14*R6 -> 219.249 | D7: =$M$7*$M$14*S6 -> 255.7905 | E7: =$M$7*$M$14*T6 -> 292.332 | F7: =$M$7*$M$14*U6 -> 328.8735 | G7: =$M$7*$M$14*V6 -> 365.415 | H7: =$M$7*$M$14*W6 -> 401.9565 | I7: =$M$7*$M$14*X6 -> 475.0395 | ... L7: =$M$7*$M$14*AA6 -> 1218.05 | M7: =AVERAGE(M4:M6) -> 1433 | P7: Other | Q7: 0.15 | R7: 0.18 | S7: 0.21 | T7: 0.24 | U7: 0.27 | V7: 0.3 | W7: 0.33 | X7: 0.39 | Y7: 0.46 | Z7: 0.59 | AA7: 1
A8: Weekly new sales needed for Target Pace | C8: =C7-B7 -> 36.5415 | D8: =D7-C7 -> 36.5415 | E8: =E7-D7 -> 36.5415 | F8: =F7-E7 -> 36.5415 | G8: =G7-F7 -> 36.5415 | H8: =H7-G7 -> 36.5415 | I8: =I7-H7 -> 73.083 | J8: =J7-I7 -> 85.2635 | ... L8: =L7-K7 -> 499.4005
A9: Actual Weekly Sales | C9: =C6-B6 -> 33
A10: Messiah 2024 | B10: =AVERAGE(B33:B35) -> 300.33333 | C10: =AVERAGE(C33:C35) -> 322.33333 | D10: =AVERAGE(D33:D35) -> 360 | E10: =AVERAGE(E33:E35) -> 395.66667 | F10: =AVERAGE(F33:F35) -> 431 | G10: =AVERAGE(G33:G35) -> 486.33333 | H10: =AVERAGE(H33:H35) -> 568.33333 | I10: =AVERAGE(I33:I35) -> 667 | ... L10: =AVERAGE(L33:L35) -> 1146
A11: Messiah 2023 | B11: =AVERAGE(B43:B45) -> 338 | C11: =AVERAGE(C43:C45) -> 372 | D11: =AVERAGE(D43:D45) -> 411 | E11: =AVERAGE(E43:E45) -> 447.33333 | F11: =AVERAGE(F43:F45) -> 494.66667 | G11: =AVERAGE(G43:G45) -> 557 | H11: =AVERAGE(H43:H45) -> 657.66667 | I11: =AVERAGE(I43:I45) -> 738.33333 | ... L11: =AVERAGE(L43:L45) -> 1180.3333
A12: Avg/Show vs Target Pace: | B12: =IF(B4>0,AVERAGE(B4:B6)-B10,"TBD") -> 82.333333 | C12: =IF(C4>0,AVERAGE(C4:C6)-C10,"TBD") -> 85.666667 | D12: =IF(D4>0,AVERAGE(D4:D6)-D10,"TBD") -> TBD | E12: =IF(E4>0,AVERAGE(E4:E6)-E10,"TBD") -> TBD | F12: =IF(F4>0,AVERAGE(F4:F6)-F10,"TBD") -> TBD | G12: =IF(G4>0,AVERAGE(G4:G6)-G10,"TBD") -> TBD | H12: =IF(H4>0,AVERAGE(H4:H6)-H10,"TBD") -> TBD | I12: =IF(I4>0,AVERAGE(I4:I6)-I10,"TBD") -> TBD | ... L12: =IF(L4>0,AVERAGE(L4:L6)-L10,"TBD") -> TBD
M13: OCC Target
M14: 0.85
A31: Single Tickets | B31: 10 | C31: 9 | D31: 8 | E31: 7 | F31: 6 | G31: 5 | H31: 4 | I31: 3 | J31: 2 | K31: 1 | L31: 0
A32: Handel's Messiah | B32: 45558 | C32: 45565 | D32: 45572 | E32: 45579 | F32: 45586 | G32: 45593 | H32: 45600 | I32: 45607 | J32: 45614 | K32: 45621 | L32: 45628 | M32: # Single Tickets to sell out 100% | N32: Final Occupancy Sold %
A33: 12/06/2024 Sales (Friday) | B33: 269 | C33: 295 | D33: 314 | E33: 335 | F33: 385 | G33: 425 | H33: 522 | I33: 615 | J33: 771 | K33: 912 | L33: 1078 | M33: 1450 | N33: 0.8834
A34: 12/07/2024 Sales (Saturday) | B34: 318 | C34: 333 | D34: 368 | E34: 392 | F34: 424 | G34: 483 | H34: 549 | I34: 660 | J34: 751 | K34: 918 | L34: 1127 | M34: 1450 | N34: 0.9662
A35: 12/08/2024 Sales (Sunday) | B35: 314 | C35: 339 | D35: 398 | E35: 460 | F35: 484 | G35: 551 | H35: 634 | I35: 726 | J35: 849 | K35: 1033 | L35: 1233 | M35: 1450 | N35: 0.9751
A36: Pace for 85% OCC
A37: Avg/Show vs Target Pace:
M38: OCC Target
M39: 0.85
A41: Single Tickets | B41: 10 | C41: 9 | D41: 8 | E41: 7 | F41: 6 | G41: 5 | H41: 4 | I41: 3 | J41: 2 | K41: 1 | L41: 0
A42: Handel's Messiah | B42: 45187 | C42: 45194 | D42: 45201 | E42: 45208 | F42: 45215 | G42: 45222 | H42: 45229 | I42: 45236 | J42: 45243 | K42: 45250 | L42: 45988 | M42: # Single Tickets to sell out 100% | N42: Final Occupancy Sold %
A43: 12/01/2023 Sales (Friday) | B43: 292 | C43: 312 | D43: 345 | E43: 367 | F43: 421 | G43: 468 | H43: 562 | I43: 635 | J43: 855 | K43: 992 | L43: 1129 | M43: 1450 | N43: 0.9434
A44: 12/02/2023 Sales (Saturday) | B44: 345 | C44: 396 | D44: 439 | E44: 495 | F44: 538 | G44: 590 | H44: 693 | I44: 784 | J44: 929 | K44: 1043 | L44: 1153 | M44: 1450 | N44: 0.991
A45: 12/03/2023 Sales (Sunday) | B45: 377 | C45: 408 | D45: 449 | E45: 480 | F45: 525 | G45: 613 | H45: 718 | I45: 796 | J45: 945 | K45: 1105 | L45: 1259 | M45: 1450 | N45: 1
A46: Avg/Show vs Target Pace:
M47: OCC Target
M48: 0.85

Sheet XMas Festival
D1: # weeks out
A2: Single Tickets | B2: 10 | C2: 9 | D2: 8 | E2: 7 | F2: 6 | G2: 5 | H2: 4 | I2: 3 | J2: 2 | K2: 1 | L2: 0 | Q2: Estimates Only | U2: Historical Data
A3: Christmas Festival | B3: 45936 | C3: 45943 | D3: 45950 | E3: 45957 | F3: 45964 | G3: 45971 | H3: 45978 | I3: 45985 | J3: 45992 | K3: 45999 | L3: 46006 | M3: # Single Tickets to sell out 100% | N3: Projected OCC% | P3: # Weeks Until Performance | Q3: 10 | R3: 9 | S3: 8 | T3: 7 | U3: 6 | V3: 5 | W3: 4 | X3: 3 | Y3: 2 | Z3: 1 | AA3: 0
A4: 12/18/2025 (Thu) | B4: 220 | M4: ='Performances by Week'!AF43-'Performances by Week'!AB43 -> 1433 | N4: ='Performances by Week'!O43 -> Too early | P4: Classical | Q4: 0.15 | R4: 0.18 | S4: 0.21 | T4: 0.24 | U4: 0.27 | V4: 0.3 | W4: 0.33 | X4: 0.39 | Y4: 0.46 | Z4: 0.59 | AA4: 1
A5: 12/19/2025 (Fri) | B5: 211 | M5: ='Performances by Week'!AF44-'Performances by Week'!AB44 -> 1433 | N5: ='Performances by Week'!O44 -> Too early | P5: Pops | Q5: 0.15 | R5: 0.18 | S5: 0.21 | T5: 0.24 | U5: 0.27 | V5: 0.3 | W5: 0.33 | X5: 0.39 | Y5: 0.46 | Z5: 0.59 | AA5: 1
A6: 12/20/2025 (Sat 1) | B6: 388 | M6: ='Performances by Week'!AF45-'Performances by Week'!AB45 -> 1433 | N6: ='Performances by Week'!O45 -> Too early | P6: Specials | Q6: 0.15 | R6: 0.18 | S6: 0.21 | T6: 0.24 | U6: 0.27 | V6: 0.3 | W6: 0.33 | X6: 0.39 | Y6: 0.46 | Z6: 0.59 | AA6: 1
A7: 12/20/2025 (Sat 2) | B7: 292 | M7: ='Performances by Week'!AF46-'Performances by Week'!AB46 -> 1433 | N7: ='Performances by Week'!O46 -> Too early | P7: Other | Q7: 0.15 | R7: 0.18 | S7: 0.21 | T7: 0.24 | U7: 0.27 | V7: 0.3 | W7: 0.33 | X7: 0.39 | Y7: 0.46 | Z7: 0.59 | AA7: 1
A8: 12/21/2025 (Sun 1) | B8: 328 | M8: ='Performances by Week'!AF47-'Performances by Week'!AB47 -> 1132 | N8: ='Performances by Week'!O47 -> Too early
