Workbook

Sheet Performances by Week
E1: Status: | F1: Updated 9/22 | H1: Denotes Piazza | I1: Update all fields in Blue each week | J1: We expect 50% of Single Sales 1 Week Prior | K1: 85%+ occupancy | O1: 95%+ of Budget | S1: 100%+ of Target
K2: 70-85% occupancy | O2: 85-95% of Budget | S2: 90-99% of Target
G3: Week # | K3: <70% occupancy | O3: <85% of Budget | S3: <90% of Target
D4: TICKET SALES REPORT as of 9/22/2025 | G4: 4 | I4: TOTAL SALES (Singles + Subs) | P4: Single Tickets | X4: Subscription Tickets | AB4: Hall Data | AE4: Audience Data | AH4: Revenue last week | AI4: Increase over week
A5: Wk # | B5: # Weeks Until Perf | C5: Perf. Week (Mon) | D5: Performance | G5: Performance Date(s) | H5: Performance Type | I5: Actual Total Tickets Sold | J5: Projected Single Tickets + Actual Subs | K5: Projected Total OCC at Performance | L5: Total Actual Revenue | M5: TOTAL BUDGET | N5: Actual/ Budget % | O5: Projected/ Budget % | P5: Actual Single Tickets Sold | Q5: Target Single Tickets for 85% OCC | R5: Projected Single Tickets | S5: Projected Single Tickets vs 85% OCC Target | T5: Actual Revenue | U5: BUDGET | V5: Actual/ Budget % | W5: Projected/ Budget % | X5: Actual Sub Tickets Sold | Y5: Actual Revenue | Z5: BUDGET | AA5: Actual vs Budget % | AB5: Max CAP | AC5: Actual OCC SOLD | AD5: Single Ticket ATP | AE5: # New HH | AF5: # Ret HH | AG5: # Total HH
A6: 1 | B6: =A6-$G$4 -> -3 | C6: 45901 | D6: 26 Morgan Freeman's Symphonic Blues | G6: 45902.833 | H6: Specials | I6: =P6+X6 -> 1169 | J6: =IF(R6="Too early",R6,R6+X6) -> #N/A | K6: =IF(J6="Too early",J6,J6/AB6) -> #N/A | L6: =T6+Y6 -> 137698 | M6: =U6+Z6 -> 153473 | N6: =L6/M6 -> 0.89721319 | O6: =IF($J6="Too early",J6,J6*AD6/M6) -> #N/A | P6: 1169 | Q6: =(AB6-X6)*0.85 -> 1106.7 | R6: =IF(B6<7,(P6/VLOOKUP(B6,'Sales Pacing'!$A$23:$E$36,2)),"Too early") -> #N/A | S6: =IF(R6="Too early","Too early",R6/Q6) -> #N/A | T6: 137698 | U6: 153473 | V6: =IF(T6>0,T6/U6,"") -> 0.89721319 | W6: =IF($R6="Too early",R6,R6*AD6/U6) -> #N/A | Z6: 0 | AA6: =IF(Y6>0,Y6/Z6,"") | AB6: 1302 | AC6: =I6/AB6 -> 0.89784946 | AD6: =L6/I6 -> 117.79127 | AE6: 228 | AF6: 295 | AG6: 523 | AH6: 137698 | AI6: =L6-AH6 -> 0
A7: 1 | B7: =A7-$G$4 -> -3 | C7: 45901 | D7: 26 Morgan Freeman's Symphonic Blues | G7: 45903.833 | H7: Specials | I7: =P7+X7 -> 1148 | J7: =IF(R7="Too early",R7,R7+X7) -> #N/A | K7: =IF(J7="Too early",J7,J7/AB7) -> #N/A | L7: =T7+Y7 -> 134386 | M7: =U7+Z7 -> 153473 | N7: =L7/M7 -> 0.87563285 | O7: =IF($J7="Too early",J7,J7*AD7/M7) -> #N/A | P7: 1148 | Q7: =(AB7-X7)*0.85 -> 1106.7 | R7: =IF(B7<7,(P7/VLOOKUP(B7,'Sales Pacing'!$A$23:$E$36,2)),"Too early") -> #N/A | S7: =IF(R7="Too early","Too early",R7/Q7) -> #N/A | T7: 134386 | U7: 153473 | V7: =IF(T7>0,T7/U7,"") -> 0.87563285 | W7: =IF($R7="Too early",R7,R7*AD7/U7) -> #N/A | Z7: 0 | AA7: =IF(Y7>0,Y7/Z7,"") | AB7: 1302 | AC7: =I7/AB7 -> 0.88172043 | AD7: =L7/I7 -> 117.06098 | AE7: 227 | AF7: 289 | AG7: 516 | AH7: 134386 | AI7: =L7-AH7 -> 0
A8: 1 | B8: =A8-$G$4 -> -3 | C8: 45901 | D8: 26 La nuit sombre | G8: 45905.833 | H8: Specials | I8: =P8+X8 -> 699 | J8: =IF(R8="Too early",R8,R8+X8) -> #N/A | K8: =IF(J8="Too early",J8,J8/AB8) -> #N/A | L8: =T8+Y8 -> 20005 | M8: =U8+Z8 -> 15000 | N8: =L8/M8 -> 1.3336667 | O8: =IF($J8="Too early",J8,J8*AD8/M8) -> #N/A | P8: 699 | Q8: =(AB8-X8)*0.85 -> 510 | R8: =IF(B8<7,(P8/VLOOKUP(B8,'Sales Pacing'!$A$23:$E$36,2)),"Too early") -> #N/A | S8: =IF(R8="Too early","Too early",R8/Q8) -> #N/A | T8: 20005 | U8: 15000 | V8: =IF(T8>0,T8/U8,"") -> 1.3336667 | W8: =IF($R8="Too early",R8,R8*AD8/U8) -> #N/A | Z8: 0 | AA8: =IF(Y8>0,Y8/Z8,"") | AB8: 600 | AC8: =I8/AB8 -> 1.165 | AD8: =L8/I8 -> 28.619456 | AE8: 86 | AF8: 209 | AG8: 295 | AH8: 20005 | AI8: =L8-AH8 -> 0
A9: 2 | B9: =A9-$G$4 -> -2 | C9: 45908 | D9: OPEN - Recording Week | I9: =P9+X9 -> 0 | J9: =IF(R9="Too early",R9,R9+X9) -> #N/A | N9: =L9/M9 -> #DIV/0! | R9: =IF(B9<7,(P9/VLOOKUP(B9,'Sales Pacing'!$A$23:$E$36,2)),"Too early") -> #N/A | V9: =IF(T9>0,T9/U9,"") | AA9: N/A | AC9: =I9/AB9 -> #DIV/0!
A10: 3 | B10: =A10-$G$4 -> -1 | C10: 45915 | D10: 26 PS1 Music of Journey | G10: 45919.833 | H10: Pops | I10: =P10+X10 -> 1130 | J10: =IF(R10="Too early",R10,R10+X10) -> #N/A | K10: =IF(J10="Too early",J10,J10/AB10) -> #N/A | L10: =T10+Y10 -> 75516.6 | M10: =U10+Z10 -> 100666 | N10: =L10/M10 -> 0.75016987 | O10: =IF($J10="Too early",J10,J10*AD10/M10) -> #N/A | P10: 515 | Q10: =(AB10-X10)*0.85 -> 828.75 | R10: =IF(B10<7,(P10/VLOOKUP(B10,'Sales Pacing'!$A$23:$E$36,2)),"Too early") -> #N/A | S10: =IF(R10="Too early","Too early",R10/Q10) -> #N/A | T10: 30148 | U10: 59333 | V10: =IF(T10>0,T10/U10,"") -> 0.50811521 | W10: =IF($R10="Too early",R10,R10*AD10/U10) -> #N/A | X10: 615 | Y10: 45368.6 | Z10: 41333 | AA10: =IF(Y10>0,Y10/Z10,"") -> 1.0976363 | AB10: 1590 | AC10: =I10/AB10 -> 0.71069182 | AD10: =L10/I10 -> 66.82885 | AE10: 67 | AF10: 416 | AG10: 483 | AH10: 71854.6 | AI10: =L10-AH10 -> 3662
A11: 3 | B11: =A11-$G$4 -> -1 | C11: 45915 | D11: 26 PS1 Music of Journey | G11: 45920.833 | H11: Pops | I11: =P11+X11 -> 1068 | J11: =IF(R11="Too early",R11,R11+X11) -> #N/A | K11: =IF(J11="Too early",J11,J11/AB11) -> #N/A | L11: =T11+Y11 -> 74220.3 | M11: =U11+Z11 -> 100667 | N11: =L11/M11 -> 0.73728531 | O11: =IF($J11="Too early",J11,J11*AD11/M11) -> #N/A | P11: 554 | Q11: =(AB11-X11)*0.85 -> 914.6 | R11: =IF(B11<7,(P11/VLOOKUP(B11,'Sales Pacing'!$A$23:$E$36,2)),"Too early") -> #N/A | S11: =IF(R11="Too early","Too early",R11/Q11) -> #N/A | T11: 35672 | U11: 59333 | V11: =IF(T11>0,T11/U11,"") -> 0.60121686 | W11: =IF($R11="Too early",R11,R11*AD11/U11) -> #N/A | X11: 514 | Y11: 38548.3 | Z11: 41334 | AA11: =IF(Y11>0,Y11/Z11,"") -> 0.93260512 | AB11: 1590 | AC11: =I11/AB11 -> 0.67169811 | AD11: =L11/I11 -> 69.494663 | AE11: 78 | AF11: 376 | AG11: 454 | AH11: 70013.3 | AI11: =L11-AH11 -> 4207
A12: 3 | B12: =A12-$G$4 -> -1 | C12: 45915 | D12: 26 PS1 Music of Journey | G12: 45921.583 | H12: Pops | I12: =P12+X12 -> 1008 | J12: =IF(R12="Too early",R12,R12+X12) -> #N/A | K12: =IF(J12="Too early",J12,J12/AB12) -> #N/A | L12: =T12+Y12 -> 64499.8 | M12: =U12+Z12 -> 100666 | N12: =L12/M12 -> 0.64073073 | O12: =IF($J12="Too early",J12,J12*AD12/M12) -> #N/A | P12: 664 | Q12: =(AB12-X12)*0.85 -> 1059.1 | R12: =IF(B12<7,(P12/VLOOKUP(B12,'Sales Pacing'!$A$23:$E$36,2)),"Too early") -> #N/A | S12: =IF(R12="Too early","Too early",R12/Q12) -> #N/A | T12: 40352 | U12: 59333 | V12: =IF(T12>0,T12/U12,"") -> 0.68009371 | W12: =IF($R12="Too early",R12,R12*AD12/U12) -> #N/A | X12: 344 | Y12: 24147.8 | Z12: 41333 | AA12: =IF(Y12>0,Y12/Z12,"") -> 0.58422568 | AB12: 1590 | AC12: =I12/AB12 -> 0.63396226 | AD12: =L12/I12 -> 63.987897 | AE12: 74 | AF12: 286 | AG12: 360 | AH12: 56072.3 | AI12: =L12-AH12 -> 8427.5
A13: 4 | B13: =A13-$G$4 -> 0 | C13: 45922 | D13: 26 FS1 The Orchestra Games | G13: 45928.583 | H13: Family | I13: =P13+X13 -> 539 | J13: =IF(R13="Too early",R13,R13+X13) -> 539 | K13: =IF(J13="Too early",J13,J13/AB13) -> 0.41397849 | L13: =T13+Y13 -> 14134 | M13: =U13+Z13 -> 19500 | N13: =L13/M13 -> 0.72482051 | O13: =IF($J13="Too early",J13,J13*AD13/M13) -> 0.72482051 | P13: 343 | Q13: =(AB13-X13)*0.85 -> 940.1 | R13: =IF(B13<7,(P13/VLOOKUP(B13,'Sales Pacing'!$A$23:$E$36,2)),"Too early") -> 343 | S13: =IF(R13="Too early","Too early",R13/Q13) -> 0.3648548 | T13: 8917 | U13: 10000 | V13: =IF(T13>0,T13/U13,"") -> 0.8917 | W13: =IF($R13="Too early",R13,R13*AD13/U13) -> 0.89943636 | X13: 196 | Y13: 5217 | Z13: 9500 | AA13: =IF(Y13>0,Y13/Z13,"") -> 0.54915789 | AB13: 1302 | AC13: =I13/AB13 -> 0.41397849 | AD13: =L13/I13 -> 26.222635 | AE13: 21 | AF13: 104 | AG13: 125 | AH13: 12684 | AI13: =L13-AH13 -> 1450
A14: 5 | B14: =A14-$G$4 -> 1 | C14: 45929 | D14: Chicken Fried | G14: 45934 | H14: Specials | I14: =P14+X14 -> 52 | J14: =IF(R14="Too early",R14,R14+X14) -> 88.135593 | K14: =IF(J14="Too early",J14,J14/AB14) -> 0.055431191 | L14: =T14+Y14 -> 4410 | M14: =U14+Z14 -> 58000 | N14: =L14/M14 -> 0.076034483 | O14: =IF($J14="Too early",J14,J14*AD14/M14) -> 0.128872 | P14: 52 | Q14: =(AB14-X14)*0.85 -> 1351.5 | R14: =IF(B14<7,(P14/VLOOKUP(B14,'Sales Pacing'!$A$23:$E$36,2)),"Too early") -> 88.135593 | S14: =IF(R14="Too early","Too early",R14/Q14) -> 0.065213166 | T14: 4410 | U14: 58000 | V14: =IF(T14>0,T14/U14,"") -> 0.076034483 | W14: =IF($R14="Too early",R14,R14*AD14/U14) -> 0.128872 | AA14: =IF(Y14>0,Y14/Z14,"") | AB14: 1590 | AC14: =I14/AB14 -> 0.032704403 | AD14: =L14/I14 -> 84.807692 | AE14: 7 | AF14: 70 | AG14: 77 | AH14: 15091 | AI14: =L14-AH14 -> -10681
A15: 6 | B15: =A15-$G$4 -> 2 | C15: 45936 | D15: 26 CS01 Appalachian Spring | G15: 45940.833 | H15: Classical | I15: =P15+X15 -> 764 | J15: =IF(R15="Too early",R15,R15+X15) -> 1063.3478 | K15: =IF(J15="Too early",J15,J15/AB15) -> 0.74204314 | L15: =T15+Y15 -> 48632 | M15: =U15+Z15 -> 49999 | N15: =L15/M15 -> 0.97265945 | O15: =IF($J15="Too early",J15,J15*AD15/M15) -> 1.3537635 | P15: 255 | Q15: =(AB15-X15)*0.85 -> 785.4 | R15: =IF(B15<7,(P15/VLOOKUP(B15,'Sales Pacing'!$A$23:$E$36,2)),"Too early") -> 554.34783 | S15: =IF(R15="Too early","Too early",R15/Q15) -> 0.70581592 | T15: 14669 | U15: 16666 | V15: =IF(T15>0,T15/U15,"") -> 0.88017521 | W15: =IF($R15="Too early",R15,R15*AD15/U15) -> 2.1172871 | X15: 509 | Y15: 33963 | Z15: 33333 | AA15: =IF(Y15>0,Y15/Z15,"") -> 1.0189002 | AB15: 1433 | AC15: =I15/AB15 -> 0.53314724 | AD15: =L15/I15 -> 63.65445 | AE15: 13 | AF15: 370 | AG15: 383 | AH15: 47640 | AI15: =L15-AH15 -> 992
A16: 6 | B16: =A16-$G$4 -> 2 | C16: 45936 | D16: 26 CS01 Appalachian Spring | G16: 45941.833 | H16: Classical | I16: =P16+X16 -> 859 | J16: =IF(R16="Too early",R16,R16+X16) -> 1198.2609 | K16: =IF(J16="Too early",J16,J16/AB16) -> 0.83619042 | L16: =T16+Y16 -> 56697.1 | M16: =U16+Z16 -> 49999 | N16: =L16/M16 -> 1.1339647 | O16: =IF($J16="Too early",J16,J16*AD16/M16) -> 1.5818225 | P16: 289 | Q16: =(AB16-X16)*0.85 -> 733.55 | R16: =IF(B16<7,(P16/VLOOKUP(B16,'Sales Pacing'!$A$23:$E$36,2)),"Too early") -> 628.26087 | S16: =IF(R16="Too early","Too early",R16/Q16) -> 0.85646632 | T16: 18093 | U16: 16666 | V16: =IF(T16>0,T16/U16,"") -> 1.0856234 | W16: =IF($R16="Too early",R16,R16*AD16/U16) -> 2.4881486 | X16: 570 | Y16: 38604.1 | Z16: 33333 | AA16: =IF(Y16>0,Y16/Z16,"") -> 1.1581346 | AB16: 1433 | AC16: =I16/AB16 -> 0.59944173 | AD16: =L16/I16 -> 66.003609 | AE16: 21 | AF16: 386 | AG16: 407 | AH16: 55614.1 | AI16: =L16-AH16 -> 1083
A17: 6 | B17: =A17-$G$4 -> 2 | C17: 45936 | D17: 26 CS01 Appalachian Spring | G17: 45942.583 | H17: Classical | I17: =P17+X17 -> 950 | J17: =IF(R17="Too early",R17,R17+X17) -> 1362.0435 | K17: =IF(J17="Too early",J17,J17/AB17) -> 0.95048393 | L17: =T17+Y17 -> 59240.6 | M17: =U17+Z17 -> 50000 | N17: =L17/M17 -> 1.184812 | O17: =IF($J17="Too early",J17,J17*AD17/M17) -> 1.6987005 | P17: 351 | Q17: =(AB17-X17)*0.85 -> 708.9 | R17: =IF(B17<7,(P17/VLOOKUP(B17,'Sales Pacing'!$A$23:$E$36,2)),"Too early") -> 763.04348 | S17: =IF(R17="Too early","Too early",R17/Q17) -> 1.0763768 | T17: 20577 | U17: 16666 | V17: =IF(T17>0,T17/U17,"") -> 1.2346694 | W17: =IF($R17="Too early",R17,R17*AD17/U17) -> 2.8550502 | X17: 599 | Y17: 38663.6 | Z17: 33334 | AA17: =IF(Y17>0,Y17/Z17,"") -> 1.1598848 | AB17: 1433 | AC17: =I17/AB17 -> 0.66294487 | AD17: =L17/I17 -> 62.358526 | AE17: 17 | AF17: 455 | AG17: 472 | AH17: 57932.6 | AI17: =L17-AH17 -> 1308
A18: 7 | B18: =A18-$G$4 -> 3 | C18: 45943 | D18: 26 Top Gun: Maverick in Concert | G18: 45947.792 | H18: Specials/Film | I18: =P18+X18 -> 716 | J18: =IF(R18="Too early",R18,R18+X18) -> 1835.8974 | K18: =IF(J18="Too early",J18,J18/AB18) -> 1.4100595 | L18: =T18+Y18 -> 53565.5 | M18: =U18+Z18 -> 103497 | N18: =L18/M18 -> 0.51755606 | O18: =IF($J18="Too early",J18,J18*AD18/M18) -> 1.3270668 | P18: 716 | Q18: =(AB18-X18)*0.85 -> 1106.7 | R18: =IF(B18<7,(P18/VLOOKUP(B18,'Sales Pacing'!$A$23:$E$36,2)),"Too early") -> 1835.8974 | S18: =IF(R18="Too early","Too early",R18/Q18) -> 1.6588935 | T18: 53565.5 | U18: 103497 | V18: =IF(T18>0,T18/U18,"") -> 0.51755606 | W18: =IF($R18="Too early",R18,R18*AD18/U18) -> 1.3270668 | AA18: =IF(Y18>0,Y18/Z18,"") | AB18: 1302 | AC18: =I18/AB18 -> 0.5499232 | AD18: =L18/I18 -> 74.812151 | AE18: 51 | AF18: 179 | AG18: 230 | AH18: 48750 | AI18: =L18-AH18 -> 4815.5
A19: 7 | B19: =A19-$G$4 -> 3 | C19: 45943 | D19: 26 Top Gun: Maverick in Concert | G19: 45948.792 | H19: Specials/Film | I19: =P19+X19 -> 861 | J19: =IF(R19="Too early",R19,R19+X19) -> 2207.6923 | K19: =IF(J19="Too early",J19,J19/AB19) -> 1.6956162 | L19: =T19+Y19 -> 64353 | M19: =U19+Z19 -> 103497 | N19: =L19/M19 -> 0.62178614 | O19: =IF($J19="Too early",J19,J19*AD19/M19) -> 1.5943234 | P19: 861 | Q19: =(AB19-X19)*0.85 -> 1106.7 | R19: =IF(B19<7,(P19/VLOOKUP(B19,'Sales Pacing'!$A$23:$E$36,2)),"Too early") -> 2207.6923 | S19: =IF(R19="Too early","Too early",R19/Q19) -> 1.9948426 | T19: 64353 | U19: 103497 | V19: =IF(T19>0,T19/U19,"") -> 0.62178614 | W19: =IF($R19="Too early",R19,R19*AD19/U19) -> 1.5943234 | AA19: =IF(Y19>0,Y19/Z19,"") | AB19: 1302 | AC19: =I19/AB19 -> 0.66129032 | AD19: =L19/I19 -> 74.74216 | AE19: 74 | AF19: 184 | AG19: 258 | AH19: 60628 | AI19: =L19-AH19 -> 3725
A20: 7 | B20: =A20-$G$4 -> 3 | C20: 45943 | D20: 26 Top Gun: Maverick in Concert | G20: 45949.583 | H20: Specials/Film | I20: =P20+X20 -> 650 | J20: =IF(R20="Too early",R20,R20+X20) -> 1666.6667 | K20: =IF(J20="Too early",J20,J20/AB20) -> 1.2800819 | L20: =T20+Y20 -> 48516 | M20: =U20+Z20 -> 103496 | N20: =L20/M20 -> 0.46877174 | O20: =IF($J20="Too early",J20,J20*AD20/M20) -> 1.2019788 | P20: 650 | Q20: =(AB20-X20)*0.85 -> 1106.7 | R20: =IF(B20<7,(P20/VLOOKUP(B20,'Sales Pacing'!$A$23:$E$36,2)),"Too early") -> 1666.6667 | S20: =IF(R20="Too early","Too early",R20/Q20) -> 1.5059787 | T20: 48516 | U20: 103496 | V20: =IF(T20>0,T20/U20,"") -> 0.46877174 | W20: =IF($R20="Too early",R20,R20*AD20/U20) -> 1.2019788 | AA20: =IF(Y20>0,Y20/Z20,"") | AB20: 1302 | AC20: =I20/AB20 -> 0.49923195 | AD20: =L20/I20 -> 74.64 | AE20: 38 | AF20: 149 | AG20: 187 | AH20: 44494 | AI20: =L20-AH20 -> 4022
A21: 8 | B21: =A21-$G$4 -> 4 | C21: 45950 | D21: 26 The Lodger | G21: 45952.792 | H21: Specials/Film | I21: =P21+X21 -> 216 | J21: =IF(R21="Too early",R21,R21+X21) -> 654.54545 | K21: =IF(J21="Too early",J21,J21/AB21) -> 0.50272308 | L21: =T21+Y21 -> 11006 | M21: =U21+Z21 -> 50000 | N21: =L21/M21 -> 0.22012 | O21: =IF($J21="Too early",J21,J21*AD21/M21) -> 0.6670303 | P21: 216 | Q21: =(AB21-X21)*0.85 -> 1106.7 | R21: =IF(B21<7,(P21/VLOOKUP(B21,'Sales Pacing'!$A$23:$E$36,2)),"Too early") -> 654.54545 | S21: =IF(R21="Too early","Too early",R21/Q21) -> 0.59143892 | T21: 11006 | U21: 50000 | V21: =IF(T21>0,T21/U21,"") -> 0.22012 | W21: =IF($R21="Too early",R21,R21*AD21/U21) -> 0.6670303 | AA21: =IF(Y21>0,Y21/Z21,"") | AB21: 1302 | AC21: =I21/AB21 -> 0.16589862 | AD21: =L21/I21 -> 50.953704 | AE21: 5 | AF21: 78 | AG21: 83 | AH21: 10588 | AI21: =L21-AH21 -> 418
A22: 8 | B22: =A22-$G$4 -> 4 | C22: 45950 | D22: 26 PS2 90s Mixtape | G22: 45954.833 | H22: Pops | I22: =P22+X22 -> 829 | J22: =IF(R22="Too early",R22,R22+X22) -> 1074.6667 | K22: =IF(J22="Too early",J22,J22/AB22) -> 0.67589099 | L22: =T22+Y22 -> 58685.9 | M22: =U22+Z22 -> 92333 | N22: =L22/M22 -> 0.63558966 | O22: =IF($J22="Too early",J22,J22*AD22/M22) -> 0.82394092 | P22: 121 | Q22: =(AB22-X22)*0.85 -> 749.7 | R22: =IF(B22<7,(P22/VLOOKUP(B22,'Sales Pacing'!$A$23:$E$36,2)),"Too early") -> 366.66667 | S22: =IF(R22="Too early","Too early",R22/Q22) -> 0.48908452 | T22: 7406 | U22: 53333 | V22: =IF(T22>0,T22/U22,"") -> 0.13886337 | W22: =IF($R22="Too early",R22,R22*AD22/U22) -> 0.4866925 | X22: 708 | Y22: 51279.9 | Z22: 39000 | AA22: =IF(Y22>0,Y22/Z22,"") -> 1.3148692 | AB22: 1590 | AC22: =I22/AB22 -> 0.52138365 | AD22: =L22/I22 -> 70.791194 | AE22: 7 | AF22: 350 | AG22: 357 | AH22: 57609.1 | AI22: =L22-AH22 -> 1076.8
A23: 8 | B23: =A23-$G$4 -> 4 | C23: 45950 | D23: 26 PS2 90s Mixtape | G23: 45955.833 | H23: Pops | I23: =P23+X23 -> 787 | J23: =IF(R23="Too early",R23,R23+X23) -> 1107.7879 | K23: =IF(J23="Too early",J23,J23/AB23) -> 0.69672194 | L23: =T23+Y23 -> 54528.8 | M23: =U23+Z23 -> 92333 | N23: =L23/M23 -> 0.59056675 | O23: =IF($J23="Too early",J23,J23*AD23/M23) -> 0.83128677 | P23: 158 | Q23: =(AB23-X23)*0.85 -> 816.85 | R23: =IF(B23<7,(P23/VLOOKUP(B23,'Sales Pacing'!$A$23:$E$36,2)),"Too early") -> 478.78788 | S23: =IF(R23="Too early","Too early",R23/Q23) -> 0.58613929 | T23: 9368 | U23: 53333 | V23: =IF(T23>0,T23/U23,"") -> 0.1756511 | W23: =IF($R23="Too early",R23,R23*AD23/U23) -> 0.6220114 | X23: 629 | Y23: 45160.8 | Z23: 39000 | AA23: =IF(Y23>0,Y23/Z23,"") -> 1.1579692 | AB23: 1590 | AC23: =I23/AB23 -> 0.49496855 | AD23: =L23/I23 -> 69.286912 | AE23: 11 | AF23: 320 | AG23: 311 | AH23: 52382.8 | AI23: =L23-AH23 -> 2146
A24: 8 | B24: =A24-$G$4 -> 4 | C24: 45950 | D24: 26 PS2 90s Mixtape | G24: 45956.583 | H24: Pops | I24: =P24+X24 -> 501 | J24: =IF(R24="Too early",R24,R24+X24) -> 742.60606 | K24: =IF(J24="Too early",J24,J24/AB24) -> 0.46704784 | L24: =T24+Y24 -> 33546.5 | M24: =U24+Z24 -> 92333 | N24: =L24/M24 -> 0.36332081 | O24: =IF($J24="Too early",J24,J24*AD24/M24) -> 0.5385314 | P24: 119 | Q24: =(AB24-X24)*0.85 -> 1026.8 | R24: =IF(B24<7,(P24/VLOOKUP(B24,'Sales Pacing'!$A$23:$E$36,2)),"Too early") -> 360.60606 | S24: =IF(R24="Too early","Too early",R24/Q24) -> 0.35119406 | T24: 7648 | U24: 53333 | V24: =IF(T24>0,T24/U24,"") -> 0.1434009 | W24: =IF($R24="Too early",R24,R24*AD24/U24) -> 0.45273753 | X24: 382 | Y24: 25898.5 | Z24: 39000 | AA24: =IF(Y24>0,Y24/Z24,"") -> 0.6640641 | AB24: 1590 | AC24: =I24/AB24 -> 0.31509434 | AD24: =L24/I24 -> 66.959082 | AE24: 6 | AF24: 209 | AG24: 203 | AH24: 31818.5 | AI24: =L24-AH24 -> 1728
A25: 9 | B25: =A25-$G$4 -> 5 | C25: 45957 | D25: 26 On-Stage 1 George Li | G25: 45959.833 | H25: On Stage | I25: =P25+X25 -> 25 | J25: =IF(R25="Too early",R25,R25+X25) -> 83.333333 | K25: =IF(J25="Too early",J25,J25/AB25) -> 0.83333333 | L25: =T25+Y25 -> 2800 | M25: 11200 | N25: =L25/M25 -> 0.25 | O25: =IF($J25="Too early",J25,J25*AD25/M25) -> 0.83333333 | P25: 25 | Q25: =(AB25-X25)*0.85 -> 85 | R25: =IF(B25<7,(P25/VLOOKUP(B25,'Sales Pacing'!$A$23:$E$36,2)),"Too early") -> 83.333333 | S25: =IF(R25="Too early","Too early",R25/Q25) -> 0.98039216 | T25: 2800 | U25: 11200 | V25: =IF(T25>0,T25/U25,"") -> 0.25 | W25: =IF($R25="Too early",R25,R25*AD25/U25) -> 0.83333333 | AA25: =IF(Y25>0,Y25/Z25,"") | AB25: 100 | AC25: =I25/AB25 -> 0.25 | AD25: =L25/I25 -> 112 | AE25: 0 | AF25: 11 | AG25: 11 | AH25: 2800 | AI25: =L25-AH25 -> 0
A26: 9 | B26: =A26-$G$4 -> 5 | C26: 45957 | D26: 26 CS02 Rachmaninoff Cele Pt 1 | G26: 45961.833 | H26: Classical | I26: =P26+X26 -> 479 | J26: =IF(R26="Too early",R26,R26+X26) -> 798.66667 | K26: =IF(J26="Too early",J26,J26/AB26) -> 0.55733892 | L26: =T26+Y26 -> 31327 | M26: =U26+Z26 -> 52000 | N26: =L26/M26 -> 0.60244231 | O26: =IF($J26="Too early",J26,J26*AD26/M26) -> 1.0044897 | P26: 137 | Q26: =(AB26-X26)*0.85 -> 927.35 | R26: =IF(B26<7,(P26/VLOOKUP(B26,'Sales Pacing'!$A$23:$E$36,2)),"Too early") -> 456.66667 | S26: =IF(R26="Too early","Too early",R26/Q26) -> 0.49244262 | T26: 7526 | U26: 22000 | V26: =IF(T26>0,T26/U26,"") -> 0.34209091 | W26: =IF($R26="Too early",R26,R26*AD26/U26) -> 1.3575628 | X26: 342 | Y26: 23801 | Z26: 30000 | AA26: =IF(Y26>0,Y26/Z26,"") -> 0.79336667 | AB26: 1433 | AC26: =I26/AB26 -> 0.33426378 | AD26: =L26/I26 -> 65.400835 | AE26: 10 | AF26: 222 | AG26: 232 | AH26: 30757 | AI26: =L26-AH26 -> 570
A27: 9 | B27: =A27-$G$4 -> 5 | C27: 45957 | D27: 26 CS02 Rachmaninoff Cele Pt 1 | G27: 45962.833 | H27: Classical | I27: =P27+X27 -> 964 | J27: =IF(R27="Too early",R27,R27+X27) -> 1911.3333 | K27: =IF(J27="Too early",J27,J27/AB27) -> 1.3337986 | L27: =T27+Y27 -> 60170 | M27: =U27+Z27 -> 86500 | N27: =L27/M27 -> 0.69560694 | O27: =IF($J27="Too early",J27,J27*AD27/M27) -> 1.3791875 | P27: 406 | Q27: =(AB27-X27)*0.85 -> 743.75 | R27: =IF(B27<7,(P27/VLOOKUP(B27,'Sales Pacing'!$A$23:$E$36,2)),"Too early") -> 1353.3333 | S27: =IF(R27="Too early","Too early",R27/Q27) -> 1.8196078 | T27: 23689 | U27: 31500 | V27: =IF(T27>0,T27/U27,"") -> 0.75203175 | W27: =IF($R27="Too early",R27,R27*AD27/U27) -> 2.6816198 | X27: 558 | Y27: 36481 | Z27: 55000 | AA27: =IF(Y27>0,Y27/Z27,"") -> 0.66329091 | AB27: 1433 | AC27: =I27/AB27 -> 0.67271458 | AD27: =L27/I27 -> 62.417012 | AE27: 26 | AF27: 397 | AG27: 423 | AH27: 57693 | AI27: =L27-AH27 -> 2477
A28: 9 | B28: =A28-$G$4 -> 5 | C28: 45957 | D28: 26 CS02 Rachmaninoff Cele Pt 1 | G28: 45963.583 | H28: Classical | I28: =P28+X28 -> 852 | J28: =IF(R28="Too early",R28,R28+X28) -> 1531 | K28: =IF(J28="Too early",J28,J28/AB28) -> 1.068388 | L28: =T28+Y28 -> 53260.1 | M28: =U28+Z28 -> 86500 | N28: =L28/M28 -> 0.6157237 | O28: =IF($J28="Too early",J28,J28*AD28/M28) -> 1.1064237 | P28: 291 | Q28: =(AB28-X28)*0.85 -> 741.2 | R28: =IF(B28<7,(P28/VLOOKUP(B28,'Sales Pacing'!$A$23:$E$36,2)),"Too early") -> 970 | S28: =IF(R28="Too early","Too early",R28/Q28) -> 1.3086886 | T28: 17068 | U28: 31500 | V28: =IF(T28>0,T28/U28,"") -> 0.54184127 | W28: =IF($R28="Too early",R28,R28*AD28/U28) -> 1.9249682 | X28: 561 | Y28: 36192.1 | Z28: 55000 | AA28: =IF(Y28>0,Y28/Z28,"") -> 0.65803818 | AB28: 1433 | AC28: =I28/AB28 -> 0.59455687 | AD28: =L28/I28 -> 62.511854 | AE28: 17 | AF28: 407 | AG28: 424 | AH28: 51432.1 | AI28: =L28-AH28 -> 1828
A29: 10 | B29: =A29-$G$4 -> 6 | C29: 45964 | D29: 26 FS2 Carnival of the Animals | G29: 45970.583 | H29: Family | I29: =P29+X29 -> 465 | J29: =IF(R29="Too early",R29,R29+X29) -> 892.18519 | K29: =IF(J29="Too early",J29,J29/AB29) -> 0.6862963 | L29: =T29+Y29 -> 11301 | M29: =U29+Z29 -> 19500 | N29: =L29/M29 -> 0.57953846 | O29: =IF($J29="Too early",J29,J29*AD29/M29) -> 1.1119476 | P29: 158 | Q29: =(AB29-X29)*0.85 -> 844.05 | R29: =IF(B29<7,(P29/VLOOKUP(B29,'Sales Pacing'!$A$23:$E$36,2)),"Too early") -> 585.18519 | S29: =IF(R29="Too early","Too early",R29/Q29) -> 0.6933063 | T29: 4465 | U29: 10000 | V29: =IF(T29>0,T29/U29,"") -> 0.4465 | W29: =IF($R29="Too early",R29,R29*AD29/U29) -> 1.4221888 | X29: 307 | Y29: 6836 | Z29: 9500 | AA29: =IF(Y29>0,Y29/Z29,"") -> 0.71957895 | AB29: 1300 | AC29: =I29/AB29 -> 0.35769231 | AD29: =L29/I29 -> 24.303226 | AE29: 9 | AF29: 103 | AG29: 112 | AH29: 10703 | AI29: =L29-AH29 -> 598
A30: 11 | B30: =A30-$G$4 -> 7 | C30: 45971 | D30: OPEN | I30: =P30+X30 -> 0 | J30: =IF(R30="Too early",R30,R30+X30) -> Too early | L30: =T30+Y30 -> 0 | M30: =U30+Z30 -> 0 | N30: =L30/M30 -> #DIV/0! | R30: =IF(B30<7,(P30/VLOOKUP(B30,'Sales Pacing'!$A$23:$E$36,2)),"Too early") -> Too early | V30: =IF(T30>0,T30/U30,"") | AA30: N/A | AC30: =I30/AB30 -> #DIV/0! | AD30: =L30/I30 -> #DIV/0! | AH30: 0
A31: 12 | B31: =A31-$G$4 -> 8 | C31: 45978 | D31: 26 CS03 Matthias and Mahler 7 | G31: 45982.833 | H31: Classical | I31: =P31+X31 -> 446 | J31: =IF(R31="Too early",R31,R31+X31) -> Too early | K31: =IF(J31="Too early",J31,J31/AB31) -> Too early | L31: =T31+Y31 -> 29373 | M31: =U31+Z31 -> 40000 | N31: =L31/M31 -> 0.734325 | O31: =IF($J31="Too early",J31,J31*AD31/M31) -> Too early | P31: 79 | Q31: =(AB31-X31)*0.85 -> 1039.55 | R31: =IF(B31<7,(P31/VLOOKUP(B31,'Sales Pacing'!$A$23:$E$36,2)),"Too early") -> Too early | S31: =IF(R31="Too early","Too early",R31/Q31) -> Too early | T31: 4025 | U31: 15000 | V31: =IF(T31>0,T31/U31,"") -> 0.26833333 | W31: =IF($R31="Too early",R31,R31*AD31/U31) -> Too early | X31: 367 | Y31: 25348 | Z31: 25000 | AA31: =IF(Y31>0,Y31/Z31,"") -> 1.01392 | AB31: 1590 | AC31: =I31/AB31 -> 0.28050314 | AD31: =L31/I31 -> 65.858744 | AE31: 1 | AF31: 221 | AG31: 222 | AH31: 29114 | AI31: =L31-AH31 -> 259
A32: 12 | B32: =A32-$G$4 -> 8 | C32: 45978 | D32: 26 CS03 Matthias and Mahler 7 | G32: 45983.833 | H32: Classical | I32: =P32+X32 -> 705 | J32: =IF(R32="Too early",R32,R32+X32) -> Too early | K32: =IF(J32="Too early",J32,J32/AB32) -> Too early | L32: =T32+Y32 -> 47252.9 | M32: =U32+Z32 -> 66500 | N32: =L32/M32 -> 0.71056992 | O32: =IF($J32="Too early",J32,J32*AD32/M32) -> Too early | P32: 122 | Q32: =(AB32-X32)*0.85 -> 855.95 | R32: =IF(B32<7,(P32/VLOOKUP(B32,'Sales Pacing'!$A$23:$E$36,2)),"Too early") -> Too early | S32: =IF(R32="Too early","Too early",R32/Q32) -> Too early | T32: 7546 | U32: 11500 | V32: =IF(T32>0,T32/U32,"") -> 0.65617391 | W32: =IF($R32="Too early",R32,R32*AD32/U32) -> Too early | X32: 583 | Y32: 39706.9 | Z32: 55000 | AA32: =IF(Y32>0,Y32/Z32,"") -> 0.72194364 | AB32: 1590 | AC32: =I32/AB32 -> 0.44339623 | AD32: =L32/I32 -> 67.02539 | AE32: 4 | AF32: 347 | AG32: 351 | AH32: 47477.9 | AI32: =L32-AH32 -> -225
A33: 12 | B33: =A33-$G$4 -> 8 | C33: 45978 | D33: 26 CS03 Matthias and Mahler 7 | G33: 45984.583 | H33: Classical | I33: =P33+X33 -> 722 | J33: =IF(R33="Too early",R33,R33+X33) -> Too early | K33: =IF(J33="Too early",J33,J33/AB33) -> Too early | L33: =T33+Y33 -> 46768.2 | M33: =U33+Z33 -> 66500 | N33: =L33/M33 -> 0.7032812 | O33: =IF($J33="Too early",J33,J33*AD33/M33) -> Too early | P33: 100 | Q33: =(AB33-X33)*0.85 -> 822.8 | R33: =IF(B33<7,(P33/VLOOKUP(B33,'Sales Pacing'!$A$23:$E$36,2)),"Too early") -> Too early | S33: =IF(R33="Too early","Too early",R33/Q33) -> Too early | T33: 6613 | U33: 11500 | V33: =IF(T33>0,T33/U33,"") -> 0.57504348 | W33: =IF($R33="Too early",R33,R33*AD33/U33) -> Too early | X33: 622 | Y33: 40155.2 | Z33: 55000 | AA33: =IF(Y33>0,Y33/Z33,"") -> 0.73009455 | AB33: 1590 | AC33: =I33/AB33 -> 0.45408805 | AD33: =L33/I33 -> 64.7759 | AE33: 3 | AF33: 391 | AG33: 394 | AH33: 46613.2 | AI33: =L33-AH33 -> 155
A34: 13 | B34: =A34-$G$4 -> 9 | C34: 45985 | D34: 26 Elf™ in Concert | G34: 45989.792 | H34: Specials/Film | I34: =P34+X34 -> 327 | J34: =IF(R34="Too early",R34,R34+X34) -> Too early | K34: =IF(J34="Too early",J34,J34/AB34) -> Too early | L34: =T34+Y34 -> 22459 | M34: =U34+Z34 -> 107500 | N34: =L34/M34 -> 0.20892093 | O34: =IF($J34="Too early",J34,J34*AD34/M34) -> Too early | P34: 327 | Q34: =(AB34-X34)*0.85 -> 1106.7 | R34: =IF(B34<7,(P34/VLOOKUP(B34,'Sales Pacing'!$A$23:$E$36,2)),"Too early") -> Too early | S34: =IF(R34="Too early","Too early",R34/Q34) -> Too early | T34: 22459 | U34: 107500 | V34: =IF(T34>0,T34/U34,"") -> 0.20892093 | W34: =IF($R34="Too early",R34,R34*AD34/U34) -> Too early | AA34: =IF(Y34>0,Y34/Z34,"") | AB34: 1302 | AC34: =I34/AB34 -> 0.25115207 | AD34: =L34/I34 -> 68.681957 | AE34: 17 | AF34: 45 | AG34: 62 | AH34: 20977.6 | AI34: =L34-AH34 -> 1481.4
A35: 13 | B35: =A35-$G$4 -> 9 | C35: 45985 | D35: 26 Elf™ in Concert | G35: 45990.542 | H35: Specials/Film | I35: =P35+X35 -> 374 | J35: =IF(R35="Too early",R35,R35+X35) -> Too early | K35: =IF(J35="Too early",J35,J35/AB35) -> Too early | L35: =T35+Y35 -> 24726.6 | M35: =U35+Z35 -> 107500 | N35: =L35/M35 -> 0.23001488 | O35: =IF($J35="Too early",J35,J35*AD35/M35) -> Too early | P35: 374 | Q35: =(AB35-X35)*0.85 -> 1106.7 | R35: =IF(B35<7,(P35/VLOOKUP(B35,'Sales Pacing'!$A$23:$E$36,2)),"Too early") -> Too early | S35: =IF(R35="Too early","Too early",R35/Q35) -> Too early | T35: 24726.6 | U35: 107500 | V35: =IF(T35>0,T35/U35,"") -> 0.23001488 | W35: =IF($R35="Too early",R35,R35*AD35/U35) -> Too early | AA35: =IF(Y35>0,Y35/Z35,"") | AB35: 1302 | AC35: =I35/AB35 -> 0.28725038 | AD35: =L35/I35 -> 66.113904 | AE35: 22 | AF35: 53 | AG35: 75 | AH35: 24414.6 | AI35: =L35-AH35 -> 312
A36: 13 | B36: =A36-$G$4 -> 9 | C36: 45985 | D36: 26 Elf™ in Concert | G36: 45990.792 | H36: Specials/Film | I36: =P36+X36 -> 303 | J36: =IF(R36="Too early",R36,R36+X36) -> Too early | K36: =IF(J36="Too early",J36,J36/AB36) -> Too early | L36: =T36+Y36 -> 20120 | M36: =U36+Z36 -> 107500 | N36: =L36/M36 -> 0.18716279 | O36: =IF($J36="Too early",J36,J36*AD36/M36) -> Too early | P36: 303 | Q36: =(AB36-X36)*0.85 -> 1106.7 | R36: =IF(B36<7,(P36/VLOOKUP(B36,'Sales Pacing'!$A$23:$E$36,2)),"Too early") -> Too early | S36: =IF(R36="Too early","Too early",R36/Q36) -> Too early | T36: 20120 | U36: 107500 | V36: =IF(T36>0,T36/U36,"") -> 0.18716279 | W36: =IF($R36="Too early",R36,R36*AD36/U36) -> Too early | AA36: =IF(Y36>0,Y36/Z36,"") | AB36: 1302 | AC36: =I36/AB36 -> 0.23271889 | AD36: =L36/I36 -> 66.40264 | AE36: 12 | AF36: 56 | AG36: 68 | AH36: 19000 | AI36: =L36-AH36 -> 1120
A37: 13 | B37: =A37-$G$4 -> 9 | C37: 45985 | D37: 26 Elf™ in Concert | G37: 45991.583 | H37: Specials/Film | I37: =P37+X37 -> 524 | J37: =IF(R37="Too early",R37,R37+X37) -> Too early | K37: =IF(J37="Too early",J37,J37/AB37) -> Too early | L37: =T37+Y37 -> 36614.6 | M37: =U37+Z37 -> 107500 | N37: =L37/M37 -> 0.34060093 | O37: =IF($J37="Too early",J37,J37*AD37/M37) -> Too early | P37: 524 | Q37: =(AB37-X37)*0.85 -> 1106.7 | R37: =IF(B37<7,(P37/VLOOKUP(B37,'Sales Pacing'!$A$23:$E$36,2)),"Too early") -> Too early | S37: =IF(R37="Too early","Too early",R37/Q37) -> Too early | T37: 36614.6 | U37: 107500 | V37: =IF(T37>0,T37/U37,"") -> 0.34060093 | W37: =IF($R37="Too early",R37,R37*AD37/U37) -> Too early | AA37: =IF(Y37>0,Y37/Z37,"") | AB37: 1302 | AC37: =I37/AB37 -> 0.40245776 | AD37: =L37/I37 -> 69.875191 | AE37: 21 | AF37: 88 | AG37: 109 | AH37: 34569.6 | AI37: =L37-AH37 -> 2045
A38: 14 | B38: =A38-$G$4 -> 10 | C38: 45992 | D38: 26 Handel's Messiah | G38: 45996.792 | H38: Holiday | I38: =P38+X38 -> 373 | J38: =IF(R38="Too early",R38,R38+X38) -> Too early | K38: =IF(J38="Too early",J38,J38/AB38) -> Too early | L38: =T38+Y38 -> 19843.5 | M38: =U38+Z38 -> 78333 | N38: =L38/M38 -> 0.25332235 | O38: =IF($J38="Too early",J38,J38*AD38/M38) -> Too early | P38: 373 | Q38: =(AB38-X38)*0.85 -> 1218.05 | R38: =IF(B38<7,(P38/VLOOKUP(B38,'Sales Pacing'!$A$23:$E$36,2)),"Too early") -> Too early | S38: =IF(R38="Too early","Too early",R38/Q38) -> Too early | T38: 19843.5 | U38: 78333 | V38: =IF(T38>0,T38/U38,"") -> 0.25332235 | W38: =IF($R38="Too early",R38,R38*AD38/U38) -> Too early | AA38: =IF(Y38>0,Y38/Z38,"") | AB38: 1433 | AC38: =I38/AB38 -> 0.26029309 | AD38: =L38/I38 -> 53.199732 | AE38: 19 | AF38: 86 | AG38: 105 | AH38: 18853.5 | AI38: =L38-AH38 -> 990
A39: 14 | B39: =A39-$G$4 -> 10 | C39: 45992 | D39: 26 Handel's Messiah | G39: 45997.792 | H39: Holiday | I39: =P39+X39 -> 378 | J39: =IF(R39="Too early",R39,R39+X39) -> Too early | K39: =IF(J39="Too early",J39,J39/AB39) -> Too early | L39: =T39+Y39 -> 22606.5 | M39: =U39+Z39 -> 78334 | N39: =L39/M39 -> 0.28859116 | O39: =IF($J39="Too early",J39,J39*AD39/M39) -> Too early | P39: 378 | Q39: =(AB39-X39)*0.85 -> 1218.05 | R39: =IF(B39<7,(P39/VLOOKUP(B39,'Sales Pacing'!$A$23:$E$36,2)),"Too early") -> Too early | S39: =IF(R39="Too early","Too early",R39/Q39) -> Too early | T39: 22606.5 | U39: 78334 | V39: =IF(T39>0,T39/U39,"") -> 0.28859116 | W39: =IF($R39="Too early",R39,R39*AD39/U39) -> Too early | AA39: =IF(Y39>0,Y39/Z39,"") | AB39: 1433 | AC39: =I39/AB39 -> 0.26378227 | AD39: =L39/I39 -> 59.805556 | AE39: 20 | AF39: 95 | AG39: 115 | AH39: 22001.5 | AI39: =L39-AH39 -> 605
A40: 14 | B40: =A40-$G$4 -> 10 | C40: 45992 | D40: 26 Handel's Messiah | G40: 45998.583 | H40: Holiday | I40: =P40+X40 -> 425 | J40: =IF(R40="Too early",R40,R40+X40) -> Too early | K40: =IF(J40="Too early",J40,J40/AB40) -> Too early | L40: =T40+Y40 -> 22602.5 | M40: =U40+Z40 -> 78333 | N40: =L40/M40 -> 0.28854378 | O40: =IF($J40="Too early",J40,J40*AD40/M40) -> Too early | P40: 425 | Q40: =(AB40-X40)*0.85 -> 1218.05 | R40: =IF(B40<7,(P40/VLOOKUP(B40,'Sales Pacing'!$A$23:$E$36,2)),"Too early") -> Too early | S40: =IF(R40="Too early","Too early",R40/Q40) -> Too early | T40: 22602.5 | U40: 78333 | V40: =IF(T40>0,T40/U40,"") -> 0.28854378 | W40: =IF($R40="Too early",R40,R40*AD40/U40) -> Too early | AA40: =IF(Y40>0,Y40/Z40,"") | AB40: 1433 | AC40: =I40/AB40 -> 0.2965806 | AD40: =L40/I40 -> 53.182353 | AE40: 26 | AF40: 105 | AG40: 131 | AH40: 21652.5 | AI40: =L40-AH40 -> 950
...

Sheet PS1 Journey
B1: # weeks out
A2: Single Tickets | B2: 5 | C2: 4 | D2: 3 | E2: 2 | F2: 1 | G2: 0 | L2: Estimates Only | P2: Historical Data
A3: PS1 Journey | B3: 45880 | C3: 45887 | D3: 45894 | E3: 45901 | F3: 45908 | G3: 45915 | H3: # Single Tickets to sell out 100% | I3: Projected OCC% | K3: # Weeks Until Performance | L3: 10 | M3: 9 | N3: 8 | O3: 7 | P3: 6 | Q3: 5 | R3: 4 | S3: 3 | T3: 2 | U3: 1 | V3: 0
A4: 9/19/2025 Sales (Fri) | B4: 60 | C4: 160 | D4: 205 | E4: 262 | F4: 311 | G4: 390 | H4: ='Performances by Week'!AB10-'Performances by Week'!X10 -> 975 | I4: ='Performances by Week'!K10 -> #N/A | K4: Classical | L4: 0.15 | M4: 0.18 | N4: 0.21 | O4: 0.24 | P4: 0.27 | Q4: 0.3 | R4: 0.33 | S4: 0.39 | T4: 0.46 | U4: 0.59 | V4: 1
A5: 9/20/2025 Sales (Sat) | B5: 63 | C5: 206 | D5: 250 | E5: 294 | F5: 360 | G5: 422 | H5: ='Performances by Week'!AB11-'Performances by Week'!X11 -> 1076 | I5: ='Performances by Week'!K11 -> #N/A | K5: Pops | L5: 0.15 | M5: 0.18 | N5: 0.21 | O5: 0.24 | P5: 0.27 | Q5: 0.3 | R5: 0.33 | S5: 0.39 | T5: 0.46 | U5: 0.59 | V5: 1
A6: 9/21/2025 Sales (Sun) | B6: 57 | C6: 219 | D6: 296 | E6: 322 | F6: 444 | G6: 516 | H6: ='Performances by Week'!AB12-'Performances by Week'!X12 -> 1246 | I6: ='Performances by Week'!K12 -> #N/A | K6: Specials | L6: 0.15 | M6: 0.18 | N6: 0.21 | O6: 0.24 | P6: 0.27 | Q6: 0.3 | R6: 0.33 | S6: 0.39 | T6: 0.46 | U6: 0.59 | V6: 1
A7: Pace for 85% OCC | B7: =$H$7*$H$10*Q5 -> 280.245 | C7: =$H$7*$H$10*R5 -> 308.2695 | D7: =$H$7*$H$10*S5 -> 364.3185 | E7: =$H$7*$H$10*T5 -> 429.709 | F7: =$H$7*$H$10*U5 -> 551.1485 | G7: =$H$7*$H$10*V5 -> 934.15 | H7: =AVERAGE(H4:H6) -> 1099 | K7: Other | L7: 0.15 | M7: 0.18 | N7: 0.21 | O7: 0.24 | P7: 0.27 | Q7: 0.3 | R7: 0.33 | S7: 0.39 | T7: 0.46 | U7: 0.59 | V7: 1
A8: Avg/Show vs Target Pace: | B8: =IF(B4>0,AVERAGE(B4:B6)-B7,"TBD") -> -220.245 | C8: =IF(C4>0,AVERAGE(C4:C6)-C7,"TBD") -> -113.2695 | D8: =IF(D4>0,AVERAGE(D4:D6)-D7,"TBD") -> -113.98517 | E8: =IF(E4>0,AVERAGE(E4:E6)-E7,"TBD") -> -137.04233 | F8: =IF(F4>0,AVERAGE(F4:F6)-F7,"TBD") -> -179.48183 | G8: =IF(G4>0,AVERAGE(G4:G6)-G7,"TBD") -> -491.48333
H9: OCC Target
H10: 0.85

Sheet CS1 Appalachian
B1: # weeks out
A2: Single Tickets | B2: 8 | C2: 7 | D2: 6 | E2: 5 | F2: 4 | G2: 3 | H2: 2 | I2: 1 | J2: 0 | O2: Estimates Only | S2: Historical Data
A3: CS1 Appalachian | B3: 45880 | C3: 45887 | D3: 45894 | E3: 45901 | F3: 45908 | G3: 45915 | H3: 45922 | I3: 45929 | J3: 45936 | K3: # Single Tickets to sell out 100% | L3: Projected OCC% | N3: # Weeks Until Performance | O3: 10 | P3: 9 | Q3: 8 | R3: 7 | S3: 6 | T3: 5 | U3: 4 | V3: 3 | W3: 2 | X3: 1 | Y3: 0
A4: 10/10/2025 Sales (Fri) | B4: 60 | C4: 100 | D4: 106 | E4: 135 | F4: 193 | G4: 212 | H4: 238 | K4: =1433-543 -> 890 | L4: ='Performances by Week'!K15 -> 0.74204314 | N4: Classical | O4: 0.15 | P4: 0.18 | Q4: 0.21 | R4: 0.24 | S4: 0.27 | T4: 0.3 | U4: 0.33 | V4: 0.39 | W4: 0.46 | X4: 0.59 | Y4: 1
A5: 10/11/2025 Sales (Sat) | B5: 63 | C5: 98 | D5: 115 | E5: 130 | F5: 179 | G5: 225 | H5: 258 | K5: =1433-581 -> 852 | L5: ='Performances by Week'!K16 -> 0.83619042 | N5: Pops | O5: 0.15 | P5: 0.18 | Q5: 0.21 | R5: 0.24 | S5: 0.27 | T5: 0.3 | U5: 0.33 | V5: 0.39 | W5: 0.46 | X5: 0.59 | Y5: 1
A6: 10/12/2025 Sales (Sun) | B6: 57 | C6: 137 | D6: 154 | E6: 174 | F6: 239 | G6: 295 | H6: 328 | K6: =1433-613 -> 820 | L6: ='Performances by Week'!K17 -> 0.95048393 | N6: Specials | O6: 0.15 | P6: 0.18 | Q6: 0.21 | R6: 0.24 | S6: 0.27 | T6: 0.3 | U6: 0.33 | V6: 0.39 | W6: 0.46 | X6: 0.59 | Y6: 1
A7: Pace for 85% OCC | B7: =$K$7*$K$10*Q4 -> 151.725 | C7: =$K$7*$K$10*R4 -> 173.4 | D7: =$K$7*$K$10*S4 -> 195.075 | E7: =$K$7*$K$10*T4 -> 216.75 | F7: =$K$7*$K$10*U4 -> 238.425 | G7: =$K$7*$K$10*V4 -> 281.775 | H7: =$K$7*$K$10*W4 -> 332.35 | I7: =$K$7*$K$10*X4 -> 426.275 | J7: =$K$7*$K$10*Y4 -> 722.5 | K7: 850 | N7: Other | O7: 0.15 | P7: 0.18 | Q7: 0.21 | R7: 0.24 | S7: 0.27 | T7: 0.3 | U7: 0.33 | V7: 0.39 | W7: 0.46 | X7: 0.59 | Y7: 1
A8: Avg/Show vs Target Pace: | B8: =IF(B4>0,AVERAGE(B4:B6)-B7,"TBD") -> -91.725 | C8: =IF(C4>0,AVERAGE(C4:C6)-C7,"TBD") -> -61.733333 | D8: =IF(D4>0,AVERAGE(D4:D6)-D7,"TBD") -> -70.075 | E8: =IF(E4>0,AVERAGE(E4:E6)-E7,"TBD") -> -70.416667 | F8: =IF(F4>0,AVERAGE(F4:F6)-F7,"TBD") -> -34.758333 | G8: =IF(G4>0,AVERAGE(G4:G6)-G7,"TBD") -> -37.775 | H8: =IF(H4>0,AVERAGE(H4:H6)-H7,"TBD") -> -57.683333 | I8: =IF(I4>0,AVERAGE(I4:I6)-I7,"TBD") -> TBD | J8: =IF(J4>0,AVERAGE(J4:J6)-J7,"TBD") -> TBD
K9: OCC Target
K10: 0.85

Sheet PS2 90s Mixtape
B1: # Weeks Out | Q1: Estimates Only | U1: Historical Data
A2: Single Tickets | B2: 10 | C2: 9 | D2: 8 | E2: 7 | F2: 6 | G2: 5 | H2: 4 | I2: 3 | J2: 2 | K2: 1 | L2: 0 | P2: # Weeks Until Performance | Q2: 10 | R2: 9 | S2: 8 | T2: 7 | U2: 6 | V2: 5 | W2: 4 | X2: 3 | Y2: 2 | Z2: 1 | AA2: 0
A3: PS2 90s Mixtape (Name?) | B3: 45880 | C3: 45887 | D3: 45894 | E3: 45901 | F3: 45908 | G3: 45915 | H3: 45922 | I3: 45929 | J3: 45936 | K3: 45943 | L3: 45950 | M3: # Single Tickets to sell out 100% | N3: Projected OCC% | P3: Classical | Q3: 0.15 | R3: 0.18 | S3: 0.21 | T3: 0.24 | U3: 0.27 | V3: 0.3 | W3: 0.33 | X3: 0.39 | Y3: 0.46 | Z3: 0.59 | AA3: 1
A4: 10/24/2025 Sales (Fri) | B4: 60 | C4: 64 | D4: 68 | E4: 74 | F4: 80 | G4: 92 | M4: ='Performances by Week'!AB22-'Performances by Week'!X22 -> 882 | N4: ='Performances by Week'!K22 -> 0.67589099 | P4: Pops | Q4: 0.15 | R4: 0.18 | S4: 0.21 | T4: 0.24 | U4: 0.27 | V4: 0.3 | W4: 0.33 | X4: 0.39 | Y4: 0.46 | Z4: 0.59 | AA4: 1
A5: 10/25/2025 Sales (Sat) | B5: 63 | C5: 63 | D5: 73 | E5: 93 | F5: 106 | G5: 114 | M5: ='Performances by Week'!AB23-'Performances by Week'!X23 -> 961 | N5: ='Performances by Week'!K23 -> 0.69672194 | P5: Specials | Q5: 0.15 | R5: 0.18 | S5: 0.21 | T5: 0.24 | U5: 0.27 | V5: 0.3 | W5: 0.33 | X5: 0.39 | Y5: 0.46 | Z5: 0.59 | AA5: 1
A6: 10/26/2025 Sales (Sun) | B6: 57 | C6: 59 | D6: 66 | E6: 74 | F6: 76 | G6: 87 | M6: ='Performances by Week'!AB24-'Performances by Week'!X24 -> 1208 | N6: ='Performances by Week'!K24 -> 0.46704784 | P6: Other | Q6: 0.15 | R6: 0.18 | S6: 0.21 | T6: 0.24 | U6: 0.27 | V6: 0.3 | W6: 0.33 | X6: 0.39 | Y6: 0.46 | Z6: 0.59 | AA6: 1
A7: Pace for 85% OCC | B7: =$M$7*$M$10*Q4 -> 129.6675 | C7: =$M$7*$M$10*R4 -> 155.601 | D7: =$M$7*$M$10*S4 -> 181.5345 | E7: =$M$7*$M$10*T4 -> 207.468 | F7: =$M$7*$M$10*U4 -> 233.4015 | G7: =$M$7*$M$10*V4 -> 259.335 | H7: =$M$7*$M$10*W4 -> 285.2685 | I7: =$M$7*$M$10*X4 -> 337.1355 | ... L7: =$M$7*$M$10*AA4 -> 864.45 | M7: =AVERAGE(M4:M6) -> 1017
A8: Avg/Show vs Target Pace: | B8: =IF(B4>0,AVERAGE(B4:B6)-B7,"TBD") -> -69.6675 | C8: =IF(C4>0,AVERAGE(C4:C6)-C7,"TBD") -> -93.601 | D8: =IF(D4>0,AVERAGE(D4:D6)-D7,"TBD") -> -112.5345 | E8: =IF(E4>0,AVERAGE(E4:E6)-E7,"TBD") -> -127.13467 | F8: =IF(F4>0,AVERAGE(F4:F6)-F7,"TBD") -> -146.06817 | G8: =IF(G4>0,AVERAGE(G4:G6)-G7,"TBD") -> -161.66833 | H8: =IF(H4>0,AVERAGE(H4:H6)-H7,"TBD") -> TBD | I8: =IF(I4>0,AVERAGE(I4:I6)-I7,"TBD") -> TBD | ... L8: =IF(L4>0,AVERAGE(L4:L6)-L7,"TBD") -> TBD
M9: OCC Target
M10: 0.85

Sheet MFSB
A1: Single Tickets | B1: 3 | C1: 2 | D1: 1 | E1: 0 | L1: Single Tickets
A2: MFSB | B2: 45880 | C2: 45887 | D2: 45894 | E2: 45901 | F2: # Single Tickets to sell out 100% | K2: # Weeks Until Performance | L2: Classical | M2: Pops | N2: Specials | O2: Other
A3: 9/2/2025 Sales (Tue) | B3: 754 | C3: 915 | D3: 1013 | E3: 1096 | G3: =E3/F5 -> 0.84178187
A4: 9/3/2025 Sales (Wed) | B4: 651 | C4: 826 | D4: 926 | E4: 1027 | G4: =E4/F5 -> 0.78878648 | K4: 0 | L4: 1 | M4: 1 | N4: 1 | O4: 1
A5: Pace for 85% OCC | B5: =$F$5*$G$5*N7 -> 431.613 | C5: =$F$5*$G$5*N6 -> 509.082 | D5: =$F$5*$G$5*N5 -> 652.953 | E5: =$F$5*$G$5*N4 -> 1106.7 | F5: 1302 | G5: 0.85 | K5: 1 | L5: 0.59 | M5: 0.59 | N5: 0.59 | O5: 0.59
K6: 2 | L6: 0.46 | M6: 0.46 | N6: 0.46 | O6: 0.46
K7: 3 | L7: 0.39 | M7: 0.39 | N7: 0.39 | O7: 0.39
K8: 4 | L8: 0.33 | M8: 0.33 | N8: 0.33 | O8: 0.33
K9: 5 | L9: 0.3 | M9: 0.3 | N9: 0.3 | O9: 0.3
K10: 6 | L10: 0.27 | M10: 0.27 | N10: 0.27 | O10: 0.27

Sheet CS2 Rachmaninoff
D1: # weeks out
A2: Single Tickets | B2: 10 | C2: 9 | D2: 8 | E2: 7 | F2: 6 | G2: 5 | H2: 4 | I2: 3 | J2: 2 | K2: 1 | L2: 0 | Q2: Estimates Only | U2: Historical Data
A3: CS2 Rachmaninoff | B3: 45887 | C3: 45894 | D3: 45901 | E3: 45908 | F3: 45915 | G3: 45922 | H3: 45929 | I3: 45936 | J3: 45943 | K3: 45950 | L3: 45957 | M3: # Single Tickets to sell out 100% | N3: Projected OCC% | P3: # Weeks Until Performance | Q3: 10 | R3: 9 | S3: 8 | T3: 7 | U3: 6 | V3: 5 | W3: 4 | X3: 3 | Y3: 2 | Z3: 1 | AA3: 0
A4: 10/31/2025 Sales (Fri, Piazza) | B4: 87 | C4: 93 | D4: 102 | E4: 106 | F4: 111 | G4: 124 | M4: ='Performances by Week'!AB26-'Performances by Week'!X26 -> 1091 | N4: ='Performances by Week'!K26 -> 0.55733892 | P4: Classical | Q4: 0.15 | R4: 0.18 | S4: 0.21 | T4: 0.24 | U4: 0.27 | V4: 0.3 | W4: 0.33 | X4: 0.39 | Y4: 0.46 | Z4: 0.59 | AA4: 1
A5: 11/01/2025 Sales (Sat) | B5: 192 | C5: 209 | D5: 256 | E5: 310 | F5: 340 | G5: 382 | M5: ='Performances by Week'!AB27-'Performances by Week'!X27 -> 875 | N5: ='Performances by Week'!K27 -> 1.3337986 | P5: Pops | Q5: 0.15 | R5: 0.18 | S5: 0.21 | T5: 0.24 | U5: 0.27 | V5: 0.3 | W5: 0.33 | X5: 0.39 | Y5: 0.46 | Z5: 0.59 | AA5: 1
A6: 11/02/2025 Sales (Sun) | B6: 138 | C6: 165 | D6: 187 | E6: 219 | F6: 232 | G6: 267 | M6: ='Performances by Week'!AB28-'Performances by Week'!X28 -> 872 | N6: ='Performances by Week'!K28 -> 1.068388 | P6: Specials | Q6: 0.15 | R6: 0.18 | S6: 0.21 | T6: 0.24 | U6: 0.27 | V6: 0.3 | W6: 0.33 | X6: 0.39 | Y6: 0.46 | Z6: 0.59 | AA6: 1
A7: Pace for 85% OCC | B7: =$M$7*$M$10*Q4 -> 120.615 | C7: =$M$7*$M$10*R4 -> 144.738 | D7: =$M$7*$M$10*S4 -> 168.861 | E7: =$M$7*$M$10*T4 -> 192.984 | F7: =$M$7*$M$10*U4 -> 217.107 | G7: =$M$7*$M$10*V4 -> 241.23 | H7: =$M$7*$M$10*W4 -> 265.353 | I7: =$M$7*$M$10*X4 -> 313.599 | ... L7: =$M$7*$M$10*AA4 -> 804.1 | M7: =AVERAGE(M4:M6) -> 946 | P7: Other | Q7: 0.15 | R7: 0.18 | S7: 0.21 | T7: 0.24 | U7: 0.27 | V7: 0.3 | W7: 0.33 | X7: 0.39 | Y7: 0.46 | Z7: 0.59 | AA7: 1
A8: Avg/Show vs Target Pace: | B8: =IF(B4>0,AVERAGE(B4:B6)-B7,"TBD") -> 18.385 | C8: =IF(C4>0,AVERAGE(C4:C6)-C7,"TBD") -> 10.928667 | D8: =IF(D4>0,AVERAGE(D4:D6)-D7,"TBD") -> 12.805667 | E8: =IF(E4>0,AVERAGE(E4:E6)-E7,"TBD") -> 18.682667 | F8: =IF(F4>0,AVERAGE(F4:F6)-F7,"TBD") -> 10.559667 | G8: =IF(G4>0,AVERAGE(G4:G6)-G7,"TBD") -> 16.436667 | H8: =IF(H4>0,AVERAGE(H4:H6)-H7,"TBD") -> TBD | I8: =IF(I4>0,AVERAGE(I4:I6)-I7,"TBD") -> TBD | ... L8: =IF(L4>0,AVERAGE(L4:L6)-L7,"TBD") -> TBD
M9: OCC Target
M10: 0.85

Sheet CS3 Mahler
D1: # weeks out
A2: Single Tickets | B2: 10 | C2: 9 | D2: 8 | E2: 7 | F2: 6 | G2: 5 | H2: 4 | I2: 3 | J2: 2 | K2: 1 | L2: 0 | Q2: Estimates Only | U2: Historical Data
A3: CS3 Mahler | B3: 45908 | C3: 45915 | D3: 45922 | E3: 45929 | F3: 45936 | G3: 45943 | H3: 45950 | I3: 45957 | J3: 45964 | K3: 45971 | L3: 45978 | M3: # Single Tickets to sell out 100% | N3: Projected OCC% | P3: # Weeks Until Performance | Q3: 10 | R3: 9 | S3: 8 | T3: 7 | U3: 6 | V3: 5 | W3: 4 | X3: 3 | Y3: 2 | Z3: 1 | AA3: 0
A4: 11/21/2025 Sales (Fri, Piazza) | B4: 55 | C4: 60 | D4: 66 | M4: ='Performances by Week'!AB31-'Performances by Week'!X31 -> 1223 | N4: ='Performances by Week'!K31 -> Too early | P4: Classical | Q4: 0.15 | R4: 0.18 | S4: 0.21 | T4: 0.24 | U4: 0.27 | V4: 0.3 | W4: 0.33 | X4: 0.39 | Y4: 0.46 | Z4: 0.59 | AA4: 1
A5: 11/22/2025 Sales (Sat) | B5: 95 | C5: 110 | D5: 114 | M5: ='Performances by Week'!AB32-'Performances by Week'!X32 -> 1007 | N5: ='Performances by Week'!K32 -> Too early | P5: Pops | Q5: 0.15 | R5: 0.18 | S5: 0.21 | T5: 0.24 | U5: 0.27 | V5: 0.3 | W5: 0.33 | X5: 0.39 | Y5: 0.46 | Z5: 0.59 | AA5: 1
A6: 11/23/2025 Sales (Sun) | B6: 75 | C6: 81 | D6: 83 | M6: ='Performances by Week'!AB33-'Performances by Week'!X33 -> 968 | N6: ='Performances by Week'!K33 -> Too early | P6: Specials | Q6: 0.15 | R6: 0.18 | S6: 0.21 | T6: 0.24 | U6: 0.27 | V6: 0.3 | W6: 0.33 | X6: 0.39 | Y6: 0.46 | Z6: 0.59 | AA6: 1
A7: Pace for 85% OCC | B7: =$M$7*$M$10*Q4 -> 135.915 | C7: =$M$7*$M$10*R4 -> 163.098 | D7: =$M$7*$M$10*S4 -> 190.281 | E7: =$M$7*$M$10*T4 -> 217.464 | F7: =$M$7*$M$10*U4 -> 244.647 | G7: =$M$7*$M$10*V4 -> 271.83 | H7: =$M$7*$M$10*W4 -> 299.013 | I7: =$M$7*$M$10*X4 -> 353.379 | ... L7: =$M$7*$M$10*AA4 -> 906.1 | M7: =AVERAGE(M4:M6) -> 1066 | P7: Other | Q7: 0.15 | R7: 0.18 | S7: 0.21 | T7: 0.24 | U7: 0.27 | V7: 0.3 | W7: 0.33 | X7: 0.39 | Y7: 0.46 | Z7: 0.59 | AA7: 1
A8: Avg/Show vs Target Pace: | B8: =IF(B4>0,AVERAGE(B4:B6)-B7,"TBD") -> -60.915 | C8: =IF(C4>0,AVERAGE(C4:C6)-C7,"TBD") -> -79.431333 | D8: =IF(D4>0,AVERAGE(D4:D6)-D7,"TBD") -> -102.61433 | E8: =IF(E4>0,AVERAGE(E4:E6)-E7,"TBD") -> TBD | F8: =IF(F4>0,AVERAGE(F4:F6)-F7,"TBD") -> TBD | G8: =IF(G4>0,AVERAGE(G4:G6)-G7,"TBD") -> TBD | H8: =IF(H4>0,AVERAGE(H4:H6)-H7,"TBD") -> TBD | I8: =IF(I4>0,AVERAGE(I4:I6)-I7,"TBD") -> TBD | ... L8: =IF(L4>0,AVERAGE(L4:L6)-L7,"TBD") -> TBD
M9: OCC Target
M10: 0.85

Sheet Elf
D1: # weeks out
A2: Single Tickets | B2: 10 | C2: 9 | D2: 8 | E2: 7 | F2: 6 | G2: 5 | H2: 4 | I2: 3 | J2: 2 | K2: 1 | L2: 0 | Q2: Estimates Only | U2: Historical Data
A3: Elf in Concert | B3: 45915 | C3: 45922 | D3: 45929 | E3: 45936 | F3: 45943 | G3: 45950 | H3: 45957 | I3: 45964 | J3: 45971 | K3: 45978 | L3: 45985 | M3: # Single Tickets to sell out 100% | N3: Projected OCC% | P3: # Weeks Until Performance | Q3: 10 | R3: 9 | S3: 8 | T3: 7 | U3: 6 | V3: 5 | W3: 4 | X3: 3 | Y3: 2 | Z3: 1 | AA3: 0
A4: 11/28/2025 (Fri) | B4: 306 | C4: 323 | M4: ='Performances by Week'!AB34-'Performances by Week'!X34 -> 1302 | N4: ='Performances by Week'!K34 -> Too early | P4: Classical | Q4: 0.15 | R4: 0.18 | S4: 0.21 | T4: 0.24 | U4: 0.27 | V4: 0.3 | W4: 0.33 | X4: 0.39 | Y4: 0.46 | Z4: 0.59 | AA4: 1
A5: 11/29/2025 (Sat 1) | B5: 370 | C5: 374 | M5: ='Performances by Week'!AB35-'Performances by Week'!X35 -> 1302 | N5: ='Performances by Week'!K35 -> Too early | P5: Pops | Q5: 0.15 | R5: 0.18 | S5: 0.21 | T5: 0.24 | U5: 0.27 | V5: 0.3 | W5: 0.33 | X5: 0.39 | Y5: 0.46 | Z5: 0.59 | AA5: 1
A6: 11/29/2025 (Sat 2) | B6: 283 | C6: 303 | M6: ='Performances by Week'!AB36-'Performances by Week'!X36 -> 1302 | N6: ='Performances by Week'!K36 -> Too early | P6: Specials | Q6: 0.15 | R6: 0.18 | S6: 0.21 | T6: 0.24 | U6: 0.27 | V6: 0.3 | W6: 0.33 | X6: 0.39 | Y6: 0.46 | Z6: 0.59 | AA6: 1
A7: 11/30/2025 (Sun) | B7: 483 | C7: 514 | M7: ='Performances by Week'!AB37-'Performances by Week'!X37 -> 1302 | N7: ='Performances by Week'!K37 -> Too early | P7: Other | Q7: 0.15 | R7: 0.18 | S7: 0.21 | T7: 0.24 | U7: 0.27 | V7: 0.3 | W7: 0.33 | X7: 0.39 | Y7: 0.46 | Z7: 0.59 | AA7: 1
A8: Pace for 85% OCC | B8: =$M$8*$M$13*Q6 -> 166.005 | C8: =$M$8*$M$13*R6 -> 199.206 | D8: =$M$8*$M$13*S6 -> 232.407 | E8: =$M$8*$M$13*T6 -> 265.608 | F8: =$M$8*$M$13*U6 -> 298.809 | G8: =$M$8*$M$13*V6 -> 332.01 | H8: =$M$8*$M$13*W6 -> 365.211 | I8: =$M$8*$M$13*X6 -> 431.613 | ... L8: =$M$8*$M$13*AA6 -> 1106.7 | M8: =AVERAGE(M4:M7) -> 1302
A9: Home Alone 2024 | B9: =AVERAGE(B32:B35) -> 480.5 | C9: =AVERAGE(C32:C35) -> 532.5 | D9: =AVERAGE(D32:D35) -> 570.5 | E9: =AVERAGE(E32:E35) -> 607.5 | F9: =AVERAGE(F32:F35) -> 645.75 | G9: =AVERAGE(G32:G35) -> 720 | H9: =AVERAGE(H32:H35) -> 836.5 | I9: =AVERAGE(I32:I35) -> 956.75 | ... L9: =AVERAGE(L32:L35) -> 1293.25
A10: Muppet XMas 2023 | B10: =AVERAGE(B43:B44) -> 943.5 | C10: =AVERAGE(C43:C44) -> 992.5 | D10: =AVERAGE(D43:D44) -> 1056 | E10: =AVERAGE(E43:E44) -> 1088 | F10: =AVERAGE(F43:F44) -> 1158 | G10: =AVERAGE(G43:G44) -> 1220 | H10: =AVERAGE(H43:H44) -> 1242.5 | I10: =AVERAGE(I43:I44) -> 1259.5 | ... L10: =AVERAGE(L43:L44) -> 1288.5
A11: Avg/Show vs 2024 Pace: | B11: =IF(B4>0,AVERAGE(B4:B7)-B9,"TBD") -> -120 | C11: =IF(C4>0,AVERAGE(C4:C7)-C9,"TBD") -> -154 | D11: =IF(D4>0,AVERAGE(D4:D7)-D9,"TBD") -> TBD | E11: =IF(E4>0,AVERAGE(E4:E7)-E9,"TBD") -> TBD | F11: =IF(F4>0,AVERAGE(F4:F7)-F9,"TBD") -> TBD | G11: =IF(G4>0,AVERAGE(G4:G7)-G9,"TBD") -> TBD | H11: =IF(H4>0,AVERAGE(H4:H7)-H9,"TBD") -> TBD | I11: =IF(I4>0,AVERAGE(I4:I7)-I9,"TBD") -> TBD | ... L11: =IF(L4>0,AVERAGE(L4:L7)-L9,"TBD") -> TBD
M12: OCC Target
M13: 0.85
A30: Single Tickets | B30: 10 | C30: 9 | D30: 8 | E30: 7 | F30: 6 | G30: 5 | H30: 4 | I30: 3 | J30: 2 | K30: 1 | L30: 0
A31: Home Alone | B31: 45551 | C31: 45558 | D31: 45565 | E31: 45572 | F31: 45579 | G31: 45586 | H31: 45593 | I31: 45600 | J31: 45607 | K31: 45614 | L31: 45621 | M31: # Single Tickets to sell out 100% | N31: Final Occupancy Sold %
A32: 11/29/2024 Sales (Friday) | B32: 395 | C32: 422 | D32: 451 | E32: 488 | F32: 518 | G32: 591 | H32: 667 | I32: 754 | J32: 913 | K32: 1165 | L32: 1276 | M32: 1342 | N32: 0.9664
A33: 11/30/2024, 2pm (Saturday) | B33: 604 | C33: 669 | D33: 701 | E33: 735 | F33: 763 | G33: 832 | H33: 955 | I33: 1040 | J33: 1229 | K33: 1269 | L33: 1301 | M33: 1342 | N33: 0.9873
A34: 11/30/2024, 8pm (Saturday) | B34: 302 | C34: 353 | D34: 391 | E34: 422 | F34: 454 | G34: 500 | H34: 657 | I34: 813 | J34: 988 | K34: 1200 | L34: 1301 | M34: 1342 | N34: 0.9836
A35: 12/01/2024 Sales (Sunday) | B35: 621 | C35: 686 | D35: 739 | E35: 785 | F35: 848 | G35: 957 | H35: 1067 | I35: 1220 | J35: 1269 | K35: 1275 | L35: 1295 | M35: 1342 | N35: 0.9813
A36: Pace for 85% OCC
A37: Avg/Show vs Target Pace:
M38: OCC Target
M39: 0.85
A41: Single Tickets | B41: 10 | C41: 9 | D41: 8 | E41: 7 | F41: 6 | G41: 5 | H41: 4 | I41: 3 | J41: 2 | K41: 1 | L41: 0
A42: A Muppet Christmas Carol | B42: 45194 | C42: 45201 | D42: 45208 | E42: 45215 | F42: 45222 | G42: 45229 | H42: 45236 | I42: 45243 | J42: 45250 | K42: 45988 | L42: 45995 | M42: # Single Tickets to sell out 100% | N42: Final Occupancy Sold %
A43: 12/08/2023 Sales (Friday) | B43: 844 | C43: 894 | D43: 980 | E43: 1010 | F43: 1104 | G43: 1218 | H43: 1244 | I43: 1264 | J43: 1268 | K43: 1279 | L43: 1289 | M43: 1334 | N43: 0.9962
A44: 12/09/2023, 1pm Sales (Saturday) | B44: 1043 | C44: 1091 | D44: 1132 | E44: 1166 | F44: 1212 | G44: 1222 | H44: 1241 | I44: 1255 | J44: 1265 | K44: 1270 | L44: 1288 | M44: 1334 | N44: 0.979
A45: Pace for 85% OCC
A46: Avg/Show vs Target Pace:
M47: OCC Target
M48: 0.85

Sheet Messiah
D1: # weeks out
A2: Single Tickets | B2: 10 | C2: 9 | D2: 8 | E2: 7 | F2: 6 | G2: 5 | H2: 4 | I2: 3 | J2: 2 | K2: 1 | L2: 0 | Q2: Estimates Only | U2: Historical Data
A3: Handel's Messiah | B3: 45922 | C3: 45929 | D3: 45936 | E3: 45943 | F3: 45950 | G3: 45957 | H3: 45964 | I3: 45971 | J3: 45978 | K3: 45985 | L3: 45992 | M3: # Single Tickets to sell out 100% | N3: Projected OCC% | P3: # Weeks Until Performance | Q3: 10 | R3: 9 | S3: 8 | T3: 7 | U3: 6 | V3: 5 | W3: 4 | X3: 3 | Y3: 2 | Z3: 1 | AA3: 0
A4: 12/5/2025 (Fri) | B4: 369 | M4: ='Performances by Week'!AB38-'Performances by Week'!X38 -> 1433 | N4: ='Performances by Week'!K38 -> Too early | P4: Classical | Q4: 0.15 | R4: 0.18 | S4: 0.21 | T4: 0.24 | U4: 0.27 | V4: 0.3 | W4: 0.33 | X4: 0.39 | Y4: 0.46 | Z4: 0.59 | AA4: 1
A5: 12/6/2025 (Sat) | B5: 369 | M5: ='Performances by Week'!AB39-'Performances by Week'!X39 -> 1433 | N5: ='Performances by Week'!K39 -> Too early | P5: Pops | Q5: 0.15 | R5: 0.18 | S5: 0.21 | T5: 0.24 | U5: 0.27 | V5: 0.3 | W5: 0.33 | X5: 0.39 | Y5: 0.46 | Z5: 0.59 | AA5: 1
A6: 12/7/2025 (Sun) | B6: 410 | M6: ='Performances by Week'!AB40-'Performances by Week'!X40 -> 1433 | N6: ='Performances by Week'!K40 -> Too early | P6: Specials | Q6: 0.15 | R6: 0.18 | S6: 0.21 | T6: 0.24 | U6: 0.27 | V6: 0.3 | W6: 0.33 | X6: 0.39 | Y6: 0.46 | Z6: 0.59 | AA6: 1
A7: Pace for 85% OCC | B7: =$M$7*$M$12*Q6 -> 182.7075 | C7: =$M$7*$M$12*R6 -> 219.249 | D7: =$M$7*$M$12*S6 -> 255.7905 | E7: =$M$7*$M$12*T6 -> 292.332 | F7: =$M$7*$M$12*U6 -> 328.8735 | G7: =$M$7*$M$12*V6 -> 365.415 | H7: =$M$7*$M$12*W6 -> 401.9565 | I7: =$M$7*$M$12*X6 -> 475.0395 | ... L7: =$M$7*$M$12*AA6 -> 1218.05 | M7: =AVERAGE(M4:M6) -> 1433 | P7: Other | Q7: 0.15 | R7: 0.18 | S7: 0.21 | T7: 0.24 | U7: 0.27 | V7: 0.3 | W7: 0.33 | X7: 0.39 | Y7: 0.46 | Z7: 0.59 | AA7: 1
A8: Messiah 2024 | B8: =AVERAGE(B31:B33) -> 300.33333 | C8: =AVERAGE(C31:C33) -> 322.33333 | D8: =AVERAGE(D31:D33) -> 360 | E8: =AVERAGE(E31:E33) -> 395.66667 | F8: =AVERAGE(F31:F33) -> 431 | G8: =AVERAGE(G31:G33) -> 486.33333 | H8: =AVERAGE(H31:H33) -> 568.33333 | I8: =AVERAGE(I31:I33) -> 667 | ... L8: =AVERAGE(L31:L33) -> 1146
A9: Messiah 2023 | B9: =AVERAGE(B41:B43) -> 338 | C9: =AVERAGE(C41:C43) -> 372 | D9: =AVERAGE(D41:D43) -> 411 | E9: =AVERAGE(E41:E43) -> 447.33333 | F9: =AVERAGE(F41:F43) -> 494.66667 | G9: =AVERAGE(G41:G43) -> 557 | H9: =AVERAGE(H41:H43) -> 657.66667 | I9: =AVERAGE(I41:I43) -> 738.33333 | ... L9: =AVERAGE(L41:L43) -> 1180.3333
A10: Avg/Show vs Target Pace: | B10: =IF(B4>0,AVERAGE(B4:B6)-B8,"TBD") -> 82.333333 | C10: =IF(C4>0,AVERAGE(C4:C6)-C8,"TBD") -> TBD | D10: =IF(D4>0,AVERAGE(D4:D6)-D8,"TBD") -> TBD | E10: =IF(E4>0,AVERAGE(E4:E6)-E8,"TBD") -> TBD | F10: =IF(F4>0,AVERAGE(F4:F6)-F8,"TBD") -> TBD | G10: =IF(G4>0,AVERAGE(G4:G6)-G8,"TBD") -> TBD | H10: =IF(H4>0,AVERAGE(H4:H6)-H8,"TBD") -> TBD | I10: =IF(I4>0,AVERAGE(I4:I6)-I8,"TBD") -> TBD | ... L10: =IF(L4>0,AVERAGE(L4:L6)-L8,"TBD") -> TBD
M11: OCC Target
M12: 0.85
A29: Single Tickets | B29: 10 | C29: 9 | D29: 8 | E29: 7 | F29: 6 | G29: 5 | H29: 4 | I29: 3 | J29: 2 | K29: 1 | L29: 0
A30: Handel's Messiah | B30: 45558 | C30: 45565 | D30: 45572 | E30: 45579 | F30: 45586 | G30: 45593 | H30: 45600 | I30: 45607 | J30: 45614 | K30: 45621 | L30: 45628 | M30: # Single Tickets to sell out 100% | N30: Final Occupancy Sold %
A31: 12/06/2024 Sales (Friday) | B31: 269 | C31: 295 | D31: 314 | E31: 335 | F31: 385 | G31: 425 | H31: 522 | I31: 615 | J31: 771 | K31: 912 | L31: 1078 | M31: 1450 | N31: 0.8834
A32: 12/07/2024 Sales (Saturday) | B32: 318 | C32: 333 | D32: 368 | E32: 392 | F32: 424 | G32: 483 | H32: 549 | I32: 660 | J32: 751 | K32: 918 | L32: 1127 | M32: 1450 | N32: 0.9662
A33: 12/08/2024 Sales (Sunday) | B33: 314 | C33: 339 | D33: 398 | E33: 460 | F33: 484 | G33: 551 | H33: 634 | I33: 726 | J33: 849 | K33: 1033 | L33: 1233 | M33: 1450 | N33: 0.9751
A34: Pace for 85% OCC
A35: Avg/Show vs Target Pace:
M36: OCC Target
M37: 0.85
A39: Single Tickets | B39: 10 | C39: 9 | D39: 8 | E39: 7 | F39: 6 | G39: 5 | H39: 4 | I39: 3 | J39: 2 | K39: 1 | L39: 0
A40: Handel's Messiah | B40: 45187 | C40: 45194 | D40: 45201 | E40: 45208 | F40: 45215 | G40: 45222 | H40: 45229 | I40: 45236 | J40: 45243 | K40: 45250 | L40: 45988 | M40: # Single Tickets to sell out 100% | N40: Final Occupancy Sold %
A41: 12/01/2023 Sales (Friday) | B41: 292 | C41: 312 | D41: 345 | E41: 367 | F41: 421 | G41: 468 | H41: 562 | I41: 635 | J41: 855 | K41: 992 | L41: 1129 | M41: 1450 | N41: 0.9434
A42: 12/02/2023 Sales (Saturday) | B42: 345 | C42: 396 | D42: 439 | E42: 495 | F42: 538 | G42: 590 | H42: 693 | I42: 784 | J42: 929 | K42: 1043 | L42: 1153 | M42: 1450 | N42: 0.991
A43: 12/03/2023 Sales (Sunday) | B43: 377 | C43: 408 | D43: 449 | E43: 480 | F43: 525 | G43: 613 | H43: 718 | I43: 796 | J43: 945 | K43: 1105 | L43: 1259 | M43: 1450 | N43: 1
A44: Avg/Show vs Target Pace:
M45: OCC Target
M46: 0.85

Sheet XMas Festival
D1: # weeks out
A2: Single Tickets | B2: 10 | C2: 9 | D2: 8 | E2: 7 | F2: 6 | G2: 5 | H2: 4 | I2: 3 | J2: 2 | K2: 1 | L2: 0 | Q2: Estimates Only | U2: Historical Data
A3: Christmas Festival | B3: 45936 | C3: 45943 | D3: 45950 | E3: 45957 | F3: 45964 | G3: 45971 | H3: 45978 | I3: 45985 | J3: 45992 | K3: 45999 | L3: 46006 | M3: # Single Tickets to sell out 100% | N3: Projected OCC% | P3: # Weeks Until Performance | Q3: 10 | R3: 9 | S3: 8 | T3: 7 | U3: 6 | V3: 5 | W3: 4 | X3: 3 | Y3: 2 | Z3: 1 | AA3: 0
A4: 12/18/2025 (Thu) | M4: ='Performances by Week'!AB43-'Performances by Week'!X43 -> 1433 | N4: ='Performances by Week'!K43 -> Too early | P4: Classical | Q4: 0.15 | R4: 0.18 | S4: 0.21 | T4: 0.24 | U4: 0.27 | V4: 0.3 | W4: 0.33 | X4: 0.39 | Y4: 0.46 | Z4: 0.59 | AA4: 1
A5: 12/19/2025 (Fri) | M5: ='Performances by Week'!AB44-'Performances by Week'!X44 -> 1433 | N5: ='Performances by Week'!K44 -> Too early | P5: Pops | Q5: 0.15 | R5: 0.18 | S5: 0.21 | T5: 0.24 | U5: 0.27 | V5: 0.3 | W5: 0.33 | X5: 0.39 | Y5: 0.46 | Z5: 0.59 | AA5: 1
A6: 12/20/2025 (Sat 1) | M6: ='Performances by Week'!AB45-'Performances by Week'!X45 -> 1433 | N6: ='Performances by Week'!K45 -> Too early | P6: Specials | Q6: 0.15 | R6: 0.18 | S6: 0.21 | T6: 0.24 | U6: 0.27 | V6: 0.3 | W6: 0.33 | X6: 0.39 | Y6: 0.46 | Z6: 0.59 | AA6: 1
A7: 12/20/2025 (Sat 2) | M7: ='Performances by Week'!AB46-'Performances by Week'!X46 -> 1433 | N7: ='Performances by Week'!K46 -> Too early | P7: Other | Q7: 0.15 | R7: 0.18 | S7: 0.21 | T7: 0.24 | U7: 0.27 | V7: 0.3 | W7: 0.33 | X7: 0.39 | Y7: 0.46 | Z7: 0.59 | AA7: 1
A8: 12/21/2025 (Sun 1) | M8: ='Performances by Week'!AB47-'Performances by Week'!X47 -> 1132 | N8: ='Performances by Week'!K47 -> Too early
A9: 12/21/2025 (Sun 2) | M9: ='Performances by Week'!AB48-'Performances by Week'!X48 -> 1433 | N9: ='Performances by Week'!K48 -> Too early
A10: Pace for 85% OCC | B10: =$M$10*$M$15*Q6 -> 176.31125 | C10: =$M$10*$M$15*R6 -> 211.5735 | D10: =$M$10*$M$15*S6 -> 246.83575 | E10: =$M$10*$M$15*T6 -> 282.098 | F10: =$M$10*$M$15*U6 -> 317.36025 | G10: =$M$10*$M$15*V6 -> 352.6225 | H10: =$M$10*$M$15*W6 -> 387.88475 | I10: =$M$10*$M$15*X6 -> 458.40925 | ... L10: =$M$10*$M$15*AA6 -> 1175.4083 | M10: =AVERAGE(M4:M9) -> 1382.8333
A11: XMas 2024 | B11: =AVERAGE(B34:B39) -> 261.33333 | C11: =AVERAGE(C34:C39) -> 282.66667 | D11: =AVERAGE(D34:D39) -> 315.5 | E11: =AVERAGE(E34:E39) -> 360.16667 | F11: =AVERAGE(F34:F39) -> 412.16667 | G11: =AVERAGE(G34:G39) -> 494.33333 | H11: =AVERAGE(H34:H39) -> 597.83333 | I11: =AVERAGE(I34:I39) -> 699.5 | ... L11: =AVERAGE(L34:L39) -> 1111.3333
A12: XMas 2023 | B12: =AVERAGE(B45:B50) -> 349.16667 | C12: =AVERAGE(C45:C50) -> 378.16667 | D12: =AVERAGE(D45:D50) -> 414.66667 | E12: =AVERAGE(E45:E50) -> 459.16667 | F12: =AVERAGE(F45:F50) -> 530.83333 | G12: =AVERAGE(G45:G50) -> 599.66667 | H12: =AVERAGE(H45:H50) -> 709 | I12: =AVERAGE(I45:I50) -> 795.5 | ... L12: =AVERAGE(L45:L50) -> 1105.8333
A13: Avg/Show vs Target Pace: | B13: =IF(B4>0,AVERAGE(B4:B9)-B10,"TBD") -> TBD | C13: =IF(C4>0,AVERAGE(C4:C9)-C10,"TBD") -> TBD | D13: =IF(D4>0,AVERAGE(D4:D9)-D10,"TBD") -> TBD | E13: =IF(E4>0,AVERAGE(E4:E9)-E10,"TBD") -> TBD | F13: =IF(F4>0,AVERAGE(F4:F9)-F10,"TBD") -> TBD | G13: =IF(G4>0,AVERAGE(G4:G9)-G10,"TBD") -> TBD | H13: =IF(H4>0,AVERAGE(H4:H9)-H10,"TBD") -> TBD | I13: =IF(I4>0,AVERAGE(I4:I9)-I10,"TBD") -> TBD | ... L13: =IF(L4>0,AVERAGE(L4:L9)-L10,"TBD") -> TBD
M14: OCC Target
M15: 0.85
A32: Single Tickets | B32: 10 | C32: 9 | D32: 8 | E32: 7 | F32: 6 | G32: 5 | H32: 4 | I32: 3 | J32: 2 | K32: 1 | L32: 0
A33: Christmas Festival | B33: 45572 | C33: 45579 | D33: 45586 | E33: 45593 | F33: 45600 | G33: 45607 | H33: 45614 | I33: 45621 | J33: 45628 | K33: 45635 | L33: 45642 | M33: # Single Tickets to sell out 100% | N33: Final Occupancy Sold %
A34: 12/19/2024 Sales (Thursday) | B34: 261 | C34: 267 | D34: 297 | E34: 341 | F34: 395 | G34: 447 | H34: 602 | I34: 693 | J34: 750 | K34: 932 | L34: 1069 | M34: 1446 | N34: 0.7897
A35: 12/20/2024 Sales (Friday) | B35: 206 | C35: 216 | D35: 256 | E35: 310 | F35: 370 | G35: 432 | H35: 509 | I35: 605 | J35: 732 | K35: 848 | L35: 1052 | M35: 1476 | N35: 0.8741
A36: 12/21/2024, 1pm Sales (Saturday) | B36: 349 | C36: 398 | D36: 427 | E36: 464 | F36: 526 | G36: 606 | H36: 670 | I36: 745 | J36: 848 | K36: 1034 | L36: 1180 | M36: 1476 | N36: 0.8934
A37: 12/21/2024, 7pm Sales (Saturday) | B37: 276 | C37: 294 | D37: 340 | E37: 375 | F37: 400 | G37: 480 | H37: 584 | I37: 715 | J37: 844 | K37: 995 | L37: 1184 | M37: 1476 | N37: 0.9591
A38: 12/22/2024, 2pm Sales (Sunday) | B38: 302 | C38: 336 | D38: 363 | E38: 411 | F38: 486 | G38: 624 | H38: 730 | I38: 857 | J38: 986 | K38: 1089 | L38: 1104 | M38: 1168 | N38: 0.9412
A39: 12/22/2024, 7pm Sales (Sunday) | B39: 174 | C39: 185 | D39: 210 | E39: 260 | F39: 296 | G39: 377 | H39: 492 | I39: 582 | J39: 677 | K39: 833 | L39: 1079 | M39: 1476 | N39: 0.9751
M40: OCC Target
M41: 0.85
A43: Single Tickets | B43: 10 | C43: 9 | D43: 8 | E43: 7 | F43: 6 | G43: 5 | H43: 4 | I43: 3 | J43: 2 | K43: 1 | L43: 0
A44: Christmas Festival | B44: 45201 | C44: 45208 | D44: 45215 | E44: 45222 | F44: 45229 | G44: 45236 | H44: 45243 | I44: 45250 | J44: 45988 | K44: 45995 | L44: 46002 | M44: # Single Tickets to sell out 100% | N44: Final Occupancy Sold %
