Workbook

Sheet Performances by Week
E1: Status: | F1: Updated 9/1 | H1: Denotes Piazza | I1: Update all fields in Blue each week | J1: We expect 50% of Single Sales 1 Week Prior | K1: 85%+ occupancy | O1: 95%+ of Budget | S1: 100%+ of Target
K2: 70-85% occupancy | O2: 85-95% of Budget | S2: 90-99% of Target
G3: Week # | K3: <70% occupancy | O3: <85% of Budget | S3: <90% of Target
D4: TICKET SALES REPORT as of 9/1/2025 | G4: 1 | I4: TOTAL SALES (Singles + Subs) | P4: Single Tickets | X4: Subscription Tickets | AB4: Hall Data | AE4: Audience Data | AH4: Revenue last week | AI4: Increase over week
A5: Wk # | B5: # Weeks Until Perf | C5: Perf. Week (Mon) | D5: Performance | G5: Performance Date(s) | H5: Performance Type | I5: Actual Total Tickets Sold | J5: Projected Single Tickets + Actual Subs | K5: Projected Total OCC at Performance | L5: Total Actual Revenue | M5: TOTAL BUDGET | N5: Actual/ Budget % | O5: Projected/ Budget % | P5: Actual Single Tickets Sold | Q5: Target Single Tickets for 85% OCC | R5: Projected Tickets | S5: Projected Single Tickets vs 85% OCC Target | T5: Actual Revenue | U5: BUDGET | V5: Actual/ Budget % | W5: Projected/ Budget % | X5: Actual Sub Tickets Sold | Y5: Actual Revenue | Z5: BUDGET | AA5: Actual vs Budget % | AB5: Max CAP | AC5: Actual OCC SOLD | AD5: Single Ticket ATP | AE5: # New HH | AF5: # Ret HH | AG5: # Total HH
A6: 1 | B6: =A6-$G$4 -> 0 | C6: 45901 | D6: 26 Morgan Freeman's Symphonic Blues | G6: 45902.833 | H6: Specials | I6: =P6+X6 -> 1153 | J6: =IF(R6="Too early",R6,R6+X6) -> 1153 | K6: =IF(J6="Too early",J6,J6/AB6) -> 0.88556068 | L6: =T6+Y6 -> 130808 | M6: =U6+Z6 -> 153473 | N6: =L6/M6 -> 0.8523193 | O6: =IF($J6="Too early",J6,J6*AD6/M6) -> 0.8523193 | P6: 1153 | Q6: =AB6-X6 -> 1302 | R6: =IF(B6<7,(P6/VLOOKUP(B6,'Sales Pacing'!$A$23:$E$36,2)),"Too early") -> 1153 | S6: =IF(R6="Too early","Too early",R6/Q6) -> 0.88556068 | T6: 130808 | U6: 153473 | V6: =IF(T6>0,T6/U6,"") -> 0.8523193 | W6: =IF($R6="Too early",R6,R6*AD6/U6) -> 0.8523193 | Z6: 0 | AA6: =IF(Y6>0,Y6/Z6,"") | AB6: 1302 | AC6: =I6/AB6 -> 0.88556068 | AD6: =L6/I6 -> 113.45013 | AE6: 209 | AF6: 280 | AG6: 489 | AH6: 121597 | AI6: =L6-AH6 -> 9211
A7: 1 | B7: =A7-$G$4 -> 0 | C7: 45901 | D7: 26 Morgan Freeman's Symphonic Blues | G7: 45903.833 | H7: Specials | I7: =P7+X7 -> 1084 | J7: =IF(R7="Too early",R7,R7+X7) -> 1084 | K7: =IF(J7="Too early",J7,J7/AB7) -> 0.83256528 | L7: =T7+Y7 -> 123301 | M7: =U7+Z7 -> 153473 | N7: =L7/M7 -> 0.80340516 | O7: =IF($J7="Too early",J7,J7*AD7/M7) -> 0.80340516 | P7: 1084 | Q7: =AB7-X7 -> 1302 | R7: =IF(B7<7,(P7/VLOOKUP(B7,'Sales Pacing'!$A$23:$E$36,2)),"Too early") -> 1084 | S7: =IF(R7="Too early","Too early",R7/Q7) -> 0.83256528 | T7: 123301 | U7: 153473 | V7: =IF(T7>0,T7/U7,"") -> 0.80340516 | W7: =IF($R7="Too early",R7,R7*AD7/U7) -> 0.80340516 | Z7: 0 | AA7: =IF(Y7>0,Y7/Z7,"") | AB7: 1302 | AC7: =I7/AB7 -> 0.83256528 | AD7: =L7/I7 -> 113.74631 | AE7: 186 | AF7: 268 | AG7: 454 | AH7: 111049 | AI7: =L7-AH7 -> 12252
A8: 1 | B8: =A8-$G$4 -> 0 | C8: 45901 | D8: 26 La nuit sombre | G8: 45905.833 | H8: Specials | I8: =P8+X8 -> 662 | J8: =IF(R8="Too early",R8,R8+X8) -> 662 | K8: =IF(J8="Too early",J8,J8/AB8) -> 1.1033333 | L8: =T8+Y8 -> 18755 | M8: =U8+Z8 -> 15000 | N8: =L8/M8 -> 1.2503333 | O8: =IF($J8="Too early",J8,J8*AD8/M8) -> 1.2503333 | P8: 662 | Q8: =AB8-X8 -> 600 | R8: =IF(B8<7,(P8/VLOOKUP(B8,'Sales Pacing'!$A$23:$E$36,2)),"Too early") -> 662 | S8: =IF(R8="Too early","Too early",R8/Q8) -> 1.1033333 | T8: 18755 | U8: 15000 | V8: =IF(T8>0,T8/U8,"") -> 1.2503333 | W8: =IF($R8="Too early",R8,R8*AD8/U8) -> 1.2503333 | Z8: 0 | AA8: =IF(Y8>0,Y8/Z8,"") | AB8: 600 | AC8: =I8/AB8 -> 1.1033333 | AD8: =L8/I8 -> 28.330816 | AE8: 77 | AF8: 203 | AG8: 280 | AH8: 17555 | AI8: =L8-AH8 -> 1200
A9: 2 | B9: =A9-$G$4 -> 1 | C9: 45908 | D9: OPEN - Recording Week | I9: =P9+X9 -> 0 | J9: =IF(R9="Too early",R9,R9+X9) -> 0 | N9: =L9/M9 -> #DIV/0! | R9: =IF(B9<7,(P9/VLOOKUP(B9,'Sales Pacing'!$A$23:$E$36,2)),"Too early") -> 0 | V9: =IF(T9>0,T9/U9,"") | AA9: N/A | AC9: =I9/AB9 -> #DIV/0!
A10: 3 | B10: =A10-$G$4 -> 2 | C10: 45915 | D10: 26 PS1 Music of Journey | G10: 45919.833 | H10: Pops | I10: =P10+X10 -> 960 | J10: =IF(R10="Too early",R10,R10+X10) -> 1278.1304 | K10: =IF(J10="Too early",J10,J10/AB10) -> 0.80385562 | L10: =T10+Y10 -> 66728.1 | M10: =U10+Z10 -> 100666 | N10: =L10/M10 -> 0.66286631 | O10: =IF($J10="Too early",J10,J10*AD10/M10) -> 0.88253084 | P10: 271 | Q10: =AB10-X10 -> 901 | R10: =IF(B10<7,(P10/VLOOKUP(B10,'Sales Pacing'!$A$23:$E$36,2)),"Too early") -> 589.13043 | S10: =IF(R10="Too early","Too early",R10/Q10) -> 0.65386286 | T10: 17322 | U10: 59333 | V10: =IF(T10>0,T10/U10,"") -> 0.29194546 | W10: =IF($R10="Too early",R10,R10*AD10/U10) -> 0.6901646 | X10: 689 | Y10: 49406.1 | Z10: 41333 | AA10: =IF(Y10>0,Y10/Z10,"") -> 1.1953185 | AB10: 1590 | AC10: =I10/AB10 -> 0.60377358 | AD10: =L10/I10 -> 69.508437 | AE10: 38 | AF10: 402 | AG10: 440 | AH10: 63589.3 | AI10: =L10-AH10 -> 3138.8
A11: 3 | B11: =A11-$G$4 -> 2 | C11: 45915 | D11: 26 PS1 Music of Journey | G11: 45920.833 | H11: Pops | I11: =P11+X11 -> 911 | J11: =IF(R11="Too early",R11,R11+X11) -> 1260.8261 | K11: =IF(J11="Too early",J11,J11/AB11) -> 0.79297238 | L11: =T11+Y11 -> 64763.8 | M11: =U11+Z11 -> 100667 | N11: =L11/M11 -> 0.64334688 | O11: =IF($J11="Too early",J11,J11*AD11/M11) -> 0.89039355 | P11: 298 | Q11: =AB11-X11 -> 977 | R11: =IF(B11<7,(P11/VLOOKUP(B11,'Sales Pacing'!$A$23:$E$36,2)),"Too early") -> 647.82609 | S11: =IF(R11="Too early","Too early",R11/Q11) -> 0.66307685 | T11: 20387 | U11: 59333 | V11: =IF(T11>0,T11/U11,"") -> 0.34360305 | W11: =IF($R11="Too early",R11,R11*AD11/U11) -> 0.77620435 | X11: 613 | Y11: 44376.8 | Z11: 41334 | AA11: =IF(Y11>0,Y11/Z11,"") -> 1.0736149 | AB11: 1590 | AC11: =I11/AB11 -> 0.57295597 | AD11: =L11/I11 -> 71.090889 | AE11: 51 | AF11: 354 | AG11: 405 | AH11: 62401.3 | AI11: =L11-AH11 -> 2362.5
A12: 3 | B12: =A12-$G$4 -> 2 | C12: 45915 | D12: 26 PS1 Music of Journey | G12: 45921.583 | H12: Pops | I12: =P12+X12 -> 706 | J12: =IF(R12="Too early",R12,R12+X12) -> 1095.7391 | K12: =IF(J12="Too early",J12,J12/AB12) -> 0.68914411 | L12: =T12+Y12 -> 47103.8 | M12: =U12+Z12 -> 100666 | N12: =L12/M12 -> 0.46792164 | O12: =IF($J12="Too early",J12,J12*AD12/M12) -> 0.72623237 | P12: 332 | Q12: =AB12-X12 -> 1216 | R12: =IF(B12<7,(P12/VLOOKUP(B12,'Sales Pacing'!$A$23:$E$36,2)),"Too early") -> 721.73913 | S12: =IF(R12="Too early","Too early",R12/Q12) -> 0.59353547 | T12: 21628 | U12: 59333 | V12: =IF(T12>0,T12/U12,"") -> 0.3645189 | W12: =IF($R12="Too early",R12,R12*AD12/U12) -> 0.8115872 | X12: 374 | Y12: 25475.8 | Z12: 41333 | AA12: =IF(Y12>0,Y12/Z12,"") -> 0.61635497 | AB12: 1590 | AC12: =I12/AB12 -> 0.44402516 | AD12: =L12/I12 -> 66.719263 | AE12: 53 | AF12: 253 | AG12: 306 | AH12: 45027.8 | AI12: =L12-AH12 -> 2076
A13: 4 | B13: =A13-$G$4 -> 3 | C13: 45922 | D13: 26 FS1 The Orchestra Games | G13: 45928.583 | H13: Family | I13: =P13+X13 -> 444 | J13: =IF(R13="Too early",R13,R13+X13) -> 677.05128 | K13: =IF(J13="Too early",J13,J13/AB13) -> 0.52000867 | L13: =T13+Y13 -> 11640 | M13: =U13+Z13 -> 19500 | N13: =L13/M13 -> 0.59692308 | O13: =IF($J13="Too early",J13,J13*AD13/M13) -> 0.91024219 | P13: 149 | Q13: =AB13-X13 -> 1007 | R13: =IF(B13<7,(P13/VLOOKUP(B13,'Sales Pacing'!$A$23:$E$36,2)),"Too early") -> 382.05128 | S13: =IF(R13="Too early","Too early",R13/Q13) -> 0.37939551 | T13: 5057 | U13: 10000 | V13: =IF(T13>0,T13/U13,"") -> 0.5057 | W13: =IF($R13="Too early",R13,R13*AD13/U13) -> 1.0015939 | X13: 295 | Y13: 6583 | Z13: 9500 | AA13: =IF(Y13>0,Y13/Z13,"") -> 0.69294737 | AB13: 1302 | AC13: =I13/AB13 -> 0.34101382 | AD13: =L13/I13 -> 26.216216 | AE13: 15 | AF13: 88 | AG13: 103 | AH13: 11177 | AI13: =L13-AH13 -> 463
A14: 5 | B14: =A14-$G$4 -> 4 | C14: 45929 | D14: Chicken Fried | G14: 45934 | H14: Specials | I14: =P14+X14 -> 171 | J14: =IF(R14="Too early",R14,R14+X14) -> 518.18182 | K14: =IF(J14="Too early",J14,J14/AB14) -> 0.32590051 | L14: =T14+Y14 -> 12321 | M14: =U14+Z14 -> 58000 | N14: =L14/M14 -> 0.21243103 | O14: =IF($J14="Too early",J14,J14*AD14/M14) -> 0.64373041 | P14: 171 | Q14: =AB14-X14 -> 1590 | R14: =IF(B14<7,(P14/VLOOKUP(B14,'Sales Pacing'!$A$23:$E$36,2)),"Too early") -> 518.18182 | S14: =IF(R14="Too early","Too early",R14/Q14) -> 0.32590051 | T14: 12321 | U14: 58000 | V14: =IF(T14>0,T14/U14,"") -> 0.21243103 | W14: =IF($R14="Too early",R14,R14*AD14/U14) -> 0.64373041 | AA14: =IF(Y14>0,Y14/Z14,"") | AB14: 1590 | AC14: =I14/AB14 -> 0.10754717 | AD14: =L14/I14 -> 72.052632 | AE14: 6 | AF14: 62 | AG14: 68 | AH14: 10596 | AI14: =L14-AH14 -> 1725
A15: 6 | B15: =A15-$G$4 -> 5 | C15: 45936 | D15: 26 CS01 Appalachian Spring | G15: 45940.833 | H15: Classical | I15: =P15+X15 -> 692 | J15: =IF(R15="Too early",R15,R15+X15) -> 1037.3333 | K15: =IF(J15="Too early",J15,J15/AB15) -> 0.72388928 | L15: =T15+Y15 -> 45390 | M15: 100000 | N15: =L15/M15 -> 0.4539 | O15: =IF($J15="Too early",J15,J15*AD15/M15) -> 0.68041272 | P15: 148 | Q15: =AB15-X15 -> 889 | R15: =IF(B15<7,(P15/VLOOKUP(B15,'Sales Pacing'!$A$23:$E$36,2)),"Too early") -> 493.33333 | S15: =IF(R15="Too early","Too early",R15/Q15) -> 0.55493063 | T15: 8956 | U15: 16666 | V15: =IF(T15>0,T15/U15,"") -> 0.5373815 | W15: =IF($R15="Too early",R15,R15*AD15/U15) -> 1.9416152 | X15: 544 | Y15: 36434 | Z15: 33333 | AA15: =IF(Y15>0,Y15/Z15,"") -> 1.0930309 | AB15: 1433 | AC15: =I15/AB15 -> 0.482903 | AD15: =L15/I15 -> 65.592486 | AE15: 11 | AF15: 343 | AG15: 354 | AH15: 43762.3 | AI15: =L15-AH15 -> 1627.7
A16: 6 | B16: =A16-$G$4 -> 5 | C16: 45936 | D16: 26 CS01 Appalachian Spring | G16: 45941.833 | H16: Classical | I16: =P16+X16 -> 746 | J16: =IF(R16="Too early",R16,R16+X16) -> 1121.6667 | K16: =IF(J16="Too early",J16,J16/AB16) -> 0.78274017 | L16: =T16+Y16 -> 49773.1 | M16: 100000 | N16: =L16/M16 -> 0.497731 | O16: =IF($J16="Too early",J16,J16*AD16/M16) -> 0.7483757 | P16: 161 | Q16: =AB16-X16 -> 848 | R16: =IF(B16<7,(P16/VLOOKUP(B16,'Sales Pacing'!$A$23:$E$36,2)),"Too early") -> 536.66667 | S16: =IF(R16="Too early","Too early",R16/Q16) -> 0.63286164 | T16: 10192 | U16: 16666 | V16: =IF(T16>0,T16/U16,"") -> 0.61154446 | W16: =IF($R16="Too early",R16,R16*AD16/U16) -> 2.1484691 | X16: 585 | Y16: 39581.1 | Z16: 33333 | AA16: =IF(Y16>0,Y16/Z16,"") -> 1.1874449 | AB16: 1433 | AC16: =I16/AB16 -> 0.52058618 | AD16: =L16/I16 -> 66.719973 | AE16: 16 | AF16: 366 | AG16: 382 | AH16: 48541.1 | AI16: =L16-AH16 -> 1232
A17: 6 | B17: =A17-$G$4 -> 5 | C17: 45936 | D17: 26 CS01 Appalachian Spring | G17: 45942.583 | H17: Classical | I17: =P17+X17 -> 804 | J17: =IF(R17="Too early",R17,R17+X17) -> 1266 | K17: =IF(J17="Too early",J17,J17/AB17) -> 0.88346127 | L17: =T17+Y17 -> 52146.6 | M17: 100000 | N17: =L17/M17 -> 0.521466 | O17: =IF($J17="Too early",J17,J17*AD17/M17) -> 0.82111437 | P17: 198 | Q17: =AB17-X17 -> 827 | R17: =IF(B17<7,(P17/VLOOKUP(B17,'Sales Pacing'!$A$23:$E$36,2)),"Too early") -> 660 | S17: =IF(R17="Too early","Too early",R17/Q17) -> 0.7980653 | T17: 12884 | U17: 16666 | V17: =IF(T17>0,T17/U17,"") -> 0.77307092 | W17: =IF($R17="Too early",R17,R17*AD17/U17) -> 2.5685174 | X17: 606 | Y17: 39262.6 | Z17: 33334 | AA17: =IF(Y17>0,Y17/Z17,"") -> 1.1778544 | AB17: 1433 | AC17: =I17/AB17 -> 0.56106071 | AD17: =L17/I17 -> 64.858955 | AE17: 16 | AF17: 424 | AG17: 440 | AH17: 51198.6 | AI17: =L17-AH17 -> 948
A18: 7 | B18: =A18-$G$4 -> 6 | C18: 45943 | D18: 26 Top Gun: Maverick in Concert | G18: 45947.792 | H18: Specials/Film | I18: =P18+X18 -> 592 | J18: =IF(R18="Too early",R18,R18+X18) -> 2192.5926 | K18: =IF(J18="Too early",J18,J18/AB18) -> 1.6840189 | L18: =T18+Y18 -> 44890 | M18: =U18+Z18 -> 103497 | N18: =L18/M18 -> 0.43373238 | O18: =IF($J18="Too early",J18,J18*AD18/M18) -> 1.6064162 | P18: 592 | Q18: =AB18-X18 -> 1302 | R18: =IF(B18<7,(P18/VLOOKUP(B18,'Sales Pacing'!$A$23:$E$36,2)),"Too early") -> 2192.5926 | S18: =IF(R18="Too early","Too early",R18/Q18) -> 1.6840189 | T18: 44890 | U18: 103497 | V18: =IF(T18>0,T18/U18,"") -> 0.43373238 | W18: =IF($R18="Too early",R18,R18*AD18/U18) -> 1.6064162 | AA18: =IF(Y18>0,Y18/Z18,"") | AB18: 1302 | AC18: =I18/AB18 -> 0.4546851 | AD18: =L18/I18 -> 75.827703 | AE18: 47 | AF18: 175 | AG18: 222 | AH18: 41731.5 | AI18: =L18-AH18 -> 3158.5
A19: 7 | B19: =A19-$G$4 -> 6 | C19: 45943 | D19: 26 Top Gun: Maverick in Concert | G19: 45948.792 | H19: Specials/Film | I19: =P19+X19 -> 707 | J19: =IF(R19="Too early",R19,R19+X19) -> 2618.5185 | K19: =IF(J19="Too early",J19,J19/AB19) -> 2.0111509 | L19: =T19+Y19 -> 53528 | M19: =U19+Z19 -> 103497 | N19: =L19/M19 -> 0.51719374 | O19: =IF($J19="Too early",J19,J19*AD19/M19) -> 1.9155324 | P19: 707 | Q19: =AB19-X19 -> 1302 | R19: =IF(B19<7,(P19/VLOOKUP(B19,'Sales Pacing'!$A$23:$E$36,2)),"Too early") -> 2618.5185 | S19: =IF(R19="Too early","Too early",R19/Q19) -> 2.0111509 | T19: 53528 | U19: 103497 | V19: =IF(T19>0,T19/U19,"") -> 0.51719374 | W19: =IF($R19="Too early",R19,R19*AD19/U19) -> 1.9155324 | AA19: =IF(Y19>0,Y19/Z19,"") | AB19: 1302 | AC19: =I19/AB19 -> 0.54301075 | AD19: =L19/I19 -> 75.711457 | AH19: 50068 | AI19: =L19-AH19 -> 3460
A20: 7 | B20: =A20-$G$4 -> 6 | C20: 45943 | D20: 26 Top Gun: Maverick in Concert | G20: 45949.583 | H20: Specials/Film | I20: =P20+X20 -> 492 | J20: =IF(R20="Too early",R20,R20+X20) -> 1822.2222 | K20: =IF(J20="Too early",J20,J20/AB20) -> 1.3995562 | L20: =T20+Y20 -> 37634 | M20: =U20+Z20 -> 103496 | N20: =L20/M20 -> 0.36362758 | O20: =IF($J20="Too early",J20,J20*AD20/M20) -> 1.3467688 | P20: 492 | Q20: =AB20-X20 -> 1302 | R20: =IF(B20<7,(P20/VLOOKUP(B20,'Sales Pacing'!$A$23:$E$36,2)),"Too early") -> 1822.2222 | S20: =IF(R20="Too early","Too early",R20/Q20) -> 1.3995562 | T20: 37634 | U20: 103496 | V20: =IF(T20>0,T20/U20,"") -> 0.36362758 | W20: =IF($R20="Too early",R20,R20*AD20/U20) -> 1.3467688 | AA20: =IF(Y20>0,Y20/Z20,"") | AB20: 1302 | AC20: =I20/AB20 -> 0.37788018 | AD20: =L20/I20 -> 76.49187 | AH20: 36255 | AI20: =L20-AH20 -> 1379
A21: 8 | B21: =A21-$G$4 -> 7 | C21: 45950 | D21: 26 The Lodger | G21: 45952.792 | H21: Specials/Film | I21: =P21+X21 -> 193 | J21: =IF(R21="Too early",R21,R21+X21) -> Too early | K21: =IF(J21="Too early",J21,J21/AB21) -> Too early | L21: =T21+Y21 -> 9678 | M21: =U21+Z21 -> 50000 | N21: =L21/M21 -> 0.19356 | O21: =IF($J21="Too early",J21,J21*AD21/M21) -> Too early | P21: 193 | Q21: =AB21-X21 -> 1302 | R21: =IF(B21<7,(P21/VLOOKUP(B21,'Sales Pacing'!$A$23:$E$36,2)),"Too early") -> Too early | S21: =IF(R21="Too early","Too early",R21/Q21) -> Too early | T21: 9678 | U21: 50000 | V21: =IF(T21>0,T21/U21,"") -> 0.19356 | W21: =IF($R21="Too early",R21,R21*AD21/U21) -> Too early | AA21: =IF(Y21>0,Y21/Z21,"") | AB21: 1302 | AC21: =I21/AB21 -> 0.14823349 | AD21: =L21/I21 -> 50.145078 | AH21: 9513 | AI21: =L21-AH21 -> 165
A22: 8 | B22: =A22-$G$4 -> 7 | C22: 45950 | D22: 26 PS2 Night of Symphonic 90s | G22: 45954.833 | H22: Pops | I22: =P22+X22 -> 797 | J22: =IF(R22="Too early",R22,R22+X22) -> Too early | K22: =IF(J22="Too early",J22,J22/AB22) -> Too early | L22: =T22+Y22 -> 56620.1 | M22: =U22+Z22 -> 92333 | N22: =L22/M22 -> 0.61321629 | O22: =IF($J22="Too early",J22,J22*AD22/M22) -> Too early | P22: 80 | Q22: =AB22-X22 -> 873 | R22: =IF(B22<7,(P22/VLOOKUP(B22,'Sales Pacing'!$A$23:$E$36,2)),"Too early") -> Too early | S22: =IF(R22="Too early","Too early",R22/Q22) -> Too early | T22: 4847 | U22: 53333 | V22: =IF(T22>0,T22/U22,"") -> 0.090881818 | W22: =IF($R22="Too early",R22,R22*AD22/U22) -> Too early | X22: 717 | Y22: 51773.1 | Z22: 39000 | AA22: =IF(Y22>0,Y22/Z22,"") -> 1.3275154 | AB22: 1590 | AC22: =I22/AB22 -> 0.50125786 | AD22: =L22/I22 -> 71.041531 | AE22: 7 | AF22: 348 | AG22: 355 | AH22: 55866.3 | AI22: =L22-AH22 -> 753.8
A23: 8 | B23: =A23-$G$4 -> 7 | C23: 45950 | D23: 26 PS2 Night of Symphonic 90s | G23: 45955.833 | H23: Pops | I23: =P23+X23 -> 738 | J23: =IF(R23="Too early",R23,R23+X23) -> Too early | K23: =IF(J23="Too early",J23,J23/AB23) -> Too early | L23: =T23+Y23 -> 51872.8 | M23: =U23+Z23 -> 92333 | N23: =L23/M23 -> 0.56180131 | O23: =IF($J23="Too early",J23,J23*AD23/M23) -> Too early | P23: 96 | Q23: =AB23-X23 -> 948 | R23: =IF(B23<7,(P23/VLOOKUP(B23,'Sales Pacing'!$A$23:$E$36,2)),"Too early") -> Too early | S23: =IF(R23="Too early","Too early",R23/Q23) -> Too early | T23: 5373 | U23: 53333 | V23: =IF(T23>0,T23/U23,"") -> 0.10074438 | W23: =IF($R23="Too early",R23,R23*AD23/U23) -> Too early | X23: 642 | Y23: 46499.8 | Z23: 39000 | AA23: =IF(Y23>0,Y23/Z23,"") -> 1.1923026 | AB23: 1590 | AC23: =I23/AB23 -> 0.46415094 | AD23: =L23/I23 -> 70.288347 | AE23: 9 | AF23: 315 | AG23: 324 | AH23: 50141.3 | AI23: =L23-AH23 -> 1731.5
A24: 8 | B24: =A24-$G$4 -> 7 | C24: 45950 | D24: 26 PS2 Night of Symphonic 90s | G24: 45956.583 | H24: Pops | I24: =P24+X24 -> 465 | J24: =IF(R24="Too early",R24,R24+X24) -> Too early | K24: =IF(J24="Too early",J24,J24/AB24) -> Too early | L24: =T24+Y24 -> 31093.5 | M24: =U24+Z24 -> 92333 | N24: =L24/M24 -> 0.33675392 | O24: =IF($J24="Too early",J24,J24*AD24/M24) -> Too early | P24: 83 | Q24: =AB24-X24 -> 1208 | R24: =IF(B24<7,(P24/VLOOKUP(B24,'Sales Pacing'!$A$23:$E$36,2)),"Too early") -> Too early | S24: =IF(R24="Too early","Too early",R24/Q24) -> Too early | T24: 5064 | U24: 53333 | V24: =IF(T24>0,T24/U24,"") -> 0.094950593 | W24: =IF($R24="Too early",R24,R24*AD24/U24) -> Too early | X24: 382 | Y24: 26029.5 | Z24: 39000 | AA24: =IF(Y24>0,Y24/Z24,"") -> 0.66742308 | AB24: 1590 | AC24: =I24/AB24 -> 0.29245283 | AD24: =L24/I24 -> 66.867742 | AE24: 6 | AF24: 207 | AG24: 213 | AH24: 30489 | AI24: =L24-AH24 -> 604.5
A25: 9 | B25: =A25-$G$4 -> 8 | C25: 45957 | D25: 26 On-Stage 1 | G25: 45959.833 | H25: On Stage | I25: =P25+X25 -> 23 | J25: =IF(R25="Too early",R25,R25+X25) -> Too early | K25: =IF(J25="Too early",J25,J25/AB25) -> Too early | L25: =T25+Y25 -> 2520 | M25: 11200 | N25: =L25/M25 -> 0.225 | O25: =IF($J25="Too early",J25,J25*AD25/M25) -> Too early | P25: 23 | Q25: =AB25-X25 -> 100 | R25: =IF(B25<7,(P25/VLOOKUP(B25,'Sales Pacing'!$A$23:$E$36,2)),"Too early") -> Too early | S25: =IF(R25="Too early","Too early",R25/Q25) -> Too early | T25: 2520 | U25: 11200 | V25: =IF(T25>0,T25/U25,"") -> 0.225 | W25: =IF($R25="Too early",R25,R25*AD25/U25) -> Too early | AA25: =IF(Y25>0,Y25/Z25,"") | AB25: 100 | AC25: =I25/AB25 -> 0.23 | AD25: =L25/I25 -> 109.56522 | AE25: 0 | AF25: 10 | AG25: 10 | AH25: 2520 | AI25: =L25-AH25 -> 0
A26: 9 | B26: =A26-$G$4 -> 8 | C26: 45957 | D26: 26 CS02 Rachmaninoff Cele Pt 1 | G26: 45961.833 | H26: Classical | I26: =P26+X26 -> 467 | J26: =IF(R26="Too early",R26,R26+X26) -> Too early | K26: =IF(J26="Too early",J26,J26/AB26) -> Too early | L26: =T26+Y26 -> 30782 | M26: =U26+Z26 -> 52000 | N26: =L26/M26 -> 0.59196154 | O26: =IF($J26="Too early",J26,J26*AD26/M26) -> Too early | P26: 111 | Q26: =AB26-X26 -> 1077 | R26: =IF(B26<7,(P26/VLOOKUP(B26,'Sales Pacing'!$A$23:$E$36,2)),"Too early") -> Too early | S26: =IF(R26="Too early","Too early",R26/Q26) -> Too early | T26: 5865 | U26: 22000 | V26: =IF(T26>0,T26/U26,"") -> 0.26659091 | W26: =IF($R26="Too early",R26,R26*AD26/U26) -> Too early | X26: 356 | Y26: 24917 | Z26: 30000 | AA26: =IF(Y26>0,Y26/Z26,"") -> 0.83056667 | AB26: 1433 | AC26: =I26/AB26 -> 0.32588974 | AD26: =L26/I26 -> 65.914347 | AH26: 30054 | AI26: =L26-AH26 -> 728
A27: 9 | B27: =A27-$G$4 -> 8 | C27: 45957 | D27: 26 CS02 Rachmaninoff Cele Pt 1 | G27: 45962.833 | H27: Classical | I27: =P27+X27 -> 846 | J27: =IF(R27="Too early",R27,R27+X27) -> Too early | K27: =IF(J27="Too early",J27,J27/AB27) -> Too early | L27: =T27+Y27 -> 53777 | M27: =U27+Z27 -> 86500 | N27: =L27/M27 -> 0.62169942 | O27: =IF($J27="Too early",J27,J27*AD27/M27) -> Too early | P27: 280 | Q27: =AB27-X27 -> 867 | R27: =IF(B27<7,(P27/VLOOKUP(B27,'Sales Pacing'!$A$23:$E$36,2)),"Too early") -> Too early | S27: =IF(R27="Too early","Too early",R27/Q27) -> Too early | T27: 16828 | U27: 31500 | V27: =IF(T27>0,T27/U27,"") -> 0.53422222 | W27: =IF($R27="Too early",R27,R27*AD27/U27) -> Too early | X27: 566 | Y27: 36949 | Z27: 55000 | AA27: =IF(Y27>0,Y27/Z27,"") -> 0.6718 | AB27: 1433 | AC27: =I27/AB27 -> 0.59036985 | AD27: =L27/I27 -> 63.566194 | AH27: 52200 | AI27: =L27-AH27 -> 1577
A28: 9 | B28: =A28-$G$4 -> 8 | C28: 45957 | D28: 26 CS02 Rachmaninoff Cele Pt 1 | G28: 45963.583 | H28: Classical | I28: =P28+X28 -> 757 | J28: =IF(R28="Too early",R28,R28+X28) -> Too early | K28: =IF(J28="Too early",J28,J28/AB28) -> Too early | L28: =T28+Y28 -> 47931.1 | M28: =U28+Z28 -> 86500 | N28: =L28/M28 -> 0.55411676 | O28: =IF($J28="Too early",J28,J28*AD28/M28) -> Too early | P28: 207 | Q28: =AB28-X28 -> 883 | R28: =IF(B28<7,(P28/VLOOKUP(B28,'Sales Pacing'!$A$23:$E$36,2)),"Too early") -> Too early | S28: =IF(R28="Too early","Too early",R28/Q28) -> Too early | T28: 12164 | U28: 31500 | V28: =IF(T28>0,T28/U28,"") -> 0.38615873 | W28: =IF($R28="Too early",R28,R28*AD28/U28) -> Too early | X28: 550 | Y28: 35767.1 | Z28: 55000 | AA28: =IF(Y28>0,Y28/Z28,"") -> 0.65031091 | AB28: 1433 | AC28: =I28/AB28 -> 0.52826239 | AD28: =L28/I28 -> 63.317173 | AH28: 46474.1 | AI28: =L28-AH28 -> 1457
A29: 10 | B29: =A29-$G$4 -> 9 | C29: 45964 | D29: 26 FS2 Carnival of the Animals | G29: 45970.583 | H29: Family | I29: =P29+X29 -> 415 | J29: =IF(R29="Too early",R29,R29+X29) -> Too early | K29: =IF(J29="Too early",J29,J29/AB29) -> Too early | L29: =T29+Y29 -> 10198 | M29: =U29+Z29 -> 19500 | N29: =L29/M29 -> 0.52297436 | O29: =IF($J29="Too early",J29,J29*AD29/M29) -> Too early | P29: 116 | Q29: =AB29-X29 -> 1001 | R29: =IF(B29<7,(P29/VLOOKUP(B29,'Sales Pacing'!$A$23:$E$36,2)),"Too early") -> Too early | S29: =IF(R29="Too early","Too early",R29/Q29) -> Too early | T29: 3559 | U29: 10000 | V29: =IF(T29>0,T29/U29,"") -> 0.3559 | W29: =IF($R29="Too early",R29,R29*AD29/U29) -> Too early | X29: 299 | Y29: 6639 | Z29: 9500 | AA29: =IF(Y29>0,Y29/Z29,"") -> 0.69884211 | AB29: 1300 | AC29: =I29/AB29 -> 0.31923077 | AD29: =L29/I29 -> 24.573494 | AH29: 9815 | AI29: =L29-AH29 -> 383
A30: 11 | B30: =A30-$G$4 -> 10 | C30: 45971 | D30: OPEN | I30: =P30+X30 -> 0 | J30: =IF(R30="Too early",R30,R30+X30) -> Too early | L30: =T30+Y30 -> 0 | M30: =U30+Z30 -> 0 | N30: =L30/M30 -> #DIV/0! | R30: =IF(B30<7,(P30/VLOOKUP(B30,'Sales Pacing'!$A$23:$E$36,2)),"Too early") -> Too early | V30: =IF(T30>0,T30/U30,"") | AA30: N/A | AC30: =I30/AB30 -> #DIV/0! | AD30: =L30/I30 -> #DIV/0! | AH30: 0
A31: 12 | B31: =A31-$G$4 -> 11 | C31: 45978 | D31: 26 CS03 Matthias and Mahler 7 | G31: 45982.833 | H31: Classical | I31: =P31+X31 -> 430 | J31: =IF(R31="Too early",R31,R31+X31) -> Too early | K31: =IF(J31="Too early",J31,J31/AB31) -> Too early | L31: =T31+Y31 -> 28847 | M31: =U31+Z31 -> 40000 | N31: =L31/M31 -> 0.721175 | O31: =IF($J31="Too early",J31,J31*AD31/M31) -> Too early | P31: 61 | Q31: =AB31-X31 -> 1221 | R31: =IF(B31<7,(P31/VLOOKUP(B31,'Sales Pacing'!$A$23:$E$36,2)),"Too early") -> Too early | S31: =IF(R31="Too early","Too early",R31/Q31) -> Too early | T31: 3143 | U31: 15000 | V31: =IF(T31>0,T31/U31,"") -> 0.20953333 | W31: =IF($R31="Too early",R31,R31*AD31/U31) -> Too early | X31: 369 | Y31: 25704 | Z31: 25000 | AA31: =IF(Y31>0,Y31/Z31,"") -> 1.02816 | AB31: 1590 | AC31: =I31/AB31 -> 0.27044025 | AD31: =L31/I31 -> 67.086047 | AH31: 28545 | AI31: =L31-AH31 -> 302
A32: 12 | B32: =A32-$G$4 -> 11 | C32: 45978 | D32: 26 CS03 Matthias and Mahler 7 | G32: 45983.833 | H32: Classical | I32: =P32+X32 -> 668 | J32: =IF(R32="Too early",R32,R32+X32) -> Too early | K32: =IF(J32="Too early",J32,J32/AB32) -> Too early | L32: =T32+Y32 -> 45114.9 | M32: =U32+Z32 -> 66500 | N32: =L32/M32 -> 0.67841955 | O32: =IF($J32="Too early",J32,J32*AD32/M32) -> Too early | P32: 84 | Q32: =AB32-X32 -> 1006 | R32: =IF(B32<7,(P32/VLOOKUP(B32,'Sales Pacing'!$A$23:$E$36,2)),"Too early") -> Too early | S32: =IF(R32="Too early","Too early",R32/Q32) -> Too early | T32: 5244 | U32: 11500 | V32: =IF(T32>0,T32/U32,"") -> 0.456 | W32: =IF($R32="Too early",R32,R32*AD32/U32) -> Too early | X32: 584 | Y32: 39870.9 | Z32: 55000 | AA32: =IF(Y32>0,Y32/Z32,"") -> 0.72492545 | AB32: 1590 | AC32: =I32/AB32 -> 0.42012579 | AD32: =L32/I32 -> 67.537275 | AH32: 44302.9 | AI32: =L32-AH32 -> 812
A33: 12 | B33: =A33-$G$4 -> 11 | C33: 45978 | D33: 26 CS03 Matthias and Mahler 7 | G33: 45984.583 | H33: Classical | I33: =P33+X33 -> 710 | J33: =IF(R33="Too early",R33,R33+X33) -> Too early | K33: =IF(J33="Too early",J33,J33/AB33) -> Too early | L33: =T33+Y33 -> 46272.2 | M33: =U33+Z33 -> 66500 | N33: =L33/M33 -> 0.69582256 | O33: =IF($J33="Too early",J33,J33*AD33/M33) -> Too early | P33: 87 | Q33: =AB33-X33 -> 967 | R33: =IF(B33<7,(P33/VLOOKUP(B33,'Sales Pacing'!$A$23:$E$36,2)),"Too early") -> Too early | S33: =IF(R33="Too early","Too early",R33/Q33) -> Too early | T33: 5948 | U33: 11500 | V33: =IF(T33>0,T33/U33,"") -> 0.51721739 | W33: =IF($R33="Too early",R33,R33*AD33/U33) -> Too early | X33: 623 | Y33: 40324.2 | Z33: 55000 | AA33: =IF(Y33>0,Y33/Z33,"") -> 0.73316727 | AB33: 1590 | AC33: =I33/AB33 -> 0.44654088 | AD33: =L33/I33 -> 65.172113 | AH33: 45933.2 | AI33: =L33-AH33 -> 339
A34: 13 | B34: =A34-$G$4 -> 12 | C34: 45985 | D34: 26 Elf™ in Concert | G34: 45989.792 | H34: Specials/Film | I34: =P34+X34 -> 272 | J34: =IF(R34="Too early",R34,R34+X34) -> Too early | K34: =IF(J34="Too early",J34,J34/AB34) -> Too early | L34: =T34+Y34 -> 18219 | M34: =U34+Z34 -> 107500 | N34: =L34/M34 -> 0.16947907 | O34: =IF($J34="Too early",J34,J34*AD34/M34) -> Too early | P34: 272 | Q34: =AB34-X34 -> 1302 | R34: =IF(B34<7,(P34/VLOOKUP(B34,'Sales Pacing'!$A$23:$E$36,2)),"Too early") -> Too early | S34: =IF(R34="Too early","Too early",R34/Q34) -> Too early | T34: 18219 | U34: 107500 | V34: =IF(T34>0,T34/U34,"") -> 0.16947907 | W34: =IF($R34="Too early",R34,R34*AD34/U34) -> Too early | AA34: =IF(Y34>0,Y34/Z34,"") | AB34: 1302 | AC34: =I34/AB34 -> 0.20890937 | AD34: =L34/I34 -> 66.981618 | AH34: 18219 | AI34: =L34-AH34 -> 0
A35: 13 | B35: =A35-$G$4 -> 12 | C35: 45985 | D35: 26 Elf™ in Concert | G35: 45990.542 | H35: Specials/Film | I35: =P35+X35 -> 306 | J35: =IF(R35="Too early",R35,R35+X35) -> Too early | K35: =IF(J35="Too early",J35,J35/AB35) -> Too early | L35: =T35+Y35 -> 19848 | M35: =U35+Z35 -> 107500 | N35: =L35/M35 -> 0.18463256 | O35: =IF($J35="Too early",J35,J35*AD35/M35) -> Too early | P35: 306 | Q35: =AB35-X35 -> 1302 | R35: =IF(B35<7,(P35/VLOOKUP(B35,'Sales Pacing'!$A$23:$E$36,2)),"Too early") -> Too early | S35: =IF(R35="Too early","Too early",R35/Q35) -> Too early | T35: 19848 | U35: 107500 | V35: =IF(T35>0,T35/U35,"") -> 0.18463256 | W35: =IF($R35="Too early",R35,R35*AD35/U35) -> Too early | AA35: =IF(Y35>0,Y35/Z35,"") | AB35: 1302 | AC35: =I35/AB35 -> 0.23502304 | AD35: =L35/I35 -> 64.862745 | AH35: 16760 | AI35: =L35-AH35 -> 3088
A36: 13 | B36: =A36-$G$4 -> 12 | C36: 45985 | D36: 26 Elf™ in Concert | G36: 45990.792 | H36: Specials/Film | I36: =P36+X36 -> 253 | J36: =IF(R36="Too early",R36,R36+X36) -> Too early | K36: =IF(J36="Too early",J36,J36/AB36) -> Too early | L36: =T36+Y36 -> 16912 | M36: =U36+Z36 -> 107500 | N36: =L36/M36 -> 0.15732093 | O36: =IF($J36="Too early",J36,J36*AD36/M36) -> Too early | P36: 253 | Q36: =AB36-X36 -> 1302 | R36: =IF(B36<7,(P36/VLOOKUP(B36,'Sales Pacing'!$A$23:$E$36,2)),"Too early") -> Too early | S36: =IF(R36="Too early","Too early",R36/Q36) -> Too early | T36: 16912 | U36: 107500 | V36: =IF(T36>0,T36/U36,"") -> 0.15732093 | W36: =IF($R36="Too early",R36,R36*AD36/U36) -> Too early | AA36: =IF(Y36>0,Y36/Z36,"") | AB36: 1302 | AC36: =I36/AB36 -> 0.19431644 | AD36: =L36/I36 -> 66.84585 | AH36: 15945 | AI36: =L36-AH36 -> 967
A37: 13 | B37: =A37-$G$4 -> 12 | C37: 45985 | D37: 26 Elf™ in Concert | G37: 45991.583 | H37: Specials/Film | I37: =P37+X37 -> 451 | J37: =IF(R37="Too early",R37,R37+X37) -> Too early | K37: =IF(J37="Too early",J37,J37/AB37) -> Too early | L37: =T37+Y37 -> 32022 | M37: =U37+Z37 -> 107500 | N37: =L37/M37 -> 0.29787907 | O37: =IF($J37="Too early",J37,J37*AD37/M37) -> Too early | P37: 451 | Q37: =AB37-X37 -> 1302 | R37: =IF(B37<7,(P37/VLOOKUP(B37,'Sales Pacing'!$A$23:$E$36,2)),"Too early") -> Too early | S37: =IF(R37="Too early","Too early",R37/Q37) -> Too early | T37: 32022 | U37: 107500 | V37: =IF(T37>0,T37/U37,"") -> 0.29787907 | W37: =IF($R37="Too early",R37,R37*AD37/U37) -> Too early | AA37: =IF(Y37>0,Y37/Z37,"") | AB37: 1302 | AC37: =I37/AB37 -> 0.34639017 | AD37: =L37/I37 -> 71.002217 | AH37: 29095 | AI37: =L37-AH37 -> 2927
A38: 14 | B38: =A38-$G$4 -> 13 | C38: 45992 | D38: 26 Handel's Messiah | G38: 45996.792 | H38: Holiday | I38: =P38+X38 -> 293 | J38: =IF(R38="Too early",R38,R38+X38) -> Too early | K38: =IF(J38="Too early",J38,J38/AB38) -> Too early | L38: =T38+Y38 -> 15145 | M38: =U38+Z38 -> 78333 | N38: =L38/M38 -> 0.19334125 | O38: =IF($J38="Too early",J38,J38*AD38/M38) -> Too early | P38: 293 | Q38: =AB38-X38 -> 1433 | R38: =IF(B38<7,(P38/VLOOKUP(B38,'Sales Pacing'!$A$23:$E$36,2)),"Too early") -> Too early | S38: =IF(R38="Too early","Too early",R38/Q38) -> Too early | T38: 15145 | U38: 78333 | V38: =IF(T38>0,T38/U38,"") -> 0.19334125 | W38: =IF($R38="Too early",R38,R38*AD38/U38) -> Too early | AA38: =IF(Y38>0,Y38/Z38,"") | AB38: 1433 | AC38: =I38/AB38 -> 0.20446615 | AD38: =L38/I38 -> 51.68942 | AH38: 14705.5 | AI38: =L38-AH38 -> 439.5
A39: 14 | B39: =A39-$G$4 -> 13 | C39: 45992 | D39: 26 Handel's Messiah | G39: 45997.792 | H39: Holiday | I39: =P39+X39 -> 335 | J39: =IF(R39="Too early",R39,R39+X39) -> Too early | K39: =IF(J39="Too early",J39,J39/AB39) -> Too early | L39: =T39+Y39 -> 20502 | M39: =U39+Z39 -> 78334 | N39: =L39/M39 -> 0.26172543 | O39: =IF($J39="Too early",J39,J39*AD39/M39) -> Too early | P39: 335 | Q39: =AB39-X39 -> 1433 | R39: =IF(B39<7,(P39/VLOOKUP(B39,'Sales Pacing'!$A$23:$E$36,2)),"Too early") -> Too early | S39: =IF(R39="Too early","Too early",R39/Q39) -> Too early | T39: 20502 | U39: 78334 | V39: =IF(T39>0,T39/U39,"") -> 0.26172543 | W39: =IF($R39="Too early",R39,R39*AD39/U39) -> Too early | AA39: =IF(Y39>0,Y39/Z39,"") | AB39: 1433 | AC39: =I39/AB39 -> 0.2337753 | AD39: =L39/I39 -> 61.2 | AH39: 18906.5 | AI39: =L39-AH39 -> 1595.5
A40: 14 | B40: =A40-$G$4 -> 13 | C40: 45992 | D40: 26 Handel's Messiah | G40: 45998.583 | H40: Holiday | I40: =P40+X40 -> 359 | J40: =IF(R40="Too early",R40,R40+X40) -> Too early | K40: =IF(J40="Too early",J40,J40/AB40) -> Too early | L40: =T40+Y40 -> 18477 | M40: =U40+Z40 -> 78333 | N40: =L40/M40 -> 0.2358776 | O40: =IF($J40="Too early",J40,J40*AD40/M40) -> Too early | P40: 359 | Q40: =AB40-X40 -> 1433 | R40: =IF(B40<7,(P40/VLOOKUP(B40,'Sales Pacing'!$A$23:$E$36,2)),"Too early") -> Too early | S40: =IF(R40="Too early","Too early",R40/Q40) -> Too early | T40: 18477 | U40: 78333 | V40: =IF(T40>0,T40/U40,"") -> 0.2358776 | W40: =IF($R40="Too early",R40,R40*AD40/U40) -> Too early | AA40: =IF(Y40>0,Y40/Z40,"") | AB40: 1433 | AC40: =I40/AB40 -> 0.25052338 | AD40: =L40/I40 -> 51.467967 | AH40: 16445 | AI40: =L40-AH40 -> 2032
...

Sheet PS1 Journey
A1: Single Tickets | B1: Mon | C1: Mon | D1: Mon | E1: Mon | F1: Wed | G1: Mon (Est) | H1: Mon (Est) | O1: Single Tickets
A2: PS1 Journey | B2: 45880 | C2: 45887 | D2: 45894 | E2: 45901 | F2: 45903 | G2: 45908 | H2: 45915 | I2: Sellout Target | N2: # Weeks Until Performance | O2: Classical | P2: Pops | Q2: Specials | R2: Other
B3: 5 | C3: 4 | D3: 3 | E3: 2 | G3: 1 | H3: 0
A4: 9/19/2025 Sales | B4: 60 | C4: 160 | D4: 205 | E4: 262 | F4: 280 | I4: =1590-689 -> 901 | N4: 0 | O4: 1 | P4: 1 | Q4: 1 | R4: 1
A5: 9/20/2025 Sales | B5: 63 | C5: 206 | D5: 250 | E5: 294 | F5: 309 | I5: =1590-613 -> 977 | N5: 1 | O5: 0.59 | P5: 0.59 | Q5: 0.59 | R5: 0.59
A6: 9/21/2025 Sales | B6: 57 | C6: 219 | D6: 296 | E6: 322 | F6: 338 | I6: =1590-374 -> 1216 | N6: 2 | O6: 0.46 | P6: 0.46 | Q6: 0.46 | R6: 0.46
A7: Pace for 85% OCC | B7: =$I$7*$J$7*P9 -> 255 | C7: =$I$7*$J$7*P8 -> 280.5 | D7: =$I$7*$J$7*P7 -> 331.5 | E7: =$I$7*$J$7*P6 -> 391 | F7: 410 | G7: =$I$7*$J$7*P5 -> 501.5 | H7: =$I$7*$J$7*P4 -> 850 | I7: 1000 | J7: 0.85 | N7: 3 | O7: 0.39 | P7: 0.39 | Q7: 0.39 | R7: 0.39
A8: Avg/Show vs Target Pace: | B8: =AVERAGE(B4:B6)-B7 -> -195 | C8: =AVERAGE(C4:C6)-C7 -> -85.5 | D8: =AVERAGE(D4:D6)-D7 -> -81.166667 | E8: =AVERAGE(E4:E6)-E7 -> -98.333333 | F8: =AVERAGE(F4:F6)-F7 -> -101 | N8: 4 | O8: 0.33 | P8: 0.33 | Q8: 0.33 | R8: 0.33
N9: 5 | O9: 0.3 | P9: 0.3 | Q9: 0.3 | R9: 0.3
N10: 6 | O10: 0.27 | P10: 0.27 | Q10: 0.27 | R10: 0.27

Sheet CS1 Appalachian
A1: Single Tickets | B1: Mon | C1: Mon | D1: Mon | E1: Mon | F1: Wed | G1: Mon (Est) | H1: Mon (Est) | S1: Single Tickets
A2: PS1 Journey | B2: 45880 | C2: 45887 | D2: 45894 | E2: 45901 | F2: 45903 | G2: 45908 | H2: 45915 | I2: 45922 | J2: 45929 | K2: 45936 | L2: Sellout Target | Q2: # Weeks Until Performance | R2: Classical | S2: Pops | T2: Specials | U2: Other
B3: 8 | C3: 7 | D3: 6 | E3: 5 | G3: 4 | H3: 3 | I3: 2 | J3: 1 | K3: 0
A4: 9/19/2025 Sales | B4: 60 | C4: 100 | D4: 106 | E4: 135 | F4: 136 | L4: =1433-543 -> 890 | Q4: 0 | R4: 1 | S4: 1 | T4: 1 | U4: 1
A5: 9/20/2025 Sales | B5: 63 | C5: 98 | D5: 115 | E5: 130 | F5: 136 | L5: =1433-581 -> 852 | Q5: 1 | R5: 0.59 | S5: 0.59 | T5: 0.59 | U5: 0.59
A6: 9/21/2025 Sales | B6: 57 | C6: 137 | D6: 154 | E6: 174 | F6: 184 | L6: =1433-613 -> 820 | Q6: 2 | R6: 0.46 | S6: 0.46 | T6: 0.46 | U6: 0.46
A7: Pace for 85% OCC | D7: =$L$7*0.85*R10 -> 195.075 | E7: =$L$7*0.85*R9 -> 216.75 | F7: 225 | G7: =$L$7*0.85*R8 -> 238.425 | H7: =$L$7*0.85*R7 -> 281.775 | I7: =$L$7*0.85*R6 -> 332.35 | J7: =$L$7*0.85*R5 -> 426.275 | K7: =$L$7*0.85*R4 -> 722.5 | L7: 850 | M7: 0.85 | Q7: 3 | R7: 0.39 | S7: 0.39 | T7: 0.39 | U7: 0.39
A8: Avg/Show vs Target Pace: | D8: =AVERAGE(D4:D6)-D7 -> -70.075 | E8: =AVERAGE(E4:E6)-E7 -> -70.416667 | F8: =AVERAGE(F4:F6)-F7 -> -73 | Q8: 4 | R8: 0.33 | S8: 0.33 | T8: 0.33 | U8: 0.33
Q9: 5 | R9: 0.3 | S9: 0.3 | T9: 0.3 | U9: 0.3
Q10: 6 | R10: 0.27 | S10: 0.27 | T10: 0.27 | U10: 0.27

Sheet Subscriptions
B1: KANSAS CITY SYMPHONY | E1: Update all fields in Blue each week | J1: 100%+ of FY26 Goal
B2: 2025-26 Subscriptions | E2: We expect 50% of Total by Week 5 | J2: 90-99% of FY26 Goal | N2: Classical | S2: FY26 Budget - Classical
E3: We expect 90% of Total by Week 10/11 | J3: <90% of FY26 Goal | N3: 0.72 | O3: % of total subscriptions | S3: Units | T3: Revenue
O4: =O8/S8*S4 -> 190.76952 | P4: =P8/O8*O4 -> 67934.779 | Q4: =Q8/S8*S4 -> 2954.7347 | R4: =R8/Q8*Q4 -> 1567065.2 | S4: =T4/(T8/S8) -> 3145.5043 | T4: 1635000 | U4: Total
B5: FY26 Sales - Classical | O5: =O9/S9*S5 -> 8.6708651 | P5: =P9/O9*O5 -> 2639.1544 | Q5: =Q9/S9*S5 -> 267.83339 | R5: =R9/Q9*Q5 -> 147753.15 | S5: =T5/(T8/S8) -> 276.50425 | T5: =T4-T8 -> 143724 | U5: Difference vs FY25
C6: New | F6: Renewals | I6: Total | N6: FY25 Actuals - Classical
A7: Weeks On Sale | C7: Actual Units | D7: Proj | E7: Actual Rev | F7: Actual Units | G7: Proj | H7: Actual Rev | I7: Actual Units | J7: Proj | K7: Actual Rev | L7: W/W Change | O7: New Units | P7: New Revenue | Q7: Renewal Units | R7: Renewal Revenue | S7: Total Units | T7: Total Revenue | U7: Change
A8: Projected Total | I8: =I16 -> 2456 | K8: =K16 -> 1408430 | N8: Final | O8: =O21 -> 174 | P8: =P21 -> 61963 | Q8: =Q21 -> 2695 | R8: =R21 -> 1429313 | S8: =S21 -> 2869 | T8: =T21 -> 1491276
A9: 1 | B9: 45747 | C9: 30 | D9: =C9/'Sales Pacing'!B3 -> 713.33333 | E9: 16220 | F9: 898 | G9: =F9/'Sales Pacing'!E3 -> 3554.0218 | H9: 527973 | I9: =C9+F9 -> 928 | J9: =D9+G9 -> 4267.3552 | K9: =E9+H9 -> 544193 | N9: 45383 | O9: 27 | P9: 8218 | Q9: 834 | R9: 460085 | S9: =O9+Q9 -> 861 | T9: =P9+R9 -> 468303
A10: 2 | B10: 45754 | C10: 39 | D10: =C10/'Sales Pacing'!B4 -> 642 | E10: 21024 | F10: 1136 | G10: =F10/'Sales Pacing'!E4 -> 3593.8233 | H10: 652031 | I10: =C10+F10 -> 1175 | J10: =D10+G10 -> 4235.8233 | K10: =E10+H10 -> 673055 | L10: =IF(K10>0,K10-K9,0) -> 128862 | N10: =N9+7 -> 45390 | O10: 32 | P10: 12068 | Q10: 1194 | R10: 655718 | S10: =O10+Q10 -> 1226 | T10: =P10+R10 -> 667786 | U10: =IF(T10>0,T10-T9,0) -> 199483
A11: 3 | B11: 45761 | C11: 50 | D11: =C11/'Sales Pacing'!B5 -> 455.31915 | E11: 27424 | F11: 1387 | G11: =F11/'Sales Pacing'!E5 -> 3529.55 | H11: 817109 | I11: =C11+F11 -> 1437 | J11: =D11+G11 -> 3984.8691 | K11: =E11+H11 -> 844533 | L11: =IF(K11>0,K11-K10,0) -> 171478 | N11: =N10+7 -> 45397 | O11: 36 | P11: 13657 | Q11: 1434 | R11: 789833 | S11: =O11+Q11 -> 1470 | T11: =P11+R11 -> 803490 | U11: =IF(T11>0,T11-T10,0) -> 135704
A12: 4 | B12: 45768 | C12: 76 | D12: =C12/'Sales Pacing'!B6 -> 591.41818 | E12: 40984 | F12: 1739 | G12: =F12/'Sales Pacing'!E6 -> 3653.0333 | H12: 1005395 | I12: =C12+F12 -> 1815 | J12: =D12+G12 -> 4244.4515 | K12: =E12+H12 -> 1046379 | L12: =IF(K12>0,K12-K11,0) -> 201846 | N12: =N11+7 -> 45404 | O12: 45 | P12: 17584 | Q12: 1789 | R12: 976040 | S12: =O12+Q12 -> 1834 | T12: =P12+R12 -> 993624 | U12: =IF(T12>0,T12-T11,0) -> 190134
A13: 5 | B13: =B12+7 -> 45775 | C13: 112 | D13: =C13/'Sales Pacing'!B7 -> 684.8 | E13: 54163 | F13: 2160 | G13: =F13/'Sales Pacing'!E7 -> 3788.4885 | H13: 1232817 | I13: =C13+F13 -> 2272 | J13: =D13+G13 -> 4473.2885 | K13: =E13+H13 -> 1286980 | L13: =IF(K13>0,K13-K12,0) -> 240601 | N13: =N12+7 -> 45411 | O13: 47 | P13: 17987 | Q13: 2005 | R13: 1080463 | S13: =O13+Q13 -> 2052 | T13: =P13+R13 -> 1098450 | U13: =IF(T13>0,T13-T12,0) -> 104826
A14: 6 | B14: =B13+7 -> 45782 | C14: 121 | D14: =C14/'Sales Pacing'!B8 -> 533.89691 | E14: 58153 | F14: 2252 | G14: =F14/'Sales Pacing'!E8 -> 3121.3817 | H14: 1294295 | I14: =C14+F14 -> 2373 | J14: =D14+G14 -> 3655.2787 | K14: =E14+H14 -> 1352448 | L14: =IF(K14>0,K14-K13,0) -> 65468 | N14: =N13+7 -> 45418 | O14: 70 | P14: 26832 | Q14: 2362 | R14: 1271615 | S14: =O14+Q14 -> 2432 | T14: =P14+R14 -> 1298447 | U14: =IF(T14>0,T14-T13,0) -> 199997
A15: 7 | B15: =B14+7 -> 45789 | C15: 122 | D15: =C15/'Sales Pacing'!B9 -> 404.77519 | E15: 59763 | F15: 2293 | G15: =F15/'Sales Pacing'!E9 -> 2534.0926 | H15: 1322554 | I15: =C15+F15 -> 2415 | J15: =D15+G15 -> 2938.8678 | K15: =E15+H15 -> 1382317 | L15: =IF(K15>0,K15-K14,0) -> 29869 | N15: =N14+7 -> 45425 | O15: 76 | P15: 28802 | Q15: 2443 | R15: 1319275 | S15: =O15+Q15 -> 2519 | T15: =P15+R15 -> 1348077 | U15: =IF(T15>0,T15-T14,0) -> 49630
A16: 8 | B16: =B15+7 -> 45796 | C16: 134 | D16: =C16/'Sales Pacing'!B10 -> 382.34667 | E16: 63528 | F16: 2322 | G16: =F16/'Sales Pacing'!E10 -> 2473.787 | H16: 1344902 | I16: =C16+F16 -> 2456 | J16: =D16+G16 -> 2856.1337 | K16: =E16+H16 -> 1408430 | L16: =IF(K16>0,K16-K15,0) -> 26113 | N16: =N15+7 -> 45432 | O16: 85 | P16: 30752 | Q16: 2473 | R16: 1329297 | S16: =O16+Q16 -> 2558 | T16: =P16+R16 -> 1360049 | U16: =IF(T16>0,T16-T15,0) -> 11972
A17: 9 | B17: =B16+7 -> 45803 | C17: 146 | D17: =C17/'Sales Pacing'!B11 -> 369.75148 | E17: 67946 | F17: 2345 | G17: =F17/'Sales Pacing'!E11 -> 2468.3763 | H17: 1357272 | I17: =C17+F17 -> 2491 | J17: =D17+G17 -> 2838.1277 | K17: =E17+H17 -> 1425218 | L17: =IF(K17>0,K17-K16,0) -> 16788 | N17: =N16+7 -> 45439 | O17: 91 | P17: 32154 | Q17: 2513 | R17: 1344658 | S17: =O17+Q17 -> 2604 | T17: =P17+R17 -> 1376812 | U17: =IF(T17>0,T17-T16,0) -> 16763
A18: 10 | B18: =B17+7 -> 45810 | C18: 165 | D18: =C18/'Sales Pacing'!B12 -> 377.64706 | E18: 75744 | F18: 2369 | G18: =F18/'Sales Pacing'!E12 -> 2461.486 | H18: 1380368 | I18: =C18+F18 -> 2534 | J18: =D18+G18 -> 2839.1331 | K18: =E18+H18 -> 1456112 | L18: =IF(K18>0,K18-K17,0) -> 30894 | N18: =N17+7 -> 45446 | O18: 94 | P18: 32854 | Q18: 2608 | R18: 1391277 | S18: =O18+Q18 -> 2702 | T18: =P18+R18 -> 1424131 | U18: =IF(T18>0,T18-T17,0) -> 47319
A19: 11 | B19: =B18+7 -> 45817 | C19: 186 | D19: =C19/'Sales Pacing'!B13 -> 396.0597 | E19: 89633 | F19: 2384 | G19: =F19/'Sales Pacing'!E13 -> 2469.1125 | H19: 1390065 | I19: =C19+F19 -> 2570 | J19: =D19+G19 -> 2865.1722 | K19: =E19+H19 -> 1479698 | L19: =IF(K19>0,K19-K18,0) -> 23586 | N19: =N18+7 -> 45453 | O19: 95 | P19: 33169 | Q19: 2628 | R19: 1398365 | S19: =O19+Q19 -> 2723 | T19: =P19+R19 -> 1431534 | U19: =IF(T19>0,T19-T18,0) -> 7403
A20: 12 | B20: =B19+7 -> 45824 | C20: 205 | D20: =C20/'Sales Pacing'!B14 -> 404.3318 | E20: 94753 | F20: 2413 | G20: =F20/'Sales Pacing'!E14 -> 2491.1434 | H20: 1408181 | I20: =C20+F20 -> 2618 | J20: =D20+G20 -> 2895.4752 | K20: =E20+H20 -> 1502934 | L20: =IF(K20>0,K20-K19,0) -> 23236 | N20: =N19+7 -> 45460 | O20: 103 | P20: 35745 | Q20: 2655 | R20: 1411925 | S20: =O20+Q20 -> 2758 | T20: =P20+R20 -> 1447670 | U20: =IF(T20>0,T20-T19,0) -> 16136
A21: 13+ | B21: 45901 | C21: 290 | D21: =C21/'Sales Pacing'!B15 -> 290 | E21: 131355 | F21: 2425 | G21: =F21/'Sales Pacing'!E15 -> 2425 | H21: 1410448 | I21: =C21+F21 -> 2715 | J21: =D21+G21 -> 2715 | K21: =E21+H21 -> 1541803 | L21: =IF(K21>0,K21-K20,0) -> 38869 | N21: Rest of Season | O21: 174 | P21: 61963 | Q21: 2695 | R21: 1429313 | S21: =O21+Q21 -> 2869 | T21: =P21+R21 -> 1491276 | U21: =IF(T21>0,T21-T20,0) -> 43606
I22: vs. FY26 Goal | J22: =J21/$S$4 -> 0.86313665 | K22: =K21/$T$4 -> 0.94299878
B23: 25-26 Renewal as % of 24-25 Total
B24: =F15/S8 -> 0.79923318 | E24: 3rd Classical mailer drops 22nd/23rd of August | N24: Pops | S24: FY26 Budget - Pops
N25: 0.26 | O25: % of total subscriptions | S25: Units | T25: Revenue
O26: =O30/S30*S26 -> 240.07343 | P26: =P30/O30*O26 -> 69318.269 | Q26: =Q30/S30*S26 -> 1547.1399 | R26: =R30/Q30*Q26 -> 549681.73 | S26: =T26/(T30/S30) -> 1787.2133 | T26: 619000 | U26: Total
B27: FY26 Sales - Pops | O27: =O31/S31*S27 -> 3.2060949 | P27: =P31/O31*O27 -> 1038.7747 | Q27: =Q31/S31*S27 -> 109.00723 | R27: =R31/Q31*Q27 -> 44362.735 | S27: =T27/(T30/S30) -> 112.21332 | T27: =T26-T30 -> 38865 | U27: Difference vs FY25
C28: New | F28: Renewals | I28: Total | N28: FY25 Actuals - Pops
C29: Actual Units | D29: Proj | E29: Actual Rev | F29: Actual Units | G29: Proj | H29: Actual Rev | I29: Actual Units | J29: Proj | K29: Actual Rev | L29: W/W Change | O29: New Units | P29: New Revenue | Q29: Renewal Units | R29: Renewal Revenue | S29: Total Units | T29: Total Revenue | U29: Change
A30: Projected Total | I30: =I38 -> 1561 | K30: =K38 -> 591188 | N30: Final | O30: =O43 -> 225 | P30: =P43 -> 64966 | Q30: =Q43 -> 1450 | R30: =R43 -> 515169 | S30: =S43 -> 1675 | T30: =T43 -> 580135
A31: 1 | B31: 45747 | C31: 38 | D31: =C31/'Sales Pacing'!C3 -> 1048.1667 | E31: 13163 | F31: 636 | G31: =F31/'Sales Pacing'!F3 -> 5546.3927 | H31: 258782 | I31: =C31+F31 -> 674 | J31: =D31+G31 -> 6594.5593 | K31: =E31+H31 -> 271945 | N31: 45383 | O31: 2 | P31: 648 | Q31: 68 | R31: 27674 | S31: =O31+Q31 -> 70 | T31: =P31+R31 -> 28322
A32: 2 | B32: 45754 | C32: 44 | D32: =C32/'Sales Pacing'!C4 -> 606.83333 | E32: 14651 | F32: 785 | G32: =F32/'Sales Pacing'!F4 -> 3783.5789 | H32: 312531 | I32: =C32+F32 -> 829 | J32: =D32+G32 -> 4390.4122 | K32: =E32+H32 -> 327182 | L32: =IF(K32>0,K32-K31,0) -> 55237 | N32: =N31+7 -> 45390 | O32: 54 | P32: 17576 | Q32: 181 | R32: 68648 | S32: =O32+Q32 -> 235 | T32: =P32+R32 -> 86224 | U32: =IF(T32>0,T32-T31,0) -> 57902
A33: 3 | B33: 45761 | C33: 54 | D33: =C33/'Sales Pacing'!C5 -> 616.34483 | E33: 19061 | F33: 893 | G33: =F33/'Sales Pacing'!F5 -> 3135.2144 | H33: 353304 | I33: =C33+F33 -> 947 | J33: =D33+G33 -> 3751.5592 | K33: =E33+H33 -> 372365 | L33: =IF(K33>0,K33-K32,0) -> 45183 | N33: =N32+7 -> 45397 | O33: 66 | P33: 20302 | Q33: 283 | R33: 105425 | S33: =O33+Q33 -> 349 | T33: =P33+R33 -> 125727 | U33: =IF(T33>0,T33-T32,0) -> 39503
A34: 4 | B34: 45768 | C34: 60 | D34: =C34/'Sales Pacing'!C6 -> 484.39024 | E34: 20782 | F34: 1067 | G34: =F34/'Sales Pacing'!F6 -> 2921.075 | H34: 417996 | I34: =C34+F34 -> 1127 | J34: =D34+G34 -> 3405.4653 | K34: =E34+H34 -> 438778 | L34: =IF(K34>0,K34-K33,0) -> 66413 | N34: =N33+7 -> 45404 | O34: 86 | P34: 26557 | Q34: 389 | R34: 146108 | S34: =O34+Q34 -> 475 | T34: =P34+R34 -> 172665 | U34: =IF(T34>0,T34-T33,0) -> 46938
A35: 5 | B35: =B34+7 -> 45775 | C35: 118 | D35: =C35/'Sales Pacing'!C7 -> 566.05797 | E35: 38918 | F35: 1300 | G35: =F35/'Sales Pacing'!F7 -> 2887.9509 | H35: 502867 | I35: =C35+F35 -> 1418 | J35: =D35+G35 -> 3454.0088 | K35: =E35+H35 -> 541785 | L35: =IF(K35>0,K35-K34,0) -> 103007 | N35: =N34+7 -> 45411 | O35: 86 | P35: 26557 | Q35: 476 | R35: 178054 | S35: =O35+Q35 -> 562 | T35: =P35+R35 -> 204611 | U35: =IF(T35>0,T35-T34,0) -> 31946
A36: 6 | B36: =B35+7 -> 45782 | C36: 157 | D36: =C36/'Sales Pacing'!C8 -> 683.77632 | E36: 51765 | F36: 1358 | G36: =F36/'Sales Pacing'!F8 -> 2121.6398 | H36: 522161 | I36: =C36+F36 -> 1515 | J36: =D36+G36 -> 2805.4161 | K36: =E36+H36 -> 573926 | L36: =IF(K36>0,K36-K35,0) -> 32141 | N36: =N35+7 -> 45418 | O36: 98 | P36: 31472 | Q36: 806 | R36: 294720 | S36: =O36+Q36 -> 904 | T36: =P36+R36 -> 326192 | U36: =IF(T36>0,T36-T35,0) -> 121581
A37: 7 | B37: =B36+7 -> 45789 | C37: 165 | D37: =C37/'Sales Pacing'!C9 -> 593.6413 | E37: 54301 | F37: 1365 | G37: =F37/'Sales Pacing'!F9 -> 1717.375 | H37: 525805 | I37: =C37+F37 -> 1530 | J37: =D37+G37 -> 2311.0163 | K37: =E37+H37 -> 580106 | L37: =IF(K37>0,K37-K36,0) -> 6180 | N37: =N36+7 -> 45425 | O37: 113 | P37: 36672 | Q37: 1031 | R37: 372369 | S37: =O37+Q37 -> 1144 | T37: =P37+R37 -> 409041 | U37: =IF(T37>0,T37-T36,0) -> 82849
A38: 8 | B38: =B37+7 -> 45796 | C38: 199 | D38: =C38/'Sales Pacing'!C10 -> 639.50485 | E38: 65018 | F38: 1362 | G38: =F38/'Sales Pacing'!F10 -> 1532.8471 | H38: 526170 | I38: =C38+F38 -> 1561 | J38: =D38+G38 -> 2172.3519 | K38: =E38+H38 -> 591188 | L38: =IF(K38>0,K38-K37,0) -> 11082 | N38: =N37+7 -> 45432 | O38: 127 | P38: 40518 | Q38: 1267 | R38: 452816 | S38: =O38+Q38 -> 1394 | T38: =P38+R38 -> 493334 | U38: =IF(T38>0,T38-T37,0) -> 84293
A39: 9 | B39: =B38+7 -> 45803 | C39: 220 | D39: =C39/'Sales Pacing'!C11 -> 568.90625 | E39: 73218 | F39: 1368 | G39: =F39/'Sales Pacing'!F11 -> 1451.7935 | H39: 531352 | I39: =C39+F39 -> 1588 | J39: =D39+G39 -> 2020.6998 | K39: =E39+H39 -> 604570 | L39: =IF(K39>0,K39-K38,0) -> 13382 | N39: =N38+7 -> 45439 | O39: 160 | P39: 48485 | Q39: 1395 | R39: 497335 | S39: =O39+Q39 -> 1555 | T39: =P39+R39 -> 545820 | U39: =IF(T39>0,T39-T38,0) -> 52486
A40: 10 | B40: =B39+7 -> 45810 | C40: 239 | D40: =C40/'Sales Pacing'!C12 -> 557.10563 | E40: 80035 | F40: 1374 | G40: =F40/'Sales Pacing'!F12 -> 1439.2578 | H40: 536728 | I40: =C40+F40 -> 1613 | J40: =D40+G40 -> 1996.3634 | K40: =E40+H40 -> 616763 | L40: =IF(K40>0,K40-K39,0) -> 12193 | N40: =N39+7 -> 45446 | O40: 172 | P40: 51234 | Q40: 1411 | R40: 502695 | S40: =O40+Q40 -> 1583 | T40: =P40+R40 -> 553929 | U40: =IF(T40>0,T40-T39,0) -> 8109
...

Sheet Channels (Draft)
A1: MARKETING CHANNEL PERFORMANCE
B2: Owned Marketing Channels | H2: Paid Channels
A3: To start, let’s pull last 12 months of data. | B3: Phone | C3: Direct Mail | D3: Email | E3: Social | F3: In-hall | G3: SEO | H3: SEM | I3: Media | J3: Phone | K3: Total
B4: (Box Office) | E4: (FB, IG, X, other) | F4: (book, posters) | I4: (TV, radio, OOH) | J4: (Bennett)
A5: # Impressions: | D5: 13.7M
A6: calls made, e/mails delivered, etc.
A7: # Engagement: | D7: 4.7M
A8: calls answered, opens, etc.
A9: Engagement rate | D9: 34%
A10: # Actions (Success): | D10: 89k
A11: conversations, clicks, etc.
A12: Action rate | D12: 0.6%
A13: % of total Actions
A15: Channel cost ($, time)
A16: ROI: $/Action
A17: Attributed revenue ($) | J17: ~$220k
A18: ROI: $/channel cost
A20: SALES CHANNEL PERFORMANCE
A21: To start, let’s pull last 12 months of data. | B21: Phone | C21: Website | D21: KCPA | E21: Total
B22: (Box Office)
A23: # Traffic: | C23: 471,563
A24: calls received, visits
A25: % Traffic by Marketing Channel
A26: #, $ Conversions (Success): | C26: 4,547
A27: Conversion rate | C27: 0.94%
A28: % of total Conversions | D28: 15%?
A29: Total Sales Revenue | B29: ~$6,500k? | C29: $877k
A31: Channel cost ($, time)
A32: ROI: $/Conversion
A33: Attributed revenue ($)
A34: ROI: $/channel cost
A36: EXPERIENCE CHANNEL PERFORMANCE
B37: Total
A38: # total attendance
A39: % Repeat:
A40: % returning from prior season
A41: # Frequency:
A42: avg. attendance/customer
A44: Total Revenue, ROI?
A45: Avg. CSAT, NPS
...

Sheet Grassroots Flyer Locations
A1: MF Location | B1: MF Staff Member | C1: Date Posted | E1: CF Location | F1: CF Staff Member | G1: Date Posted | I1: Fam Location | J1: Fam Staff Member | K1: Date Posted
A2: Mildreds (NO CORKBOARD)
A3: Pizza Shuttle | B3: Stephen, Sarah and Adeca | C3: 45870
A4: The Bauer Gallery | B4: Stephen, Sarah and Adeca | C4: 45870
A5: Bizz and Weezy's | B5: Stephen, Sarah and Adeca | C5: 45870
A6: The Sewing Labs | B6: Sarah | C6: 45875
A7: Filling Station - Midtown | B7: Hannah | C7: 45875
A8: Good Karma Coffee Shop | B8: Hannah | C8: 45875

Sheet Summary (Draft)
B2: Overall Season | G2: # Tickets Sold | H2: Projected Tickets Sold | I2: Projected Occupancy (% +GYR) | J2: Total Revenue | K2: BUDGET | L2: Projected Revenue vs Budget (% +GYR)
B3: ALL CONCERTS | G3: ='Performances by Week'!I126 -> 0 | H3: ='Performances by Week'!J126 -> 0 | I3: ='Performances by Week'!K126 -> 0 | J3: ='Performances by Week'!L126 -> 0 | K3: ='Performances by Week'!M126 -> 6268640 | L3: ='Performances by Week'!O126
B5: Season Attendance By Ticket Type | G5: # Tickets Sold | H5: Projected Tickets Sold | J5: Total Revenue | K5: BUDGET | L5: Projected Revenue vs Budget (% +GYR)
B6: All Subscriptions | G6: ='Performances by Week'!X126 -> 0 | J6: ='Performances by Week'!Y126 -> 0 | K6: ='Performances by Week'!Z126 -> 2169893 | L6: ='Performances by Week'!AA126
B7: All Single Tickets | G7: ='Performances by Week'!P126 -> 0 | H7: ='Performances by Week'!R126 -> 0 | J7: ='Performances by Week'!T126 -> 0 | K7: ='Performances by Week'!U126 -> 3973690 | L7: ='Performances by Week'!W126
B9: Concert Attendance By Performance Type | G9: # Tickets Sold | H9: Projected Tickets Sold | I9: Projected Occupancy (% +GYR) | J9: Total Revenue | K9: BUDGET | L9: Projected Revenue vs Budget (% +GYR)
B10: CLASSICAL TRADITIONAL TOTAL | G10: ='Performances by Week'!I119 -> 0 | H10: ='Performances by Week'!J119 -> 0 | I10: ='Performances by Week'!K119 -> 0 | J10: ='Performances by Week'!L119 -> 0 | K10: ='Performances by Week'!M119 -> 2139000 | L10: ='Performances by Week'!O119
B11: SYMPHONIC PIAZZA TOTAL | G11: ='Performances by Week'!I120 -> 0 | H11: ='Performances by Week'!J120 -> 0 | I11: ='Performances by Week'!K120 -> 0 | J11: ='Performances by Week'!L120 -> 0 | K11: ='Performances by Week'!M120 -> 363000 | L11: ='Performances by Week'!O120
B12: POPS TOTAL | G12: ='Performances by Week'!I121 -> 0 | H12: ='Performances by Week'!J121 -> 0 | I12: ='Performances by Week'!K121 -> 0 | J12: ='Performances by Week'!L121 -> 0 | K12: ='Performances by Week'!M121 -> 1457000 | L12: ='Performances by Week'!O121
B13: FAMILY SERIES TOTAL | G13: ='Performances by Week'!I122 -> 0 | H13: ='Performances by Week'!J122 -> 0 | I13: ='Performances by Week'!K122 -> 0 | J13: ='Performances by Week'!L122 -> 0 | K13: ='Performances by Week'!M122 -> 525950 | L13: ='Performances by Week'!O122
B14: FILM TOTAL | G14: ='Performances by Week'!I123 -> 0 | H14: ='Performances by Week'!J123 -> 0 | I14: ='Performances by Week'!K123 -> 0 | J14: ='Performances by Week'!L123 -> 0 | K14: ='Performances by Week'!M123 -> 1745490 | L14: ='Performances by Week'!O123
B15: ON STAGE CONCERTS TOTAL | G15: ='Performances by Week'!I124 -> 0 | H15: ='Performances by Week'!J124 -> 0 | I15: ='Performances by Week'!K124 -> 0 | J15: ='Performances by Week'!L124 -> 0 | K15: ='Performances by Week'!M124 -> 38200 | L15: ='Performances by Week'!O124
B16: OTHER CONCERT TOTAL | G16: ='Performances by Week'!I125 -> 0 | H16: ='Performances by Week'!J125 -> 0 | I16: ='Performances by Week'!K125 -> 0 | J16: ='Performances by Week'!L125 -> 0 | K16: ='Performances by Week'!M125 -> 0 | L16: ='Performances by Week'!O125

Sheet Sales Pacing
B1: New Subs | E1: Renewal Subs
A2: # Weeks On Sale | B2: Classical | C2: Pops | E2: Classical | F2: Pops
A3: 1 | B3: 0.042056075 | C3: 0.036253776 | E3: 0.25267149 | F3: 0.11466913
A4: 2 | B4: 0.060747664 | C4: 0.072507553 | E4: 0.3160979 | F4: 0.20747552
A5: 3 | B5: 0.10981308 | C5: 0.087613293 | E5: 0.39296794 | F5: 0.28482901
A6: 4 | B6: 0.12850467 | C6: 0.12386707 | E6: 0.47604274 | F6: 0.36527648
A7: 5 | B7: 0.1635514 | C7: 0.20845921 | E7: 0.57014822 | F7: 0.45014616
A8: 6 | B8: 0.22663551 | C8: 0.22960725 | E8: 0.72147535 | F8: 0.64007095
A9: 7 | B9: 0.30140187 | C9: 0.27794562 | E9: 0.90486039 | F9: 0.79481765
A10: 8 | B10: 0.35046729 | C10: 0.31117825 | E10: 0.93864185 | F10: 0.88854264
A11: 9 | B11: 0.39485981 | C11: 0.38670695 | E11: 0.95001724 | F11: 0.94228277
A12: 10 | B12: 0.43691589 | C12: 0.42900302 | E12: 0.96242675 | F12: 0.95465872
A13: 11 | B13: 0.46962617 | C13: 0.48036254 | E13: 0.96552913 | F13: 0.96530297
A14: 12 | B14: 0.50700935 | C14: 0.57401813 | E14: 0.96863151 | F14: 0.97390663
A15: 13+ | B15: 1 | C15: 1 | E15: 1 | F15: 1
B21: Single Tickets
A22: # Weeks Until Performance | B22: Classical | C22: Pops | D22: Specials | E22: Other
A23: 0 | B23: 1 | C23: 1 | D23: 1 | E23: 1
A24: 1 | B24: 0.59 | C24: 0.59 | D24: 0.59 | E24: 0.59
A25: 2 | B25: 0.46 | C25: 0.46 | D25: 0.46 | E25: 0.46
A26: 3 | B26: 0.39 | C26: 0.39 | D26: 0.39 | E26: 0.39
A27: 4 | B27: 0.33 | C27: 0.33 | D27: 0.33 | E27: 0.33
A28: 5 | B28: 0.3 | C28: 0.3 | D28: 0.3 | E28: 0.3
A29: 6 | B29: 0.27 | C29: 0.27 | D29: 0.27 | E29: 0.27
A30: 7
A31: 8
A32: 9
A33: 10
A34: 11
A35: 12
A36: 13+
A38: Future Improvements:
A39: Extend data for single ticket sales beyond 6 weeks
A40: Differentiate single ticket sales by performance type
A41: Improve pacing data (always)

Sheet Social Reporting
A1: DATE | B1: Social Post | C1: Views | D1: Engagement
A2: 45891 | B2: Chicken Fried IG | C2: 1625 | D2: 11 interactions
A3: 45891 | B3: Chicken Fried FB | C3: 2570 | D3: 15 interactions, 6 link clicks
A4: 45890 | B4: Journey Reel IG | C4: 1005 | D4: 16 interactions
A5: 45890 | B5: Journey Reel FB | C5: 813 | D5: 12 interactions
A6: 45883 | B6: KC Blues Society Video IG | C6: 966 | D6: 32 interactions
A7: 45883 | B7: KC Blues Society Video FB | C7: 1895 | D7: 19 interactions, 61 link clicks
A8: 45881 | B8: CS1 Nora Video IG | C8: 3290 | D8: 42 interactions
A9: 45881 | B9: CS1 Nora Video FB | C9: 1785 | D9: 42 interactions
A10: 45876 | B10: Orchestra Games IG | C10: 2394 | D10: 54 interactions
A11: 45876 | B11: Orchestra Games FB | C11: 1879 | D11: 15 interactions, 2 link clicks
A12: 45876 | B12: Morgan Freeman interview reshare FB | C12: 2731 | D12: 52 interactions, 53 link clicks
A13: 45875 | B13: Nora Intro IG | C13: 3331 | D13: 65 interactions
... A16: 45874 | B16: Journey Graphic FB | C16: 4997 | D16: 28 interactions, 22 link clicks
B18: Meta Ads
A19: 7/30-8/13 | B19: Morgan Freeman video | C19: 88,119 impressions | D19: 3,269 link clicks
A20: Ends 8/22 | B20: Music of Journey | C20: 56,165 impressions | D20: 3,537 link clicks
A24: 45870 | B24: La Nuit Sombre video IG Reel | C24: 953 | D24: 46 interactions
A25: 45870 | B25: La Nuit Sombre video FB Reel | C25: 1105 | D25: 14 interactions
A26: 45860 | B26: La Nuit Sombre Price Increase FB | C26: 3465 | D26: 19 interactions, 9 link clicks
A27: 45860 | B27: La Nuit Sombre Price Increase IG | C27: 1537 | D27: 19 interactions, 11 link clicks
A28: 45865 | B28: Music is for Everyone FB Reel | C28: 563 | D28: 13 interactions
A29: 45865 | B29: Music is for Everyone IG Reel | C29: 1735 | D29: 36 interactions
A30: 45865 | B30: Music is for Everyone TikTok | C30: 256 | D30: 16 interactions
A31: 45853 | B31: Are you single? FB Reel | C31: 1641 | D31: 22 interactions
A32: 45853 | B32: Are you single? IG Reel | C32: 4321 | D32: 170 interactions
A33: 45853 | B33: Are you single? TikTok | C33: 1013 | D33: 45 interactions
A34: 45853 | B34: Are you single? YT | C34: 1115 | D34: 16 interactions
A35: 45854 | B35: Single Tickets Graphic FB | C35: 3157 | D35: 26 interactions
... A45: 45856 | B45: Music is for Everyone YT | C45: 32 | D45: 1 interaction
B47: Meta Ads
A48: 45832 | B48: Specials/Films ad | C48: 1k impressions | D48: 18 clicks
A49: 45838 | B49: Morgan Freeman video | C49: 22k impressions | D49: 1234 link clicks
A50: 45841 | B50: Holiday concerts ad | C50: 68k impressions | D50: 1011 link clicks

Sheet Email Reporting
A1: EMAILS SENT | B1: DELIVERIES | C1: OPENS | D1: CLICK RATE
A2: 8/20 Bi-weekly Merchandise Email | B2: 95473 | C2: 35,125 (37%) | D2: 754 (1%)
A3: 8/12 Music of Journey Promo | B3: 94241 | C3: 35,743 (37.9%) | D3: 577 0.6% | E3: https://conta.cc/4mdHLVC
A4: 8/6 Bi-weekly Merchandise Email | B4: 94322 | C4: 36,401 (38.6%) | D4: 937 (1%) | E4: https://conta.cc/3Hoy3k2
A5: 7/21 La Nuit Sombre Matthias Video | B5: 95893 | C5: 35,531 (37.1%) | D5: 491 (0.5%)
A6: 7/23 Morgan Freeman Promo | B6: 96012 | C6: 35,064 (36.5%) | D6: 769 (0.8%)
A7: 7/15 Single Ticket On Sale Announcement | B7: 95831 | C7: 35,285 (37.2%) | D7: 1,708 (2%)
A8: 7/8 Leslie Odom Jr. Promo | B8: 94927 | C8: 35, 660 (37.6%) | D8: 550 (0.6%)
A9: Tuesday 7/1 Holiday Presentations On Sale | B9: 95059 | C9: 35039 (36.9%) | D9: 822 (0.9%) | E9: Header: 64, Elf in Concert: 473, Handel's Messiah: 390, LOJ: 110, Christmas Festival: 144, Wonderful Life: 129
A10: Tuesday 6/25 Special Presentations On Sale | B10: 95219 | C10: 35,617 (37%) | D10: 1,469 (2%) | E10: Full lineup: 248, Morgan Freeman: 438, Chicken Fried: 456, Top Gun: 559, Lodger: 100, Indiana Jones: 204, Chris Thile: 134, Harry Potter: 139, Final Symphony: 74, Ben Rector: 108, On Stage George: 45, On Stage Leila: 53, On Stage Gil: 37, On Stage 38
A11: Tuesday 6/17 Mark Your Calendar | B11: 104371 | C11: 37,343 (39%) | D11: 1,999 (2%)
A12: Monday 6/9 Mobile Music Box June Concert | B12: 95,460 | C12: 36,052 (38%) | D12: 594 (1%)
A13: Wednesday 6/4 CS14 Student Rush Promo | B13: 174 | C13: 77 (44%) | D13: 0
A14: Wednesday 6/4 CS14 Student Rush Promo | B14: 174 | C14: 77 (44%) | D14: 0
A15: Wednesday 6/4 CS14 Student Pass Promo | B15: 80 | C15: 38 (47%) | D15: 1 | J15: AVERAGE OPEN RATE: | K15: 0.37
A16: Wednesday 6/4 CS14 BOGO Promo | B16: 4954 | C16: 2,165 (44%) | D16: 65 (1%)
A17: Wednesday 6/4 Four Larks Subscriber Early Access | B17: 2185 | C17: 1,452 (66.5%) | D17: 135 (6.2%) | J17: AVERAGE CLICK RATE: | K17: 0.02
A18: Friday 6/6 Four Lark Public On-Sale | B18: 96846 | C18: 35,136 (36%) | D18: 616 (0.6%)

Sheet Website Reporting
A1: Timeframe: August 11-18
A2: ECOMMERCE PURCHASES: 877 | B2: WEBSITE REVENUE: $74,429 | C2: # OF ITEMS
A3: Morgan Freeman | B3: 18052 | C3: 164
A4: Music of Journey | B4: 8322 | C4: 66
A5: Top Gun | B5: 7065 | C5: 86
A6: Leslie Odom Jr. | B6: 4084.5 | C6: 54
A7: Indiana Jones | B7: 3441 | C7: 38
A8: Elf in Concert | B8: 2892 | C8: 44
A9: Harry Potter | B9: 2521 | C9: 29
A10: It's a wonderful life | B10: 2454 | C10: 52
A12: Timeframe: July 20-July 28
A13: ECOMMERCE PURCHASES: 973 | B13: WEBSITE REVENUE: $67,220 | C13: # OF ITEMS
A14: Leslie Odom Jr. | B14: 17681 | C14: 161
A15: Morgan Freeman | B15: 7995 | C15: 64
A16: Top Gun | B16: 5293 | C16: 64
A17: 2025/26 COY Package | B17: 4084 | C17: 54
A18: It's a wonderful life | B18: 2684 | C18: 31
A19: Elf in Concert | B19: 2343 | C19: 26
A20: Christmas Festival | B20: 2341 | C20: 38
A21: La nuit sombre | B21: 2308 | C21: 49
A22: Harry Potter 2 | B22: 2030 | C22: 26
A23: Indiana Jones | B23: 2004 | C23: 26
A27: Timeframe: July 20-July 28
A28: ECOMMERCE PURCHASES: 1,718 | B28: WEBSITE REVENUE: $115,644 | C28: # OF ITEMS
A29: Morgan Freeman | B29: 27675 | C29: 215
A30: Top Gun | B30: 9650 | C30: 116
A31: It's a wonderful life | B31: 8677 | C31: 104
A32: Leslie Odom Jr. | B32: 9110 | C32: 84
A33: Elf in Concert | B33: 5110 | C33: 80
A34: 2025/26 COY Package | B34: 5435 | C34: 73
A35: Harry Potter 2 | B35: 5145 | C35: 61
A36: 2025/26 Sunday Masterworks | B36: 4200 | C36: 56
A37: Handel's Messiah | B37: 2970 | C37: 55
A43: Timeframe: July 14-July 20
A44: ECOMMERCE PURCHASES: 3,027 | B44: WEBSITE REVENUE: $188,688 | C44: # OF ITEMS
A45: Top Gun | B45: 19205 | C45: 234
A46: Morgan Freeman | B46: 16175 | C46: 130
A47: Leslie Odom Jr. | B47: 14107 | C47: 139
A48: Indiana Jones | B48: 12729 | C48: 186
A49: Billy Joel + Elton John | B49: 11391 | C49: 149
...
