Workbook

Sheet Performances by Week
E1: Status: | F1: Updated 10/27 | H1: Denotes Piazza | I1: Update all fields in Blue each week | J1: We expect 50% of Single Sales 1 Week Prior | K1: 85%+ occupancy | V1: 100%+ of Target
K2: 70-85% occupancy | V2: 90-99% of Target
G3: Week # | K3: <70% occupancy | V3: <90% of Target
D4: TICKET SALES REPORT as of 10/27/2025 | G4: 9 | I4: TOTAL SALES (Singles + Subs) | S4: Single Tickets | AC4: Subscription Tickets | AG4: Hall Data | AJ4: Audience Data | AM4: Revenue last week | AN4: Increase over week
A5: Wk # | B5: # Weeks Until Perf | C5: Perf. Week (Mon) | D5: Performance | G5: Performance Date(s) | H5: Performance Type | I5: % OCC Target | J5: Actual OCC SOLD | K5: Actual Total Tickets Sold | L5: Total Actual Revenue | M5: TOTAL BUDGET | N5: Actual - Budget | O5: Projected Total OCC at Performance | P5: Projected Total Tickets Sold | Q5: Projected Total Revenue | R5: Projected- Budget | S5: Actual Single Tickets Sold | T5: Maximum Single Ticket Capacity | U5: Target Single Tickets for % OCC Target | V5: Projected Single Tickets | W5: Projected Single Ticket Revenue | X5: Projected Single Tickets vs % OCC Target | Y5: Actual Revenue | Z5: BUDGET | AA5: Actual/ Budget % | AB5: Projected/ Budget % | AC5: Actual Sub Tickets Sold | AD5: Actual Revenue | AE5: BUDGET | AF5: Actual vs Budget % | AG5: Max CAP | AH5: Single Ticket ATP | AI5: # New HH | AJ5: # Ret HH | AK5: # Total HH
A6: 1 | B6: =A6-$G$4 -> -8 | C6: 45901 | D6: 26 Morgan Freeman's Symphonic Blues | G6: 45902.833 | H6: Specials | I6: 0.85 | J6: =K6/AG6 -> 0.89093702 | K6: =S6+AC6 -> 1160 | L6: =Y6+AD6 -> 137698 | M6: =Z6+AE6 -> 153473 | N6: =L6-M6 -> -15775 | O6: =IF(P6="Too early",P6,P6/AG6) -> #N/A | P6: =IF(V6="Too early",V6,V6+AC6) -> #N/A | Q6: =AD6+V6*AH6 -> #N/A | R6: =IF(V6="Too early",V6,Q6-M6) -> #N/A | S6: 1160 | T6: =AG6-AC6 -> 1302 | U6: =(AG6-AC6)*I6 -> 1106.7 | V6: =IF(B6<11,MIN((S6/VLOOKUP(B6,'Sales Pacing'!$A$23:$E$36,2)),T6),"Too early") -> #N/A | W6: =Q6-AD6 -> #N/A | X6: =IF(V6="Too early","Too early",V6/U6) -> #N/A | Y6: 137698 | Z6: 153473 | AA6: =IF(Y6>0,Y6/Z6,"") -> 0.89721319 | AB6: =IF($V6="Too early",V6,V6*AH6/Z6) -> #N/A | AE6: 0 | AF6: =IF(AD6>0,AD6/AE6,"") | AG6: 1302 | AH6: =Y6/S6 -> 118.70517 | AI6: 228 | AJ6: 295 | AK6: 523 | AL6: 137698 | AM6: =L6-AL6 -> 0
A7: 1 | B7: =A7-$G$4 -> -8 | C7: 45901 | D7: 26 Morgan Freeman's Symphonic Blues | G7: 45903.833 | H7: Specials | I7: 0.85 | J7: =K7/AG7 -> 0.87480799 | K7: =S7+AC7 -> 1139 | L7: =Y7+AD7 -> 134386 | M7: =Z7+AE7 -> 153474 | N7: =L7-M7 -> -19088 | O7: =IF(P7="Too early",P7,P7/AG7) -> #N/A | P7: =IF(V7="Too early",V7,V7+AC7) -> #N/A | Q7: =AD7+V7*AH7 -> #N/A | R7: =IF(V7="Too early",V7,Q7-M7) -> #N/A | S7: 1139 | T7: =AG7-AC7 -> 1302 | U7: =(AG7-AC7)*I7 -> 1106.7 | V7: =IF(B7<11,MIN((S7/VLOOKUP(B7,'Sales Pacing'!$A$23:$E$36,2)),T7),"Too early") -> #N/A | W7: =Q7-AD7 -> #N/A | X7: =IF(V7="Too early","Too early",V7/U7) -> #N/A | Y7: 134386 | Z7: 153474 | AA7: =IF(Y7>0,Y7/Z7,"") -> 0.87562714 | AB7: =IF($V7="Too early",V7,V7*AH7/Z7) -> #N/A | AE7: 0 | AF7: =IF(AD7>0,AD7/AE7,"") | AG7: 1302 | AH7: =Y7/S7 -> 117.98595 | AI7: 227 | AJ7: 289 | AK7: 516 | AL7: 134386 | AM7: =L7-AL7 -> 0
A8: 1 | B8: =A8-$G$4 -> -8 | C8: 45901 | D8: 26 La nuit sombre | G8: 45905.833 | H8: Specials | I8: 0.85 | J8: =K8/AG8 -> 1.165 | K8: =S8+AC8 -> 699 | L8: =Y8+AD8 -> 20005 | M8: =Z8+AE8 -> 55000 | N8: =L8-M8 -> -34995 | O8: =IF(P8="Too early",P8,P8/AG8) -> #N/A | P8: =IF(V8="Too early",V8,V8+AC8) -> #N/A | Q8: =AD8+V8*AH8 -> #N/A | R8: =IF(V8="Too early",V8,Q8-M8) -> #N/A | S8: 699 | T8: =AG8-AC8 -> 600 | U8: =(AG8-AC8)*I8 -> 510 | V8: =IF(B8<11,MIN((S8/VLOOKUP(B8,'Sales Pacing'!$A$23:$E$36,2)),T8),"Too early") -> #N/A | W8: =Q8-AD8 -> #N/A | X8: =IF(V8="Too early","Too early",V8/U8) -> #N/A | Y8: 20005 | Z8: 55000 | AA8: =IF(Y8>0,Y8/Z8,"") -> 0.36372727 | AB8: =IF($V8="Too early",V8,V8*AH8/Z8) -> #N/A | AE8: 0 | AF8: =IF(AD8>0,AD8/AE8,"") | AG8: 600 | AH8: =Y8/S8 -> 28.619456 | AI8: 86 | AJ8: 209 | AK8: 295 | AL8: 20005 | AM8: =L8-AL8 -> 0
A9: 2 | B9: =A9-$G$4 -> -7 | C9: 45908 | D9: OPEN - Recording Week | J9: =K9/AG9 -> #DIV/0! | K9: =S9+AC9 -> 0 | P9: =IF(V9="Too early",V9,V9+AC9) -> #N/A | Q9: =AD9+V9*AH9 -> #N/A | R9: =IF(V9="Too early",V9,Q9-M9) -> #N/A | T9: =AG9-AC9 -> 0 | U9: =(AG9-AC9)*I9 -> 0 | V9: =IF(B9<11,MIN((S9/VLOOKUP(B9,'Sales Pacing'!$A$23:$E$36,2)),T9),"Too early") -> #N/A | W9: =Q9-AD9 -> #N/A | AA9: =IF(Y9>0,Y9/Z9,"") | AF9: N/A
A10: 3 | B10: =A10-$G$4 -> -6 | C10: 45915 | D10: 26 PS1 Music of Journey | G10: 45919.833 | H10: Pops | I10: 0.85 | J10: =K10/AG10 -> 0.70880503 | K10: =S10+AC10 -> 1127 | L10: =Y10+AD10 -> 75282.6 | M10: =Z10+AE10 -> 100666 | N10: =L10-M10 -> -25383.4 | O10: =IF(P10="Too early",P10,P10/AG10) -> #N/A | P10: =IF(V10="Too early",V10,V10+AC10) -> #N/A | Q10: =AD10+V10*AH10 -> #N/A | R10: =IF(V10="Too early",V10,Q10-M10) -> #N/A | S10: =508+4 -> 512 | T10: =AG10-AC10 -> 975 | U10: =(AG10-AC10)*I10 -> 828.75 | V10: =IF(B10<11,MIN((S10/VLOOKUP(B10,'Sales Pacing'!$A$23:$E$36,2)),T10),"Too early") -> #N/A | W10: =Q10-AD10 -> #N/A | X10: =IF(V10="Too early","Too early",V10/U10) -> #N/A | Y10: =29619+295 -> 29914 | Z10: 59333 | AA10: =IF(Y10>0,Y10/Z10,"") -> 0.50417137 | AB10: =IF($V10="Too early",V10,V10*AH10/Z10) -> #N/A | AC10: 615 | AD10: 45368.6 | AE10: 41333 | AF10: =IF(AD10>0,AD10/AE10,"") -> 1.0976363 | AG10: 1590 | AH10: =Y10/S10 -> 58.425781 | AI10: 67 | AJ10: 416 | AK10: 483 | AL10: 71854.6 | AM10: =L10-AL10 -> 3428
A11: 3 | B11: =A11-$G$4 -> -6 | C11: 45915 | D11: 26 PS1 Music of Journey | G11: 45920.833 | H11: Pops | I11: 0.85 | J11: =K11/AG11 -> 0.67169811 | K11: =S11+AC11 -> 1068 | L11: =Y11+AD11 -> 74220.3 | M11: =Z11+AE11 -> 100667 | N11: =L11-M11 -> -26446.7 | O11: =IF(P11="Too early",P11,P11/AG11) -> #N/A | P11: =IF(V11="Too early",V11,V11+AC11) -> #N/A | Q11: =AD11+V11*AH11 -> #N/A | R11: =IF(V11="Too early",V11,Q11-M11) -> #N/A | S11: =550+4 -> 554 | T11: =AG11-AC11 -> 1076 | U11: =(AG11-AC11)*I11 -> 914.6 | V11: =IF(B11<11,MIN((S11/VLOOKUP(B11,'Sales Pacing'!$A$23:$E$36,2)),T11),"Too early") -> #N/A | W11: =Q11-AD11 -> #N/A | X11: =IF(V11="Too early","Too early",V11/U11) -> #N/A | Y11: =35384+288 -> 35672 | Z11: 59333 | AA11: =IF(Y11>0,Y11/Z11,"") -> 0.60121686 | AB11: =IF($V11="Too early",V11,V11*AH11/Z11) -> #N/A | AC11: 514 | AD11: 38548.3 | AE11: 41334 | AF11: =IF(AD11>0,AD11/AE11,"") -> 0.93260512 | AG11: 1590 | AH11: =Y11/S11 -> 64.389892 | AI11: 78 | AJ11: 376 | AK11: 454 | AL11: 70013.3 | AM11: =L11-AL11 -> 4207
A12: 3 | B12: =A12-$G$4 -> -6 | C12: 45915 | D12: 26 PS1 Music of Journey | G12: 45921.583 | H12: Pops | I12: 0.85 | J12: =K12/AG12 -> 0.63018868 | K12: =S12+AC12 -> 1002 | L12: =Y12+AD12 -> 63946.8 | M12: =Z12+AE12 -> 100667 | N12: =L12-M12 -> -36720.2 | O12: =IF(P12="Too early",P12,P12/AG12) -> #N/A | P12: =IF(V12="Too early",V12,V12+AC12) -> #N/A | Q12: =AD12+V12*AH12 -> #N/A | R12: =IF(V12="Too early",V12,Q12-M12) -> #N/A | S12: =656+2 -> 658 | T12: =AG12-AC12 -> 1246 | U12: =(AG12-AC12)*I12 -> 1059.1 | V12: =IF(B12<11,MIN((S12/VLOOKUP(B12,'Sales Pacing'!$A$23:$E$36,2)),T12),"Too early") -> #N/A | W12: =Q12-AD12 -> #N/A | X12: =IF(V12="Too early","Too early",V12/U12) -> #N/A | Y12: =39634+165 -> 39799 | Z12: 59334 | AA12: =IF(Y12>0,Y12/Z12,"") -> 0.67076213 | AB12: =IF($V12="Too early",V12,V12*AH12/Z12) -> #N/A | AC12: 344 | AD12: 24147.8 | AE12: 41333 | AF12: =IF(AD12>0,AD12/AE12,"") -> 0.58422568 | AG12: 1590 | AH12: =Y12/S12 -> 60.484802 | AI12: 74 | AJ12: 286 | AK12: 360 | AL12: 56072.3 | AM12: =L12-AL12 -> 7874.5
A13: 4 | B13: =A13-$G$4 -> -5 | C13: 45922 | D13: 26 FS1 The Orchestra Games | G13: 45928.583 | H13: Family | I13: 0.5 | J13: =K13/AG13 -> 0.55376344 | K13: =S13+AC13 -> 721 | L13: =Y13+AD13 -> 16696 | M13: =Z13+AE13 -> 19500 | N13: =L13-M13 -> -2804 | O13: =IF(P13="Too early",P13,P13/AG13) -> #N/A | P13: =IF(V13="Too early",V13,V13+AC13) -> #N/A | Q13: =IF(V13="Too early",V13,AD13+V13*AH13) -> #N/A | R13: =IF(V13="Too early",V13,Q13-M13) -> #N/A | S13: 503 | T13: =AG13-AC13 -> 1084 | U13: =(AG13-AC13)*I13 -> 542 | V13: =IF(B13<11,MIN((S13/VLOOKUP(B13,'Sales Pacing'!$A$23:$E$36,2)),T13),"Too early") -> #N/A | W13: =Q13-AD13 -> #N/A | X13: =IF(V13="Too early","Too early",V13/U13) -> #N/A | Y13: 10721 | Z13: 10000 | AA13: =IF(Y13>0,Y13/Z13,"") -> 1.0721 | AB13: =IF($V13="Too early",V13,V13*AH13/Z13) -> #N/A | AC13: 218 | AD13: 5975 | AE13: 9500 | AF13: =IF(AD13>0,AD13/AE13,"") -> 0.62894737 | AG13: 1302 | AH13: =Y13/S13 -> 21.314115 | AI13: 21 | AJ13: 104 | AK13: 125 | AL13: 12684 | AM13: =L13-AL13 -> 4012
A14: 5 | B14: =A14-$G$4 -> -4 | C14: 45929 | D14: OPEN - was Chicken Fried | J14: =K14/AG14 -> #DIV/0! | Q14: =IF(V14="Too early",V14,AD14+V14*AH14) -> #N/A | R14: =IF(V14="Too early",V14,Q14-M14) -> #N/A | T14: =AG14-AC14 -> 0 | U14: =(AG14-AC14)*I14 -> 0 | V14: =IF(B14<11,MIN((S14/VLOOKUP(B14,'Sales Pacing'!$A$23:$E$36,2)),T14),"Too early") -> #N/A | W14: =Q14-AD14 -> #N/A
A15: 6 | B15: =A15-$G$4 -> -3 | C15: 45936 | D15: 26 CS01 Appalachian Spring | G15: 45940.833 | H15: Classical | I15: 0.85 | J15: =K15/AG15 -> 0.75575715 | K15: =S15+AC15 -> 1083 | L15: =Y15+AD15 -> 62663 | M15: =Z15+AE15 -> 50000 | N15: =L15-M15 -> 12663 | O15: =IF(P15="Too early",P15,P15/AG15) -> #N/A | P15: =IF(V15="Too early",V15,V15+AC15) -> #N/A | Q15: =IF(V15="Too early",V15,AD15+V15*AH15) -> #N/A | R15: =IF(V15="Too early",V15,Q15-M15) -> #N/A | S15: =623+17 -> 640 | T15: =AG15-AC15 -> 990 | U15: =(AG15-AC15)*I15 -> 841.5 | V15: =IF(B15<11,MIN((S15/VLOOKUP(B15,'Sales Pacing'!$A$23:$E$36,2)),T15),"Too early") -> #N/A | W15: =Q15-AD15 -> #N/A | X15: =IF(V15="Too early","Too early",V15/U15) -> #N/A | Y15: =31125+1209 -> 32334 | Z15: 16667 | AA15: =IF(Y15>0,Y15/Z15,"") -> 1.9400012 | AB15: =IF($V15="Too early",V15,V15*AH15/Z15) -> #N/A | AC15: 443 | AD15: 30329 | AE15: 33333 | AF15: =IF(AD15>0,AD15/AE15,"") -> 0.9098791 | AG15: 1433 | AH15: =Y15/S15 -> 50.521875 | AI15: 13 | AJ15: 370 | AK15: 383 | AL15: 47640 | AM15: =L15-AL15 -> 15023
A16: 6 | B16: =A16-$G$4 -> -3 | C16: 45936 | D16: 26 CS01 Appalachian Spring | G16: 45941.833 | H16: Classical | I16: 0.85 | J16: =K16/AG16 -> 0.78157711 | K16: =S16+AC16 -> 1120 | L16: =Y16+AD16 -> 67352.7 | M16: =Z16+AE16 -> 50000 | N16: =L16-M16 -> 17352.7 | O16: =IF(P16="Too early",P16,P16/AG16) -> #N/A | P16: =IF(V16="Too early",V16,V16+AC16) -> #N/A | Q16: =IF(V16="Too early",V16,AD16+V16*AH16) -> #N/A | R16: =IF(V16="Too early",V16,Q16-M16) -> #N/A | S16: =628+28 -> 656 | T16: =AG16-AC16 -> 969 | U16: =(AG16-AC16)*I16 -> 823.65 | V16: =IF(B16<11,MIN((S16/VLOOKUP(B16,'Sales Pacing'!$A$23:$E$36,2)),T16),"Too early") -> #N/A | W16: =Q16-AD16 -> #N/A | X16: =IF(V16="Too early","Too early",V16/U16) -> #N/A | Y16: =32749+1801 -> 34550 | Z16: 16667 | AA16: =IF(Y16>0,Y16/Z16,"") -> 2.0729585 | AB16: =IF($V16="Too early",V16,V16*AH16/Z16) -> #N/A | AC16: 464 | AD16: 32802.7 | AE16: 33333 | AF16: =IF(AD16>0,AD16/AE16,"") -> 0.98409084 | AG16: 1433 | AH16: =Y16/S16 -> 52.667683 | AI16: 21 | AJ16: 386 | AK16: 407 | AL16: 55614.1 | AM16: =L16-AL16 -> 11738.6
A17: 6 | B17: =A17-$G$4 -> -3 | C17: 45936 | D17: 26 CS01 Appalachian Spring | G17: 45942.583 | H17: Classical | I17: 0.85 | J17: =K17/AG17 -> 0.86461968 | K17: =S17+AC17 -> 1239 | L17: =Y17+AD17 -> 72775.2 | M17: =Z17+AE17 -> 50000 | N17: =L17-M17 -> 22775.2 | O17: =IF(P17="Too early",P17,P17/AG17) -> #N/A | P17: =IF(V17="Too early",V17,V17+AC17) -> #N/A | Q17: =IF(V17="Too early",V17,AD17+V17*AH17) -> #N/A | R17: =IF(V17="Too early",V17,Q17-M17) -> #N/A | S17: =708+19 -> 727 | T17: =AG17-AC17 -> 921 | U17: =(AG17-AC17)*I17 -> 782.85 | V17: =IF(B17<11,MIN((S17/VLOOKUP(B17,'Sales Pacing'!$A$23:$E$36,2)),T17),"Too early") -> #N/A | W17: =Q17-AD17 -> #N/A | X17: =IF(V17="Too early","Too early",V17/U17) -> #N/A | Y17: =37234+1325 -> 38559 | Z17: 16666 | AA17: =IF(Y17>0,Y17/Z17,"") -> 2.3136325 | AB17: =IF($V17="Too early",V17,V17*AH17/Z17) -> #N/A | AC17: 512 | AD17: 34216.2 | AE17: 33334 | AF17: =IF(AD17>0,AD17/AE17,"") -> 1.0264655 | AG17: 1433 | AH17: =Y17/S17 -> 53.038514 | AI17: 17 | AJ17: 455 | AK17: 472 | AL17: 57932.6 | AM17: =L17-AL17 -> 14842.6
A18: 7 | B18: =A18-$G$4 -> -2 | C18: 45943 | D18: 26 Top Gun: Maverick in Concert | G18: 45947.792 | H18: Specials/Film | I18: 0.85 | J18: =K18/AG18 -> 0.87034277 | K18: =S18+AC18 -> 1168 | L18: =Y18+AD18 -> 87476 | M18: =Z18+AE18 -> 103497 | N18: =L18-M18 -> -16021 | O18: =IF(P18="Too early",P18,P18/AG18) -> #N/A | P18: =IF(V18="Too early",V18,V18+AC18) -> #N/A | Q18: =IF(V18="Too early",V18,AD18+V18*AH18) -> #N/A | R18: =IF(V18="Too early",V18,Q18-M18) -> #N/A | S18: =1162+6 -> 1168 | T18: =AG18-AC18 -> 1342 | U18: =(AG18-AC18)*I18 -> 1140.7 | V18: =IF(B18<11,MIN((S18/VLOOKUP(B18,'Sales Pacing'!$A$23:$E$36,2)),T18),"Too early") -> #N/A | W18: =Q18-AD18 -> #N/A | X18: =IF(V18="Too early","Too early",V18/U18) -> #N/A | Y18: =87153+323 -> 87476 | Z18: 103497 | AA18: =IF(Y18>0,Y18/Z18,"") -> 0.84520324 | AB18: =IF($V18="Too early",V18,V18*AH18/Z18) -> #N/A | AF18: =IF(AD18>0,AD18/AE18,"") | AG18: 1342 | AH18: =Y18/S18 -> 74.893836 | AI18: 51 | AJ18: 179 | AK18: 230 | AL18: 48750 | AM18: =L18-AL18 -> 38726
A19: 7 | B19: =A19-$G$4 -> -2 | C19: 45943 | D19: 26 Top Gun: Maverick in Concert | G19: 45948.792 | H19: Specials/Film | I19: 0.85 | J19: =K19/AG19 -> 0.9538003 | K19: =S19+AC19 -> 1280 | L19: =Y19+AD19 -> 97657 | M19: =Z19+AE19 -> 103497 | N19: =L19-M19 -> -5840 | O19: =IF(P19="Too early",P19,P19/AG19) -> #N/A | P19: =IF(V19="Too early",V19,V19+AC19) -> #N/A | Q19: =IF(V19="Too early",V19,AD19+V19*AH19) -> #N/A | R19: =IF(V19="Too early",V19,Q19-M19) -> #N/A | S19: =1268+12 -> 1280 | T19: =AG19-AC19 -> 1342 | U19: =(AG19-AC19)*I19 -> 1140.7 | V19: =IF(B19<11,MIN((S19/VLOOKUP(B19,'Sales Pacing'!$A$23:$E$36,2)),T19),"Too early") -> #N/A | W19: =Q19-AD19 -> #N/A | X19: =IF(V19="Too early","Too early",V19/U19) -> #N/A | Y19: =96649+1008 -> 97657 | Z19: 103497 | AA19: =IF(Y19>0,Y19/Z19,"") -> 0.94357324 | AB19: =IF($V19="Too early",V19,V19*AH19/Z19) -> #N/A | AF19: =IF(AD19>0,AD19/AE19,"") | AG19: 1342 | AH19: =Y19/S19 -> 76.294531 | AI19: 74 | AJ19: 184 | AK19: 258 | AL19: 60628 | AM19: =L19-AL19 -> 37029
A20: 7 | B20: =A20-$G$4 -> -2 | C20: 45943 | D20: 26 Top Gun: Maverick in Concert | G20: 45949.583 | H20: Specials/Film | I20: 0.85 | J20: =K20/AG20 -> 0.74217586 | K20: =S20+AC20 -> 996 | L20: =Y20+AD20 -> 78145 | M20: =Z20+AE20 -> 103496 | N20: =L20-M20 -> -25351 | O20: =IF(P20="Too early",P20,P20/AG20) -> #N/A | P20: =IF(V20="Too early",V20,V20+AC20) -> #N/A | Q20: =IF(V20="Too early",V20,AD20+V20*AH20) -> #N/A | R20: =IF(V20="Too early",V20,Q20-M20) -> #N/A | S20: =982+14 -> 996 | T20: =AG20-AC20 -> 1342 | U20: =(AG20-AC20)*I20 -> 1140.7 | V20: =IF(B20<11,MIN((S20/VLOOKUP(B20,'Sales Pacing'!$A$23:$E$36,2)),T20),"Too early") -> #N/A | W20: =Q20-AD20 -> #N/A | X20: =IF(V20="Too early","Too early",V20/U20) -> #N/A | Y20: =77074+1071 -> 78145 | Z20: 103496 | AA20: =IF(Y20>0,Y20/Z20,"") -> 0.75505334 | AB20: =IF($V20="Too early",V20,V20*AH20/Z20) -> #N/A | AF20: =IF(AD20>0,AD20/AE20,"") | AG20: 1342 | AH20: =Y20/S20 -> 78.458835 | AI20: 38 | AJ20: 149 | AK20: 187 | AL20: 44494 | AM20: =L20-AL20 -> 33651
A21: 8 | B21: =A21-$G$4 -> -1 | C21: 45950 | D21: 26 The Lodger | G21: 45952.792 | H21: Specials/Film | I21: 0.5 | J21: =K21/AG21 -> 0.28092399 | K21: =S21+AC21 -> 377 | L21: =Y21+AD21 -> 19285 | M21: =Z21+AE21 -> 50000 | N21: =L21-M21 -> -30715 | O21: =IF(P21="Too early",P21,P21/AG21) -> #N/A | P21: =IF(V21="Too early",V21,V21+AC21) -> #N/A | Q21: =IF(V21="Too early",V21,AD21+V21*AH21) -> #N/A | R21: =IF(V21="Too early",V21,Q21-M21) -> #N/A | S21: =375+2 -> 377 | T21: =AG21-AC21 -> 1342 | U21: =(AG21-AC21)*I21 -> 671 | V21: =IF(B21<11,MIN((S21/VLOOKUP(B21,'Sales Pacing'!$A$23:$E$36,2)),T21),"Too early") -> #N/A | W21: =Q21-AD21 -> #N/A | X21: =IF(V21="Too early","Too early",V21/U21) -> #N/A | Y21: 19285 | Z21: 50000 | AA21: =IF(Y21>0,Y21/Z21,"") -> 0.3857 | AB21: =IF($V21="Too early",V21,V21*AH21/Z21) -> #N/A | AF21: =IF(AD21>0,AD21/AE21,"") | AG21: 1342 | AH21: =Y21/S21 -> 51.153846 | AI21: 5 | AJ21: 78 | AK21: 83 | AL21: 10588 | AM21: =L21-AL21 -> 8697
A22: 8 | B22: =A22-$G$4 -> -1 | C22: 45950 | D22: 26 PS2 90s Mixtape | G22: 45954.833 | H22: Pops | I22: 0.85 | J22: =K22/AG22 -> 0.57026858 | K22: =S22+AC22 -> 913 | L22: =Y22+AD22 -> 63970 | M22: =Z22+AE22 -> 92333 | N22: =L22-M22 -> -28363 | O22: =IF(P22="Too early",P22,P22/AG22) -> #N/A | P22: =IF(V22="Too early",V22,V22+AC22) -> #N/A | Q22: =IF(V22="Too early",V22,AD22+V22*AH22) -> #N/A | R22: =IF(V22="Too early",V22,Q22-M22) -> #N/A | S22: =271+6 -> 277 | T22: =AG22-AC22 -> 965 | U22: =(AG22-AC22)*I22 -> 820.25 | V22: =IF(B22<11,MIN((S22/VLOOKUP(B22,'Sales Pacing'!$A$23:$E$36,2)),T22),"Too early") -> #N/A | W22: =Q22-AD22 -> #N/A | X22: =IF(V22="Too early","Too early",V22/U22) -> #N/A | Y22: =16908+370 -> 17278 | Z22: 53333 | AA22: =IF(Y22>0,Y22/Z22,"") -> 0.32396452 | AB22: =IF($V22="Too early",V22,V22*AH22/Z22) -> #N/A | AC22: 636 | AD22: 46692 | AE22: 39000 | AF22: =IF(AD22>0,AD22/AE22,"") -> 1.1972308 | AG22: 1601 | AH22: =Y22/S22 -> 62.375451 | AI22: 7 | AJ22: 350 | AK22: 357 | AL22: 57609.1 | AM22: =L22-AL22 -> 6360.9
A23: 8 | B23: =A23-$G$4 -> -1 | C23: 45950 | D23: 26 PS2 90s Mixtape | G23: 45955.833 | H23: Pops | I23: 0.85 | J23: =K23/AG23 -> 0.64022486 | K23: =S23+AC23 -> 1025 | L23: =Y23+AD23 -> 63357 | M23: =Z23+AE23 -> 92333 | N23: =L23-M23 -> -28976 | O23: =IF(P23="Too early",P23,P23/AG23) -> #N/A | P23: =IF(V23="Too early",V23,V23+AC23) -> #N/A | Q23: =IF(V23="Too early",V23,AD23+V23*AH23) -> #N/A | R23: =IF(V23="Too early",V23,Q23-M23) -> #N/A | S23: =488+3 -> 491 | T23: =AG23-AC23 -> 1067 | U23: =(AG23-AC23)*I23 -> 906.95 | V23: =IF(B23<11,MIN((S23/VLOOKUP(B23,'Sales Pacing'!$A$23:$E$36,2)),T23),"Too early") -> #N/A | W23: =Q23-AD23 -> #N/A | X23: =IF(V23="Too early","Too early",V23/U23) -> #N/A | Y23: =24042+217 -> 24259 | Z23: 53333 | AA23: =IF(Y23>0,Y23/Z23,"") -> 0.45485909 | AB23: =IF($V23="Too early",V23,V23*AH23/Z23) -> #N/A | AC23: 534 | AD23: 39098 | AE23: 39000 | AF23: =IF(AD23>0,AD23/AE23,"") -> 1.0025128 | AG23: 1601 | AH23: =Y23/S23 -> 49.407332 | AI23: 11 | AJ23: 320 | AK23: 311 | AL23: 52382.8 | AM23: =L23-AL23 -> 10974.2
A24: 8 | B24: =A24-$G$4 -> -1 | C24: 45950 | D24: 26 PS2 90s Mixtape | G24: 45956.583 | H24: Pops | I24: 0.85 | J24: =K24/AG24 -> 0.5321674 | K24: =S24+AC24 -> 852 | L24: =Y24+AD24 -> 44080 | M24: =Z24+AE24 -> 92334 | N24: =L24-M24 -> -48254 | O24: =IF(P24="Too early",P24,P24/AG24) -> #N/A | P24: =IF(V24="Too early",V24,V24+AC24) -> #N/A | Q24: =IF(V24="Too early",V24,AD24+V24*AH24) -> #N/A | R24: =IF(V24="Too early",V24,Q24-M24) -> #N/A | S24: =515+4 -> 519 | T24: =AG24-AC24 -> 1268 | U24: =(AG24-AC24)*I24 -> 1077.8 | V24: =IF(B24<11,MIN((S24/VLOOKUP(B24,'Sales Pacing'!$A$23:$E$36,2)),T24),"Too early") -> #N/A | W24: =Q24-AD24 -> #N/A | X24: =IF(V24="Too early","Too early",V24/U24) -> #N/A | Y24: =20477+360 -> 20837 | Z24: 53334 | AA24: =IF(Y24>0,Y24/Z24,"") -> 0.39068887 | AB24: =IF($V24="Too early",V24,V24*AH24/Z24) -> #N/A | AC24: 333 | AD24: 23243 | AE24: 39000 | AF24: =IF(AD24>0,AD24/AE24,"") -> 0.59597436 | AG24: 1601 | AH24: =Y24/S24 -> 40.148362 | AI24: 6 | AJ24: 209 | AK24: 203 | AL24: 31818.5 | AM24: =L24-AL24 -> 12261.5
A25: 9 | B25: =A25-$G$4 -> 0 | C25: 45957 | D25: 26 On-Stage 1 George Li | G25: 45959.833 | H25: On Stage | I25: 0.85 | J25: =K25/AG25 -> 0.38 | K25: =S25+AC25 -> 38 | L25: =Y25+AD25 -> 4620 | M25: 11200 | N25: =L25-M25 -> -6580 | O25: =IF(P25="Too early",P25,P25/AG25) -> 0.38 | P25: =IF(V25="Too early",V25,V25+AC25) -> 38 | Q25: =IF(V25="Too early",V25,AD25+V25*AH25) -> 4620 | R25: =IF(V25="Too early",V25,Q25-M25) -> -6580 | S25: 38 | T25: =AG25-AC25 -> 100 | U25: =(AG25-AC25)*I25 -> 85 | V25: =IF(B25<11,MIN((S25/VLOOKUP(B25,'Sales Pacing'!$A$23:$E$36,2)),T25),"Too early") -> 38 | W25: =Q25-AD25 -> 4620 | X25: =IF(V25="Too early","Too early",V25/U25) -> 0.44705882 | Y25: 4620 | Z25: 11200 | AA25: =IF(Y25>0,Y25/Z25,"") -> 0.4125 | AB25: =IF($V25="Too early",V25,V25*AH25/Z25) -> 0.4125 | AF25: =IF(AD25>0,AD25/AE25,"") | AG25: 100 | AH25: =Y25/S25 -> 121.57895 | AI25: 0 | AJ25: 11 | AK25: 11 | AL25: 2800 | AM25: =L25-AL25 -> 1820
A26: 9 | B26: =A26-$G$4 -> 0 | C26: 45957 | D26: 26 CS02 Rachmaninoff Cele Pt 1 | G26: 45961.833 | H26: Classical | I26: 0.5 | J26: =K26/AG26 -> 0.44 | K26: =S26+AC26 -> 638 | L26: =Y26+AD26 -> 37062 | M26: =Z26+AE26 -> 52000 | N26: =L26-M26 -> -14938 | O26: =IF(P26="Too early",P26,P26/AG26) -> 0.44 | P26: =IF(V26="Too early",V26,V26+AC26) -> 638 | Q26: =IF(V26="Too early",V26,AD26+V26*AH26) -> 37062 | R26: =IF(V26="Too early",V26,Q26-M26) -> -14938 | S26: =316+14 -> 330 | T26: =AG26-AC26 -> 1142 | U26: =(AG26-AC26)*I26 -> 571 | V26: =IF(B26<11,MIN((S26/VLOOKUP(B26,'Sales Pacing'!$A$23:$E$36,2)),T26),"Too early") -> 330 | W26: =Q26-AD26 -> 15733 | X26: =IF(V26="Too early","Too early",V26/U26) -> 0.57793345 | Y26: =14842+891 -> 15733 | Z26: 22000 | AA26: =IF(Y26>0,Y26/Z26,"") -> 0.71513636 | AB26: =IF($V26="Too early",V26,V26*AH26/Z26) -> 0.71513636 | AC26: 308 | AD26: 21329 | AE26: 30000 | AF26: =IF(AD26>0,AD26/AE26,"") -> 0.71096667 | AG26: 1450 | AH26: =Y26/S26 -> 47.675758 | AI26: 10 | AJ26: 222 | AK26: 232 | AL26: 30757 | AM26: =L26-AL26 -> 6305
A27: 9 | B27: =A27-$G$4 -> 0 | C27: 45957 | D27: 26 CS02 Rachmaninoff Cele Pt 1 | G27: 45962.833 | H27: Classical | I27: 0.85 | J27: =K27/AG27 -> 0.90965517 | K27: =S27+AC27 -> 1319 | L27: =Y27+AD27 -> 77243 | M27: =Z27+AE27 -> 86500 | N27: =L27-M27 -> -9257 | O27: =IF(P27="Too early",P27,P27/AG27) -> 0.90965517 | P27: =IF(V27="Too early",V27,V27+AC27) -> 1319 | Q27: =IF(V27="Too early",V27,AD27+V27*AH27) -> 77243 | R27: =IF(V27="Too early",V27,Q27-M27) -> -9257 | S27: =790+22 -> 812 | T27: =AG27-AC27 -> 943 | U27: =(AG27-AC27)*I27 -> 801.55 | V27: =IF(B27<11,MIN((S27/VLOOKUP(B27,'Sales Pacing'!$A$23:$E$36,2)),T27),"Too early") -> 812 | W27: =Q27-AD27 -> 43676 | X27: =IF(V27="Too early","Too early",V27/U27) -> 1.0130372 | Y27: =42354+1322 -> 43676 | Z27: 31500 | AA27: =IF(Y27>0,Y27/Z27,"") -> 1.3865397 | AB27: =IF($V27="Too early",V27,V27*AH27/Z27) -> 1.3865397 | AC27: 507 | AD27: 33567 | AE27: 55000 | AF27: =IF(AD27>0,AD27/AE27,"") -> 0.61030909 | AG27: 1450 | AH27: =Y27/S27 -> 53.788177 | AI27: 26 | AJ27: 397 | AK27: 423 | AL27: 57693 | AM27: =L27-AL27 -> 19550
A28: 9 | B28: =A28-$G$4 -> 0 | C28: 45957 | D28: 26 CS02 Rachmaninoff Cele Pt 1 | G28: 45963.583 | H28: Classical | I28: 0.85 | J28: =K28/AG28 -> 0.77862069 | K28: =S28+AC28 -> 1129 | L28: =Y28+AD28 -> 68813 | M28: =Z28+AE28 -> 86500 | N28: =L28-M28 -> -17687 | O28: =IF(P28="Too early",P28,P28/AG28) -> 0.77862069 | P28: =IF(V28="Too early",V28,V28+AC28) -> 1129 | Q28: =IF(V28="Too early",V28,AD28+V28*AH28) -> 68813 | R28: =IF(V28="Too early",V28,Q28-M28) -> -17687 | S28: =568+25 -> 593 | T28: =AG28-AC28 -> 914 | U28: =(AG28-AC28)*I28 -> 776.9 | V28: =IF(B28<11,MIN((S28/VLOOKUP(B28,'Sales Pacing'!$A$23:$E$36,2)),T28),"Too early") -> 593 | W28: =Q28-AD28 -> 34069 | X28: =IF(V28="Too early","Too early",V28/U28) -> 0.76329 | Y28: =32590+1479 -> 34069 | Z28: 31500 | AA28: =IF(Y28>0,Y28/Z28,"") -> 1.0815556 | AB28: =IF($V28="Too early",V28,V28*AH28/Z28) -> 1.0815556 | AC28: 536 | AD28: 34744 | AE28: 55000 | AF28: =IF(AD28>0,AD28/AE28,"") -> 0.63170909 | AG28: 1450 | AH28: =Y28/S28 -> 57.451939 | AI28: 17 | AJ28: 407 | AK28: 424 | AL28: 51432.1 | AM28: =L28-AL28 -> 17380.9
A29: 10 | B29: =A29-$G$4 -> 1 | C29: 45964 | D29: 26 FS2 Carnival of the Animals | G29: 45970.583 | H29: Family | I29: 0.5 | J29: =K29/AG29 -> 0.42391304 | K29: =S29+AC29 -> 585 | L29: =Y29+AD29 -> 15626 | M29: =Z29+AE29 -> 19500 | N29: =L29-M29 -> -3874 | O29: =IF(P29="Too early",P29,P29/AG29) -> 0.55282486 | P29: =IF(V29="Too early",V29,V29+AC29) -> 762.89831 | Q29: =IF(V29="Too early",V29,AD29+V29*AH29) -> 21207.559 | R29: =IF(V29="Too early",V29,Q29-M29) -> 1707.5593 | S29: =252+4 -> 256 | T29: =AG29-AC29 -> 1051 | U29: =(AG29-AC29)*I29 -> 525.5 | V29: =IF(B29<11,MIN((S29/VLOOKUP(B29,'Sales Pacing'!$A$23:$E$36,2)),T29),"Too early") -> 433.89831 | W29: =Q29-AD29 -> 13613.559 | X29: =IF(V29="Too early","Too early",V29/U29) -> 0.82568659 | Y29: =7888+144 -> 8032 | Z29: 10000 | AA29: =IF(Y29>0,Y29/Z29,"") -> 0.8032 | AB29: =IF($V29="Too early",V29,V29*AH29/Z29) -> 1.3613559 | AC29: 329 | AD29: 7594 | AE29: 9500 | AF29: =IF(AD29>0,AD29/AE29,"") -> 0.79936842 | AG29: 1380 | AH29: =Y29/S29 -> 31.375 | AI29: 9 | AJ29: 103 | AK29: 112 | AL29: 10703 | AM29: =L29-AL29 -> 4923
A30: 11 | B30: =A30-$G$4 -> 2 | C30: 45971 | D30: OPEN | J30: =K30/AG30 -> #DIV/0! | K30: =S30+AC30 -> 0 | L30: =Y30+AD30 -> 0 | M30: =Z30+AE30 -> 0 | P30: =IF(V30="Too early",V30,V30+AC30) -> 0 | Q30: =IF(V30="Too early",V30,AD30+V30*AH30) -> #DIV/0! | R30: =IF(V30="Too early",V30,Q30-M30) -> #DIV/0! | T30: =AG30-AC30 -> 0 | U30: =(AG30-AC30)*I30 -> 0 | V30: =IF(B30<7,(S30/VLOOKUP(B30,'Sales Pacing'!$A$23:$E$36,2)),"Too early") -> 0 | W30: =Q30-AD30 -> #DIV/0! | AA30: =IF(Y30>0,Y30/Z30,"") | AF30: N/A | AH30: =Y30/S30 -> #DIV/0! | AL30: 0
A31: 12 | B31: =A31-$G$4 -> 3 | C31: 45978 | D31: 26 CS03 Matthias and Mahler 7 | G31: 45982.833 | H31: Classical | I31: 0.5 | J31: =K31/AG31 -> 0.33416304 | K31: =S31+AC31 -> 537 | L31: =Y31+AD31 -> 34142 | M31: =Z31+AE31 -> 40000 | N31: =L31-M31 -> -5858 | O31: =IF(P31="Too early",P31,P31/AG31) -> 0.5093581 | P31: =IF(V31="Too early",V31,V31+AC31) -> 818.53846 | Q31: =IF(V31="Too early",V31,AD31+V31*AH31) -> 48775.744 | R31: =IF(V31="Too early",V31,Q31-M31) -> 8775.7436 | S31: =167+13 -> 180 | T31: =AG31-AC31 -> 1250 | U31: =(AG31-AC31)*I31 -> 625 | V31: =IF(B31<11,MIN((S31/VLOOKUP(B31,'Sales Pacing'!$A$23:$E$36,2)),T31),"Too early") -> 461.53846 | W31: =Q31-AD31 -> 23989.744 | X31: =IF(V31="Too early","Too early",V31/U31) -> 0.73846154 | Y31: =8573+783 -> 9356 | Z31: 15000 | AA31: =IF(Y31>0,Y31/Z31,"") -> 0.62373333 | AB31: =IF($V31="Too early",V31,V31*AH31/Z31) -> 1.5993162 | AC31: 357 | AD31: 24786 | AE31: 25000 | AF31: =IF(AD31>0,AD31/AE31,"") -> 0.99144 | AG31: 1607 | AH31: =Y31/S31 -> 51.977778 | AI31: 1 | AJ31: 221 | AK31: 222 | AL31: 29114 | AM31: =L31-AL31 -> 5028
A32: 12 | B32: =A32-$G$4 -> 3 | C32: 45978 | D32: 26 CS03 Matthias and Mahler 7 | G32: 45983.833 | H32: Classical | I32: 0.85 | J32: =K32/AG32 -> 0.50342253 | K32: =S32+AC32 -> 809 | L32: =Y32+AD32 -> 52590 | M32: =Z32+AE32 -> 66500 | N32: =L32-M32 -> -13910 | O32: =IF(P32="Too early",P32,P32/AG32) -> 0.73214941 | P32: =IF(V32="Too early",V32,V32+AC32) -> 1176.5641 | Q32: =IF(V32="Too early",V32,AD32+V32*AH32) -> 73522.385 | R32: =IF(V32="Too early",V32,Q32-M32) -> 7022.3846 | S32: =225+10 -> 235 | T32: =AG32-AC32 -> 1033 | U32: =(AG32-AC32)*I32 -> 878.05 | V32: =IF(B32<11,MIN((S32/VLOOKUP(B32,'Sales Pacing'!$A$23:$E$36,2)),T32),"Too early") -> 602.5641 | W32: =Q32-AD32 -> 34315.385 | X32: =IF(V32="Too early","Too early",V32/U32) -> 0.68625261 | Y32: =12689+694 -> 13383 | Z32: 11500 | AA32: =IF(Y32>0,Y32/Z32,"") -> 1.1637391 | AB32: =IF($V32="Too early",V32,V32*AH32/Z32) -> 2.9839465 | AC32: 574 | AD32: 39207 | AE32: 55000 | AF32: =IF(AD32>0,AD32/AE32,"") -> 0.71285455 | AG32: 1607 | AH32: =Y32/S32 -> 56.948936 | AI32: 4 | AJ32: 347 | AK32: 351 | AL32: 47477.9 | AM32: =L32-AL32 -> 5112.1
A33: 12 | B33: =A33-$G$4 -> 3 | C33: 45978 | D33: 26 CS03 Matthias and Mahler 7 | G33: 45984.583 | H33: Classical | I33: 0.85 | J33: =K33/AG33 -> 0.48911014 | K33: =S33+AC33 -> 786 | L33: =Y33+AD33 -> 50274 | M33: =Z33+AE33 -> 66500 | N33: =L33-M33 -> -16226 | O33: =IF(P33="Too early",P33,P33/AG33) -> 0.67209165 | P33: =IF(V33="Too early",V33,V33+AC33) -> 1080.0513 | Q33: =IF(V33="Too early",V33,AD33+V33*AH33) -> 68447.308 | R33: =IF(V33="Too early",V33,Q33-M33) -> 1947.3077 | S33: =172+16 -> 188 | T33: =AG33-AC33 -> 1009 | U33: =(AG33-AC33)*I33 -> 857.65 | V33: =IF(B33<11,MIN((S33/VLOOKUP(B33,'Sales Pacing'!$A$23:$E$36,2)),T33),"Too early") -> 482.05128 | W33: =Q33-AD33 -> 29792.308 | X33: =IF(V33="Too early","Too early",V33/U33) -> 0.56206061 | Y33: =10778+841 -> 11619 | Z33: 11500 | AA33: =IF(Y33>0,Y33/Z33,"") -> 1.0103478 | AB33: =IF($V33="Too early",V33,V33*AH33/Z33) -> 2.5906355 | AC33: 598 | AD33: 38655 | AE33: 55000 | AF33: =IF(AD33>0,AD33/AE33,"") -> 0.70281818 | AG33: 1607 | AH33: =Y33/S33 -> 61.803191 | AI33: 3 | AJ33: 391 | AK33: 394 | AL33: 46613.2 | AM33: =L33-AL33 -> 3660.8
A34: 13 | B34: =A34-$G$4 -> 4 | C34: 45985 | D34: 26 Elf™ in Concert | G34: 45989.792 | H34: Specials/Film | I34: 0.85 | J34: =K34/AG34 -> 0.57603687 | K34: =S34+AC34 -> 750 | L34: =Y34+AD34 -> 52612 | M34: =Z34+AE34 -> 107500 | N34: =L34-M34 -> -54888 | O34: =IF(P34="Too early",P34,P34/AG34) -> 1 | P34: =IF(V34="Too early",V34,V34+AC34) -> 1302 | Q34: =IF(V34="Too early",V34,AD34+V34*AH34) -> 91334.432 | R34: =IF(V34="Too early",V34,Q34-M34) -> -16165.568 | S34: =746+4 -> 750 | T34: =AG34-AC34 -> 1302 | U34: =(AG34-AC34)*I34 -> 1106.7 | V34: =IF(B34<11,MIN((S34/VLOOKUP(B34,'Sales Pacing'!$A$23:$E$36,2)),T34),"Too early") -> 1302 | W34: =Q34-AD34 -> 91334.432 | X34: =IF(V34="Too early","Too early",V34/U34) -> 1.1764706 | Y34: =52269+343 -> 52612 | Z34: 107500 | AA34: =IF(Y34>0,Y34/Z34,"") -> 0.48941395 | AB34: =IF($V34="Too early",V34,V34*AH34/Z34) -> 0.84962262 | AF34: =IF(AD34>0,AD34/AE34,"") | AG34: 1302 | AH34: =Y34/S34 -> 70.149333 | AI34: 17 | AJ34: 45 | AK34: 62 | AL34: 20977.6 | AM34: =L34-AL34 -> 31634.4
A35: 13 | B35: =A35-$G$4 -> 4 | C35: 45985 | D35: 26 Elf™ in Concert | G35: 45990.542 | H35: Specials/Film | I35: 0.85 | J35: =K35/AG35 -> 0.56912442 | K35: =S35+AC35 -> 741 | L35: =Y35+AD35 -> 50110 | M35: =Z35+AE35 -> 107500 | N35: =L35-M35 -> -57390 | O35: =IF(P35="Too early",P35,P35/AG35) -> 1 | P35: =IF(V35="Too early",V35,V35+AC35) -> 1302 | Q35: =IF(V35="Too early",V35,AD35+V35*AH35) -> 88047.53 | R35: =IF(V35="Too early",V35,Q35-M35) -> -19452.47 | S35: =741 -> 741 | T35: =AG35-AC35 -> 1302 | U35: =(AG35-AC35)*I35 -> 1106.7 | V35: =IF(B35<11,MIN((S35/VLOOKUP(B35,'Sales Pacing'!$A$23:$E$36,2)),T35),"Too early") -> 1302 | W35: =Q35-AD35 -> 88047.53 | X35: =IF(V35="Too early","Too early",V35/U35) -> 1.1764706 | Y35: 50110 | Z35: 107500 | AA35: =IF(Y35>0,Y35/Z35,"") -> 0.46613953 | AB35: =IF($V35="Too early",V35,V35*AH35/Z35) -> 0.81904679 | AF35: =IF(AD35>0,AD35/AE35,"") | AG35: 1302 | AH35: =Y35/S35 -> 67.624831 | AI35: 22 | AJ35: 53 | AK35: 75 | AL35: 24414.6 | AM35: =L35-AL35 -> 25695.4
A36: 13 | B36: =A36-$G$4 -> 4 | C36: 45985 | D36: 26 Elf™ in Concert | G36: 45990.792 | H36: Specials/Film | I36: 0.85 | J36: =K36/AG36 -> 0.4969278 | K36: =S36+AC36 -> 647 | L36: =Y36+AD36 -> 45552 | M36: =Z36+AE36 -> 107500 | N36: =L36-M36 -> -61948 | O36: =IF(P36="Too early",P36,P36/AG36) -> 1 | P36: =IF(V36="Too early",V36,V36+AC36) -> 1302 | Q36: =IF(V36="Too early",V36,AD36+V36*AH36) -> 91667.24 | R36: =IF(V36="Too early",V36,Q36-M36) -> -15832.76 | S36: 647 | T36: =AG36-AC36 -> 1302 | U36: =(AG36-AC36)*I36 -> 1106.7 | V36: =IF(B36<11,MIN((S36/VLOOKUP(B36,'Sales Pacing'!$A$23:$E$36,2)),T36),"Too early") -> 1302 | W36: =Q36-AD36 -> 91667.24 | X36: =IF(V36="Too early","Too early",V36/U36) -> 1.1764706 | Y36: 45552 | Z36: 107500 | AA36: =IF(Y36>0,Y36/Z36,"") -> 0.42373953 | AB36: =IF($V36="Too early",V36,V36*AH36/Z36) -> 0.85271851 | AF36: =IF(AD36>0,AD36/AE36,"") | AG36: 1302 | AH36: =Y36/S36 -> 70.404946 | AI36: 12 | AJ36: 56 | AK36: 68 | AL36: 19000 | AM36: =L36-AL36 -> 26552
A37: 13 | B37: =A37-$G$4 -> 4 | C37: 45985 | D37: 26 Elf™ in Concert | G37: 45991.583 | H37: Specials/Film | I37: 0.85 | J37: =K37/AG37 -> 0.66589862 | K37: =S37+AC37 -> 867 | L37: =Y37+AD37 -> 60390 | M37: =Z37+AE37 -> 107500 | N37: =L37-M37 -> -47110 | O37: =IF(P37="Too early",P37,P37/AG37) -> 1 | P37: =IF(V37="Too early",V37,V37+AC37) -> 1302 | Q37: =IF(V37="Too early",V37,AD37+V37*AH37) -> 90689.481 | R37: =IF(V37="Too early",V37,Q37-M37) -> -16810.519 | S37: =857+10 -> 867 | T37: =AG37-AC37 -> 1302 | U37: =(AG37-AC37)*I37 -> 1106.7 | V37: =IF(B37<11,MIN((S37/VLOOKUP(B37,'Sales Pacing'!$A$23:$E$36,2)),T37),"Too early") -> 1302 | W37: =Q37-AD37 -> 90689.481 | X37: =IF(V37="Too early","Too early",V37/U37) -> 1.1764706 | Y37: 60390 | Z37: 107500 | AA37: =IF(Y37>0,Y37/Z37,"") -> 0.56176744 | AB37: =IF($V37="Too early",V37,V37*AH37/Z37) -> 0.84362308 | AF37: =IF(AD37>0,AD37/AE37,"") | AG37: 1302 | AH37: =Y37/S37 -> 69.653979 | AI37: 21 | AJ37: 88 | AK37: 109 | AL37: 34569.6 | AM37: =L37-AL37 -> 25820.4
A38: 14 | B38: =A38-$G$4 -> 5 | C38: 45992 | D38: 26 Handel's Messiah | G38: 45996.792 | H38: Holiday | I38: 0.85 | J38: =K38/AG38 -> 0.43628809 | K38: =S38+AC38 -> 630 | L38: =Y38+AD38 -> 33156 | M38: =Z38+AE38 -> 78333 | N38: =L38-M38 -> -45177 | O38: =IF(P38="Too early",P38,P38/AG38) -> 1 | P38: =IF(V38="Too early",V38,V38+AC38) -> 1444 | Q38: =IF(V38="Too early",V38,AD38+V38*AH38) -> 75995.657 | R38: =IF(V38="Too early",V38,Q38-M38) -> -2337.3429 | S38: =626+4 -> 630 | T38: =AG38-AC38 -> 1444 | U38: =(AG38-AC38)*I38 -> 1227.4 | V38: =IF(B38<11,MIN((S38/VLOOKUP(B38,'Sales Pacing'!$A$23:$E$36,2)),T38),"Too early") -> 1444 | W38: =Q38-AD38 -> 75995.657 | X38: =IF(V38="Too early","Too early",V38/U38) -> 1.1764706 | Y38: =32850+306 -> 33156 | Z38: 78333 | AA38: =IF(Y38>0,Y38/Z38,"") -> 0.42326989 | AB38: =IF($V38="Too early",V38,V38*AH38/Z38) -> 0.97016145 | AF38: =IF(AD38>0,AD38/AE38,"") | AG38: 1444 | AH38: =Y38/S38 -> 52.628571 | AI38: 19 | AJ38: 86 | AK38: 105 | AL38: 18853.5 | AM38: =L38-AL38 -> 14302.5
A39: 14 | B39: =A39-$G$4 -> 5 | C39: 45992 | D39: 26 Handel's Messiah | G39: 45997.792 | H39: Holiday | I39: 0.85 | J39: =K39/AG39 -> 0.46052632 | K39: =S39+AC39 -> 665 | L39: =Y39+AD39 -> 35973 | M39: =Z39+AE39 -> 78334 | N39: =L39-M39 -> -42361 | O39: =IF(P39="Too early",P39,P39/AG39) -> 1 | P39: =IF(V39="Too early",V39,V39+AC39) -> 1444 | Q39: =IF(V39="Too early",V39,AD39+V39*AH39) -> 78112.8 | R39: =IF(V39="Too early",V39,Q39-M39) -> -221.2 | S39: =656+9 -> 665 | T39: =AG39-AC39 -> 1444 | U39: =(AG39-AC39)*I39 -> 1227.4 | V39: =IF(B39<11,MIN((S39/VLOOKUP(B39,'Sales Pacing'!$A$23:$E$36,2)),T39),"Too early") -> 1444 | W39: =Q39-AD39 -> 78112.8 | X39: =IF(V39="Too early","Too early",V39/U39) -> 1.1764706 | Y39: =35501+472 -> 35973 | Z39: 78334 | AA39: =IF(Y39>0,Y39/Z39,"") -> 0.45922588 | AB39: =IF($V39="Too early",V39,V39*AH39/Z39) -> 0.99717619 | AF39: =IF(AD39>0,AD39/AE39,"") | AG39: 1444 | AH39: =Y39/S39 -> 54.094737 | AI39: 20 | AJ39: 95 | AK39: 115 | AL39: 22001.5 | AM39: =L39-AL39 -> 13971.5
A40: 14 | B40: =A40-$G$4 -> 5 | C40: 45992 | D40: 26 Handel's Messiah | G40: 45998.583 | H40: Holiday | I40: 0.85 | J40: =K40/AG40 -> 0.49099723 | K40: =S40+AC40 -> 709 | L40: =Y40+AD40 -> 38151 | M40: =Z40+AE40 -> 78333 | N40: =L40-M40 -> -40182 | O40: =IF(P40="Too early",P40,P40/AG40) -> 1 | P40: =IF(V40="Too early",V40,V40+AC40) -> 1444 | Q40: =IF(V40="Too early",V40,AD40+V40*AH40) -> 77701.049 | R40: =IF(V40="Too early",V40,Q40-M40) -> -631.95063 | S40: =695+14 -> 709 | T40: =AG40-AC40 -> 1444 | U40: =(AG40-AC40)*I40 -> 1227.4 | V40: =IF(B40<11,MIN((S40/VLOOKUP(B40,'Sales Pacing'!$A$23:$E$36,2)),T40),"Too early") -> 1444 | W40: =Q40-AD40 -> 77701.049 | X40: =IF(V40="Too early","Too early",V40/U40) -> 1.1764706 | Y40: =37495+656 -> 38151 | Z40: 78333 | AA40: =IF(Y40>0,Y40/Z40,"") -> 0.48703612 | AB40: =IF($V40="Too early",V40,V40*AH40/Z40) -> 0.99193251 | AF40: =IF(AD40>0,AD40/AE40,"") | AG40: 1444 | AH40: =Y40/S40 -> 53.809591 | AI40: 26 | AJ40: 105 | AK40: 131 | AL40: 21652.5 | AM40: =L40-AL40 -> 16498.5
...

Sheet PS1 Journey
B1: # weeks out
A2: Single Tickets | B2: 5 | C2: 4 | D2: 3 | E2: 2 | F2: 1 | G2: 0 | L2: Estimates Only | P2: Historical Data
A3: PS1 Journey | B3: 45880 | C3: 45887 | D3: 45894 | E3: 45901 | F3: 45908 | G3: 45915 | H3: # Single Tickets to sell out 100% | I3: Projected OCC% | K3: # Weeks Until Performance | L3: 10 | M3: 9 | N3: 8 | O3: 7 | P3: 6 | Q3: 5 | R3: 4 | S3: 3 | T3: 2 | U3: 1 | V3: 0
A4: 9/19/2025 Sales (Fri) | B4: 60 | C4: 160 | D4: 205 | E4: 262 | F4: 311 | G4: 390 | H4: ='Performances by Week'!AG10-'Performances by Week'!AC10 -> 975 | I4: ='Performances by Week'!O10 -> #N/A | K4: Classical | L4: 0.15 | M4: 0.18 | N4: 0.21 | O4: 0.24 | P4: 0.27 | Q4: 0.3 | R4: 0.33 | S4: 0.39 | T4: 0.46 | U4: 0.59 | V4: 1
A5: 9/20/2025 Sales (Sat) | B5: 63 | C5: 206 | D5: 250 | E5: 294 | F5: 360 | G5: 422 | H5: ='Performances by Week'!AG11-'Performances by Week'!AC11 -> 1076 | I5: ='Performances by Week'!O11 -> #N/A | K5: Pops | L5: 0.15 | M5: 0.18 | N5: 0.21 | O5: 0.24 | P5: 0.27 | Q5: 0.3 | R5: 0.33 | S5: 0.39 | T5: 0.46 | U5: 0.59 | V5: 1
A6: 9/21/2025 Sales (Sun) | B6: 57 | C6: 219 | D6: 296 | E6: 322 | F6: 444 | G6: 516 | H6: ='Performances by Week'!AG12-'Performances by Week'!AC12 -> 1246 | I6: ='Performances by Week'!O12 -> #N/A | K6: Specials | L6: 0.15 | M6: 0.18 | N6: 0.21 | O6: 0.24 | P6: 0.27 | Q6: 0.3 | R6: 0.33 | S6: 0.39 | T6: 0.46 | U6: 0.59 | V6: 1
A7: Pace for 85% OCC | B7: =$H$7*$H$10*Q5 -> 280.245 | C7: =$H$7*$H$10*R5 -> 308.2695 | D7: =$H$7*$H$10*S5 -> 364.3185 | E7: =$H$7*$H$10*T5 -> 429.709 | F7: =$H$7*$H$10*U5 -> 551.1485 | G7: =$H$7*$H$10*V5 -> 934.15 | H7: =AVERAGE(H4:H6) -> 1099 | K7: Other | L7: 0.15 | M7: 0.18 | N7: 0.21 | O7: 0.24 | P7: 0.27 | Q7: 0.3 | R7: 0.33 | S7: 0.39 | T7: 0.46 | U7: 0.59 | V7: 1
A8: Avg/Show vs Target Pace: | B8: =IF(B4>0,AVERAGE(B4:B6)-B7,"TBD") -> -220.245 | C8: =IF(C4>0,AVERAGE(C4:C6)-C7,"TBD") -> -113.2695 | D8: =IF(D4>0,AVERAGE(D4:D6)-D7,"TBD") -> -113.98517 | E8: =IF(E4>0,AVERAGE(E4:E6)-E7,"TBD") -> -137.04233 | F8: =IF(F4>0,AVERAGE(F4:F6)-F7,"TBD") -> -179.48183 | G8: =IF(G4>0,AVERAGE(G4:G6)-G7,"TBD") -> -491.48333
H9: OCC Target
H10: 0.85
I12: Final Sales: | J12: Sep 15-21 Sales | K12: % of Total
I13: 511 | J13: =I13-G4 -> 121 | K13: =J13/I13 -> 0.23679061
I14: 550 | J14: =I14-G5 -> 128 | K14: =J14/I14 -> 0.23272727
I15: 662 | J15: =I15-G6 -> 146 | K15: =J15/I15 -> 0.22054381

Sheet CS1 Appalachian
B1: # weeks out
A2: Single Tickets | B2: 8 | C2: 7 | D2: 6 | E2: 5 | F2: 4 | G2: 3 | H2: 2 | I2: 1 | J2: 0 | O2: Estimates Only | S2: Historical Data
A3: CS1 Appalachian | B3: 45880 | C3: 45887 | D3: 45894 | E3: 45901 | F3: 45908 | G3: 45915 | H3: 45922 | I3: 45929 | J3: 45936 | K3: # Single Tickets to sell out 100% | L3: Projected Total OCC% | N3: # Weeks Until Performance | O3: 10 | P3: 9 | Q3: 8 | R3: 7 | S3: 6 | T3: 5 | U3: 4 | V3: 3 | W3: 2 | X3: 1 | Y3: 0
A4: 10/10/2025 Sales (Fri) | B4: 60 | C4: 100 | D4: 106 | E4: 135 | F4: 193 | G4: 212 | H4: 238 | I4: 326 | J4: 418 | K4: =1433-543 -> 890 | L4: ='Performances by Week'!O15 -> #N/A | N4: Classical | O4: 0.15 | P4: 0.18 | Q4: 0.21 | R4: 0.24 | S4: 0.27 | T4: 0.3 | U4: 0.33 | V4: 0.39 | W4: 0.46 | X4: 0.59 | Y4: 1
A5: 10/11/2025 Sales (Sat) | B5: 63 | C5: 98 | D5: 115 | E5: 130 | F5: 179 | G5: 225 | H5: 258 | I5: 355 | J5: 429 | K5: =1433-581 -> 852 | L5: ='Performances by Week'!O16 -> #N/A | N5: Pops | O5: 0.15 | P5: 0.18 | Q5: 0.21 | R5: 0.24 | S5: 0.27 | T5: 0.3 | U5: 0.33 | V5: 0.39 | W5: 0.46 | X5: 0.59 | Y5: 1
A6: 10/12/2025 Sales (Sun) | B6: 57 | C6: 137 | D6: 154 | E6: 174 | F6: 239 | G6: 295 | H6: 328 | I6: 430 | J6: 565 | K6: =1433-613 -> 820 | L6: ='Performances by Week'!O17 -> #N/A | N6: Specials | O6: 0.15 | P6: 0.18 | Q6: 0.21 | R6: 0.24 | S6: 0.27 | T6: 0.3 | U6: 0.33 | V6: 0.39 | W6: 0.46 | X6: 0.59 | Y6: 1
A7: Pace for 85% OCC | B7: =$K$7*$K$12*Q4 -> 151.725 | C7: =$K$7*$K$12*R4 -> 173.4 | D7: =$K$7*$K$12*S4 -> 195.075 | E7: =$K$7*$K$12*T4 -> 216.75 | F7: =$K$7*$K$12*U4 -> 238.425 | G7: =$K$7*$K$12*V4 -> 281.775 | H7: =$K$7*$K$12*W4 -> 332.35 | I7: =$K$7*$K$12*X4 -> 426.275 | J7: =$K$7*$K$12*Y4 -> 722.5 | K7: 850 | N7: Other | O7: 0.15 | P7: 0.18 | Q7: 0.21 | R7: 0.24 | S7: 0.27 | T7: 0.3 | U7: 0.33 | V7: 0.39 | W7: 0.46 | X7: 0.59 | Y7: 1
A8: Weekly new sales needed for Target Pace | C8: =C7-B7 -> 21.675 | D8: =D7-C7 -> 21.675 | E8: =E7-D7 -> 21.675 | F8: =F7-E7 -> 21.675 | G8: =G7-F7 -> 43.35 | H8: =H7-G7 -> 50.575 | I8: =I7-H7 -> 93.925 | J8: =J7-I7 -> 296.225
A9: Actual Weekly Sales | C9: =IF(C4="","Too early",AVERAGE(C4:C6)-AVERAGE(B4:B6)) -> 51.666667 | D9: =IF(D4="","Too early",AVERAGE(D4:D6)-AVERAGE(C4:C6)) -> 13.333333 | E9: =IF(E4="","Too early",AVERAGE(E4:E6)-AVERAGE(D4:D6)) -> 21.333333 | F9: =IF(F4="","Too early",AVERAGE(F4:F6)-AVERAGE(E4:E6)) -> 57.333333 | G9: =IF(G4="","Too early",AVERAGE(G4:G6)-AVERAGE(F4:F6)) -> 40.333333 | H9: =IF(H4="","Too early",AVERAGE(H4:H6)-AVERAGE(G4:G6)) -> 30.666667 | I9: =IF(I4="","Too early",AVERAGE(I4:I6)-AVERAGE(H4:H6)) -> 95.666667 | J9: =IF(J4="","Too early",AVERAGE(J4:J6)-AVERAGE(I4:I6)) -> 100.33333
A10: Avg/Show vs Target Pace: | B10: =IF(B4>0,AVERAGE(B4:B6)-B7,"TBD") -> -91.725 | C10: =IF(C4>0,AVERAGE(C4:C6)-C7,"TBD") -> -61.733333 | D10: =IF(D4>0,AVERAGE(D4:D6)-D7,"TBD") -> -70.075 | E10: =IF(E4>0,AVERAGE(E4:E6)-E7,"TBD") -> -70.416667 | F10: =IF(F4>0,AVERAGE(F4:F6)-F7,"TBD") -> -34.758333 | G10: =IF(G4>0,AVERAGE(G4:G6)-G7,"TBD") -> -37.775 | H10: =IF(H4>0,AVERAGE(H4:H6)-H7,"TBD") -> -57.683333 | I10: =IF(I4>0,AVERAGE(I4:I6)-I7,"TBD") -> -55.941667 | J10: =IF(J4>0,AVERAGE(J4:J6)-J7,"TBD") -> -251.83333
K11: OCC Target
K12: 0.85

Sheet PS2 90s Mixtape
B1: # Weeks Out | Q1: Estimates Only | U1: Historical Data
A2: Single Tickets | B2: 10 | C2: 9 | D2: 8 | E2: 7 | F2: 6 | G2: 5 | H2: 4 | I2: 3 | J2: 2 | K2: 1 | L2: 0 | P2: # Weeks Until Performance | Q2: 10 | R2: 9 | S2: 8 | T2: 7 | U2: 6 | V2: 5 | W2: 4 | X2: 3 | Y2: 2 | Z2: 1 | AA2: 0
A3: PS2 90s Mixtape (Name?) | B3: 45880 | C3: 45887 | D3: 45894 | E3: 45901 | F3: 45908 | G3: 45915 | H3: 45922 | I3: 45929 | J3: 45936 | K3: 45943 | L3: 45950 | M3: # Single Tickets to sell out 100% | N3: Projected OCC% | P3: Classical | Q3: 0.15 | R3: 0.18 | S3: 0.21 | T3: 0.24 | U3: 0.27 | V3: 0.3 | W3: 0.33 | X3: 0.39 | Y3: 0.46 | Z3: 0.59 | AA3: 1
A4: 10/24/2025 Sales (Fri) | B4: 60 | C4: 64 | D4: 68 | E4: 74 | F4: 80 | G4: 92 | H4: 115 | I4: 145 | J4: 166 | K4: 193 | L4: 222 | M4: ='Performances by Week'!AG22-'Performances by Week'!AC22 -> 965 | N4: ='Performances by Week'!O22 -> #N/A | P4: Pops | Q4: 0.15 | R4: 0.18 | S4: 0.21 | T4: 0.24 | U4: 0.27 | V4: 0.3 | W4: 0.33 | X4: 0.39 | Y4: 0.46 | Z4: 0.59 | AA4: 1
A5: 10/25/2025 Sales (Sat) | B5: 63 | C5: 63 | D5: 73 | E5: 93 | F5: 106 | G5: 114 | H5: 155 | I5: 190 | J5: 218 | K5: 257 | L5: 306 | M5: ='Performances by Week'!AG23-'Performances by Week'!AC23 -> 1067 | N5: ='Performances by Week'!O23 -> #N/A | P5: Specials | Q5: 0.15 | R5: 0.18 | S5: 0.21 | T5: 0.24 | U5: 0.27 | V5: 0.3 | W5: 0.33 | X5: 0.39 | Y5: 0.46 | Z5: 0.59 | AA5: 1
A6: 10/26/2025 Sales (Sun) | B6: 57 | C6: 59 | D6: 66 | E6: 74 | F6: 76 | G6: 87 | H6: 110 | I6: 163 | J6: 181 | K6: 209 | L6: 251 | M6: ='Performances by Week'!AG24-'Performances by Week'!AC24 -> 1268 | N6: ='Performances by Week'!O24 -> #N/A | P6: Other | Q6: 0.15 | R6: 0.18 | S6: 0.21 | T6: 0.24 | U6: 0.27 | V6: 0.3 | W6: 0.33 | X6: 0.39 | Y6: 0.46 | Z6: 0.59 | AA6: 1
A7: Pace for 85% OCC | B7: =$M$7*$M$12*Q4 -> 140.25 | C7: =$M$7*$M$12*R4 -> 168.3 | D7: =$M$7*$M$12*S4 -> 196.35 | E7: =$M$7*$M$12*T4 -> 224.4 | F7: =$M$7*$M$12*U4 -> 252.45 | G7: =$M$7*$M$12*V4 -> 280.5 | H7: =$M$7*$M$12*W4 -> 308.55 | I7: =$M$7*$M$12*X4 -> 364.65 | ... L7: =$M$7*$M$12*AA4 -> 935 | M7: =AVERAGE(M4:M6) -> 1100
A8: Weekly new sales needed for Target Pace | C8: =C7-B7 -> 28.05 | D8: =D7-C7 -> 28.05 | E8: =E7-D7 -> 28.05 | F8: =F7-E7 -> 28.05 | G8: =G7-F7 -> 28.05 | H8: =H7-G7 -> 28.05 | I8: =I7-H7 -> 56.1 | J8: =J7-I7 -> 65.45 | ... L8: =L7-K7 -> 383.35
A9: Actual Weekly Sales | C9: =IF(C4="","Too early",AVERAGE(C4:C6)-AVERAGE(B4:B6)) -> 2 | D9: =IF(D4="","Too early",AVERAGE(D4:D6)-AVERAGE(C4:C6)) -> 7 | E9: =IF(E4="","Too early",AVERAGE(E4:E6)-AVERAGE(D4:D6)) -> 11.333333 | F9: =IF(F4="","Too early",AVERAGE(F4:F6)-AVERAGE(E4:E6)) -> 7 | G9: =IF(G4="","Too early",AVERAGE(G4:G6)-AVERAGE(F4:F6)) -> 10.333333 | H9: =IF(H4="","Too early",AVERAGE(H4:H6)-AVERAGE(G4:G6)) -> 29 | I9: =IF(I4="","Too early",AVERAGE(I4:I6)-AVERAGE(H4:H6)) -> 39.333333 | J9: =IF(J4="","Too early",AVERAGE(J4:J6)-AVERAGE(I4:I6)) -> 22.333333 | ... L9: =IF(L4="","Too early",AVERAGE(L4:L6)-AVERAGE(K4:K6)) -> 40
A10: Avg/Show vs Target Pace: | B10: =IF(B4>0,AVERAGE(B4:B6)-B7,"TBD") -> -80.25 | C10: =IF(C4>0,AVERAGE(C4:C6)-C7,"TBD") -> -106.3 | D10: =IF(D4>0,AVERAGE(D4:D6)-D7,"TBD") -> -127.35 | E10: =IF(E4>0,AVERAGE(E4:E6)-E7,"TBD") -> -144.06667 | F10: =IF(F4>0,AVERAGE(F4:F6)-F7,"TBD") -> -165.11667 | G10: =IF(G4>0,AVERAGE(G4:G6)-G7,"TBD") -> -182.83333 | H10: =IF(H4>0,AVERAGE(H4:H6)-H7,"TBD") -> -181.88333 | I10: =IF(I4>0,AVERAGE(I4:I6)-I7,"TBD") -> -198.65 | ... L10: =IF(L4>0,AVERAGE(L4:L6)-L7,"TBD") -> -675.33333
M11: OCC Target
M12: 0.85

Sheet MFSB
A1: Single Tickets | B1: 3 | C1: 2 | D1: 1 | E1: 0 | L1: Single Tickets
A2: MFSB | B2: 45880 | C2: 45887 | D2: 45894 | E2: 45901 | F2: # Single Tickets to sell out 100% | K2: # Weeks Until Performance | L2: Classical | M2: Pops | N2: Specials | O2: Other
A3: 9/2/2025 Sales (Tue) | B3: 754 | C3: 915 | D3: 1013 | E3: 1096 | G3: =E3/F5 -> 0.84178187
A4: 9/3/2025 Sales (Wed) | B4: 651 | C4: 826 | D4: 926 | E4: 1027 | G4: =E4/F5 -> 0.78878648 | K4: 0 | L4: 1 | M4: 1 | N4: 1 | O4: 1
A5: Pace for 85% OCC | B5: =$F$5*$G$5*N7 -> 431.613 | C5: =$F$5*$G$5*N6 -> 509.082 | D5: =$F$5*$G$5*N5 -> 652.953 | E5: =$F$5*$G$5*N4 -> 1106.7 | F5: 1302 | G5: 0.85 | K5: 1 | L5: 0.59 | M5: 0.59 | N5: 0.59 | O5: 0.59
K6: 2 | L6: 0.46 | M6: 0.46 | N6: 0.46 | O6: 0.46
K7: 3 | L7: 0.39 | M7: 0.39 | N7: 0.39 | O7: 0.39
K8: 4 | L8: 0.33 | M8: 0.33 | N8: 0.33 | O8: 0.33
K9: 5 | L9: 0.3 | M9: 0.3 | N9: 0.3 | O9: 0.3
K10: 6 | L10: 0.27 | M10: 0.27 | N10: 0.27 | O10: 0.27

Sheet CS2 Rachmaninoff
D1: # weeks out
A2: Single Tickets | B2: 10 | C2: 9 | D2: 8 | E2: 7 | F2: 6 | G2: 5 | H2: 4 | I2: 3 | J2: 2 | K2: 1 | L2: 0 | Q2: Estimates Only | U2: Historical Data
A3: CS2 Rachmaninoff | B3: 45887 | C3: 45894 | D3: 45901 | E3: 45908 | F3: 45915 | G3: 45922 | H3: 45929 | I3: 45936 | J3: 45943 | K3: 45950 | L3: 45957 | M3: # Single Tickets to sell out 100% | N3: Projected OCC% | P3: # Weeks Until Performance | Q3: 10 | R3: 9 | S3: 8 | T3: 7 | U3: 6 | V3: 5 | W3: 4 | X3: 3 | Y3: 2 | Z3: 1 | AA3: 0
A4: 10/31/2025 Sales (Fri, Piazza) | B4: 87 | C4: 93 | D4: 102 | E4: 106 | F4: 111 | G4: 124 | H4: 144 | I4: 183 | J4: 234 | K4: 291 | M4: ='Performances by Week'!AG26-'Performances by Week'!AC26 -> 1142 | N4: ='Performances by Week'!O26 -> 0.44 | P4: Classical | Q4: 0.15 | R4: 0.18 | S4: 0.21 | T4: 0.24 | U4: 0.27 | V4: 0.3 | W4: 0.33 | X4: 0.39 | Y4: 0.46 | Z4: 0.59 | AA4: 1
A5: 11/01/2025 Sales (Sat) | B5: 192 | C5: 209 | D5: 256 | E5: 310 | F5: 340 | G5: 382 | H5: 446 | I5: 527 | J5: 648 | K5: 715 | M5: ='Performances by Week'!AG27-'Performances by Week'!AC27 -> 943 | N5: ='Performances by Week'!O27 -> 0.90965517 | P5: Pops | Q5: 0.15 | R5: 0.18 | S5: 0.21 | T5: 0.24 | U5: 0.27 | V5: 0.3 | W5: 0.33 | X5: 0.39 | Y5: 0.46 | Z5: 0.59 | AA5: 1
A6: 11/02/2025 Sales (Sun) | B6: 138 | C6: 165 | D6: 187 | E6: 219 | F6: 232 | G6: 267 | H6: 309 | I6: 358 | J6: 432 | K6: 516 | M6: ='Performances by Week'!AG28-'Performances by Week'!AC28 -> 914 | N6: ='Performances by Week'!O28 -> 0.77862069 | P6: Specials | Q6: 0.15 | R6: 0.18 | S6: 0.21 | T6: 0.24 | U6: 0.27 | V6: 0.3 | W6: 0.33 | X6: 0.39 | Y6: 0.46 | Z6: 0.59 | AA6: 1
A7: Pace for 85% OCC | B7: =$M$7*$M$12*Q4 -> 127.4575 | C7: =$M$7*$M$12*R4 -> 152.949 | D7: =$M$7*$M$12*S4 -> 178.4405 | E7: =$M$7*$M$12*T4 -> 203.932 | F7: =$M$7*$M$12*U4 -> 229.4235 | G7: =$M$7*$M$12*V4 -> 254.915 | H7: =$M$7*$M$12*W4 -> 280.4065 | I7: =$M$7*$M$12*X4 -> 331.3895 | ... L7: =$M$7*$M$12*AA4 -> 849.71667 | M7: =AVERAGE(M4:M6) -> 999.66667 | P7: Other | Q7: 0.15 | R7: 0.18 | S7: 0.21 | T7: 0.24 | U7: 0.27 | V7: 0.3 | W7: 0.33 | X7: 0.39 | Y7: 0.46 | Z7: 0.59 | AA7: 1
A8: Weekly new sales needed for Target Pace | C8: =C7-B7 -> 25.4915 | D8: =D7-C7 -> 25.4915 | E8: =E7-D7 -> 25.4915 | F8: =F7-E7 -> 25.4915 | G8: =G7-F7 -> 25.4915 | H8: =H7-G7 -> 25.4915 | I8: =I7-H7 -> 50.983 | J8: =J7-I7 -> 59.480167 | ... L8: =L7-K7 -> 348.38383
A9: Actual Weekly Sales | C9: =IF(C4="","Too early",AVERAGE(C4:C7)-AVERAGE(B4:B7)) -> 18.872875 | D9: =IF(D4="","Too early",AVERAGE(D4:D7)-AVERAGE(C4:C7)) -> 25.872875 | E9: =IF(E4="","Too early",AVERAGE(E4:E7)-AVERAGE(D4:D7)) -> 28.872875 | F9: =IF(F4="","Too early",AVERAGE(F4:F7)-AVERAGE(E4:E7)) -> 18.372875 | G9: =IF(G4="","Too early",AVERAGE(G4:G7)-AVERAGE(F4:F7)) -> 28.872875 | H9: =IF(H4="","Too early",AVERAGE(H4:H7)-AVERAGE(G4:G7)) -> 37.872875 | I9: =IF(I4="","Too early",AVERAGE(I4:I7)-AVERAGE(H4:H7)) -> 54.99575 | J9: =IF(J4="","Too early",AVERAGE(J4:J7)-AVERAGE(I4:I7)) -> 76.370042 | ... L9: =IF(L4="","Too early",AVERAGE(L4:L7)-AVERAGE(K4:K7)) -> Too early
A10: Avg/Show vs Target Pace: | B10: =IF(B4>0,AVERAGE(B4:B6)-B7,"TBD") -> 11.5425 | C10: =IF(C4>0,AVERAGE(C4:C6)-C7,"TBD") -> 2.7176667 | D10: =IF(D4>0,AVERAGE(D4:D6)-D7,"TBD") -> 3.2261667 | E10: =IF(E4>0,AVERAGE(E4:E6)-E7,"TBD") -> 7.7346667 | F10: =IF(F4>0,AVERAGE(F4:F6)-F7,"TBD") -> -1.7568333 | G10: =IF(G4>0,AVERAGE(G4:G6)-G7,"TBD") -> 2.7516667 | H10: =IF(H4>0,AVERAGE(H4:H6)-H7,"TBD") -> 19.260167 | I10: =IF(I4>0,AVERAGE(I4:I6)-I7,"TBD") -> 24.6105 | ... L10: =IF(L4>0,AVERAGE(L4:L6)-L7,"TBD") -> TBD
M11: OCC Target
M12: 0.85

Sheet CS3 Mahler 7
D1: # weeks out
A2: Single Tickets | B2: 10 | C2: 9 | D2: 8 | E2: 7 | F2: 6 | G2: 5 | H2: 4 | I2: 3 | J2: 2 | K2: 1 | L2: 0 | Q2: Estimates Only | U2: Historical Data
A3: CS3 Mahler | B3: 45908 | C3: 45915 | D3: 45922 | E3: 45929 | F3: 45936 | G3: 45943 | H3: 45950 | I3: 45957 | J3: 45964 | K3: 45971 | L3: 45978 | M3: # Single Tickets to sell out 100% | N3: Projected OCC% | P3: # Weeks Until Performance | Q3: 10 | R3: 9 | S3: 8 | T3: 7 | U3: 6 | V3: 5 | W3: 4 | X3: 3 | Y3: 2 | Z3: 1 | AA3: 0
A4: 11/21/2025 Sales (Fri, Piazza) | B4: 55 | C4: 60 | D4: 66 | E4: 75 | F4: 83 | G4: 113 | H4: 138 | I4: 180 | M4: ='[1]Performances by Week'!AC31-'[1]Performances by Week'!Y31 -> 1210 | N4: ='[1]Performances by Week'!K31 -> 0.39622642 | P4: Classical | Q4: 0.15 | R4: 0.18 | S4: 0.21 | T4: 0.24 | U4: 0.27 | V4: 0.3 | W4: 0.33 | X4: 0.39 | Y4: 0.46 | Z4: 0.59 | AA4: 1
A5: 11/22/2025 Sales (Sat) | B5: 95 | C5: 110 | D5: 114 | E5: 143 | F5: 160 | G5: 189 | H5: 209 | I5: 235 | M5: ='[1]Performances by Week'!AC32-'[1]Performances by Week'!Y32 -> 999 | N5: ='[1]Performances by Week'!K32 -> 0.67987421 | P5: Pops | Q5: 0.15 | R5: 0.18 | S5: 0.21 | T5: 0.24 | U5: 0.27 | V5: 0.3 | W5: 0.33 | X5: 0.39 | Y5: 0.46 | Z5: 0.59 | AA5: 1
A6: 11/23/2025 Sales (Sun) | B6: 75 | C6: 81 | D6: 83 | E6: 93 | F6: 99 | G6: 141 | H6: 167 | I6: 188 | M6: ='[1]Performances by Week'!AC33-'[1]Performances by Week'!Y33 -> 955 | N6: ='[1]Performances by Week'!K33 -> 0.59433962 | P6: Specials | Q6: 0.15 | R6: 0.18 | S6: 0.21 | T6: 0.24 | U6: 0.27 | V6: 0.3 | W6: 0.33 | X6: 0.39 | Y6: 0.46 | Z6: 0.59 | AA6: 1
A7: Pace for 85% OCC | B7: =$M$7*$M$12*Q4 -> 134.47 | C7: =$M$7*$M$12*R4 -> 161.364 | D7: =$M$7*$M$12*S4 -> 188.258 | E7: =$M$7*$M$12*T4 -> 215.152 | F7: =$M$7*$M$12*U4 -> 242.046 | G7: =$M$7*$M$12*V4 -> 268.94 | H7: =$M$7*$M$12*W4 -> 295.834 | I7: =$M$7*$M$12*X4 -> 349.622 | ... L7: =$M$7*$M$12*AA4 -> 896.46667 | M7: =AVERAGE(M4:M6) -> 1054.6667 | P7: Other | Q7: 0.15 | R7: 0.18 | S7: 0.21 | T7: 0.24 | U7: 0.27 | V7: 0.3 | W7: 0.33 | X7: 0.39 | Y7: 0.46 | Z7: 0.59 | AA7: 1
A8: Weekly new sales needed for Target Pace | C8: =C7-B7 -> 26.894 | D8: =D7-C7 -> 26.894 | E8: =E7-D7 -> 26.894 | F8: =F7-E7 -> 26.894 | G8: =G7-F7 -> 26.894 | H8: =H7-G7 -> 26.894 | I8: =I7-H7 -> 53.788 | J8: =J7-I7 -> 62.752667 | ... L8: =L7-K7 -> 367.55133
A9: Actual Weekly Sales | C9: =IF(C4="","Too early",AVERAGE(C4:C7)-AVERAGE(B4:B7)) -> 13.2235 | D9: =IF(D4="","Too early",AVERAGE(D4:D7)-AVERAGE(C4:C7)) -> 9.7235 | E9: =IF(E4="","Too early",AVERAGE(E4:E7)-AVERAGE(D4:D7)) -> 18.7235 | F9: =IF(F4="","Too early",AVERAGE(F4:F7)-AVERAGE(E4:E7)) -> 14.4735 | G9: =IF(G4="","Too early",AVERAGE(G4:G7)-AVERAGE(F4:F7)) -> 31.9735 | H9: =IF(H4="","Too early",AVERAGE(H4:H7)-AVERAGE(G4:G7)) -> 24.4735 | I9: =IF(I4="","Too early",AVERAGE(I4:I7)-AVERAGE(H4:H7)) -> 35.697 | J9: =IF(J4="","Too early",AVERAGE(J4:J7)-AVERAGE(I4:I7)) -> Too early | ... L9: =IF(L4="","Too early",AVERAGE(L4:L7)-AVERAGE(K4:K7)) -> Too early
A10: Avg/Show vs Target Pace: | B10: =IF(B4>0,AVERAGE(B4:B6)-B7,"TBD") -> -59.47 | C10: =IF(C4>0,AVERAGE(C4:C6)-C7,"TBD") -> -77.697333 | D10: =IF(D4>0,AVERAGE(D4:D6)-D7,"TBD") -> -100.59133 | E10: =IF(E4>0,AVERAGE(E4:E6)-E7,"TBD") -> -111.48533 | F10: =IF(F4>0,AVERAGE(F4:F6)-F7,"TBD") -> -128.046 | G10: =IF(G4>0,AVERAGE(G4:G6)-G7,"TBD") -> -121.27333 | H10: =IF(H4>0,AVERAGE(H4:H6)-H7,"TBD") -> -124.50067 | I10: =IF(I4>0,AVERAGE(I4:I6)-I7,"TBD") -> -148.622 | ... L10: =IF(L4>0,AVERAGE(L4:L6)-L7,"TBD") -> TBD
M11: OCC Target
M12: 0.85

Sheet Elf
D1: # weeks out
A2: Single Tickets | B2: 10 | C2: 9 | D2: 8 | E2: 7 | F2: 6 | G2: 5 | H2: 4 | I2: 3 | J2: 2 | K2: 1 | L2: 0 | Q2: Estimates Only | U2: Historical Data
A3: Elf in Concert | B3: 45915 | C3: 45922 | D3: 45929 | E3: 45936 | F3: 45943 | G3: 45950 | H3: 45957 | I3: 45964 | J3: 45971 | K3: 45978 | L3: 45985 | M3: # Single Tickets to sell out 100% | N3: Projected OCC% | P3: # Weeks Until Performance | Q3: 10 | R3: 9 | S3: 8 | T3: 7 | U3: 6 | V3: 5 | W3: 4 | X3: 3 | Y3: 2 | Z3: 1 | AA3: 0
A4: 11/28/2025 (Fri) | B4: 306 | C4: 323 | D4: 339 | E4: 420 | F4: 464 | G4: 622 | H4: 750 | M4: ='Performances by Week'!AG34-'Performances by Week'!AC34 -> 1302 | N4: ='Performances by Week'!O34 -> 1 | P4: Classical | Q4: 0.15 | R4: 0.18 | S4: 0.21 | T4: 0.24 | U4: 0.27 | V4: 0.3 | W4: 0.33 | X4: 0.39 | Y4: 0.46 | Z4: 0.59 | AA4: 1
A5: 11/29/2025 (Sat 1) | B5: 370 | C5: 374 | D5: 414 | E5: 462 | F5: 532 | G5: 598 | H5: 741 | M5: ='Performances by Week'!AG35-'Performances by Week'!AC35 -> 1302 | N5: ='Performances by Week'!O35 -> 1 | P5: Pops | Q5: 0.15 | R5: 0.18 | S5: 0.21 | T5: 0.24 | U5: 0.27 | V5: 0.3 | W5: 0.33 | X5: 0.39 | Y5: 0.46 | Z5: 0.59 | AA5: 1
A6: 11/29/2025 (Sat 2) | B6: 283 | C6: 303 | D6: 329 | E6: 381 | F6: 416 | G6: 483 | H6: 647 | M6: ='Performances by Week'!AG36-'Performances by Week'!AC36 -> 1302 | N6: ='Performances by Week'!O36 -> 1 | P6: Specials | Q6: 0.15 | R6: 0.18 | S6: 0.21 | T6: 0.24 | U6: 0.27 | V6: 0.3 | W6: 0.33 | X6: 0.39 | Y6: 0.46 | Z6: 0.59 | AA6: 1
A7: 11/30/2025 (Sun) | B7: 483 | C7: 514 | D7: 542 | E7: 594 | F7: 651 | G7: 745 | H7: 867 | M7: ='Performances by Week'!AG37-'Performances by Week'!AC37 -> 1302 | N7: ='Performances by Week'!O37 -> 1 | P7: Other | Q7: 0.15 | R7: 0.18 | S7: 0.21 | T7: 0.24 | U7: 0.27 | V7: 0.3 | W7: 0.33 | X7: 0.39 | Y7: 0.46 | Z7: 0.59 | AA7: 1
A8: Pace for 85% OCC | B8: =$M$8*$M$15*Q6 -> 166.005 | C8: =$M$8*$M$15*R6 -> 199.206 | D8: =$M$8*$M$15*S6 -> 232.407 | E8: =$M$8*$M$15*T6 -> 265.608 | F8: =$M$8*$M$15*U6 -> 298.809 | G8: =$M$8*$M$15*V6 -> 332.01 | H8: =$M$8*$M$15*W6 -> 365.211 | I8: =$M$8*$M$15*X6 -> 431.613 | ... L8: =$M$8*$M$15*AA6 -> 1106.7 | M8: =AVERAGE(M4:M7) -> 1302
A9: Home Alone 2024 | B9: =AVERAGE(B34:B37) -> 480.5 | C9: =AVERAGE(C34:C37) -> 532.5 | D9: =AVERAGE(D34:D37) -> 570.5 | E9: =AVERAGE(E34:E37) -> 607.5 | F9: =AVERAGE(F34:F37) -> 645.75 | G9: =AVERAGE(G34:G37) -> 720 | H9: =AVERAGE(H34:H37) -> 836.5 | I9: =AVERAGE(I34:I37) -> 956.75 | ... L9: =AVERAGE(L34:L37) -> 1293.25 | M9: Target Pace
A10: Muppet XMas 2023 | B10: =AVERAGE(B45:B46) -> 943.5 | C10: =AVERAGE(C45:C46) -> 992.5 | D10: =AVERAGE(D45:D46) -> 1056 | E10: =AVERAGE(E45:E46) -> 1088 | F10: =AVERAGE(F45:F46) -> 1158 | G10: =AVERAGE(G45:G46) -> 1220 | H10: =AVERAGE(H45:H46) -> 1242.5 | I10: =AVERAGE(I45:I46) -> 1259.5 | ... L10: =AVERAGE(L45:L46) -> 1288.5
A11: Weekly new sales needed for Target Pace | C11: =C9-B9 -> 52 | D11: =D9-C9 -> 38 | E11: =E9-D9 -> 37 | F11: =F9-E9 -> 38.25 | G11: =G9-F9 -> 74.25 | H11: =H9-G9 -> 116.5 | I11: =I9-H9 -> 120.25 | J11: =J9-I9 -> 143 | ... L11: =L9-K9 -> 66
A12: Actual Weekly Sales | C12: =IF(C4="","Too early",AVERAGE(C4:C7)-AVERAGE(B4:B7)) -> 18 | D12: =IF(D4="","Too early",AVERAGE(D4:D7)-AVERAGE(C4:C7)) -> 27.5 | E12: =IF(E4="","Too early",AVERAGE(E4:E7)-AVERAGE(D4:D7)) -> 58.25 | F12: =IF(F4="","Too early",AVERAGE(F4:F7)-AVERAGE(E4:E7)) -> 51.5 | G12: =IF(G4="","Too early",AVERAGE(G4:G7)-AVERAGE(F4:F7)) -> 96.25 | H12: =IF(H4="","Too early",AVERAGE(H4:H7)-AVERAGE(G4:G7)) -> 139.25 | I12: =IF(I4="","Too early",AVERAGE(I4:I7)-AVERAGE(H4:H7)) -> Too early | J12: =IF(J4="","Too early",AVERAGE(J4:J7)-AVERAGE(I4:I7)) -> Too early | ... L12: =IF(L4="","Too early",AVERAGE(L4:L7)-AVERAGE(K4:K7)) -> Too early
A13: Avg/Show vs Target Pace: | B13: =IF(B5>0,AVERAGE(B4:B7)-B9,"TBD") -> -120 | C13: =IF(C5>0,AVERAGE(C4:C7)-C9,"TBD") -> -154 | D13: =IF(D5>0,AVERAGE(D4:D7)-D9,"TBD") -> -164.5 | E13: =IF(E5>0,AVERAGE(E4:E7)-E9,"TBD") -> -143.25 | F13: =IF(F5>0,AVERAGE(F4:F7)-F9,"TBD") -> -130 | G13: =IF(G5>0,AVERAGE(G4:G7)-G9,"TBD") -> -108 | H13: =IF(H5>0,AVERAGE(H4:H7)-H9,"TBD") -> -85.25 | I13: =IF(I5>0,AVERAGE(I4:I7)-I9,"TBD") -> TBD | ... L13: =IF(L5>0,AVERAGE(L4:L7)-L9,"TBD") -> TBD
M14: OCC Target
M15: 0.85
A32: Single Tickets | B32: 10 | C32: 9 | D32: 8 | E32: 7 | F32: 6 | G32: 5 | H32: 4 | I32: 3 | J32: 2 | K32: 1 | L32: 0
A33: Home Alone | B33: 45551 | C33: 45558 | D33: 45565 | E33: 45572 | F33: 45579 | G33: 45586 | H33: 45593 | I33: 45600 | J33: 45607 | K33: 45614 | L33: 45621 | M33: # Single Tickets to sell out 100% | N33: Final Occupancy Sold %
A34: 11/29/2024 Sales (Friday) | B34: 395 | C34: 422 | D34: 451 | E34: 488 | F34: 518 | G34: 591 | H34: 667 | I34: 754 | J34: 913 | K34: 1165 | L34: 1276 | M34: 1342 | N34: 0.9664
A35: 11/30/2024, 2pm (Saturday) | B35: 604 | C35: 669 | D35: 701 | E35: 735 | F35: 763 | G35: 832 | H35: 955 | I35: 1040 | J35: 1229 | K35: 1269 | L35: 1301 | M35: 1342 | N35: 0.9873
A36: 11/30/2024, 8pm (Saturday) | B36: 302 | C36: 353 | D36: 391 | E36: 422 | F36: 454 | G36: 500 | H36: 657 | I36: 813 | J36: 988 | K36: 1200 | L36: 1301 | M36: 1342 | N36: 0.9836
A37: 12/01/2024 Sales (Sunday) | B37: 621 | C37: 686 | D37: 739 | E37: 785 | F37: 848 | G37: 957 | H37: 1067 | I37: 1220 | J37: 1269 | K37: 1275 | L37: 1295 | M37: 1342 | N37: 0.9813
A38: Pace for 85% OCC | B38: =AVERAGE(B34:B37) -> 480.5 | C38: =AVERAGE(C34:C37) -> 532.5 | D38: =AVERAGE(D34:D37) -> 570.5 | E38: =AVERAGE(E34:E37) -> 607.5 | F38: =AVERAGE(F34:F37) -> 645.75 | G38: =AVERAGE(G34:G37) -> 720 | H38: =AVERAGE(H34:H37) -> 836.5 | I38: =AVERAGE(I34:I37) -> 956.75 | ... L38: =AVERAGE(L34:L37) -> 1293.25
A39: Avg/Show vs Target Pace: | B39: =B38/$L$38 -> 0.37154456 | C39: =C38/$L$38 -> 0.41175333 | D39: =D38/$L$38 -> 0.44113667 | E39: =E38/$L$38 -> 0.46974676 | F39: =F38/$L$38 -> 0.49932341 | G39: =G38/$L$38 -> 0.5567369 | H39: =H38/$L$38 -> 0.64682003 | I39: =I38/$L$38 -> 0.73980282 | ... K39: =K38/$L$38 -> 0.94896578 | L39: =L38/$L38 -> 1
M40: OCC Target
M41: 0.85
A43: Single Tickets | B43: 10 | C43: 9 | D43: 8 | E43: 7 | F43: 6 | G43: 5 | H43: 4 | I43: 3 | J43: 2 | K43: 1 | L43: 0
A44: A Muppet Christmas Carol | B44: 45194 | C44: 45201 | D44: 45208 | E44: 45215 | F44: 45222 | G44: 45229 | H44: 45236 | I44: 45243 | J44: 45250 | K44: 45988 | L44: 45995 | M44: # Single Tickets to sell out 100% | N44: Final Occupancy Sold %
A45: 12/08/2023 Sales (Friday) | B45: 844 | C45: 894 | D45: 980 | E45: 1010 | F45: 1104 | G45: 1218 | H45: 1244 | I45: 1264 | J45: 1268 | K45: 1279 | L45: 1289 | M45: 1334 | N45: 0.9962
A46: 12/09/2023, 1pm Sales (Saturday) | B46: 1043 | C46: 1091 | D46: 1132 | E46: 1166 | F46: 1212 | G46: 1222 | H46: 1241 | I46: 1255 | J46: 1265 | K46: 1270 | L46: 1288 | M46: 1334 | N46: 0.979
A47: Pace for 85% OCC
A48: Avg/Show vs Target Pace:
M49: OCC Target
M50: 0.85

Sheet Messiah
D1: # weeks out
A2: Single Tickets | B2: 10 | C2: 9 | D2: 8 | E2: 7 | F2: 6 | G2: 5 | H2: 4 | I2: 3 | J2: 2 | K2: 1 | L2: 0 | Q2: Estimates Only | U2: Historical Data
