Workbook

Sheet Performances by Week
E1: Status: | F1: Updated 8.25 | I1: Update all fields in Blue each week | J1: We expect 50% of Single Sales 1 Week Prior | K1: 85%+ occupancy | O1: 95%+ of Budget | R1: Denotes Piazza
K2: 70-85% occupancy | O2: 85-95% of Budget
G3: Week # | K3: <70% occupancy | O3: <85% of Budget
D4: TICKET SALES REPORT as of 8/25/2025 | G4: 0 | I4: TOTAL SALES (Singles + Subs) | P4: Single Tickets | V4: Subscription Tickets | Z4: Hall Data | AC4: Audience Data | AF4: Revenue last week | AG4: Increase over week
A5: Wk # | B5: # Weeks Until Perf | C5: Perf. Week (Mon) | D5: Performance | G5: Performance Date(s) | H5: Performance Type | I5: Actual Tickets Sold | J5: Projected Single Tickets + Actual Subs | K5: Projected Occupancy at Performance | L5: Total Actual Revenue | M5: TOTAL BUDGET | N5: Actual/ Budget % | O5: Projected/ Budget % | P5: Actual Tickets Sold | Q5: Projected Tickets | R5: Actual Revenue | S5: BUDGET | T5: Actual/ Budget % | U5: Projected/ Budget % | V5: Actual Tickets Sold | W5: Actual Revenue | X5: BUDGET | Y5: Actual vs Budget % | Z5: Max CAP | AA5: Actual OCC SOLD | AB5: Single Ticket ATP | AC5: # New HH | AD5: # Ret HH | AE5: # Total HH
A6: 1 | B6: =A6-$G$4 -> 1 | C6: 45901 | D6: 26 Morgan Freeman's Symphonic Blues | G6: 45902.833 | H6: Specials | I6: =P6+V6 -> 1021 | J6: =IF(Q6="Too early",Q6,Q6+V6) -> 1730.5085 | K6: =IF(J6="Too early",J6,J6/Z6) -> 1.3291156 | L6: =R6+W6 -> 121597 | M6: =S6+X6 -> 153473 | N6: =L6/M6 -> 0.79230223 | O6: =IF($J6="Too early",J6,J6*AB6/M6) -> 1.3428851 | P6: 1021 | Q6: =IF(B6<7,(P6/VLOOKUP(B6,'Sales Pacing'!$A$23:$E$36,2)),"Too early") -> 1730.5085 | R6: 121597 | S6: 153473 | T6: =IF(R6>0,R6/S6,"") -> 0.79230223 | U6: =IF($Q6="Too early",Q6,Q6*AB6/S6) -> 1.3428851 | X6: 0 | Y6: =IF(W6>0,W6/X6,"") | Z6: 1302 | AA6: =I6/Z6 -> 0.78417819 | AB6: =L6/I6 -> 119.09598 | AC6: 113 | AD6: 223 | AE6: 336 | AF6: 110902 | AG6: =L6-AF6 -> 10695
A7: 1 | B7: =A7-$G$4 -> 1 | C7: 45901 | D7: 26 Morgan Freeman's Symphonic Blues | G7: 45903.833 | H7: Specials | I7: =P7+V7 -> 932 | J7: =IF(Q7="Too early",Q7,Q7+V7) -> 1579.661 | K7: =IF(J7="Too early",J7,J7/Z7) -> 1.2132573 | L7: =R7+W7 -> 111049 | M7: =S7+X7 -> 153473 | N7: =L7/M7 -> 0.72357353 | O7: =IF($J7="Too early",J7,J7*AB7/M7) -> 1.2263958 | P7: 932 | Q7: =IF(B7<7,(P7/VLOOKUP(B7,'Sales Pacing'!$A$23:$E$36,2)),"Too early") -> 1579.661 | R7: 111049 | S7: 153473 | T7: =IF(R7>0,R7/S7,"") -> 0.72357353 | U7: =IF($Q7="Too early",Q7,Q7*AB7/S7) -> 1.2263958 | X7: 0 | Y7: =IF(W7>0,W7/X7,"") | Z7: 1302 | AA7: =I7/Z7 -> 0.71582181 | AB7: =L7/I7 -> 119.15129 | AC7: 95 | AD7: 187 | AE7: 282 | AF7: 100649 | AG7: =L7-AF7 -> 10400
A8: 1 | B8: =A8-$G$4 -> 1 | C8: 45901 | D8: 26 La nuit sombre | G8: 45905.833 | H8: Specials | I8: =P8+V8 -> 625 | J8: =IF(Q8="Too early",Q8,Q8+V8) -> 1059.322 | K8: =IF(J8="Too early",J8,J8/Z8) -> 1.7655367 | L8: =R8+W8 -> 17555 | M8: =S8+X8 -> 15000 | N8: =L8/M8 -> 1.1703333 | O8: =IF($J8="Too early",J8,J8*AB8/M8) -> 1.9836158 | P8: 625 | Q8: =IF(B8<7,(P8/VLOOKUP(B8,'Sales Pacing'!$A$23:$E$36,2)),"Too early") -> 1059.322 | R8: 17555 | S8: 15000 | T8: =IF(R8>0,R8/S8,"") -> 1.1703333 | U8: =IF($Q8="Too early",Q8,Q8*AB8/S8) -> 1.9836158 | X8: 0 | Y8: =IF(W8>0,W8/X8,"") | Z8: 600 | AA8: =I8/Z8 -> 1.0416667 | AB8: =L8/I8 -> 28.088 | AC8: 59 | AD8: 185 | AE8: 244 | AF8: 16435 | AG8: =L8-AF8 -> 1120
A9: 2 | B9: =A9-$G$4 -> 2 | C9: 45908 | D9: OPEN - Recording Week | I9: =P9+V9 -> 0 | J9: =IF(Q9="Too early",Q9,Q9+V9) -> 0 | N9: =L9/M9 -> #DIV/0! | Q9: =IF(B9<7,(P9/VLOOKUP(B9,'Sales Pacing'!$A$23:$E$36,2)),"Too early") -> 0 | T9: =IF(R9>0,R9/S9,"") | Y9: N/A | AA9: =I9/Z9 -> #DIV/0!
A10: 3 | B10: =A10-$G$4 -> 3 | C10: 45915 | D10: 26 PS1 Music of Journey | G10: 45919.833 | H10: Pops | I10: =P10+V10 -> 904 | J10: =IF(Q10="Too early",Q10,Q10+V10) -> 1234.0256 | K10: =IF(J10="Too early",J10,J10/Z10) -> 0.77611676 | L10: =R10+W10 -> 63589.3 | M10: =S10+X10 -> 100666 | N10: =L10/M10 -> 0.63168597 | O10: =IF($J10="Too early",J10,J10*AB10/M10) -> 0.86229722 | P10: 211 | Q10: =IF(B10<7,(P10/VLOOKUP(B10,'Sales Pacing'!$A$23:$E$36,2)),"Too early") -> 541.02564 | R10: 13694 | S10: 59333 | T10: =IF(R10>0,R10/S10,"") -> 0.23079905 | U10: =IF($Q10="Too early",Q10,Q10*AB10/S10) -> 0.64141211 | V10: 693 | W10: 49895.3 | X10: 41333 | Y10: =IF(W10>0,W10/X10,"") -> 1.2071541 | Z10: 1590 | AA10: =I10/Z10 -> 0.56855346 | AB10: =L10/I10 -> 70.342146 | AC10: 10 | AD10: 355 | AE10: 365 | AF10: 61035.1 | AG10: =L10-AF10 -> 2554.2
A11: 3 | B11: =A11-$G$4 -> 3 | C11: 45915 | D11: 26 PS1 Music of Journey | G11: 45920.833 | H11: Pops | I11: =P11+V11 -> 868 | J11: =IF(Q11="Too early",Q11,Q11+V11) -> 1265.2821 | K11: =IF(J11="Too early",J11,J11/Z11) -> 0.79577488 | L11: =R11+W11 -> 62401.3 | M11: =S11+X11 -> 100667 | N11: =L11/M11 -> 0.61987841 | O11: =IF($J11="Too early",J11,J11*AB11/M11) -> 0.90359565 | P11: 254 | Q11: =IF(B11<7,(P11/VLOOKUP(B11,'Sales Pacing'!$A$23:$E$36,2)),"Too early") -> 651.28205 | R11: 17508 | S11: 59333 | T11: =IF(R11>0,R11/S11,"") -> 0.29508031 | U11: =IF($Q11="Too early",Q11,Q11*AB11/S11) -> 0.78912666 | V11: 614 | W11: 44893.3 | X11: 41334 | Y11: =IF(W11>0,W11/X11,"") -> 1.0861107 | Z11: 1590 | AA11: =I11/Z11 -> 0.54591195 | AB11: =L11/I11 -> 71.890899 | AC11: 20 | AD11: 314 | AE11: 334 | AF11: 60302.5 | AG11: =L11-AF11 -> 2098.8
A12: 3 | B12: =A12-$G$4 -> 3 | C12: 45915 | D12: 26 PS1 Music of Journey | G12: 45921.583 | H12: Pops | I12: =P12+V12 -> 678 | J12: =IF(Q12="Too early",Q12,Q12+V12) -> 1153.4872 | K12: =IF(J12="Too early",J12,J12/Z12) -> 0.72546363 | L12: =R12+W12 -> 45027.8 | M12: =S12+X12 -> 100666 | N12: =L12/M12 -> 0.44729899 | O12: =IF($J12="Too early",J12,J12*AB12/M12) -> 0.76099358 | P12: 304 | Q12: =IF(B12<7,(P12/VLOOKUP(B12,'Sales Pacing'!$A$23:$E$36,2)),"Too early") -> 779.48718 | R12: 19552 | S12: 59333 | T12: =IF(R12>0,R12/S12,"") -> 0.32952994 | U12: =IF($Q12="Too early",Q12,Q12*AB12/S12) -> 0.87249652 | V12: 374 | W12: 25475.8 | X12: 41333 | Y12: =IF(W12>0,W12/X12,"") -> 0.61635497 | Z12: 1590 | AA12: =I12/Z12 -> 0.42641509 | AB12: =L12/I12 -> 66.412684 | AC12: 16 | AD12: 223 | AE12: 239 | AF12: 40030.8 | AG12: =L12-AF12 -> 4997
A13: 4 | B13: =A13-$G$4 -> 4 | C13: 45922 | D13: 26 FS1 The Orchestra Games | G13: 45928.583 | H13: Family | I13: =P13+V13 -> 429 | J13: =IF(Q13="Too early",Q13,Q13+V13) -> 707.15152 | K13: =IF(J13="Too early",J13,J13/Z13) -> 0.54312712 | L13: =R13+W13 -> 11177 | M13: =S13+X13 -> 19500 | N13: =L13/M13 -> 0.57317949 | O13: =IF($J13="Too early",J13,J13*AB13/M13) -> 0.94481292 | P13: 137 | Q13: =IF(B13<7,(P13/VLOOKUP(B13,'Sales Pacing'!$A$23:$E$36,2)),"Too early") -> 415.15152 | R13: 4687 | S13: 10000 | T13: =IF(R13>0,R13/S13,"") -> 0.4687 | U13: =IF($Q13="Too early",Q13,Q13*AB13/S13) -> 1.0816197 | V13: 292 | W13: 6490 | X13: 9500 | Y13: =IF(W13>0,W13/X13,"") -> 0.68315789 | Z13: 1302 | AA13: =I13/Z13 -> 0.32949309 | AB13: =L13/I13 -> 26.053613 | AC13: 15 | AD13: 88 | AE13: 103 | AF13: 10625 | AG13: =L13-AF13 -> 552
A14: 5 | B14: =A14-$G$4 -> 5 | C14: 45929 | D14: Chicken Fried | G14: 45934 | H14: Specials | I14: =P14+V14 -> 150 | J14: =IF(Q14="Too early",Q14,Q14+V14) -> 500 | K14: =IF(J14="Too early",J14,J14/Z14) -> 0.31446541 | L14: =R14+W14 -> 10596 | M14: =S14+X14 -> 58000 | N14: =L14/M14 -> 0.18268966 | O14: =IF($J14="Too early",J14,J14*AB14/M14) -> 0.60896552 | P14: 150 | Q14: =IF(B14<7,(P14/VLOOKUP(B14,'Sales Pacing'!$A$23:$E$36,2)),"Too early") -> 500 | R14: 10596 | S14: 58000 | T14: =IF(R14>0,R14/S14,"") -> 0.18268966 | U14: =IF($Q14="Too early",Q14,Q14*AB14/S14) -> 0.60896552 | Y14: =IF(W14>0,W14/X14,"") | Z14: 1590 | AA14: =I14/Z14 -> 0.094339623 | AB14: =L14/I14 -> 70.64 | AC14: 6 | AD14: 40 | AE14: 46 | AF14: 9094 | AG14: =L14-AF14 -> 1502
A15: 6 | B15: =A15-$G$4 -> 6 | C15: 45936 | D15: 26 CS01 Appalachian Spring | G15: 45940.833 | H15: Classical | I15: =P15+V15 -> 662 | J15: =IF(Q15="Too early",Q15,Q15+V15) -> 983.74074 | K15: =IF(J15="Too early",J15,J15/Z15) -> 0.6864904 | L15: =R15+W15 -> 43762.3 | M15: 100000 | N15: =L15/M15 -> 0.437623 | O15: =IF($J15="Too early",J15,J15*AB15/M15) -> 0.65031356 | P15: 119 | Q15: =IF(B15<7,(P15/VLOOKUP(B15,'Sales Pacing'!$A$23:$E$36,2)),"Too early") -> 440.74074 | R15: 7327 | S15: 16666 | T15: =IF(R15>0,R15/S15,"") -> 0.43963759 | U15: =IF($Q15="Too early",Q15,Q15*AB15/S15) -> 1.7482115 | V15: 543 | W15: 36435.3 | X15: 33333 | Y15: =IF(W15>0,W15/X15,"") -> 1.0930699 | Z15: 1433 | AA15: =I15/Z15 -> 0.4619679 | AB15: =L15/I15 -> 66.106193 | AC15: 7 | AD15: 323 | AE15: 330 | AF15: 43678.3 | AG15: =L15-AF15 -> 84
A16: 6 | B16: =A16-$G$4 -> 6 | C16: 45936 | D16: 26 CS01 Appalachian Spring | G16: 45941.833 | H16: Classical | I16: =P16+V16 -> 724 | J16: =IF(Q16="Too early",Q16,Q16+V16) -> 1110.6296 | K16: =IF(J16="Too early",J16,J16/Z16) -> 0.77503812 | L16: =R16+W16 -> 48541.1 | M16: 100000 | N16: =L16/M16 -> 0.485411 | O16: =IF($J16="Too early",J16,J16*AB16/M16) -> 0.74462961 | P16: 143 | Q16: =IF(B16<7,(P16/VLOOKUP(B16,'Sales Pacing'!$A$23:$E$36,2)),"Too early") -> 529.62963 | R16: 8845 | S16: 16666 | T16: =IF(R16>0,R16/S16,"") -> 0.53072123 | U16: =IF($Q16="Too early",Q16,Q16*AB16/S16) -> 2.1306492 | V16: 581 | W16: 39696.1 | X16: 33333 | Y16: =IF(W16>0,W16/X16,"") -> 1.1908949 | Z16: 1433 | AA16: =I16/Z16 -> 0.50523378 | AB16: =L16/I16 -> 67.045718 | AC16: 411 | AD16: 342 | AE16: 353 | AF16: 47426.6 | AG16: =L16-AF16 -> 1114.5
A17: 6 | B17: =A17-$G$4 -> 6 | C17: 45936 | D17: 26 CS01 Appalachian Spring | G17: 45942.583 | H17: Classical | I17: =P17+V17 -> 791 | J17: =IF(Q17="Too early",Q17,Q17+V17) -> 1272.2593 | K17: =IF(J17="Too early",J17,J17/Z17) -> 0.88782921 | L17: =R17+W17 -> 51198.6 | M17: 100000 | N17: =L17/M17 -> 0.511986 | O17: =IF($J17="Too early",J17,J17*AB17/M17) -> 0.8234879 | P17: 178 | Q17: =IF(B17<7,(P17/VLOOKUP(B17,'Sales Pacing'!$A$23:$E$36,2)),"Too early") -> 659.25926 | R17: 11452 | S17: 16666 | T17: =IF(R17>0,R17/S17,"") -> 0.68714749 | U17: =IF($Q17="Too early",Q17,Q17*AB17/S17) -> 2.560392 | V17: 613 | W17: 39746.6 | X17: 33334 | Y17: =IF(W17>0,W17/X17,"") -> 1.1923742 | Z17: 1433 | AA17: =I17/Z17 -> 0.55198883 | AB17: =L17/I17 -> 64.726422 | AC17: 8 | AD17: 402 | AE17: 410 | AF17: 49731.6 | AG17: =L17-AF17 -> 1467
A18: 7 | B18: =A18-$G$4 -> 7 | C18: 45943 | D18: 26 Top Gun: Maverick in Concert | G18: 45947.792 | H18: Specials/Film | I18: =P18+V18 -> 546 | J18: =IF(Q18="Too early",Q18,Q18+V18) -> Too early | K18: =IF(J18="Too early",J18,J18/Z18) -> Too early | L18: =R18+W18 -> 41731.5 | M18: =S18+X18 -> 103497 | N18: =L18/M18 -> 0.40321459 | O18: =IF($J18="Too early",J18,J18*AB18/M18) -> Too early | P18: 546 | Q18: =IF(B18<7,(P18/VLOOKUP(B18,'Sales Pacing'!$A$23:$E$36,2)),"Too early") -> Too early | R18: 41731.5 | S18: 103497 | T18: =IF(R18>0,R18/S18,"") -> 0.40321459 | U18: =IF($Q18="Too early",Q18,Q18*AB18/S18) -> Too early | Y18: =IF(W18>0,W18/X18,"") | Z18: 1302 | AA18: =I18/Z19 -> 0.41935484 | AB18: =L18/I18 -> 76.431319 | AF18: 38186 | AG18: =L18-AF18 -> 3545.5
A19: 7 | B19: =A19-$G$4 -> 7 | C19: 45943 | D19: 26 Top Gun: Maverick in Concert | G19: 45948.792 | H19: Specials/Film | I19: =P19+V19 -> 661 | J19: =IF(Q19="Too early",Q19,Q19+V19) -> Too early | K19: =IF(J19="Too early",J19,J19/Z19) -> Too early | L19: =R19+W19 -> 50068 | M19: =S19+X19 -> 103497 | N19: =L19/M19 -> 0.48376281 | O19: =IF($J19="Too early",J19,J19*AB19/M19) -> Too early | P19: 661 | Q19: =IF(B19<7,(P19/VLOOKUP(B19,'Sales Pacing'!$A$23:$E$36,2)),"Too early") -> Too early | R19: 50068 | S19: 103497 | T19: =IF(R19>0,R19/S19,"") -> 0.48376281 | U19: =IF($Q19="Too early",Q19,Q19*AB19/S19) -> Too early | Y19: =IF(W19>0,W19/X19,"") | Z19: 1302 | AA19: =I19/Z19 -> 0.50768049 | AB19: =L19/I19 -> 75.74584 | AF19: 47838 | AG19: =L19-AF19 -> 2230
A20: 7 | B20: =A20-$G$4 -> 7 | C20: 45943 | D20: 26 Top Gun: Maverick in Concert | G20: 45949.583 | H20: Specials/Film | I20: =P20+V20 -> 473 | J20: =IF(Q20="Too early",Q20,Q20+V20) -> Too early | K20: =IF(J20="Too early",J20,J20/Z20) -> Too early | L20: =R20+W20 -> 36255 | M20: =S20+X20 -> 103496 | N20: =L20/M20 -> 0.35030339 | O20: =IF($J20="Too early",J20,J20*AB20/M20) -> Too early | P20: 473 | Q20: =IF(B20<7,(P20/VLOOKUP(B20,'Sales Pacing'!$A$23:$E$36,2)),"Too early") -> Too early | R20: 36255 | S20: 103496 | T20: =IF(R20>0,R20/S20,"") -> 0.35030339 | U20: =IF($Q20="Too early",Q20,Q20*AB20/S20) -> Too early | Y20: =IF(W20>0,W20/X20,"") | Z20: 1302 | AA20: =I20/Z20 -> 0.36328725 | AB20: =L20/I20 -> 76.649049 | AF20: 34131 | AG20: =L20-AF20 -> 2124
A21: 8 | B21: =A21-$G$4 -> 8 | C21: 45950 | D21: 26 The Lodger | G21: 45952.792 | H21: Specials/Film | I21: =P21+V21 -> 187 | J21: =IF(Q21="Too early",Q21,Q21+V21) -> Too early | K21: =IF(J21="Too early",J21,J21/Z21) -> Too early | L21: =R21+W21 -> 9513 | M21: =S21+X21 -> 50000 | N21: =L21/M21 -> 0.19026 | O21: =IF($J21="Too early",J21,J21*AB21/M21) -> Too early | P21: 187 | Q21: =IF(B21<7,(P21/VLOOKUP(B21,'Sales Pacing'!$A$23:$E$36,2)),"Too early") -> Too early | R21: 9513 | S21: 50000 | T21: =IF(R21>0,R21/S21,"") -> 0.19026 | U21: =IF($Q21="Too early",Q21,Q21*AB21/S21) -> Too early | Y21: =IF(W21>0,W21/X21,"") | Z21: 1302 | AA21: =I21/Z21 -> 0.14362519 | AB21: =L21/I21 -> 50.871658 | AF21: 9284 | AG21: =L21-AF21 -> 229
A22: 8 | B22: =A22-$G$4 -> 8 | C22: 45950 | D22: 26 PS2 Night of Symphonic 90s | G22: 45954.833 | H22: Pops | I22: =P22+V22 -> 783 | J22: =IF(Q22="Too early",Q22,Q22+V22) -> Too early | K22: =IF(J22="Too early",J22,J22/Z22) -> Too early | L22: =R22+W22 -> 55866.3 | M22: =S22+X22 -> 92333 | N22: =L22/M22 -> 0.60505236 | O22: =IF($J22="Too early",J22,J22*AB22/M22) -> Too early | P22: 70 | Q22: =IF(B22<7,(P22/VLOOKUP(B22,'Sales Pacing'!$A$23:$E$36,2)),"Too early") -> Too early | R22: 4060 | S22: 53333 | T22: =IF(R22>0,R22/S22,"") -> 0.076125476 | U22: =IF($Q22="Too early",Q22,Q22*AB22/S22) -> Too early | V22: 713 | W22: 51806.3 | X22: 39000 | Y22: =IF(W22>0,W22/X22,"") -> 1.3283667 | Z22: 1590 | AA22: =I22/Z22 -> 0.49245283 | AB22: =L22/I22 -> 71.349042 | AF22: 55899.1 | AG22: =L22-AF22 -> -32.8
A23: 8 | B23: =A23-$G$4 -> 8 | C23: 45950 | D23: 26 PS2 Night of Symphonic 90s | G23: 45955.833 | H23: Pops | I23: =P23+V23 -> 703 | J23: =IF(Q23="Too early",Q23,Q23+V23) -> Too early | K23: =IF(J23="Too early",J23,J23/Z23) -> Too early | L23: =R23+W23 -> 50141.3 | M23: =S23+X23 -> 92333 | N23: =L23/M23 -> 0.54304853 | O23: =IF($J23="Too early",J23,J23*AB23/M23) -> Too early | P23: 66 | Q23: =IF(B23<7,(P23/VLOOKUP(B23,'Sales Pacing'!$A$23:$E$36,2)),"Too early") -> Too early | R23: 3760 | S23: 53333 | T23: =IF(R23>0,R23/S23,"") -> 0.070500441 | U23: =IF($Q23="Too early",Q23,Q23*AB23/S23) -> Too early | V23: 637 | W23: 46381.3 | X23: 39000 | Y23: =IF(W23>0,W23/X23,"") -> 1.1892641 | Z23: 1590 | AA23: =I23/Z23 -> 0.44213836 | AB23: =L23/I23 -> 71.324751 | AF23: 50410.5 | AG23: =L23-AF23 -> -269.2
A24: 8 | B24: =A24-$G$4 -> 8 | C24: 45950 | D24: 26 PS2 Night of Symphonic 90s | G24: 45956.583 | H24: Pops | I24: =P24+V24 -> 450 | J24: =IF(Q24="Too early",Q24,Q24+V24) -> Too early | K24: =IF(J24="Too early",J24,J24/Z24) -> Too early | L24: =R24+W24 -> 33121.5 | M24: =S24+X24 -> 92333 | N24: =L24/M24 -> 0.3587179 | O24: =IF($J24="Too early",J24,J24*AB24/M24) -> Too early | P24: 68 | Q24: =IF(B24<7,(P24/VLOOKUP(B24,'Sales Pacing'!$A$23:$E$36,2)),"Too early") -> Too early | R24: 7092 | S24: 53333 | T24: =IF(R24>0,R24/S24,"") -> 0.13297583 | U24: =IF($Q24="Too early",Q24,Q24*AB24/S24) -> Too early | V24: 382 | W24: 26029.5 | X24: 39000 | Y24: =IF(W24>0,W24/X24,"") -> 0.66742308 | Z24: 1590 | AA24: =I24/Z24 -> 0.28301887 | AB24: =L24/I24 -> 73.603333 | AF24: 32829.5 | AG24: =L24-AF24 -> 292
A25: 9 | B25: =A25-$G$4 -> 9 | C25: 45957 | D25: 26 On-Stage 1 | G25: 45959.833 | H25: On Stage | I25: =P25+V25 -> 23 | J25: =IF(Q25="Too early",Q25,Q25+V25) -> Too early | K25: =IF(J25="Too early",J25,J25/Z25) -> Too early | L25: =R25+W25 -> 2520 | M25: 11200 | N25: =L25/M25 -> 0.225 | O25: =IF($J25="Too early",J25,J25*AB25/M25) -> Too early | P25: 23 | Q25: =IF(B25<7,(P25/VLOOKUP(B25,'Sales Pacing'!$A$23:$E$36,2)),"Too early") -> Too early | R25: 2520 | S25: 11200 | T25: =IF(R25>0,R25/S25,"") -> 0.225 | U25: =IF($Q25="Too early",Q25,Q25*AB25/S25) -> Too early | Y25: =IF(W25>0,W25/X25,"") | Z25: 100 | AA25: =I25/Z25 -> 0.23 | AB25: =L25/I25 -> 109.56522 | AF25: 2520 | AG25: =L25-AF25 -> 0
A26: 9 | B26: =A26-$G$4 -> 9 | C26: 45957 | D26: 26 CS02 Rachmaninoff Cele Pt 1 | G26: 45961.833 | H26: Classical | I26: =P26+V26 -> 460 | J26: =IF(Q26="Too early",Q26,Q26+V26) -> Too early | K26: =IF(J26="Too early",J26,J26/Z26) -> Too early | L26: =R26+W26 -> 30054 | M26: =S26+X26 -> 52000 | N26: =L26/M26 -> 0.57796154 | O26: =IF($J26="Too early",J26,J26*AB26/M26) -> Too early | P26: 102 | Q26: =IF(B26<7,(P26/VLOOKUP(B26,'Sales Pacing'!$A$23:$E$36,2)),"Too early") -> Too early | R26: 5125 | S26: 22000 | T26: =IF(R26>0,R26/S26,"") -> 0.23295455 | U26: =IF($Q26="Too early",Q26,Q26*AB26/S26) -> Too early | V26: 358 | W26: 24929 | X26: 30000 | Y26: =IF(W26>0,W26/X26,"") -> 0.83096667 | Z26: 1433 | AA26: =I26/Z26 -> 0.32100488 | AB26: =L26/I26 -> 65.334783 | AF26: 29912 | AG26: =L26-AF26 -> 142
A27: 9 | B27: =A27-$G$4 -> 9 | C27: 45957 | D27: 26 CS02 Rachmaninoff Cele Pt 1 | G27: 45962.833 | H27: Classical | I27: =P27+V27 -> 799 | J27: =IF(Q27="Too early",Q27,Q27+V27) -> Too early | K27: =IF(J27="Too early",J27,J27/Z27) -> Too early | L27: =R27+W27 -> 52200 | M27: =S27+X27 -> 86500 | N27: =L27/M27 -> 0.60346821 | O27: =IF($J27="Too early",J27,J27*AB27/M27) -> Too early | P27: 229 | Q27: =IF(B27<7,(P27/VLOOKUP(B27,'Sales Pacing'!$A$23:$E$36,2)),"Too early") -> Too early | R27: 14935 | S27: 31500 | T27: =IF(R27>0,R27/S27,"") -> 0.47412698 | U27: =IF($Q27="Too early",Q27,Q27*AB27/S27) -> Too early | V27: 570 | W27: 37265 | X27: 55000 | Y27: =IF(W27>0,W27/X27,"") -> 0.67754545 | Z27: 1433 | AA27: =I27/Z27 -> 0.55757153 | AB27: =L27/I27 -> 65.331665 | AF27: 51076.8 | AG27: =L27-AF27 -> 1123.2
A28: 9 | B28: =A28-$G$4 -> 9 | C28: 45957 | D28: 26 CS02 Rachmaninoff Cele Pt 1 | G28: 45963.583 | H28: Classical | I28: =P28+V28 -> 734 | J28: =IF(Q28="Too early",Q28,Q28+V28) -> Too early | K28: =IF(J28="Too early",J28,J28/Z28) -> Too early | L28: =R28+W28 -> 46474.1 | M28: =S28+X28 -> 86500 | N28: =L28/M28 -> 0.53727283 | O28: =IF($J28="Too early",J28,J28*AB28/M28) -> Too early | P28: 185 | Q28: =IF(B28<7,(P28/VLOOKUP(B28,'Sales Pacing'!$A$23:$E$36,2)),"Too early") -> Too early | R28: 10688 | S28: 31500 | T28: =IF(R28>0,R28/S28,"") -> 0.33930159 | U28: =IF($Q28="Too early",Q28,Q28*AB28/S28) -> Too early | V28: 549 | W28: 35786.1 | X28: 55000 | Y28: =IF(W28>0,W28/X28,"") -> 0.65065636 | Z28: 1433 | AA28: =I28/Z28 -> 0.51221214 | AB28: =L28/I28 -> 63.316213 | AF28: 44684.7 | AG28: =L28-AF28 -> 1789.4
A29: 10 | B29: =A29-$G$4 -> 10 | C29: 45964 | D29: 26 FS2 Carnival of the Animals | G29: 45970.583 | H29: Family | I29: =P29+V29 -> 433 | J29: =IF(Q29="Too early",Q29,Q29+V29) -> Too early | K29: =IF(J29="Too early",J29,J29/Z29) -> Too early | L29: =R29+W29 -> 11089 | M29: =S29+X29 -> 19500 | N29: =L29/M29 -> 0.56866667 | O29: =IF($J29="Too early",J29,J29*AB29/M29) -> Too early | P29: 137 | Q29: =IF(B29<7,(P29/VLOOKUP(B29,'Sales Pacing'!$A$23:$E$36,2)),"Too early") -> Too early | R29: 4543 | S29: 10000 | T29: =IF(R29>0,R29/S29,"") -> 0.4543 | U29: =IF($Q29="Too early",Q29,Q29*AB29/S29) -> Too early | V29: 296 | W29: 6546 | X29: 9500 | Y29: =IF(W29>0,W29/X29,"") -> 0.68905263 | Z29: 1300 | AA29: =I29/Z29 -> 0.33307692 | AB29: =L29/I29 -> 25.6097 | AF29: 9445 | AG29: =L29-AF29 -> 1644
A30: 11 | B30: =A30-$G$4 -> 11 | C30: 45971 | D30: OPEN | I30: =P30+V30 -> 0 | J30: =IF(Q30="Too early",Q30,Q30+V30) -> Too early | L30: =R30+W30 -> 0 | M30: =S30+X30 -> 0 | N30: =L30/M30 -> #DIV/0! | Q30: =IF(B30<7,(P30/VLOOKUP(B30,'Sales Pacing'!$A$23:$E$36,2)),"Too early") -> Too early | T30: =IF(R30>0,R30/S30,"") | Y30: N/A | AA30: =I30/Z30 -> #DIV/0! | AB30: =L30/I30 -> #DIV/0! | AF30: 0
A31: 12 | B31: =A31-$G$4 -> 12 | C31: 45978 | D31: 26 CS03 Matthias and Mahler 7 | G31: 45982.833 | H31: Classical | I31: =P31+V31 -> 424 | J31: =IF(Q31="Too early",Q31,Q31+V31) -> Too early | K31: =IF(J31="Too early",J31,J31/Z31) -> Too early | L31: =R31+W31 -> 28545 | M31: =S31+X31 -> 40000 | N31: =L31/M31 -> 0.713625 | O31: =IF($J31="Too early",J31,J31*AB31/M31) -> Too early | P31: 57 | Q31: =IF(B31<7,(P31/VLOOKUP(B31,'Sales Pacing'!$A$23:$E$36,2)),"Too early") -> Too early | R31: 2943 | S31: 15000 | T31: =IF(R31>0,R31/S31,"") -> 0.1962 | U31: =IF($Q31="Too early",Q31,Q31*AB31/S31) -> Too early | V31: 367 | W31: 25602 | X31: 25000 | Y31: =IF(W31>0,W31/X31,"") -> 1.02408 | Z31: 1590 | AA31: =I31/Z31 -> 0.26666667 | AB31: =L31/I31 -> 67.323113 | AF31: 28545 | AG31: =L31-AF31 -> 0
A32: 12 | B32: =A32-$G$4 -> 12 | C32: 45978 | D32: 26 CS03 Matthias and Mahler 7 | G32: 45983.833 | H32: Classical | I32: =P32+V32 -> 651 | J32: =IF(Q32="Too early",Q32,Q32+V32) -> Too early | K32: =IF(J32="Too early",J32,J32/Z32) -> Too early | L32: =R32+W32 -> 44302.9 | M32: =S32+X32 -> 66500 | N32: =L32/M32 -> 0.66620902 | O32: =IF($J32="Too early",J32,J32*AB32/M32) -> Too early | P32: 75 | Q32: =IF(B32<7,(P32/VLOOKUP(B32,'Sales Pacing'!$A$23:$E$36,2)),"Too early") -> Too early | R32: 4681 | S32: 11500 | T32: =IF(R32>0,R32/S32,"") -> 0.40704348 | U32: =IF($Q32="Too early",Q32,Q32*AB32/S32) -> Too early | V32: 576 | W32: 39621.9 | X32: 55000 | Y32: =IF(W32>0,W32/X32,"") -> 0.72039818 | Z32: 1590 | AA32: =I32/Z32 -> 0.40943396 | AB32: =L32/I32 -> 68.05361 | AF32: 44221.4 | AG32: =L32-AF32 -> 81.5
A33: 12 | B33: =A33-$G$4 -> 12 | C33: 45978 | D33: 26 CS03 Matthias and Mahler 7 | G33: 45984.583 | H33: Classical | I33: =P33+V33 -> 705 | J33: =IF(Q33="Too early",Q33,Q33+V33) -> Too early | K33: =IF(J33="Too early",J33,J33/Z33) -> Too early | L33: =R33+W33 -> 45933.2 | M33: =S33+X33 -> 66500 | N33: =L33/M33 -> 0.69072481 | O33: =IF($J33="Too early",J33,J33*AB33/M33) -> Too early | P33: 84 | Q33: =IF(B33<7,(P33/VLOOKUP(B33,'Sales Pacing'!$A$23:$E$36,2)),"Too early") -> Too early | R33: 5769 | S33: 11500 | T33: =IF(R33>0,R33/S33,"") -> 0.50165217 | U33: =IF($Q33="Too early",Q33,Q33*AB33/S33) -> Too early | V33: 621 | W33: 40164.2 | X33: 55000 | Y33: =IF(W33>0,W33/X33,"") -> 0.73025818 | Z33: 1590 | AA33: =I33/Z33 -> 0.44339623 | AB33: =L33/I33 -> 65.153475 | AF33: 45373.2 | AG33: =L33-AF33 -> 560
A34: 13 | B34: =A34-$G$4 -> 13 | C34: 45985 | D34: 26 Elf™ in Concert | G34: 45989.792 | H34: Specials/Film | I34: =P34+V34 -> 272 | J34: =IF(Q34="Too early",Q34,Q34+V34) -> Too early | K34: =IF(J34="Too early",J34,J34/Z34) -> Too early | L34: =R34+W34 -> 18219 | M34: =S34+X34 -> 107500 | N34: =L34/M34 -> 0.16947907 | O34: =IF($J34="Too early",J34,J34*AB34/M34) -> Too early | P34: 272 | Q34: =IF(B34<7,(P34/VLOOKUP(B34,'Sales Pacing'!$A$23:$E$36,2)),"Too early") -> Too early | R34: 18219 | S34: 107500 | T34: =IF(R34>0,R34/S34,"") -> 0.16947907 | U34: =IF($Q34="Too early",Q34,Q34*AB34/S34) -> Too early | Y34: =IF(W34>0,W34/X34,"") | Z34: 1302 | AA34: =I34/Z34 -> 0.20890937 | AB34: =L34/I34 -> 66.981618 | AF34: 18219 | AG34: =L34-AF34 -> 0
A35: 13 | B35: =A35-$G$4 -> 13 | C35: 45985 | D35: 26 Elf™ in Concert | G35: 45990.542 | H35: Specials/Film | I35: =P35+V35 -> 250 | J35: =IF(Q35="Too early",Q35,Q35+V35) -> Too early | K35: =IF(J35="Too early",J35,J35/Z35) -> Too early | L35: =R35+W35 -> 16760 | M35: =S35+X35 -> 107500 | N35: =L35/M35 -> 0.15590698 | O35: =IF($J35="Too early",J35,J35*AB35/M35) -> Too early | P35: 250 | Q35: =IF(B35<7,(P35/VLOOKUP(B35,'Sales Pacing'!$A$23:$E$36,2)),"Too early") -> Too early | R35: 16760 | S35: 107500 | T35: =IF(R35>0,R35/S35,"") -> 0.15590698 | U35: =IF($Q35="Too early",Q35,Q35*AB35/S35) -> Too early | Y35: =IF(W35>0,W35/X35,"") | Z35: 1302 | AA35: =I35/Z35 -> 0.19201229 | AB35: =L35/I35 -> 67.04 | AF35: 15032 | AG35: =L35-AF35 -> 1728
A36: 13 | B36: =A36-$G$4 -> 13 | C36: 45985 | D36: 26 Elf™ in Concert | G36: 45990.792 | H36: Specials/Film | I36: =P36+V36 -> 242 | J36: =IF(Q36="Too early",Q36,Q36+V36) -> Too early | K36: =IF(J36="Too early",J36,J36/Z36) -> Too early | L36: =R36+W36 -> 15945 | M36: =S36+X36 -> 107500 | N36: =L36/M36 -> 0.14832558 | O36: =IF($J36="Too early",J36,J36*AB36/M36) -> Too early | P36: 242 | Q36: =IF(B36<7,(P36/VLOOKUP(B36,'Sales Pacing'!$A$23:$E$36,2)),"Too early") -> Too early | R36: 15945 | S36: 107500 | T36: =IF(R36>0,R36/S36,"") -> 0.14832558 | U36: =IF($Q36="Too early",Q36,Q36*AB36/S36) -> Too early | Y36: =IF(W36>0,W36/X36,"") | Z36: 1302 | AA36: =I36/Z36 -> 0.1858679 | AB36: =L36/I36 -> 65.88843 | AF36: 14394 | AG36: =L36-AF36 -> 1551
A37: 13 | B37: =A37-$G$4 -> 13 | C37: 45985 | D37: 26 Elf™ in Concert | G37: 45991.583 | H37: Specials/Film | I37: =P37+V37 -> 408 | J37: =IF(Q37="Too early",Q37,Q37+V37) -> Too early | K37: =IF(J37="Too early",J37,J37/Z37) -> Too early | L37: =R37+W37 -> 29095 | M37: =S37+X37 -> 107500 | N37: =L37/M37 -> 0.27065116 | O37: =IF($J37="Too early",J37,J37*AB37/M37) -> Too early | P37: 408 | Q37: =IF(B37<7,(P37/VLOOKUP(B37,'Sales Pacing'!$A$23:$E$36,2)),"Too early") -> Too early | R37: 29095 | S37: 107500 | T37: =IF(R37>0,R37/S37,"") -> 0.27065116 | U37: =IF($Q37="Too early",Q37,Q37*AB37/S37) -> Too early | Y37: =IF(W37>0,W37/X37,"") | Z37: 1302 | AA37: =I37/Z37 -> 0.31336406 | AB37: =L37/I37 -> 71.311275 | AF37: 28457 | AG37: =L37-AF37 -> 638
A38: 14 | B38: =A38-$G$4 -> 14 | C38: 45992 | D38: 26 Handel's Messiah | G38: 45996.792 | H38: Holiday | I38: =P38+V38 -> 285 | J38: =IF(Q38="Too early",Q38,Q38+V38) -> Too early | K38: =IF(J38="Too early",J38,J38/Z38) -> Too early | L38: =R38+W38 -> 14705.5 | M38: =S38+X38 -> 78333 | N38: =L38/M38 -> 0.18773059 | O38: =IF($J38="Too early",J38,J38*AB38/M38) -> Too early | P38: 285 | Q38: =IF(B38<7,(P38/VLOOKUP(B38,'Sales Pacing'!$A$23:$E$36,2)),"Too early") -> Too early | R38: 14705.5 | S38: 78333 | T38: =IF(R38>0,R38/S38,"") -> 0.18773059 | U38: =IF($Q38="Too early",Q38,Q38*AB38/S38) -> Too early | Y38: =IF(W38>0,W38/X38,"") | Z38: 1433 | AA38: =I38/Z38 -> 0.19888346 | AB38: =L38/I38 -> 51.598246 | AF38: 13735 | AG38: =L38-AF38 -> 970.5
A39: 14 | B39: =A39-$G$4 -> 14 | C39: 45992 | D39: 26 Handel's Messiah | G39: 45997.792 | H39: Holiday | I39: =P39+V39 -> 312 | J39: =IF(Q39="Too early",Q39,Q39+V39) -> Too early | K39: =IF(J39="Too early",J39,J39/Z39) -> Too early | L39: =R39+W39 -> 18906.5 | M39: =S39+X39 -> 78334 | N39: =L39/M39 -> 0.24135752 | O39: =IF($J39="Too early",J39,J39*AB39/M39) -> Too early | P39: 312 | Q39: =IF(B39<7,(P39/VLOOKUP(B39,'Sales Pacing'!$A$23:$E$36,2)),"Too early") -> Too early | R39: 18906.5 | S39: 78334 | T39: =IF(R39>0,R39/S39,"") -> 0.24135752 | U39: =IF($Q39="Too early",Q39,Q39*AB39/S39) -> Too early | Y39: =IF(W39>0,W39/X39,"") | Z39: 1433 | AA39: =I39/Z39 -> 0.21772505 | AB39: =L39/I39 -> 60.597756 | AF39: 17711 | AG39: =L39-AF39 -> 1195.5
A40: 14 | B40: =A40-$G$4 -> 14 | C40: 45992 | D40: 26 Handel's Messiah | G40: 45998.583 | H40: Holiday | I40: =P40+V40 -> 304 | J40: =IF(Q40="Too early",Q40,Q40+V40) -> Too early | K40: =IF(J40="Too early",J40,J40/Z40) -> Too early | L40: =R40+W40 -> 16445 | M40: =S40+X40 -> 78333 | N40: =L40/M40 -> 0.20993706 | O40: =IF($J40="Too early",J40,J40*AB40/M40) -> Too early | P40: 304 | Q40: =IF(B40<7,(P40/VLOOKUP(B40,'Sales Pacing'!$A$23:$E$36,2)),"Too early") -> Too early | R40: 16445 | S40: 78333 | T40: =IF(R40>0,R40/S40,"") -> 0.20993706 | U40: =IF($Q40="Too early",Q40,Q40*AB40/S40) -> Too early | Y40: =IF(W40>0,W40/X40,"") | Z40: 1433 | AA40: =I40/Z40 -> 0.21214236 | AB40: =L40/I40 -> 54.095395 | AF40: 15287 | AG40: =L40-AF40 -> 1158
...

Sheet Subscriptions
B1: KANSAS CITY SYMPHONY | E1: Update all fields in Blue each week | J1: 100%+ of FY26 Goal
B2: 2025-26 Subscriptions | E2: We expect 50% of Total by Week 5 | J2: 90-99% of FY26 Goal | N2: Classical | S2: FY26 Budget - Classical
E3: We expect 90% of Total by Week 10/11 | J3: <90% of FY26 Goal | N3: 0.72 | O3: % of total subscriptions | S3: Units | T3: Revenue
O4: =O8/S8*S4 -> 190.76952 | P4: =P8/O8*O4 -> 67934.779 | Q4: =Q8/S8*S4 -> 2954.7347 | R4: =R8/Q8*Q4 -> 1567065.2 | S4: =T4/(T8/S8) -> 3145.5043 | T4: 1635000 | U4: Total
B5: FY26 Sales - Classical | O5: =O9/S9*S5 -> 8.6708651 | P5: =P9/O9*O5 -> 2639.1544 | Q5: =Q9/S9*S5 -> 267.83339 | R5: =R9/Q9*Q5 -> 147753.15 | S5: =T5/(T8/S8) -> 276.50425 | T5: =T4-T8 -> 143724 | U5: Difference vs FY25
C6: New | F6: Renewals | I6: Total | N6: FY25 Actuals - Classical
A7: Weeks On Sale | C7: Actual Units | D7: Proj | E7: Actual Rev | F7: Actual Units | G7: Proj | H7: Actual Rev | I7: Actual Units | J7: Proj | K7: Actual Rev | L7: W/W Change | O7: New Units | P7: New Revenue | Q7: Renewal Units | R7: Renewal Revenue | S7: Total Units | T7: Total Revenue | U7: Change
A8: Projected Total | I8: =I16 -> 2456 | K8: =K16 -> 1408430 | N8: Final | O8: =O21 -> 174 | P8: =P21 -> 61963 | Q8: =Q21 -> 2695 | R8: =R21 -> 1429313 | S8: =S21 -> 2869 | T8: =T21 -> 1491276
A9: 1 | B9: 45747 | C9: 30 | D9: =C9/'Sales Pacing'!B3 -> 713.33333 | E9: 16220 | F9: 898 | G9: =F9/'Sales Pacing'!E3 -> 3554.0218 | H9: 527973 | I9: =C9+F9 -> 928 | J9: =D9+G9 -> 4267.3552 | K9: =E9+H9 -> 544193 | N9: 45383 | O9: 27 | P9: 8218 | Q9: 834 | R9: 460085 | S9: =O9+Q9 -> 861 | T9: =P9+R9 -> 468303
A10: 2 | B10: 45754 | C10: 39 | D10: =C10/'Sales Pacing'!B4 -> 642 | E10: 21024 | F10: 1136 | G10: =F10/'Sales Pacing'!E4 -> 3593.8233 | H10: 652031 | I10: =C10+F10 -> 1175 | J10: =D10+G10 -> 4235.8233 | K10: =E10+H10 -> 673055 | L10: =IF(K10>0,K10-K9,0) -> 128862 | N10: =N9+7 -> 45390 | O10: 32 | P10: 12068 | Q10: 1194 | R10: 655718 | S10: =O10+Q10 -> 1226 | T10: =P10+R10 -> 667786 | U10: =IF(T10>0,T10-T9,0) -> 199483
A11: 3 | B11: 45761 | C11: 50 | D11: =C11/'Sales Pacing'!B5 -> 455.31915 | E11: 27424 | F11: 1387 | G11: =F11/'Sales Pacing'!E5 -> 3529.55 | H11: 817109 | I11: =C11+F11 -> 1437 | J11: =D11+G11 -> 3984.8691 | K11: =E11+H11 -> 844533 | L11: =IF(K11>0,K11-K10,0) -> 171478 | N11: =N10+7 -> 45397 | O11: 36 | P11: 13657 | Q11: 1434 | R11: 789833 | S11: =O11+Q11 -> 1470 | T11: =P11+R11 -> 803490 | U11: =IF(T11>0,T11-T10,0) -> 135704
A12: 4 | B12: 45768 | C12: 76 | D12: =C12/'Sales Pacing'!B6 -> 591.41818 | E12: 40984 | F12: 1739 | G12: =F12/'Sales Pacing'!E6 -> 3653.0333 | H12: 1005395 | I12: =C12+F12 -> 1815 | J12: =D12+G12 -> 4244.4515 | K12: =E12+H12 -> 1046379 | L12: =IF(K12>0,K12-K11,0) -> 201846 | N12: =N11+7 -> 45404 | O12: 45 | P12: 17584 | Q12: 1789 | R12: 976040 | S12: =O12+Q12 -> 1834 | T12: =P12+R12 -> 993624 | U12: =IF(T12>0,T12-T11,0) -> 190134
A13: 5 | B13: =B12+7 -> 45775 | C13: 112 | D13: =C13/'Sales Pacing'!B7 -> 684.8 | E13: 54163 | F13: 2160 | G13: =F13/'Sales Pacing'!E7 -> 3788.4885 | H13: 1232817 | I13: =C13+F13 -> 2272 | J13: =D13+G13 -> 4473.2885 | K13: =E13+H13 -> 1286980 | L13: =IF(K13>0,K13-K12,0) -> 240601 | N13: =N12+7 -> 45411 | O13: 47 | P13: 17987 | Q13: 2005 | R13: 1080463 | S13: =O13+Q13 -> 2052 | T13: =P13+R13 -> 1098450 | U13: =IF(T13>0,T13-T12,0) -> 104826
A14: 6 | B14: =B13+7 -> 45782 | C14: 121 | D14: =C14/'Sales Pacing'!B8 -> 533.89691 | E14: 58153 | F14: 2252 | G14: =F14/'Sales Pacing'!E8 -> 3121.3817 | H14: 1294295 | I14: =C14+F14 -> 2373 | J14: =D14+G14 -> 3655.2787 | K14: =E14+H14 -> 1352448 | L14: =IF(K14>0,K14-K13,0) -> 65468 | N14: =N13+7 -> 45418 | O14: 70 | P14: 26832 | Q14: 2362 | R14: 1271615 | S14: =O14+Q14 -> 2432 | T14: =P14+R14 -> 1298447 | U14: =IF(T14>0,T14-T13,0) -> 199997
A15: 7 | B15: =B14+7 -> 45789 | C15: 122 | D15: =C15/'Sales Pacing'!B9 -> 404.77519 | E15: 59763 | F15: 2293 | G15: =F15/'Sales Pacing'!E9 -> 2534.0926 | H15: 1322554 | I15: =C15+F15 -> 2415 | J15: =D15+G15 -> 2938.8678 | K15: =E15+H15 -> 1382317 | L15: =IF(K15>0,K15-K14,0) -> 29869 | N15: =N14+7 -> 45425 | O15: 76 | P15: 28802 | Q15: 2443 | R15: 1319275 | S15: =O15+Q15 -> 2519 | T15: =P15+R15 -> 1348077 | U15: =IF(T15>0,T15-T14,0) -> 49630
A16: 8 | B16: =B15+7 -> 45796 | C16: 134 | D16: =C16/'Sales Pacing'!B10 -> 382.34667 | E16: 63528 | F16: 2322 | G16: =F16/'Sales Pacing'!E10 -> 2473.787 | H16: 1344902 | I16: =C16+F16 -> 2456 | J16: =D16+G16 -> 2856.1337 | K16: =E16+H16 -> 1408430 | L16: =IF(K16>0,K16-K15,0) -> 26113 | N16: =N15+7 -> 45432 | O16: 85 | P16: 30752 | Q16: 2473 | R16: 1329297 | S16: =O16+Q16 -> 2558 | T16: =P16+R16 -> 1360049 | U16: =IF(T16>0,T16-T15,0) -> 11972
A17: 9 | B17: =B16+7 -> 45803 | C17: 146 | D17: =C17/'Sales Pacing'!B11 -> 369.75148 | E17: 67946 | F17: 2345 | G17: =F17/'Sales Pacing'!E11 -> 2468.3763 | H17: 1357272 | I17: =C17+F17 -> 2491 | J17: =D17+G17 -> 2838.1277 | K17: =E17+H17 -> 1425218 | L17: =IF(K17>0,K17-K16,0) -> 16788 | N17: =N16+7 -> 45439 | O17: 91 | P17: 32154 | Q17: 2513 | R17: 1344658 | S17: =O17+Q17 -> 2604 | T17: =P17+R17 -> 1376812 | U17: =IF(T17>0,T17-T16,0) -> 16763
A18: 10 | B18: =B17+7 -> 45810 | C18: 165 | D18: =C18/'Sales Pacing'!B12 -> 377.64706 | E18: 75744 | F18: 2369 | G18: =F18/'Sales Pacing'!E12 -> 2461.486 | H18: 1380368 | I18: =C18+F18 -> 2534 | J18: =D18+G18 -> 2839.1331 | K18: =E18+H18 -> 1456112 | L18: =IF(K18>0,K18-K17,0) -> 30894 | N18: =N17+7 -> 45446 | O18: 94 | P18: 32854 | Q18: 2608 | R18: 1391277 | S18: =O18+Q18 -> 2702 | T18: =P18+R18 -> 1424131 | U18: =IF(T18>0,T18-T17,0) -> 47319
A19: 11 | B19: =B18+7 -> 45817 | C19: 186 | D19: =C19/'Sales Pacing'!B13 -> 396.0597 | E19: 89633 | F19: 2384 | G19: =F19/'Sales Pacing'!E13 -> 2469.1125 | H19: 1390065 | I19: =C19+F19 -> 2570 | J19: =D19+G19 -> 2865.1722 | K19: =E19+H19 -> 1479698 | L19: =IF(K19>0,K19-K18,0) -> 23586 | N19: =N18+7 -> 45453 | O19: 95 | P19: 33169 | Q19: 2628 | R19: 1398365 | S19: =O19+Q19 -> 2723 | T19: =P19+R19 -> 1431534 | U19: =IF(T19>0,T19-T18,0) -> 7403
A20: 12 | B20: =B19+7 -> 45824 | C20: 205 | D20: =C20/'Sales Pacing'!B14 -> 404.3318 | E20: 94753 | F20: 2413 | G20: =F20/'Sales Pacing'!E14 -> 2491.1434 | H20: 1408181 | I20: =C20+F20 -> 2618 | J20: =D20+G20 -> 2895.4752 | K20: =E20+H20 -> 1502934 | L20: =IF(K20>0,K20-K19,0) -> 23236 | N20: =N19+7 -> 45460 | O20: 103 | P20: 35745 | Q20: 2655 | R20: 1411925 | S20: =O20+Q20 -> 2758 | T20: =P20+R20 -> 1447670 | U20: =IF(T20>0,T20-T19,0) -> 16136
A21: 13+ | B21: 45894 | C21: 271 | D21: =C21/'Sales Pacing'!B15 -> 271 | E21: 124427 | F21: 2424 | G21: =F21/'Sales Pacing'!E15 -> 2424 | H21: 1409643 | I21: =C21+F21 -> 2695 | J21: =D21+G21 -> 2695 | K21: =E21+H21 -> 1534070 | L21: =IF(K21>0,K21-K20,0) -> 31136 | N21: Rest of Season | O21: 174 | P21: 61963 | Q21: 2695 | R21: 1429313 | S21: =O21+Q21 -> 2869 | T21: =P21+R21 -> 1491276 | U21: =IF(T21>0,T21-T20,0) -> 43606
I22: vs. FY26 Goal | J22: =J21/$S$4 -> 0.85677837 | K22: =K21/$T$4 -> 0.93826911
B23: 25-26 Renewal as % of 24-25 Total
B24: =F15/S8 -> 0.79923318 | E24: 3rd Classical mailer drops 22nd/23rd of August | N24: Pops | S24: FY26 Budget - Pops
N25: 0.26 | O25: % of total subscriptions | S25: Units | T25: Revenue
O26: =O30/S30*S26 -> 240.07343 | P26: =P30/O30*O26 -> 69318.269 | Q26: =Q30/S30*S26 -> 1547.1399 | R26: =R30/Q30*Q26 -> 549681.73 | S26: =T26/(T30/S30) -> 1787.2133 | T26: 619000 | U26: Total
B27: FY26 Sales - Pops | O27: =O31/S31*S27 -> 3.2060949 | P27: =P31/O31*O27 -> 1038.7747 | Q27: =Q31/S31*S27 -> 109.00723 | R27: =R31/Q31*Q27 -> 44362.735 | S27: =T27/(T30/S30) -> 112.21332 | T27: =T26-T30 -> 38865 | U27: Difference vs FY25
C28: New | F28: Renewals | I28: Total | N28: FY25 Actuals - Pops
C29: Actual Units | D29: Proj | E29: Actual Rev | F29: Actual Units | G29: Proj | H29: Actual Rev | I29: Actual Units | J29: Proj | K29: Actual Rev | L29: W/W Change | O29: New Units | P29: New Revenue | Q29: Renewal Units | R29: Renewal Revenue | S29: Total Units | T29: Total Revenue | U29: Change
A30: Projected Total | I30: =I38 -> 1561 | K30: =K38 -> 591188 | N30: Final | O30: =O43 -> 225 | P30: =P43 -> 64966 | Q30: =Q43 -> 1450 | R30: =R43 -> 515169 | S30: =S43 -> 1675 | T30: =T43 -> 580135
A31: 1 | B31: 45747 | C31: 38 | D31: =C31/'Sales Pacing'!C3 -> 1048.1667 | E31: 13163 | F31: 636 | G31: =F31/'Sales Pacing'!F3 -> 5546.3927 | H31: 258782 | I31: =C31+F31 -> 674 | J31: =D31+G31 -> 6594.5593 | K31: =E31+H31 -> 271945 | N31: 45383 | O31: 2 | P31: 648 | Q31: 68 | R31: 27674 | S31: =O31+Q31 -> 70 | T31: =P31+R31 -> 28322
A32: 2 | B32: 45754 | C32: 44 | D32: =C32/'Sales Pacing'!C4 -> 606.83333 | E32: 14651 | F32: 785 | G32: =F32/'Sales Pacing'!F4 -> 3783.5789 | H32: 312531 | I32: =C32+F32 -> 829 | J32: =D32+G32 -> 4390.4122 | K32: =E32+H32 -> 327182 | L32: =IF(K32>0,K32-K31,0) -> 55237 | N32: =N31+7 -> 45390 | O32: 54 | P32: 17576 | Q32: 181 | R32: 68648 | S32: =O32+Q32 -> 235 | T32: =P32+R32 -> 86224 | U32: =IF(T32>0,T32-T31,0) -> 57902
A33: 3 | B33: 45761 | C33: 54 | D33: =C33/'Sales Pacing'!C5 -> 616.34483 | E33: 19061 | F33: 893 | G33: =F33/'Sales Pacing'!F5 -> 3135.2144 | H33: 353304 | I33: =C33+F33 -> 947 | J33: =D33+G33 -> 3751.5592 | K33: =E33+H33 -> 372365 | L33: =IF(K33>0,K33-K32,0) -> 45183 | N33: =N32+7 -> 45397 | O33: 66 | P33: 20302 | Q33: 283 | R33: 105425 | S33: =O33+Q33 -> 349 | T33: =P33+R33 -> 125727 | U33: =IF(T33>0,T33-T32,0) -> 39503
A34: 4 | B34: 45768 | C34: 60 | D34: =C34/'Sales Pacing'!C6 -> 484.39024 | E34: 20782 | F34: 1067 | G34: =F34/'Sales Pacing'!F6 -> 2921.075 | H34: 417996 | I34: =C34+F34 -> 1127 | J34: =D34+G34 -> 3405.4653 | K34: =E34+H34 -> 438778 | L34: =IF(K34>0,K34-K33,0) -> 66413 | N34: =N33+7 -> 45404 | O34: 86 | P34: 26557 | Q34: 389 | R34: 146108 | S34: =O34+Q34 -> 475 | T34: =P34+R34 -> 172665 | U34: =IF(T34>0,T34-T33,0) -> 46938
A35: 5 | B35: =B34+7 -> 45775 | C35: 118 | D35: =C35/'Sales Pacing'!C7 -> 566.05797 | E35: 38918 | F35: 1300 | G35: =F35/'Sales Pacing'!F7 -> 2887.9509 | H35: 502867 | I35: =C35+F35 -> 1418 | J35: =D35+G35 -> 3454.0088 | K35: =E35+H35 -> 541785 | L35: =IF(K35>0,K35-K34,0) -> 103007 | N35: =N34+7 -> 45411 | O35: 86 | P35: 26557 | Q35: 476 | R35: 178054 | S35: =O35+Q35 -> 562 | T35: =P35+R35 -> 204611 | U35: =IF(T35>0,T35-T34,0) -> 31946
A36: 6 | B36: =B35+7 -> 45782 | C36: 157 | D36: =C36/'Sales Pacing'!C8 -> 683.77632 | E36: 51765 | F36: 1358 | G36: =F36/'Sales Pacing'!F8 -> 2121.6398 | H36: 522161 | I36: =C36+F36 -> 1515 | J36: =D36+G36 -> 2805.4161 | K36: =E36+H36 -> 573926 | L36: =IF(K36>0,K36-K35,0) -> 32141 | N36: =N35+7 -> 45418 | O36: 98 | P36: 31472 | Q36: 806 | R36: 294720 | S36: =O36+Q36 -> 904 | T36: =P36+R36 -> 326192 | U36: =IF(T36>0,T36-T35,0) -> 121581
A37: 7 | B37: =B36+7 -> 45789 | C37: 165 | D37: =C37/'Sales Pacing'!C9 -> 593.6413 | E37: 54301 | F37: 1365 | G37: =F37/'Sales Pacing'!F9 -> 1717.375 | H37: 525805 | I37: =C37+F37 -> 1530 | J37: =D37+G37 -> 2311.0163 | K37: =E37+H37 -> 580106 | L37: =IF(K37>0,K37-K36,0) -> 6180 | N37: =N36+7 -> 45425 | O37: 113 | P37: 36672 | Q37: 1031 | R37: 372369 | S37: =O37+Q37 -> 1144 | T37: =P37+R37 -> 409041 | U37: =IF(T37>0,T37-T36,0) -> 82849
A38: 8 | B38: =B37+7 -> 45796 | C38: 199 | D38: =C38/'Sales Pacing'!C10 -> 639.50485 | E38: 65018 | F38: 1362 | G38: =F38/'Sales Pacing'!F10 -> 1532.8471 | H38: 526170 | I38: =C38+F38 -> 1561 | J38: =D38+G38 -> 2172.3519 | K38: =E38+H38 -> 591188 | L38: =IF(K38>0,K38-K37,0) -> 11082 | N38: =N37+7 -> 45432 | O38: 127 | P38: 40518 | Q38: 1267 | R38: 452816 | S38: =O38+Q38 -> 1394 | T38: =P38+R38 -> 493334 | U38: =IF(T38>0,T38-T37,0) -> 84293
A39: 9 | B39: =B38+7 -> 45803 | C39: 220 | D39: =C39/'Sales Pacing'!C11 -> 568.90625 | E39: 73218 | F39: 1368 | G39: =F39/'Sales Pacing'!F11 -> 1451.7935 | H39: 531352 | I39: =C39+F39 -> 1588 | J39: =D39+G39 -> 2020.6998 | K39: =E39+H39 -> 604570 | L39: =IF(K39>0,K39-K38,0) -> 13382 | N39: =N38+7 -> 45439 | O39: 160 | P39: 48485 | Q39: 1395 | R39: 497335 | S39: =O39+Q39 -> 1555 | T39: =P39+R39 -> 545820 | U39: =IF(T39>0,T39-T38,0) -> 52486
A40: 10 | B40: =B39+7 -> 45810 | C40: 239 | D40: =C40/'Sales Pacing'!C12 -> 557.10563 | E40: 80035 | F40: 1374 | G40: =F40/'Sales Pacing'!F12 -> 1439.2578 | H40: 536728 | I40: =C40+F40 -> 1613 | J40: =D40+G40 -> 1996.3634 | K40: =E40+H40 -> 616763 | L40: =IF(K40>0,K40-K39,0) -> 12193 | N40: =N39+7 -> 45446 | O40: 172 | P40: 51234 | Q40: 1411 | R40: 502695 | S40: =O40+Q40 -> 1583 | T40: =P40+R40 -> 553929 | U40: =IF(T40>0,T40-T39,0) -> 8109
...

Sheet Channels (Draft)
A1: MARKETING CHANNEL PERFORMANCE
B2: Owned Marketing Channels | H2: Paid Channels
A3: To start, let’s pull last 12 months of data. | B3: Phone | C3: Direct Mail | D3: Email | E3: Social | F3: In-hall | G3: SEO | H3: SEM | I3: Media | J3: Phone | K3: Total
B4: (Box Office) | E4: (FB, IG, X, other) | F4: (book, posters) | I4: (TV, radio, OOH) | J4: (Bennett)
A5: # Impressions: | D5: 13.7M
A6: calls made, e/mails delivered, etc.
A7: # Engagement: | D7: 4.7M
A8: calls answered, opens, etc.
A9: Engagement rate | D9: 34%
A10: # Actions (Success): | D10: 89k
A11: conversations, clicks, etc.
A12: Action rate | D12: 0.6%
A13: % of total Actions
A15: Channel cost ($, time)
A16: ROI: $/Action
A17: Attributed revenue ($) | J17: ~$220k
A18: ROI: $/channel cost
A20: SALES CHANNEL PERFORMANCE
A21: To start, let’s pull last 12 months of data. | B21: Phone | C21: Website | D21: KCPA | E21: Total
B22: (Box Office)
A23: # Traffic: | C23: 471,563
A24: calls received, visits
A25: % Traffic by Marketing Channel
A26: #, $ Conversions (Success): | C26: 4,547
A27: Conversion rate | C27: 0.94%
A28: % of total Conversions | D28: 15%?
A29: Total Sales Revenue | B29: ~$6,500k? | C29: $877k
A31: Channel cost ($, time)
A32: ROI: $/Conversion
A33: Attributed revenue ($)
A34: ROI: $/channel cost
A36: EXPERIENCE CHANNEL PERFORMANCE
B37: Total
A38: # total attendance
A39: % Repeat:
A40: % returning from prior season
A41: # Frequency:
A42: avg. attendance/customer
A44: Total Revenue, ROI?
A45: Avg. CSAT, NPS
...

Sheet Sales Pacing
B1: New Subs | E1: Renewal Subs
A2: # Weeks On Sale | B2: Classical | C2: Pops | E2: Classical | F2: Pops
A3: 1 | B3: 0.042056075 | C3: 0.036253776 | E3: 0.25267149 | F3: 0.11466913
A4: 2 | B4: 0.060747664 | C4: 0.072507553 | E4: 0.3160979 | F4: 0.20747552
A5: 3 | B5: 0.10981308 | C5: 0.087613293 | E5: 0.39296794 | F5: 0.28482901
A6: 4 | B6: 0.12850467 | C6: 0.12386707 | E6: 0.47604274 | F6: 0.36527648
A7: 5 | B7: 0.1635514 | C7: 0.20845921 | E7: 0.57014822 | F7: 0.45014616
A8: 6 | B8: 0.22663551 | C8: 0.22960725 | E8: 0.72147535 | F8: 0.64007095
A9: 7 | B9: 0.30140187 | C9: 0.27794562 | E9: 0.90486039 | F9: 0.79481765
A10: 8 | B10: 0.35046729 | C10: 0.31117825 | E10: 0.93864185 | F10: 0.88854264
A11: 9 | B11: 0.39485981 | C11: 0.38670695 | E11: 0.95001724 | F11: 0.94228277
A12: 10 | B12: 0.43691589 | C12: 0.42900302 | E12: 0.96242675 | F12: 0.95465872
A13: 11 | B13: 0.46962617 | C13: 0.48036254 | E13: 0.96552913 | F13: 0.96530297
A14: 12 | B14: 0.50700935 | C14: 0.57401813 | E14: 0.96863151 | F14: 0.97390663
A15: 13+ | B15: 1 | C15: 1 | E15: 1 | F15: 1
B21: Single Tickets
A22: # Weeks Until Performance | B22: Classical | C22: Pops | D22: Specials | E22: Other
A23: 0 | B23: 1 | C23: 1 | D23: 1 | E23: 1
A24: 1 | B24: 0.59 | C24: 0.59 | D24: 0.59 | E24: 0.59
A25: 2 | B25: 0.46 | C25: 0.46 | D25: 0.46 | E25: 0.46
A26: 3 | B26: 0.39 | C26: 0.39 | D26: 0.39 | E26: 0.39
A27: 4 | B27: 0.33 | C27: 0.33 | D27: 0.33 | E27: 0.33
A28: 5 | B28: 0.3 | C28: 0.3 | D28: 0.3 | E28: 0.3
A29: 6 | B29: 0.27 | C29: 0.27 | D29: 0.27 | E29: 0.27
A30: 7
A31: 8
A32: 9
A33: 10
A34: 11
A35: 12
A36: 13+
A38: Future Improvements:
A39: Extend data for single ticket sales beyond 6 weeks
A40: Differentiate single ticket sales by performance type
A41: Improve pacing data (always)

Sheet Summary (Draft)
B2: Overall Season | G2: # Tickets Sold | H2: Projected Tickets Sold | I2: Projected Occupancy (% +GYR) | J2: Total Revenue | K2: BUDGET | L2: Projected Revenue vs Budget (% +GYR)
B3: ALL CONCERTS | G3: ='Performances by Week'!I126 -> 0 | H3: ='Performances by Week'!J126 -> 0 | I3: ='Performances by Week'!K126 -> 0 | J3: ='Performances by Week'!L126 -> 0 | K3: ='Performances by Week'!M126 -> 6268640 | L3: ='Performances by Week'!O126
B5: Season Attendance By Ticket Type | G5: # Tickets Sold | H5: Projected Tickets Sold | J5: Total Revenue | K5: BUDGET | L5: Projected Revenue vs Budget (% +GYR)
B6: All Subscriptions | G6: ='Performances by Week'!V126 -> 0 | J6: ='Performances by Week'!W126 -> 0 | K6: ='Performances by Week'!X126 -> 2169893 | L6: ='Performances by Week'!Y126
B7: All Single Tickets | G7: ='Performances by Week'!P126 -> 0 | H7: ='Performances by Week'!Q126 -> 0 | J7: ='Performances by Week'!R126 -> 0 | K7: ='Performances by Week'!S126 -> 3973690 | L7: ='Performances by Week'!U126
B9: Concert Attendance By Performance Type | G9: # Tickets Sold | H9: Projected Tickets Sold | I9: Projected Occupancy (% +GYR) | J9: Total Revenue | K9: BUDGET | L9: Projected Revenue vs Budget (% +GYR)
B10: CLASSICAL TRADITIONAL TOTAL | G10: ='Performances by Week'!I119 -> 0 | H10: ='Performances by Week'!J119 -> 0 | I10: ='Performances by Week'!K119 -> 0 | J10: ='Performances by Week'!L119 -> 0 | K10: ='Performances by Week'!M119 -> 2139000 | L10: ='Performances by Week'!O119
B11: SYMPHONIC PIAZZA TOTAL | G11: ='Performances by Week'!I120 -> 0 | H11: ='Performances by Week'!J120 -> 0 | I11: ='Performances by Week'!K120 -> 0 | J11: ='Performances by Week'!L120 -> 0 | K11: ='Performances by Week'!M120 -> 363000 | L11: ='Performances by Week'!O120
B12: POPS TOTAL | G12: ='Performances by Week'!I121 -> 0 | H12: ='Performances by Week'!J121 -> 0 | I12: ='Performances by Week'!K121 -> 0 | J12: ='Performances by Week'!L121 -> 0 | K12: ='Performances by Week'!M121 -> 1457000 | L12: ='Performances by Week'!O121
B13: FAMILY SERIES TOTAL | G13: ='Performances by Week'!I122 -> 0 | H13: ='Performances by Week'!J122 -> 0 | I13: ='Performances by Week'!K122 -> 0 | J13: ='Performances by Week'!L122 -> 0 | K13: ='Performances by Week'!M122 -> 525950 | L13: ='Performances by Week'!O122
B14: FILM TOTAL | G14: ='Performances by Week'!I123 -> 0 | H14: ='Performances by Week'!J123 -> 0 | I14: ='Performances by Week'!K123 -> 0 | J14: ='Performances by Week'!L123 -> 0 | K14: ='Performances by Week'!M123 -> 1745490 | L14: ='Performances by Week'!O123
B15: ON STAGE CONCERTS TOTAL | G15: ='Performances by Week'!I124 -> 0 | H15: ='Performances by Week'!J124 -> 0 | I15: ='Performances by Week'!K124 -> 0 | J15: ='Performances by Week'!L124 -> 0 | K15: ='Performances by Week'!M124 -> 38200 | L15: ='Performances by Week'!O124
B16: OTHER CONCERT TOTAL | G16: ='Performances by Week'!I125 -> 0 | H16: ='Performances by Week'!J125 -> 0 | I16: ='Performances by Week'!K125 -> 0 | J16: ='Performances by Week'!L125 -> 0 | K16: ='Performances by Week'!M125 -> 0 | L16: ='Performances by Week'!O125

Sheet Social Reporting
A1: DATE | B1: Social Post | C1: Views | D1: Engagement
A2: 45891 | B2: Chicken Fried IG | C2: 1625 | D2: 11 interactions
A3: 45891 | B3: Chicken Fried FB | C3: 2570 | D3: 15 interactions, 6 link clicks
A4: 45890 | B4: Journey Reel IG | C4: 1005 | D4: 16 interactions
A5: 45890 | B5: Journey Reel FB | C5: 813 | D5: 12 interactions
A6: 45883 | B6: KC Blues Society Video IG | C6: 966 | D6: 32 interactions
A7: 45883 | B7: KC Blues Society Video FB | C7: 1895 | D7: 19 interactions, 61 link clicks
A8: 45881 | B8: CS1 Nora Video IG | C8: 3290 | D8: 42 interactions
A9: 45881 | B9: CS1 Nora Video FB | C9: 1785 | D9: 42 interactions
A10: 45876 | B10: Orchestra Games IG | C10: 2394 | D10: 54 interactions
A11: 45876 | B11: Orchestra Games FB | C11: 1879 | D11: 15 interactions, 2 link clicks
A12: 45876 | B12: Morgan Freeman interview reshare FB | C12: 2731 | D12: 52 interactions, 53 link clicks
A13: 45875 | B13: Nora Intro IG | C13: 3331 | D13: 65 interactions
... A16: 45874 | B16: Journey Graphic FB | C16: 4997 | D16: 28 interactions, 22 link clicks
B18: Meta Ads
A19: 7/30-8/13 | B19: Morgan Freeman video | C19: 88,119 impressions | D19: 3,269 link clicks
A20: Ends 8/22 | B20: Music of Journey | C20: 56,165 impressions | D20: 3,537 link clicks
A24: 45870 | B24: La Nuit Sombre video IG Reel | C24: 953 | D24: 46 interactions
A25: 45870 | B25: La Nuit Sombre video FB Reel | C25: 1105 | D25: 14 interactions
A26: 45860 | B26: La Nuit Sombre Price Increase FB | C26: 3465 | D26: 19 interactions, 9 link clicks
A27: 45860 | B27: La Nuit Sombre Price Increase IG | C27: 1537 | D27: 19 interactions, 11 link clicks
A28: 45865 | B28: Music is for Everyone FB Reel | C28: 563 | D28: 13 interactions
A29: 45865 | B29: Music is for Everyone IG Reel | C29: 1735 | D29: 36 interactions
A30: 45865 | B30: Music is for Everyone TikTok | C30: 256 | D30: 16 interactions
A31: 45853 | B31: Are you single? FB Reel | C31: 1641 | D31: 22 interactions
A32: 45853 | B32: Are you single? IG Reel | C32: 4321 | D32: 170 interactions
A33: 45853 | B33: Are you single? TikTok | C33: 1013 | D33: 45 interactions
A34: 45853 | B34: Are you single? YT | C34: 1115 | D34: 16 interactions
A35: 45854 | B35: Single Tickets Graphic FB | C35: 3157 | D35: 26 interactions
... A45: 45856 | B45: Music is for Everyone YT | C45: 32 | D45: 1 interaction
B47: Meta Ads
A48: 45832 | B48: Specials/Films ad | C48: 1k impressions | D48: 18 clicks
A49: 45838 | B49: Morgan Freeman video | C49: 22k impressions | D49: 1234 link clicks
A50: 45841 | B50: Holiday concerts ad | C50: 68k impressions | D50: 1011 link clicks

Sheet Email Reporting
A1: EMAILS SENT | B1: DELIVERIES | C1: OPENS | D1: CLICK RATE
A2: 8/20 Bi-weekly Merchandise Email | B2: 95473 | C2: 35,125 (37%) | D2: 754 (1%)
A3: 8/12 Music of Journey Promo | B3: 94241 | C3: 35,743 (37.9%) | D3: 577 0.6% | E3: https://conta.cc/4mdHLVC
A4: 8/6 Bi-weekly Merchandise Email | B4: 94322 | C4: 36,401 (38.6%) | D4: 937 (1%) | E4: https://conta.cc/3Hoy3k2
A5: 7/21 La Nuit Sombre Matthias Video | B5: 95893 | C5: 35,531 (37.1%) | D5: 491 (0.5%)
A6: 7/23 Morgan Freeman Promo | B6: 96012 | C6: 35,064 (36.5%) | D6: 769 (0.8%)
A7: 7/15 Single Ticket On Sale Announcement | B7: 95831 | C7: 35,285 (37.2%) | D7: 1,708 (2%)
A8: 7/8 Leslie Odom Jr. Promo | B8: 94927 | C8: 35, 660 (37.6%) | D8: 550 (0.6%)
A9: Tuesday 7/1 Holiday Presentations On Sale | B9: 95059 | C9: 35039 (36.9%) | D9: 822 (0.9%) | E9: Header: 64, Elf in Concert: 473, Handel's Messiah: 390, LOJ: 110, Christmas Festival: 144, Wonderful Life: 129
A10: Tuesday 6/25 Special Presentations On Sale | B10: 95219 | C10: 35,617 (37%) | D10: 1,469 (2%) | E10: Full lineup: 248, Morgan Freeman: 438, Chicken Fried: 456, Top Gun: 559, Lodger: 100, Indiana Jones: 204, Chris Thile: 134, Harry Potter: 139, Final Symphony: 74, Ben Rector: 108, On Stage George: 45, On Stage Leila: 53, On Stage Gil: 37, On Stage 38
A11: Tuesday 6/17 Mark Your Calendar | B11: 104371 | C11: 37,343 (39%) | D11: 1,999 (2%)
A12: Monday 6/9 Mobile Music Box June Concert | B12: 95,460 | C12: 36,052 (38%) | D12: 594 (1%)
A13: Wednesday 6/4 CS14 Student Rush Promo | B13: 174 | C13: 77 (44%) | D13: 0
A14: Wednesday 6/4 CS14 Student Rush Promo | B14: 174 | C14: 77 (44%) | D14: 0
A15: Wednesday 6/4 CS14 Student Pass Promo | B15: 80 | C15: 38 (47%) | D15: 1 | J15: AVERAGE OPEN RATE: | K15: 0.37
A16: Wednesday 6/4 CS14 BOGO Promo | B16: 4954 | C16: 2,165 (44%) | D16: 65 (1%)
A17: Wednesday 6/4 Four Larks Subscriber Early Access | B17: 2185 | C17: 1,452 (66.5%) | D17: 135 (6.2%) | J17: AVERAGE CLICK RATE: | K17: 0.02
A18: Friday 6/6 Four Lark Public On-Sale | B18: 96846 | C18: 35,136 (36%) | D18: 616 (0.6%)

Sheet Website Reporting
A1: Timeframe: August 11-18
A2: ECOMMERCE PURCHASES: 877 | B2: WEBSITE REVENUE: $74,429 | C2: # OF ITEMS
A3: Morgan Freeman | B3: 18052 | C3: 164
A4: Music of Journey | B4: 8322 | C4: 66
A5: Top Gun | B5: 7065 | C5: 86
A6: Leslie Odom Jr. | B6: 4084.5 | C6: 54
A7: Indiana Jones | B7: 3441 | C7: 38
A8: Elf in Concert | B8: 2892 | C8: 44
A9: Harry Potter | B9: 2521 | C9: 29
A10: It's a wonderful life | B10: 2454 | C10: 52
A12: Timeframe: July 20-July 28
A13: ECOMMERCE PURCHASES: 973 | B13: WEBSITE REVENUE: $67,220 | C13: # OF ITEMS
A14: Leslie Odom Jr. | B14: 17681 | C14: 161
A15: Morgan Freeman | B15: 7995 | C15: 64
A16: Top Gun | B16: 5293 | C16: 64
A17: 2025/26 COY Package | B17: 4084 | C17: 54
A18: It's a wonderful life | B18: 2684 | C18: 31
A19: Elf in Concert | B19: 2343 | C19: 26
A20: Christmas Festival | B20: 2341 | C20: 38
A21: La nuit sombre | B21: 2308 | C21: 49
A22: Harry Potter 2 | B22: 2030 | C22: 26
A23: Indiana Jones | B23: 2004 | C23: 26
A27: Timeframe: July 20-July 28
A28: ECOMMERCE PURCHASES: 1,718 | B28: WEBSITE REVENUE: $115,644 | C28: # OF ITEMS
A29: Morgan Freeman | B29: 27675 | C29: 215
A30: Top Gun | B30: 9650 | C30: 116
A31: It's a wonderful life | B31: 8677 | C31: 104
A32: Leslie Odom Jr. | B32: 9110 | C32: 84
A33: Elf in Concert | B33: 5110 | C33: 80
A34: 2025/26 COY Package | B34: 5435 | C34: 73
A35: Harry Potter 2 | B35: 5145 | C35: 61
A36: 2025/26 Sunday Masterworks | B36: 4200 | C36: 56
A37: Handel's Messiah | B37: 2970 | C37: 55
A43: Timeframe: July 14-July 20
A44: ECOMMERCE PURCHASES: 3,027 | B44: WEBSITE REVENUE: $188,688 | C44: # OF ITEMS
A45: Top Gun | B45: 19205 | C45: 234
A46: Morgan Freeman | B46: 16175 | C46: 130
A47: Leslie Odom Jr. | B47: 14107 | C47: 139
A48: Indiana Jones | B48: 12729 | C48: 186
A49: Billy Joel + Elton John | B49: 11391 | C49: 149
...
